Workbook
Name B_Lth: #REF!
Name B_Lth: #REF!
Name B_Lth: #REF!
Name B_Lth: #REF!
Name Brg_Posn: [1]Calculations!#REF!
Name Brg_Posn: [1]Calculations!#REF!
Name Brg_Posn: [1]Calculations!#REF!
Name Brg_Posn: [1]Calculations!#REF!
Name cargodiameter: 'DOC 5'!$D$16
Name cargodiametermm: 'DOC 5'!$D$17
Name cargoflowsec: 'DOC 5'!$D$9
Name Chamfer: '[1]PS Data'!$A$28:$B$31
Name DB_m: '[2]Engine Selection'!$C$159
Name DHP_HP: [2]Holtrop!$D$103
Name DHP_HP: [2]Power!$D$103
Name DHP_HP: [2]Power!$D$103
Name DHP_HP: [2]Power!$D$103
Name DHP_HP: [2]Power!$D$103
Name Ds: #REF!
Name Ds: #REF!
Name EnginePower: '[2]Engine Selection'!$D$36
Name Grooves: '[1]PS Data'!$E$21:$H$26
Name Key_Data: '[1]PS Data'!$A$3:$F$13
Name Keyway_Data: '[1]PS Data'!$D$35:$F$45
Name LINEB: #REF!
Name P_LD: '[1]Rdr Data'!$D$3
Name R_Brg_Posn: '[1]Rudder Stock'!$B$5
Name R_Ratio_ID: '[1]Rdr Data'!$C$10
Name R_Ratio_Multiplier: '[1]Rdr Data'!$A$7:$C$9
Name R_RF_Section_Qty: '[1]Rudder Stock'!$B$36
Name R_Section_Qty: '[1]Rdr Data'!$B$16
Name R_Section_Qty_Table: '[1]Rdr Data'!$A$13:$B$15
Name Ratio_Multiplier: '[1]PS Data'!$A$22:$D$25
Name RDs: '[1]Rudder Stock'!$B$4
Name Section_Data: '[1]PS Data'!$L$3:$O$13
Name Section_Dias: '[1]PS Data'!$K$3:$K$13
Name Section_Qty_Table: '[1]PS Data'!$L$20:$M$23
Name Section_Ratios: '[1]PS Data'!$L$2:$O$2
Name Select_R_Ratio: '[1]Rudder Stock'!$B$9
Name Select_Ratio: '[1]PS Data'!$I$15
Name SHP_kW: '[2]Engine and Power'!$C$170
Name SHP_kW: '[2]Engine Selection'!$C$170
Name SHP_kW: '[2]Engine Selection'!$C$170
Name SHP_kW: '[2]Engine Selection'!$C$170
Name SHP_kW: '[2]Engine Selection'!$C$170
Name speed: 'DOC 5'!$F$12
Name Step_Qty: '[1]PS Data'!$M$24
Name Tolerance: '[1]PS Data'!$A$34:$B$45
Name UandL_LD: '[1]Rdr Data'!$B$3:$B$5
Name Washways: '[1]PS Data'!$E$17:$G$20

Sheet GULD
A1: Data Kapal
A2: Data berdasarkan desain 1
A4: Nama Kapal | B4: MINYAK
A5: Type of Ship | B5: OIL TANKER
A6: DWT | B6: 17500 | C6: ton
A7: Kecepatan (Vs) | B7: 13 | C7: knot
A8: Endurance | B8: 11 | C8: day
A10: Perhitungan
A12: B | B12: 23.535 | C12: m
A13: H | B13: 12.354 | C13: m
A14: T | B14: 9.0537 | C14: m
A15: LPP | B15: 139.85 | C15: m
A16: LWL | B16: 145.444 | C16: m
A17: LDISP | B17: =0.5*(B15+B16) -> 142.647 | C17: m
B18: =3.28084*B17 -> 468.00198 | C18: ft
A19: CB (δ) | B19: 0.7759
A20: CM (ẞ) | B20: 0.989
A21: CP (ϕ) | B21: 0.785
A22: SLR | B22: =B7/SQRT(B18) -> 0.60092394
A23: Vdisp (▽) | B23: =B19*B17*B12*B14 -> 23583.524 | C23: m3
A24: Wdisp (▲) | B24: =B23*1.025 -> 24173.112 | C24: ton
A25: LCB | B25: 0.0215
A27: Perhitungan Koefisien Gesek
A29: 1. Reynold Number
D30: viskositas (vk) = | E30: 8.93e-07
A32: Data V | B32: Knot | C32: m/s | D32: Rn
A33: Vs+1 | B33: =B7+1 -> 14 | C33: =B33*0.514 -> 7.196 | D33: =C33*$B$16/$E$30 -> 1.1720213e+09
A34: Vs | B34: =B7 -> 13 | C34: =B34*0.514 -> 6.682 | D34: =C34*$B$16/$E$30 -> 1.0883055e+09
A35: Vs-1 | B35: =$B$7-1 -> 12 | C35: =B35*0.514 -> 6.168 | D35: =C35*$B$16/$E$30 -> 1.0045897e+09
A36: Vs-2 | B36: =$B$7-2 -> 11 | C36: =B36*0.514 -> 5.654 | D36: =C36*$B$16/$E$30 -> 9.2087388e+08
A37: Vs-3 | B37: =$B$7-3 -> 10 | C37: =B37*0.514 -> 5.14 | D37: =C37*$B$16/$E$30 -> 8.3715807e+08
A38: Vs-4 | B38: =$B$7-4 -> 9 | C38: =B38*0.514 -> 4.626 | D38: =C38*$B$16/$E$30 -> 7.5344227e+08
A39: Vs-5 | B39: =$B$7-5 -> 8 | C39: =B39*0.514 -> 4.112 | D39: =C39*$B$16/$E$30 -> 6.6972646e+08
A41: 2. Koefisien Tahanan Gesek
E42: ITTC 1957
E43: Harvald, Tahanan dan Propulsi Kapal, hal 118
A46: =A32 -> Data V | B46: =B32 -> Knot | C46: =C32 -> m/s | D46: =D32 -> Rn | E46: Cf
A47: =A33 -> Vs+1 | B47: =B33 -> 14 | C47: =C33 -> 7.196 | D47: =D33 -> 1.1720213e+09 | E47: =0.075/((LOG(D47-2))^2) -> 0.00091190298
A48: =A34 -> Vs | B48: =B34 -> 13 | C48: =C34 -> 6.682 | D48: =D34 -> 1.0883055e+09 | E48: =0.075/((LOG(D48-2))^2) -> 0.0009184101
A49: =A35 -> Vs-1 | B49: =B35 -> 12 | C49: =C35 -> 6.168 | D49: =D35 -> 1.0045897e+09 | E49: =0.075/((LOG(D49-2))^2) -> 0.00092551686
...

Sheet MAXSURF
A1: MAXSURF RT
A3: V (Knot) | B3: Fn Lwl | C3: Fn Vol | D3: RT (kN) | E3: RT Margin (kN)
A4: 8 | B4: 0.109 | C4: 0.246 | D4: 106.3 | E4: =120%*D4 -> 127.56
A5: 8.15 | B5: 0.111 | C5: 0.251 | D5: 110.1 | E5: =120%*D5 -> 132.12
A6: 8.3 | B6: 0.113 | C6: 0.255 | D6: 114 | E6: =120%*D6 -> 136.8
A7: 8.45 | B7: 0.115 | C7: 0.26 | D7: 118 | E7: =120%*D7 -> 141.6
A8: 8.6 | B8: 0.118 | C8: 0.264 | D8: 122.1 | E8: =120%*D8 -> 146.52
A9: 8.75 | B9: 0.12 | C9: 0.269 | D9: 126.2 | E9: =120%*D9 -> 151.44
A10: 8.9 | B10: 0.122 | C10: 0.274 | D10: 130.4 | E10: =120%*D10 -> 156.48
A11: 9.05 | B11: 0.124 | C11: 0.278 | D11: 134.8 | E11: =120%*D11 -> 161.76
A12: 9.2 | B12: 0.126 | C12: 0.283 | D12: 139.1 | E12: =120%*D12 -> 166.92
A13: 9.35 | B13: 0.128 | C13: 0.287 | D13: 143.6 | E13: =120%*D13 -> 172.32
A14: 9.5 | B14: 0.13 | C14: 0.292 | D14: 148.2 | E14: =120%*D14 -> 177.84
A15: 9.65 | B15: 0.132 | C15: 0.297 | D15: 152.9 | E15: =120%*D15 -> 183.48
... A45: 14 | B45: 0.191 | C45: 0.43 | D45: 364.4 | E45: =120%*D45 -> 437.28

Sheet BHP
A1: Propulsion power required prediction
C2: HOLTROP | L2: MAXSURF
A4: 1. Effective Horse Power | J4: 1. Effective Horse Power | Y4: 1 km = | Z4: 1.852 | AA4: Nautical Mile
A5: The power that would have to use to tow the ship without propulsive system | J5: The power we would have to use to tow the ship without propulsive system | Y5: 1 m = | Z5: 3.28084 | AA5: feet
A6: Rt Vs = | B6: =HOLTROP!E292 -> 549.60659 | C6: KN | D6: HOLTROP | J6: Rt Vs = | K6: =MAXSURF!E38 -> 356.28 | L6: KN | M6: MAXSURF | Y6: 1 Knots = | Z6: 0.514 | AA6: m/s
A7: Vs = | B7: =13 -> 13 | C7: knot | J7: Vs = | K7: 13 | L7: knot | Y7: 1 HP = | Z7: 0.7355 | AA7: kW
B8: =B7*(1852/3600) -> 6.6877778 | C8: m/s | K8: =K7*(1852/3600) -> 6.6877778 | L8: m/s | Y8: 1 kW = | Z8: 1.34048 | AA8: HP
Y9: 1 m3 = | Z9: 1000 | AA9: Liters | AC9: 264172 | AD9: US Gallons
B10: EHP = | C10: Rt Vs x Vs | K10: EHP = | L10: Rt Vs x Vs
B11: EHP = | C11: =B6*B8 -> 3675.6468 | D11: KW | K11: EHP = | L11: =$K$6*$K$8 -> 2382.7215 | M11: KW
B12: EHP = | C12: =C11*Z8 -> 4927.131 | D12: HP | K12: EHP = | L12: =$Z$8*$L$11 -> 3193.9905 | M12: HP
A14: 2. Delivery Horse Power | J14: 2. Delivery Horse Power
A15: Power that is absorbed by Propeller from shafting system or the power that is delivered from shafting system to the propeller to be changed into Thrust power. | J15: Power that is absorbed by Propeller from shafting system or the power that is delivered from shafting system to the propeller to be changed into Thrust power.
B18: DHP = | C18: EHP/Pc | F18: Where, Pc is propulsive coefficient | K18: DHP = | L18: EHP/Pc | O18: Where, Pc is propulsive coefficient
F19: Pc = ηH x ηrr x ηo | O19: Pc = ηH x ηrr x ηo
A20: a. hull efficiency ( ηH ) | J20: a. hull efficiency ( ηH )
B21: ηH = | C21: (1-t)/(1-w) | E21: t = | F21: thrust deduction fraction | K21: ηH = | L21: (1-t)/(1-w) | N21: t = | O21: thrust deduction fraction
E22: w = | F22: wake fraction | N22: w = | O22: wake fraction
A23: (1). | B23: Calculating Wake Friction (w) | J23: (1). | K23: Calculating Wake Friction (w)
B24: Wake friction atau arus ikut merupakan perbandingan antara kecepatan kapal dengan kecepatan air yang menuju ke propeller. The value of wake fraction is based on the Taylor Experiment, these are the result: | K24: Wake friction atau arus ikut merupakan perbandingan antara kecepatan kapal dengan kecepatan air yang menuju ke propeller. The value of wake fraction is based on the Taylor Experiment, these are the result:
E27: So, in order to find the value of w of a ship with Cb used, we must interpolate it: | N27: So, in order to find the value of w of a ship with Cb used, we must interpolate it:
F29: Cb | G29: w | O29: Cb | P29: w
F30: 0.75 | G30: 0.314 | O30: =F30 -> 0.75 | P30: =G30 -> 0.314
F31: 0.7759 | G31: x | O31: =F31 -> 0.7759 | P31: =G31 -> x
F32: 0.8 | G32: 0.354 | O32: =F32 -> 0.8 | P32: =G32 -> 0.354
F33: 0.7759 - 0.75 | G33: = | H33: w - 0.314 | O33: =F33 -> 0.7759 - 0.75 | P33: =G33 -> = | Q33: =H33 -> w - 0.314
F34: 0.8-0,75 | H34: 0.354-0,314 | O34: =F34 -> 0.8-0,75 | Q34: =H34 -> 0.354-0,314
F35: =F31-F30 -> 0.0259 | G35: = | H35: w - 0.314 | O35: =F35 -> 0.0259 | P35: =G35 -> = | Q35: =H35 -> w - 0.314
F36: =F32-F30 -> 0.05 | G36: = | H36: =G32-G30 -> 0.04 | O36: =F36 -> 0.05 | P36: =G36 -> = | Q36: =H36 -> 0.04
B37: (Principal of Naval Architecture Vol. 2, Pg.158 ) | G37: Cb = | H37: 0.7759 | K37: (Principal of Naval Architecture Vol. 2, Pg.158 ) | P37: =G37 -> Cb = | Q37: =H37 -> 0.7759
G38: w = | H38: =G30+((H36*F35)/F36) -> 0.33472 | P38: =G38 -> w = | Q38: =H38 -> 0.33472
A40: (2). | B40: Calclating Thrust Deduction Factor (t) | J40: (2). | K40: Calclating Thrust Deduction Factor (t)
B41: Nilai t dapat dicari dari nilai w yang telah diketahui yaitu : | K41: Nilai t dapat dicari dari nilai w yang telah diketahui yaitu :
E42: for a ship with single rudder plate | N42: for a ship with single rudder plate
B43: t = | C43: k.w | E43: Value k among 0.7 ~ 0.9 and taken k = | I43: 0.7 | K43: t = | L43: k.w | N43: Value k between 0.7 ~ 0.9 and taken | Q43: k = | R43: 0.7
B44: = | C44: =I43*H38 -> 0.234304 | E44: (Principal of Naval Architecture Vol. 2, Pg.159 ) | K44: = | L44: =R43*Q38 -> 0.234304 | N44: (Principal of Naval Architecture Vol. 2, Pg.158 )
B46: ηH = | C46: (1-t)/(1-w) | K46: ηH = | L46: (1-t)/(1-w)
B47: = | C47: =(1-C44)/(1-H38) -> 1.150938 | K47: = | L47: =(1-L44)/(1-Q38) -> 1.150938
A49: b. Efisiensi Relatif Rotatif (ηrr) | J49: b. Efisiensi Relatif Rotatif (ηrr)
A50: Harga ηrr untuk kapal dengan propeller tipe single screw berkisar 1.0-1.1. (Principal of Naval Architecture Vol. 2, Pg. 152 ) pada perencanaan propeller dan tabung poros propeller ini diambil harga : | J50: Harga ηrr untuk kapal dengan propeller tipe single screw berkisar 1.0-1.1. (Principal of Naval Architecture Vol. 2, Pg. 152 ) pada perencanaan propeller dan tabung poros propeller ini diambil harga :
...

Sheet EPM 
A1: PROPELLER TERPILIH | K1: DATA KAPAL
C2: Tipe | D2: Db (m) | E2: P/Db | F2: ηb | G2: nprop (RPS) | K2: Tipe Kapal | M2: OIL TANKER | P2: Type | Q2: Db(m) | R2: P/Db | S2: ηb
C3: B4-70 | D3: 4.0729253 | E3: 0.74546298 | F3: 0.55160086 | G3: 2.5944375 | H3: =E3*D3 -> 3.036215 | K3: Panjang (Lpp) | M3: 139.85 | N3: meter | P3: B4-70 | Q3: 4.0729253 | R3: 0.74546298 | S3: 0.55160086
K4: Lebar (B) | M4: 23.535 | N4: meter | P4: B5-75 | Q4: 3.9553771 | R4: 0.77444556 | S4: 0.55218322
A5: Perhitungan Beta (β) | K5: Sarat air (T) | M5: 9.05 | N5: meter | P5: B3-65 | Q5: 4.2157371 | R5: 0.72212029 | S5: 0.54383348
C6: β | D6: (0,5*Ct*S) / {(1-t)*(1-w)2 D2} | K6: Kec. Dinas (Vs) | M6: 13 | N6: knot | P6: B4-85 | Q6: 3.9441916 | R6: 0.79245648 | S6: 0.53868371
K7: t = | M7: =0.7*M8 -> 0.236565 | P7: B4-100 | Q7: 3.7932537 | R7: 0.85 | S7: 0.52373315
A8: Vs (knot) | B8: Vs (m/s) | C8: Rt trial (kN) | D8: R t sm (kN) | E8: Ct trial | F8: Ctsm | G8: βtrial | H8: βservice | K8: w = | M8: 0.33795 | P8: B5-90 | Q8: 3.8814689 | R8: 0.80600591 | S8: 0.54134946
A9: 14 | B9: =A9*0.51444 -> 7.20216 | C9: 364.4 | D9: =120%*C9 -> 437.28 | E9: =(2*C9)/(1.025*$M$9*B9^2) -> 0.002808201 | F9: =(2*D9)/(1.025*$M$9*B9^2) -> 0.0033698412 | G9: =(0.5*E9*$M$9)/((1-$M$7)*((1-$M$8)^2)*$D$3^2) -> 1.2347028 | H9: =(0.5*F9*$M$9)/((1-$M$7)*((1-$M$8)^2)*$D$3^2) -> 1.4816434 | K9: S = | M9: 4881.247 | N9: m2 | P9: B5-105 | Q9: 3.8071701 | R9: 0.85 | S9: 0.52430571
A10: 13 | B10: =A10*0.51444 -> 6.68772 | C10: 296.9 | D10: =120%*C10 -> 356.28 | E10: =(2*C10)/(1.025*$M$9*B10^2) -> 0.0026535629 | F10: =(2*D10)/(1.025*$M$9*B10^2) -> 0.0031842754 | G10: =(0.5*E10*$M$9)/((1-$M$7)*(1-$M$8)^2*$D$3^2) -> 1.1667119 | H10: =(0.5*F10*$M$9)/((1-$M$7)*((1-$M$8)^2)*$D$3^2) -> 1.4000543 | P10: B6-80 | Q10: 3.8393675 | R10: 0.81262301 | S10: 0.54507494
A11: 12 | B11: =A11*0.51444 -> 6.17328 | C11: 245.8 | D11: =120%*C11 -> 294.96 | E11: =(2*C11)/(1.025*$M$9*B11^2) -> 0.0025782515 | F11: =(2*D11)/(1.025*$M$9*B11^2) -> 0.0030939018 | G11: =(0.5*E11*$M$9)/((1-$M$7)*(1-$M$8)^2*$D$3^2) -> 1.1335992 | H11: =(0.5*F11*$M$9)/((1-$M$7)*((1-$M$8)^2)*$D$3^2) -> 1.360319 | P11: B6-95 | Q11: 3.7932537 | R11: 0.83140516 | S11: 0.53472502
A12: 11 | B12: =A12*0.51444 -> 5.65884 | C12: 200.2 | D12: =120%*C12 -> 240.24 | E12: =(2*C12)/(1.025*$M$9*B12^2) -> 0.0024991055 | F12: =(2*D12)/(1.025*$M$9*B12^2) -> 0.0029989266 | G12: =(0.5*E12*$M$9)/((1-$M$7)*(1-$M$8)^2*$D$3^2) -> 1.0988005 | H12: =(0.5*F12*$M$9)/((1-$M$7)*((1-$M$8)^2)*$D$3^2) -> 1.3185606
A13: 10 | B13: =A13*0.51444 -> 5.1444 | C13: 167.5 | D13: =120%*C13 -> 201 | E13: =(2*C13)/(1.025*$M$9*B13^2) -> 0.002530001 | F13: =(2*D13)/(1.025*$M$9*B13^2) -> 0.0030360012 | G13: =(0.5*E13*$M$9)/((1-$M$7)*(1-$M$8)^2*$D$3^2) -> 1.1123846 | H13: =(0.5*F13*$M$9)/((1-$M$7)*((1-$M$8)^2)*$D$3^2) -> 1.3348615
A14: 9 | B14: =A14*0.51444 -> 4.62996 | C14: 134.8 | D14: =120%*C14 -> 161.76 | E14: =(2*C14)/(1.025*$M$9*B14^2) -> 0.0025136845 | F14: =(2*D14)/(1.025*$M$9*B14^2) -> 0.0030164214 | G14: =(0.5*E14*$M$9)/((1-$M$7)*(1-$M$8)^2*$D$3^2) -> 1.1052105 | H14: =(0.5*F14*$M$9)/((1-$M$7)*((1-$M$8)^2)*$D$3^2) -> 1.3262526
A16: Menghitung KT (Koefisien Thrust) Trial
A17: J = | B17: Va/n*Db | C17: = | D17: ='[3]Propeller '!E19/(G3*D3) -> 0.45124006 | F17: KT = | G17: β x J2 | H17: = | I17: =G10*(D17^2) -> 0.23756307
B19: Trial
B20: J | C20: KT pada Vs
C21: 14 | D21: 13 | E21: 12 | F21: 11 | G21: 10 | H21: 9
B22: 0 | C22: =$G$9*(B22^2) -> 0 | D22: =$G$10*(B22^2) -> 0 | E22: =$G$11*(B22^2) -> 0 | F22: =$G$12*(B22^2) -> 0 | G22: =$G$13*(B22^2) -> 0 | H22: =$G$14*(B22^2) -> 0
B23: 0.1 | C23: =$G$9*(B23^2) -> 0.012347028 | D23: =$G$10*(B23^2) -> 0.011667119 | E23: =$G$11*(B23^2) -> 0.011335992 | F23: =$G$12*(B23^2) -> 0.010988005 | G23: =$G$13*(B23^2) -> 0.011123846 | H23: =$G$14*(B23^2) -> 0.011052105
B24: 0.2 | C24: =$G$9*(B24^2) -> 0.049388113 | D24: =$G$10*(B24^2) -> 0.046668477 | E24: =$G$11*(B24^2) -> 0.045343968 | F24: =$G$12*(B24^2) -> 0.04395202 | G24: =$G$13*(B24^2) -> 0.044495383 | H24: =$G$14*(B24^2) -> 0.044208421
B25: 0.3 | C25: =$G$9*(B25^2) -> 0.11112325 | D25: =$G$10*(B25^2) -> 0.10500407 | E25: =$G$11*(B25^2) -> 0.10202393 | F25: =$G$12*(B25^2) -> 0.098892044 | G25: =$G$13*(B25^2) -> 0.10011461 | H25: =$G$14*(B25^2) -> 0.099468948
B26: 0.4 | C26: =$G$9*(B26^2) -> 0.19755245 | D26: =$G$10*(B26^2) -> 0.18667391 | E26: =$G$11*(B26^2) -> 0.18137587 | F26: =$G$12*(B26^2) -> 0.17580808 | G26: =$G$13*(B26^2) -> 0.17798153 | H26: =$G$14*(B26^2) -> 0.17683369
B27: 0.5 | C27: =$G$9*(B27^2) -> 0.3086757 | D27: =$G$10*(B27^2) -> 0.29167798 | E27: =$G$11*(B27^2) -> 0.2833998 | F27: =$G$12*(B27^2) -> 0.27470012 | G27: =$G$13*(B27^2) -> 0.27809614 | H27: =$G$14*(B27^2) -> 0.27630263
B28: 0.6 | C28: =$G$9*(B28^2) -> 0.44449301 | D28: =$G$10*(B28^2) -> 0.42001629 | E28: =$G$11*(B28^2) -> 0.40809571 | F28: =$G$12*(B28^2) -> 0.39556818 | G28: =$G$13*(B28^2) -> 0.40045844 | H28: =$G$14*(B28^2) -> 0.39787579
B29: 0.7 | C29: =$G$9*(B29^2) -> 0.60500438 | D29: =$G$10*(B29^2) -> 0.57168884 | E29: =$G$11*(B29^2) -> 0.55546361 | F29: =$G$12*(B29^2) -> 0.53841224 | G29: =$G$13*(B29^2) -> 0.54506844 | H29: =$G$14*(B29^2) -> 0.54155316
B30: 0.8 | C30: =$G$9*(B30^2) -> 0.7902098 | D30: =$G$10*(B30^2) -> 0.74669563 | E30: =$G$11*(B30^2) -> 0.72550348 | F30: =$G$12*(B30^2) -> 0.70323231 | G30: =$G$13*(B30^2) -> 0.71192612 | H30: =$G$14*(B30^2) -> 0.70733474
B31: 0.9 | C31: =$G$9*(B31^2) -> 1.0001093 | D31: =$G$10*(B31^2) -> 0.94503666 | E31: =$G$11*(B31^2) -> 0.91821535 | F31: =$G$12*(B31^2) -> 0.8900284 | G31: =$G$13*(B31^2) -> 0.9010315 | H31: =$G$14*(B31^2) -> 0.89522053
B32: 1 | C32: =$G$9*(B32^2) -> 1.2347028 | D32: =$G$10*(B32^2) -> 1.1667119 | E32: =$G$11*(B32^2) -> 1.1335992 | F32: =$G$12*(B32^2) -> 1.0988005 | G32: =$G$13*(B32^2) -> 1.1123846 | H32: =$G$14*(B32^2) -> 1.1052105
A51: Menghitung KT (Koefisien Thrust) Rough Hull
C53: J = | D53: Va/nD | F53: KT = | G53: β x J2
C54: = | D54: =D17 -> 0.45124006 | F54: = | G54: =I17 -> 0.23756307
B56: Rough Hull (20% Sea Margin)
B57: J | C57: KT pada Kecepatan
C58: 14 | D58: 13 | E58: 12 | F58: 11 | G58: 10 | H58: 9
B59: 0 | C59: =$H$9*(B59^2) -> 0 | D59: =$H$10*(B59^2) -> 0 | E59: =$H$11*(B59^2) -> 0 | F59: =$H$12*(B59^2) -> 0 | G59: =$H$13*(B59^2) -> 0 | H59: =$H$14*(B59^2) -> 0
B60: 0.1 | C60: =$H$9*(B60^2) -> 0.014816434 | D60: =$H$10*(B60^2) -> 0.014000543 | E60: =$H$11*(B60^2) -> 0.01360319 | F60: =$H$12*(B60^2) -> 0.013185606 | G60: =$H$13*(B60^2) -> 0.013348615 | H60: =$H$14*(B60^2) -> 0.013262526
B61: 0.2 | C61: =$H$9*(B61^2) -> 0.059265735 | D61: =$H$10*(B61^2) -> 0.056002172 | E61: =$H$11*(B61^2) -> 0.054412761 | F61: =$H$12*(B61^2) -> 0.052742424 | G61: =$H$13*(B61^2) -> 0.053394459 | H61: =$H$14*(B61^2) -> 0.053050106
B62: 0.3 | C62: =$H$9*(B62^2) -> 0.1333479 | D62: =$H$10*(B62^2) -> 0.12600489 | E62: =$H$11*(B62^2) -> 0.12242871 | F62: =$H$12*(B62^2) -> 0.11867045 | G62: =$H$13*(B62^2) -> 0.12013753 | H62: =$H$14*(B62^2) -> 0.11936274
...

Sheet DISP
A2: Main Deck | G2: Draft | M2: WL 8 | S2: WL 7 | Y2: WL 6 | AE2: WL 5 | AK2: WL 4 | AQ2: WL 3 | AW2: WL 2 | BC2: WL 1 | BI2: WL 0.5
A4: Station | B4: Area | C4: Area/2 | D4: Fs | E4: A x Fs | G4: Station | H4: Area | I4: Area/2 | J4: Fs | K4: A x Fs | M4: Station | N4: Area | O4: Area/2 | P4: Fs | Q4: A x Fs | S4: Station | T4: Area | U4: Area/2 | V4: Fs | W4: A x Fs | Y4: Station | Z4: Area | AA4: Area/2 | AB4: Fs | AC4: A x Fs | AE4: Station | AF4: Area | AG4: Area/2 | AH4: Fs | AI4: A x Fs | AK4: Station | AL4: Area | AM4: Area/2 | AN4: Fs | AO4: A x Fs | AQ4: Station | AR4: Area | AS4: Area/2 | AT4: Fs | AU4: A x Fs | AW4: Station | AX4: Area | AY4: Area/2 | AZ4: Fs | BA4: A x Fs | BC4: Station | BD4: Area | BE4: Area/2 | BF4: Fs | BG4: A x Fs | BI4: Station | BJ4: Area | BK4: Area/2 | BL4: Fs | BM4: A x Fs
A5: -2 | B5: 0 | C5: 0 | D5: 0.3 | E5: =C5*D5 -> 0 | G5: -2 | H5: 0 | I5: 0 | J5: 0.3 | K5: =I5*J5 -> 0 | M5: -2 | N5: 0 | O5: 0 | P5: 0.3 | Q5: =O5*P5 -> 0 | S5: -2 | T5: 0 | U5: 0 | V5: 0.3 | W5: =U5*V5 -> 0 | Y5: -2 | Z5: 0 | AA5: 0 | AB5: 0.3 | AC5: =AA5*AB5 -> 0 | AE5: -2 | AF5: 0 | AG5: 0 | AH5: 0.3 | AI5: =AG5*AH5 -> 0 | AK5: -2 | AL5: 0 | AM5: 0 | AN5: 0.3 | AO5: =AM5*AN5 -> 0 | AQ5: -2 | AR5: 0 | AS5: 0 | AT5: 0.3 | AU5: =AS5*AT5 -> 0 | AW5: -2 | AX5: 0 | AY5: 0 | AZ5: 0.3 | BA5: =AY5*AZ5 -> 0 | BC5: -2 | BD5: 0 | BE5: 0 | BF5: 0.3 | BG5: =BE5*BF5 -> 0 | BI5: -2 | BJ5: =BK5*$N$35 -> 0 | BK5: 0 | BL5: 0.3 | BM5: =BK5*BL5 -> 0
A6: -1 | B6: =C6*$N$35 -> 19.36 | C6: =5.85+I6 -> 9.68 | D6: 1.2 | E6: =C6*D6 -> 11.616 | G6: -1 | H6: =I6*$N$35 -> 7.66 | I6: =2.65+O6 -> 3.83 | J6: 1.2 | K6: =I6*J6 -> 4.596 | M6: -1 | N6: =O6*$N$35 -> 2.36 | O6: 1.18 | P6: 1.2 | Q6: =O6*P6 -> 1.416 | S6: -1 | T6: 0 | U6: 0 | V6: 1.2 | W6: =U6*V6 -> 0 | Y6: -1 | Z6: 0 | AA6: 0 | AB6: 1.2 | AC6: =AA6*AB6 -> 0 | AE6: -1 | AF6: 0 | AG6: 0 | AH6: 1.2 | AI6: =AG6*AH6 -> 0 | AK6: -1 | AL6: 0 | AM6: 0 | AN6: 1.2 | AO6: =AM6*AN6 -> 0 | AQ6: -1 | AR6: 0 | AS6: 0 | AT6: 1.2 | AU6: =AS6*AT6 -> 0 | AW6: -1 | AX6: 0 | AY6: 0 | AZ6: 1.2 | BA6: =AY6*AZ6 -> 0 | BC6: -1 | BD6: 0 | BE6: 0 | BF6: 1.2 | BG6: =BE6*BF6 -> 0 | BI6: -1 | BJ6: =BK6*$N$35 -> 0 | BK6: 0 | BL6: 1.2 | BM6: =BK6*BL6 -> 0
A7: AP | B7: =C7*$N$35 -> 31.4 | C7: =8.42+I7 -> 15.7 | D7: 1.3 | E7: =B7*D7 -> 40.82 | G7: AP | H7: =I7*$N$35 -> 14.56 | I7: =4.05+O7 -> 7.28 | J7: 1.3 | K7: =H7*J7 -> 18.928 | M7: AP | N7: =O7*$N$35 -> 6.46 | O7: =2.89+U7 -> 3.23 | P7: 1.3 | Q7: =O7*P7 -> 4.199 | S7: AP | T7: =U7*$N$35 -> 0.68 | U7: 0.34 | V7: 1.3 | W7: =U7*V7 -> 0.442 | Y7: AP | Z7: 0 | AA7: 0 | AB7: 1.3 | AC7: =AA7*AB7 -> 0 | AE7: AP | AF7: 0 | AG7: 0 | AH7: 1.3 | AI7: =AG7*AH7 -> 0 | AK7: AP | AL7: 0 | AM7: 0 | AN7: 1.3 | AO7: =AM7*AN7 -> 0 | AQ7: AP | AR7: 0 | AS7: 0 | AT7: 1.3 | AU7: =AS7*AT7 -> 0 | AW7: AP | AX7: 0 | AY7: 0 | AZ7: 1.3 | BA7: =AY7*AZ7 -> 0 | BC7: AP | BD7: 0 | BE7: 0 | BF7: 1.3 | BG7: =BE7*BF7 -> 0 | BI7: AP | BJ7: =BK7*$N$35 -> 0 | BK7: 0 | BL7: 1.3 | BM7: =BK7*BL7 -> 0
A8: 1 | B8: =C8*$N$35 -> 83.3 | C8: =13.16+I8 -> 41.65 | D8: 4 | E8: =B8*D8 -> 333.2 | G8: 1 | H8: =I8*$N$35 -> 56.98 | I8: =6.6+O8 -> 28.49 | J8: 4 | K8: =H8*J8 -> 227.92 | M8: 1 | N8: =O8*$N$35 -> 43.78 | O8: =5.2+U8 -> 21.89 | P8: 4 | Q8: =N8*P8 -> 175.12 | S8: 1 | T8: =U8*$N$35 -> 33.38 | U8: =4.05+AA8 -> 16.69 | V8: 4 | W8: =T8*V8 -> 133.52 | Y8: 1 | Z8: =AA8*$N$35 -> 25.28 | AA8: =3.03+AG8 -> 12.64 | AB8: 4 | AC8: =Z8*AB8 -> 101.12 | AE8: 1 | AF8: =AG8*$N$35 -> 19.22 | AG8: =2.46+AM8 -> 9.61 | AH8: 4 | AI8: =AF8*AH8 -> 76.88 | AK8: 1 | AL8: =AM8*$N$35 -> 14.3 | AM8: =2.17+AS8 -> 7.15 | AN8: 4 | AO8: =AL8*AN8 -> 57.2 | AQ8: 1 | AR8: =AS8*$N$35 -> 9.96 | AS8: =1.99+AY8 -> 4.98 | AT8: 4 | AU8: =AR8*AT8 -> 39.84 | AW8: 1 | AX8: =AY8*$N$35 -> 5.98 | AY8: =1.82+BE8 -> 2.99 | AZ8: 4 | BA8: =AX8*AZ8 -> 23.92 | BC8: 1 | BD8: =BE8*$N$35 -> 2.34 | BE8: =0.76+BK8 -> 1.17 | BF8: 4 | BG8: =BD8*BF8 -> 9.36 | BI8: 1 | BJ8: =BK8*$N$35 -> 0.82 | BK8: 0.41 | BL8: 4 | BM8: =BJ8*BL8 -> 3.28
A9: 2 | B9: =C9*$N$35 -> 139.24 | C9: =16.68+I9 -> 69.62 | D9: 2 | E9: =B9*D9 -> 278.48 | G9: 2 | H9: =I9*$N$35 -> 105.88 | I9: =8.91+O9 -> 52.94 | J9: 2 | K9: =H9*J9 -> 211.76 | M9: 2 | N9: =O9*$N$35 -> 88.06 | O9: =7.65+U9 -> 44.03 | P9: 2 | Q9: =N9*P9 -> 176.12 | S9: 2 | T9: =U9*$N$35 -> 72.76 | U9: =6.84+AA9 -> 36.38 | V9: 2 | W9: =T9*V9 -> 145.52 | Y9: 2 | Z9: =AA9*$N$35 -> 59.08 | AA9: =6.11+AG9 -> 29.54 | AB9: 2 | AC9: =Z9*AB9 -> 118.16 | AE9: 2 | AF9: =AG9*$N$35 -> 46.86 | AG9: =5.55+AM9 -> 23.43 | AH9: 2 | AI9: =AF9*AH9 -> 93.72 | AK9: 2 | AL9: =AM9*$N$35 -> 35.76 | AM9: =5.16+AS9 -> 17.88 | AN9: 2 | AO9: =AL9*AN9 -> 71.52 | AQ9: 2 | AR9: =AS9*$N$35 -> 25.44 | AS9: =4.83+AY9 -> 12.72 | AT9: 2 | AU9: =AR9*AT9 -> 50.88 | AW9: 2 | AX9: =AY9*$N$35 -> 15.78 | AY9: =4.44+BE9 -> 7.89 | AZ9: 2 | BA9: =AX9*AZ9 -> 31.56 | BC9: 2 | BD9: =BE9*$N$35 -> 6.9 | BE9: =1.97+BK9 -> 3.45 | BF9: 2 | BG9: =BD9*BF9 -> 13.8 | BI9: 2 | BJ9: =BK9*$N$35 -> 2.96 | BK9: 1.48 | BL9: 2 | BM9: =BJ9*BL9 -> 5.92
A10: 3 | B10: =C10*$N$35 -> 188.82 | C10: =19.36+I10 -> 94.41 | D10: 4 | E10: =B10*D10 -> 755.28 | G10: 3 | H10: =I10*$N$35 -> 150.1 | I10: =10.61+O10 -> 75.05 | J10: 4 | K10: =H10*J10 -> 600.4 | M10: 3 | N10: =O10*$N$35 -> 128.88 | O10: =9.5+U10 -> 64.44 | P10: 4 | Q10: =N10*P10 -> 515.52 | S10: 3 | T10: =U10*$N$35 -> 109.88 | U10: =9.02+AA10 -> 54.94 | V10: 4 | W10: =T10*V10 -> 439.52 | Y10: 3 | Z10: =AA10*$N$35 -> 91.84 | AA10: =8.63+AG10 -> 45.92 | AB10: 4 | AC10: =Z10*AB10 -> 367.36 | AE10: 3 | AF10: =AG10*$N$35 -> 74.58 | AG10: =8.32+AM10 -> 37.29 | AH10: 4 | AI10: =AF10*AH10 -> 298.32 | AK10: 3 | AL10: =AM10*$N$35 -> 57.94 | AM10: =8.04+AS10 -> 28.97 | AN10: 4 | AO10: =AL10*AN10 -> 231.76 | AQ10: 3 | AR10: =AS10*$N$35 -> 41.86 | AS10: =7.72+AY10 -> 20.93 | AT10: 4 | AU10: =AR10*AT10 -> 167.44 | AW10: 3 | AX10: =AY10*$N$35 -> 26.42 | AY10: =7.24+BE10 -> 13.21 | AZ10: 4 | BA10: =AX10*AZ10 -> 105.68 | BC10: 3 | BD10: =BE10*$N$35 -> 11.94 | BE10: =3.3+BK10 -> 5.97 | BF10: 4 | BG10: =BD10*BF10 -> 47.76 | BI10: 3 | BJ10: =BK10*$N$35 -> 5.34 | BK10: 2.67 | BL10: 4 | BM10: =BJ10*BL10 -> 21.36
A11: 4 | B11: =C11*$N$35 -> 221.45 | C11: =20.55+I11 -> 110.725 | D11: 2 | E11: =B11*D11 -> 442.9 | G11: 4 | H11: =I11*$N$35 -> 180.35 | I11: =11.71+O11 -> 90.175 | J11: 2 | K11: =H11*J11 -> 360.7 | M11: 4 | N11: =O11*$N$35 -> 156.93 | O11: =10.82+U11 -> 78.465 | P11: 2 | Q11: =N11*P11 -> 313.86 | S11: 4 | T11: =U11*$N$35 -> 135.29 | U11: =10.56+AA11 -> 67.645 | V11: 2 | W11: =T11*V11 -> 270.58 | Y11: 4 | Z11: =AA11*$N$35 -> 114.17 | AA11: =10.33+AG11 -> 57.085 | AB11: 2 | AC11: =Z11*AB11 -> 228.34 | AE11: 4 | AF11: =AG11*$N$35 -> 93.51 | AG11: =10.14+AM11 -> 46.755 | AH11: 2 | AI11: =AF11*AH11 -> 187.02 | AK11: 4 | AL11: =AM11*$N$35 -> 73.23 | AM11: =9.935+AS11 -> 36.615 | AN11: 2 | AO11: =AL11*AN11 -> 146.46 | AQ11: 4 | AR11: =AS11*$N$35 -> 53.36 | AS11: =9.66+AY11 -> 26.68 | AT11: 2 | AU11: =AR11*AT11 -> 106.72 | AW11: 4 | AX11: =AY11*$N$35 -> 34.04 | AY11: =9.2+BE11 -> 17.02 | AZ11: 2 | BA11: =AX11*AZ11 -> 68.08 | BC11: 4 | BD11: =BE11*$N$35 -> 15.64 | BE11: =4.24+BK11 -> 7.82 | BF11: 2 | BG11: =BD11*BF11 -> 31.28 | BI11: 4 | BJ11: =BK11*$N$35 -> 7.16 | BK11: 3.58 | BL11: 2 | BM11: =BJ11*BL11 -> 14.32
A12: 5 | B12: =C12*$N$35 -> 239.54 | C12: =20.82+I12 -> 119.77 | D12: 4 | E12: =B12*D12 -> 958.16 | G12: 5 | H12: =I12*$N$35 -> 197.9 | I12: =12.14+O12 -> 98.95 | J12: 4 | K12: =H12*J12 -> 791.6 | M12: 5 | N12: =O12*$N$35 -> 173.62 | O12: =11.47+U12 -> 86.81 | P12: 4 | Q12: =N12*P12 -> 694.48 | S12: 5 | T12: =U12*$N$35 -> 150.68 | U12: =11.41+AA12 -> 75.34 | V12: 4 | W12: =T12*V12 -> 602.72 | Y12: 5 | Z12: =AA12*$N$35 -> 127.86 | AA12: =11.35+AG12 -> 63.93 | AB12: 4 | AC12: =Z12*AB12 -> 511.44 | AE12: 5 | AF12: =AG12*$N$35 -> 105.16 | AG12: =11.24+AM12 -> 52.58 | AH12: 4 | AI12: =AF12*AH12 -> 420.64 | AK12: 5 | AL12: =AM12*$N$35 -> 82.68 | AM12: =11.06+AS12 -> 41.34 | AN12: 4 | AO12: =AL12*AN12 -> 330.72 | AQ12: 5 | AR12: =AS12*$N$35 -> 60.56 | AS12: =10.76+AY12 -> 30.28 | AT12: 4 | AU12: =AR12*AT12 -> 242.24 | AW12: 5 | AX12: =AY12*$N$35 -> 39.04 | AY12: =10.27+BE12 -> 19.52 | AZ12: 4 | BA12: =AX12*AZ12 -> 156.16 | BC12: 5 | BD12: =BE12*$N$35 -> 18.5 | BE12: =4.84+BK12 -> 9.25 | BF12: 4 | BG12: =BD12*BF12 -> 74 | BI12: 5 | BJ12: =BK12*$N$35 -> 8.82 | BK12: 4.41 | BL12: 4 | BM12: =BJ12*BL12 -> 35.28
A13: 6 | B13: =C13*$N$35 -> 247.54 | C13: =20.91+I13 -> 123.77 | D13: 2 | E13: =B13*D13 -> 495.08 | G13: 6 | H13: =I13*$N$35 -> 205.72 | I13: =12.25+O13 -> 102.86 | J13: 2 | K13: =H13*J13 -> 411.44 | M13: 6 | N13: =O13*$N$35 -> 181.22 | O13: =11.63+U13 -> 90.61 | P13: 2 | Q13: =N13*P13 -> 362.44 | S13: 6 | T13: =U13*$N$35 -> 157.96 | U13: =11.62+AA13 -> 78.98 | V13: 2 | W13: =T13*V13 -> 315.92 | Y13: 6 | Z13: =AA13*$N$35 -> 134.72 | AA13: =11.61+AG13 -> 67.36 | AB13: 2 | AC13: =Z13*AB13 -> 269.44 | AE13: 6 | AF13: =AG13*$N$35 -> 111.5 | AG13: =11.58+AM13 -> 55.75 | AH13: 2 | AI13: =AF13*AH13 -> 223 | AK13: 6 | AL13: =AM13*$N$35 -> 88.34 | AM13: =11.53+AS13 -> 44.17 | AN13: 2 | AO13: =AL13*AN13 -> 176.68 | AQ13: 6 | AR13: =AS13*$N$35 -> 65.28 | AS13: =11.42+AY13 -> 32.64 | AT13: 2 | AU13: =AR13*AT13 -> 130.56 | AW13: 6 | AX13: =AY13*$N$35 -> 42.44 | AY13: =11.13+BE13 -> 21.22 | AZ13: 2 | BA13: =AX13*AZ13 -> 84.88 | BC13: 6 | BD13: =BE13*$N$35 -> 20.18 | BE13: =5.29+BK13 -> 10.09 | BF13: 2 | BG13: =BD13*BF13 -> 40.36 | BI13: 6 | BJ13: =BK13*$N$35 -> 9.6 | BK13: 4.8 | BL13: 2 | BM13: =BJ13*BL13 -> 19.2
A14: 7 | B14: =C14*$N$35 -> 251.24 | C14: =21.1+I14 -> 125.62 | D14: 4 | E14: =B14*D14 -> 1004.96 | G14: 7 | H14: =I14*$N$35 -> 209.04 | I14: =12.36+O14 -> 104.52 | J14: 4 | K14: =H14*J14 -> 836.16 | M14: 7 | N14: =O14*$N$35 -> 184.32 | O14: =11.73+U14 -> 92.16 | P14: 4 | Q14: =N14*P14 -> 737.28 | S14: 7 | T14: =U14*$N$35 -> 160.86 | U14: =11.71+AA14 -> 80.43 | V14: 4 | W14: =T14*V14 -> 643.44 | Y14: 7 | Z14: =AA14*$N$35 -> 137.44 | AA14: =11.7+AG14 -> 68.72 | AB14: 4 | AC14: =Z14*AB14 -> 549.76 | AE14: 7 | AF14: =AG14*$N$35 -> 114.04 | AG14: =11.69+AM14 -> 57.02 | AH14: 4 | AI14: =AF14*AH14 -> 456.16 | AK14: 7 | AL14: =AM14*$N$35 -> 90.66 | AM14: =11.67+AS14 -> 45.33 | AN14: 4 | AO14: =AL14*AN14 -> 362.64 | AQ14: 7 | AR14: =AS14*$N$35 -> 67.32 | AS14: =11.64+AY14 -> 33.66 | AT14: 4 | AU14: =AR14*AT14 -> 269.28 | AW14: 7 | AX14: =AY14*$N$35 -> 44.04 | AY14: =11.44+BE14 -> 22.02 | AZ14: 4 | BA14: =AX14*AZ14 -> 176.16 | BC14: 7 | BD14: =BE14*$N$35 -> 21.16 | BE14: =5.49+BK14 -> 10.58 | BF14: 4 | BG14: =BD14*BF14 -> 84.64 | BI14: 7 | BJ14: =BK14*$N$35 -> 10.18 | BK14: 5.09 | BL14: 4 | BM14: =BJ14*BL14 -> 40.72
A15: 8 | B15: =C15*$N$35 -> 252.96 | C15: =21.1+I15 -> 126.48 | D15: 2 | E15: =B15*D15 -> 505.92 | G15: 8 | H15: =I15*$N$35 -> 210.76 | I15: =12.4+O15 -> 105.38 | J15: 2 | K15: =H15*J15 -> 421.52 | M15: 8 | N15: =O15*$N$35 -> 185.96 | O15: =11.77+U15 -> 92.98 | P15: 2 | Q15: =N15*P15 -> 371.92 | S15: 8 | T15: =U15*$N$35 -> 162.42 | U15: =11.77+AA15 -> 81.21 | V15: 2 | W15: =T15*V15 -> 324.84 | Y15: 8 | Z15: =AA15*$N$35 -> 138.88 | AA15: =11.77+AG15 -> 69.44 | AB15: 2 | AC15: =Z15*AB15 -> 277.76 | AE15: 8 | AF15: =AG15*$N$35 -> 115.34 | AG15: =11.77+AM15 -> 57.67 | AH15: 2 | AI15: =AF15*AH15 -> 230.68 | AK15: 8 | AL15: =AM15*$N$35 -> 91.8 | AM15: =11.77+AS15 -> 45.9 | AN15: 2 | AO15: =AL15*AN15 -> 183.6 | AQ15: 8 | AR15: =AS15*$N$35 -> 68.26 | AS15: =11.76+AY15 -> 34.13 | AT15: 2 | AU15: =AR15*AT15 -> 136.52 | AW15: 8 | AX15: =AY15*$N$35 -> 44.74 | AY15: =11.59+BE15 -> 22.37 | AZ15: 2 | BA15: =AX15*AZ15 -> 89.48 | BC15: 8 | BD15: =BE15*$N$35 -> 21.56 | BE15: =5.57+BK15 -> 10.78 | BF15: 2 | BG15: =BD15*BF15 -> 43.12 | BI15: 8 | BJ15: =BK15*$N$35 -> 10.42 | BK15: 5.21 | BL15: 2 | BM15: =BJ15*BL15 -> 20.84
A16: 9 | B16: =C16*$N$35 -> 252.96 | C16: =21.1+I16 -> 126.48 | D16: 4 | E16: =B16*D16 -> 1011.84 | G16: 9 | H16: =I16*$N$35 -> 210.76 | I16: =12.4+O16 -> 105.38 | J16: 4 | K16: =H16*J16 -> 843.04 | M16: 9 | N16: =O16*$N$35 -> 185.96 | O16: =11.77+U16 -> 92.98 | P16: 4 | Q16: =N16*P16 -> 743.84 | S16: 9 | T16: =U16*$N$35 -> 162.42 | U16: =11.77+AA16 -> 81.21 | V16: 4 | W16: =T16*V16 -> 649.68 | Y16: 9 | Z16: =AA16*$N$35 -> 138.88 | AA16: =11.77+AG16 -> 69.44 | AB16: 4 | AC16: =Z16*AB16 -> 555.52 | AE16: 9 | AF16: =AG16*$N$35 -> 115.34 | AG16: =11.77+AM16 -> 57.67 | AH16: 4 | AI16: =AF16*AH16 -> 461.36 | AK16: 9 | AL16: =AM16*$N$35 -> 91.8 | AM16: =11.77+AS16 -> 45.9 | AN16: 4 | AO16: =AL16*AN16 -> 367.2 | AQ16: 9 | AR16: =AS16*$N$35 -> 68.26 | AS16: =11.76+AY16 -> 34.13 | AT16: 4 | AU16: =AR16*AT16 -> 273.04 | AW16: 9 | AX16: =AY16*$N$35 -> 44.74 | AY16: =11.59+BE16 -> 22.37 | AZ16: 4 | BA16: =AX16*AZ16 -> 178.96 | BC16: 9 | BD16: =BE16*$N$35 -> 21.56 | BE16: =5.57+BK16 -> 10.78 | BF16: 4 | BG16: =BD16*BF16 -> 86.24 | BI16: 9 | BJ16: =BK16*$N$35 -> 10.42 | BK16: 5.21 | BL16: 4 | BM16: =BJ16*BL16 -> 41.68
A17: 10 | B17: =C17*$N$35 -> 252.96 | C17: =21.1+I17 -> 126.48 | D17: 2 | E17: =B17*D17 -> 505.92 | G17: 10 | H17: =I17*$N$35 -> 210.76 | I17: =12.4+O17 -> 105.38 | J17: 2 | K17: =H17*J17 -> 421.52 | M17: 10 | N17: =O17*$N$35 -> 185.96 | O17: =11.77+U17 -> 92.98 | P17: 2 | Q17: =N17*P17 -> 371.92 | S17: 10 | T17: =U17*$N$35 -> 162.42 | U17: =11.77+AA17 -> 81.21 | V17: 2 | W17: =T17*V17 -> 324.84 | Y17: 10 | Z17: =AA17*$N$35 -> 138.88 | AA17: =11.77+AG17 -> 69.44 | AB17: 2 | AC17: =Z17*AB17 -> 277.76 | AE17: 10 | AF17: =AG17*$N$35 -> 115.34 | AG17: =11.77+AM17 -> 57.67 | AH17: 2 | AI17: =AF17*AH17 -> 230.68 | AK17: 10 | AL17: =AM17*$N$35 -> 91.8 | AM17: =11.77+AS17 -> 45.9 | AN17: 2 | AO17: =AL17*AN17 -> 183.6 | AQ17: 10 | AR17: =AS17*$N$35 -> 68.26 | AS17: =11.76+AY17 -> 34.13 | AT17: 2 | AU17: =AR17*AT17 -> 136.52 | AW17: 10 | AX17: =AY17*$N$35 -> 44.74 | AY17: =11.59+BE17 -> 22.37 | AZ17: 2 | BA17: =AX17*AZ17 -> 89.48 | BC17: 10 | BD17: =BE17*$N$35 -> 21.56 | BE17: =5.57+BK17 -> 10.78 | BF17: 2 | BG17: =BD17*BF17 -> 43.12 | BI17: 10 | BJ17: =BK17*$N$35 -> 10.42 | BK17: 5.21 | BL17: 2 | BM17: =BJ17*BL17 -> 20.84
A18: 11 | B18: =C18*$N$35 -> 252.96 | C18: =21.1+I18 -> 126.48 | D18: 4 | E18: =B18*D18 -> 1011.84 | G18: 11 | H18: =I18*$N$35 -> 210.76 | I18: =12.4+O18 -> 105.38 | J18: 4 | K18: =H18*J18 -> 843.04 | M18: 11 | N18: =O18*$N$35 -> 185.96 | O18: =11.77+U18 -> 92.98 | P18: 4 | Q18: =N18*P18 -> 743.84 | S18: 11 | T18: =U18*$N$35 -> 162.42 | U18: =11.77+AA18 -> 81.21 | V18: 4 | W18: =T18*V18 -> 649.68 | Y18: 11 | Z18: =AA18*$N$35 -> 138.88 | AA18: =11.77+AG18 -> 69.44 | AB18: 4 | AC18: =Z18*AB18 -> 555.52 | AE18: 11 | AF18: =AG18*$N$35 -> 115.34 | AG18: =11.77+AM18 -> 57.67 | AH18: 4 | AI18: =AF18*AH18 -> 461.36 | AK18: 11 | AL18: =AM18*$N$35 -> 91.8 | AM18: =11.77+AS18 -> 45.9 | AN18: 4 | AO18: =AL18*AN18 -> 367.2 | AQ18: 11 | AR18: =AS18*$N$35 -> 68.26 | AS18: =11.76+AY18 -> 34.13 | AT18: 4 | AU18: =AR18*AT18 -> 273.04 | AW18: 11 | AX18: =AY18*$N$35 -> 44.74 | AY18: =11.59+BE18 -> 22.37 | AZ18: 4 | BA18: =AX18*AZ18 -> 178.96 | BC18: 11 | BD18: =BE18*$N$35 -> 21.56 | BE18: =5.57+BK18 -> 10.78 | BF18: 4 | BG18: =BD18*BF18 -> 86.24 | BI18: 11 | BJ18: =BK18*$N$35 -> 10.42 | BK18: 5.21 | BL18: 4 | BM18: =BJ18*BL18 -> 41.68
A19: 12 | B19: =C19*$N$35 -> 252.96 | C19: =21.1+I19 -> 126.48 | D19: 2 | E19: =B19*D19 -> 505.92 | G19: 12 | H19: =I19*$N$35 -> 210.76 | I19: =12.4+O19 -> 105.38 | J19: 2 | K19: =H19*J19 -> 421.52 | M19: 12 | N19: =O19*$N$35 -> 185.96 | O19: =11.77+U19 -> 92.98 | P19: 2 | Q19: =N19*P19 -> 371.92 | S19: 12 | T19: =U19*$N$35 -> 162.42 | U19: =11.77+AA19 -> 81.21 | V19: 2 | W19: =T19*V19 -> 324.84 | Y19: 12 | Z19: =AA19*$N$35 -> 138.88 | AA19: =11.77+AG19 -> 69.44 | AB19: 2 | AC19: =Z19*AB19 -> 277.76 | AE19: 12 | AF19: =AG19*$N$35 -> 115.34 | AG19: =11.77+AM19 -> 57.67 | AH19: 2 | AI19: =AF19*AH19 -> 230.68 | AK19: 12 | AL19: =AM19*$N$35 -> 91.8 | AM19: =11.77+AS19 -> 45.9 | AN19: 2 | AO19: =AL19*AN19 -> 183.6 | AQ19: 12 | AR19: =AS19*$N$35 -> 68.26 | AS19: =11.76+AY19 -> 34.13 | AT19: 2 | AU19: =AR19*AT19 -> 136.52 | AW19: 12 | AX19: =AY19*$N$35 -> 44.74 | AY19: =11.59+BE19 -> 22.37 | AZ19: 2 | BA19: =AX19*AZ19 -> 89.48 | BC19: 12 | BD19: =BE19*$N$35 -> 21.56 | BE19: =5.57+BK19 -> 10.78 | BF19: 2 | BG19: =BD19*BF19 -> 43.12 | BI19: 12 | BJ19: =BK19*$N$35 -> 10.42 | BK19: 5.21 | BL19: 2 | BM19: =BJ19*BL19 -> 20.84
A20: 13 | B20: =C20*$N$35 -> 252.96 | C20: =21.1+I20 -> 126.48 | D20: 4 | E20: =B20*D20 -> 1011.84 | G20: 13 | H20: =I20*$N$35 -> 210.76 | I20: =12.4+O20 -> 105.38 | J20: 4 | K20: =H20*J20 -> 843.04 | M20: 13 | N20: =O20*$N$35 -> 185.96 | O20: =11.77+U20 -> 92.98 | P20: 4 | Q20: =N20*P20 -> 743.84 | S20: 13 | T20: =U20*$N$35 -> 162.42 | U20: =11.77+AA20 -> 81.21 | V20: 4 | W20: =T20*V20 -> 649.68 | Y20: 13 | Z20: =AA20*$N$35 -> 138.88 | AA20: =11.77+AG20 -> 69.44 | AB20: 4 | AC20: =Z20*AB20 -> 555.52 | AE20: 13 | AF20: =AG20*$N$35 -> 115.34 | AG20: =11.77+AM20 -> 57.67 | AH20: 4 | AI20: =AF20*AH20 -> 461.36 | AK20: 13 | AL20: =AM20*$N$35 -> 91.8 | AM20: =11.77+AS20 -> 45.9 | AN20: 4 | AO20: =AL20*AN20 -> 367.2 | AQ20: 13 | AR20: =AS20*$N$35 -> 68.26 | AS20: =11.76+AY20 -> 34.13 | AT20: 4 | AU20: =AR20*AT20 -> 273.04 | AW20: 13 | AX20: =AY20*$N$35 -> 44.74 | AY20: =11.59+BE20 -> 22.37 | AZ20: 4 | BA20: =AX20*AZ20 -> 178.96 | BC20: 13 | BD20: =BE20*$N$35 -> 21.56 | BE20: =5.57+BK20 -> 10.78 | BF20: 4 | BG20: =BD20*BF20 -> 86.24 | BI20: 13 | BJ20: =BK20*$N$35 -> 10.42 | BK20: 5.21 | BL20: 4 | BM20: =BJ20*BL20 -> 41.68
A21: 14 | B21: =C21*$N$35 -> 252.96 | C21: =21.1+I21 -> 126.48 | D21: 2 | E21: =B21*D21 -> 505.92 | G21: 14 | H21: =I21*$N$35 -> 210.76 | I21: =12.4+O21 -> 105.38 | J21: 2 | K21: =H21*J21 -> 421.52 | M21: 14 | N21: =O21*$N$35 -> 185.96 | O21: =11.77+U21 -> 92.98 | P21: 2 | Q21: =N21*P21 -> 371.92 | S21: 14 | T21: =U21*$N$35 -> 162.42 | U21: =11.77+AA21 -> 81.21 | V21: 2 | W21: =T21*V21 -> 324.84 | Y21: 14 | Z21: =AA21*$N$35 -> 138.88 | AA21: =11.77+AG21 -> 69.44 | AB21: 2 | AC21: =Z21*AB21 -> 277.76 | AE21: 14 | AF21: =AG21*$N$35 -> 115.34 | AG21: =11.77+AM21 -> 57.67 | AH21: 2 | AI21: =AF21*AH21 -> 230.68 | AK21: 14 | AL21: =AM21*$N$35 -> 91.8 | AM21: =11.77+AS21 -> 45.9 | AN21: 2 | AO21: =AL21*AN21 -> 183.6 | AQ21: 14 | AR21: =AS21*$N$35 -> 68.26 | AS21: =11.76+AY21 -> 34.13 | AT21: 2 | AU21: =AR21*AT21 -> 136.52 | AW21: 14 | AX21: =AY21*$N$35 -> 44.74 | AY21: =11.59+BE21 -> 22.37 | AZ21: 2 | BA21: =AX21*AZ21 -> 89.48 | BC21: 14 | BD21: =BE21*$N$35 -> 21.56 | BE21: =5.57+BK21 -> 10.78 | BF21: 2 | BG21: =BD21*BF21 -> 43.12 | BI21: 14 | BJ21: =BK21*$N$35 -> 10.42 | BK21: 5.21 | BL21: 2 | BM21: =BJ21*BL21 -> 20.84
A22: 15 | B22: =C22*$N$35 -> 253.04 | C22: =21.14+I22 -> 126.52 | D22: 4 | E22: =B22*D22 -> 1012.16 | G22: 15 | H22: =I22*$N$35 -> 210.76 | I22: =12.4+O22 -> 105.38 | J22: 4 | K22: =H22*J22 -> 843.04 | M22: 15 | N22: =O22*$N$35 -> 185.96 | O22: =11.77+U22 -> 92.98 | P22: 4 | Q22: =N22*P22 -> 743.84 | S22: 15 | T22: =U22*$N$35 -> 162.42 | U22: =11.77+AA22 -> 81.21 | V22: 4 | W22: =T22*V22 -> 649.68 | Y22: 15 | Z22: =AA22*$N$35 -> 138.88 | AA22: =11.77+AG22 -> 69.44 | AB22: 4 | AC22: =Z22*AB22 -> 555.52 | AE22: 15 | AF22: =AG22*$N$35 -> 115.34 | AG22: =11.77+AM22 -> 57.67 | AH22: 4 | AI22: =AF22*AH22 -> 461.36 | AK22: 15 | AL22: =AM22*$N$35 -> 91.8 | AM22: =11.77+AS22 -> 45.9 | AN22: 4 | AO22: =AL22*AN22 -> 367.2 | AQ22: 15 | AR22: =AS22*$N$35 -> 68.26 | AS22: =11.76+AY22 -> 34.13 | AT22: 4 | AU22: =AR22*AT22 -> 273.04 | AW22: 15 | AX22: =AY22*$N$35 -> 44.74 | AY22: =11.59+BE22 -> 22.37 | AZ22: 4 | BA22: =AX22*AZ22 -> 178.96 | BC22: 15 | BD22: =BE22*$N$35 -> 21.56 | BE22: =5.57+BK22 -> 10.78 | BF22: 4 | BG22: =BD22*BF22 -> 86.24 | BI22: 15 | BJ22: =BK22*$N$35 -> 10.42 | BK22: 5.21 | BL22: 4 | BM22: =BJ22*BL22 -> 41.68
A23: 16 | B23: =C23*$N$35 -> 240.96 | C23: =20.57+I23 -> 120.48 | D23: 2 | E23: =B23*D23 -> 481.92 | G23: 16 | H23: =I23*$N$35 -> 199.82 | I23: =11.94+O23 -> 99.91 | J23: 2 | K23: =H23*J23 -> 399.64 | M23: 16 | N23: =O23*$N$35 -> 175.94 | O23: =11.25+U23 -> 87.97 | P23: 2 | Q23: =N23*P23 -> 351.88 | S23: 16 | T23: =U23*$N$35 -> 153.44 | U23: =11.19+AA23 -> 76.72 | V23: 2 | W23: =T23*V23 -> 306.88 | Y23: 16 | Z23: =AA23*$N$35 -> 131.06 | AA23: =11.16+AG23 -> 65.53 | AB23: 2 | AC23: =Z23*AB23 -> 262.12 | AE23: 16 | AF23: =AG23*$N$35 -> 108.74 | AG23: =11.12+AM23 -> 54.37 | AH23: 2 | AI23: =AF23*AH23 -> 217.48 | AK23: 16 | AL23: =AM23*$N$35 -> 86.5 | AM23: =11.09+AS23 -> 43.25 | AN23: 2 | AO23: =AL23*AN23 -> 173 | AQ23: 16 | AR23: =AS23*$N$35 -> 64.32 | AS23: =11.05+AY23 -> 32.16 | AT23: 2 | AU23: =AR23*AT23 -> 128.64 | AW23: 16 | AX23: =AY23*$N$35 -> 42.22 | AY23: =10.89+BE23 -> 21.11 | AZ23: 2 | BA23: =AX23*AZ23 -> 84.44 | BC23: 16 | BD23: =BE23*$N$35 -> 20.44 | BE23: =5.27+BK23 -> 10.22 | BF23: 2 | BG23: =BD23*BF23 -> 40.88 | BI23: 16 | BJ23: =BK23*$N$35 -> 9.9 | BK23: 4.95 | BL23: 2 | BM23: =BJ23*BL23 -> 19.8
A24: 17 | B24: =C24*$N$35 -> 213.82 | C24: =18.58+I24 -> 106.91 | D24: 4 | E24: =B24*D24 -> 855.28 | G24: 17 | H24: =I24*$N$35 -> 176.66 | I24: =10.66+O24 -> 88.33 | J24: 4 | K24: =H24*J24 -> 706.64 | M24: 17 | N24: =O24*$N$35 -> 155.34 | O24: =9.97+U24 -> 77.67 | P24: 4 | Q24: =N24*P24 -> 621.36 | S24: 17 | T24: =U24*$N$35 -> 135.4 | U24: =9.87+AA24 -> 67.7 | V24: 4 | W24: =T24*V24 -> 541.6 | Y24: 17 | Z24: =AA24*$N$35 -> 115.66 | AA24: =9.81+AG24 -> 57.83 | AB24: 4 | AC24: =Z24*AB24 -> 462.64 | AE24: 17 | AF24: =AG24*$N$35 -> 96.04 | AG24: =9.78+AM24 -> 48.02 | AH24: 4 | AI24: =AF24*AH24 -> 384.16 | AK24: 17 | AL24: =AM24*$N$35 -> 76.48 | AM24: =9.76+AS24 -> 38.24 | AN24: 4 | AO24: =AL24*AN24 -> 305.92 | AQ24: 17 | AR24: =AS24*$N$35 -> 56.96 | AS24: =9.73+AY24 -> 28.48 | AT24: 4 | AU24: =AR24*AT24 -> 227.84 | AW24: 17 | AX24: =AY24*$N$35 -> 37.5 | AY24: =9.62+BE24 -> 18.75 | AZ24: 4 | BA24: =AX24*AZ24 -> 150 | BC24: 17 | BD24: =BE24*$N$35 -> 18.26 | BE24: =4.71+BK24 -> 9.13 | BF24: 4 | BG24: =BD24*BF24 -> 73.04 | BI24: 17 | BJ24: =BK24*$N$35 -> 8.84 | BK24: 4.42 | BL24: 4 | BM24: =BJ24*BL24 -> 35.36
A25: 18 | B25: =C25*$N$35 -> 150.76 | C25: =13.29+I25 -> 75.38 | D25: 2 | E25: =B25*D25 -> 301.52 | G25: 18 | H25: =I25*$N$35 -> 124.18 | I25: =7.52+O25 -> 62.09 | J25: 2 | K25: =H25*J25 -> 248.36 | M25: 18 | N25: =O25*$N$35 -> 109.14 | O25: =7.02+U25 -> 54.57 | P25: 2 | Q25: =N25*P25 -> 218.28 | S25: 18 | T25: =U25*$N$35 -> 95.1 | U25: =6.94+AA25 -> 47.55 | V25: 2 | W25: =T25*V25 -> 190.2 | Y25: 18 | Z25: =AA25*$N$35 -> 81.22 | AA25: =6.89+AG25 -> 40.61 | AB25: 2 | AC25: =Z25*AB25 -> 162.44 | AE25: 18 | AF25: =AG25*$N$35 -> 67.44 | AG25: =6.87+AM25 -> 33.72 | AH25: 2 | AI25: =AF25*AH25 -> 134.88 | AK25: 18 | AL25: =AM25*$N$35 -> 53.7 | AM25: =6.85+AS25 -> 26.85 | AN25: 2 | AO25: =AL25*AN25 -> 107.4 | AQ25: 18 | AR25: =AS25*$N$35 -> 40 | AS25: =6.83+AY25 -> 20 | AT25: 2 | AU25: =AR25*AT25 -> 80 | AW25: 18 | AX25: =AY25*$N$35 -> 26.34 | AY25: =6.77+BE25 -> 13.17 | AZ25: 2 | BA25: =AX25*AZ25 -> 52.68 | BC25: 18 | BD25: =BE25*$N$35 -> 12.8 | BE25: =3.32+BK25 -> 6.4 | BF25: 2 | BG25: =BD25*BF25 -> 25.6 | BI25: 18 | BJ25: =BK25*$N$35 -> 6.16 | BK25: 3.08 | BL25: 2 | BM25: =BJ25*BL25 -> 12.32
A26: 19 | B26: =C26*$N$35 -> 66.6 | C26: =7.62+I26 -> 33.3 | D26: 4 | E26: =B26*D26 -> 266.4 | G26: 19 | H26: =I26*$N$35 -> 51.36 | I26: =3.8+O26 -> 25.68 | J26: 4 | K26: =H26*J26 -> 205.44 | M26: 19 | N26: =O26*$N$35 -> 43.76 | O26: =3.28+U26 -> 21.88 | P26: 4 | Q26: =N26*P26 -> 175.04 | S26: 19 | T26: =U26*$N$35 -> 37.2 | U26: =3.07+AA26 -> 18.6 | V26: 4 | W26: =T26*V26 -> 148.8 | Y26: 19 | Z26: =AA26*$N$35 -> 31.06 | AA26: =2.93+AG26 -> 15.53 | AB26: 4 | AC26: =Z26*AB26 -> 124.24 | AE26: 19 | AF26: =AG26*$N$35 -> 25.2 | AG26: =2.85+AM26 -> 12.6 | AH26: 4 | AI26: =AF26*AH26 -> 100.8 | AK26: 19 | AL26: =AM26*$N$35 -> 19.5 | AM26: =2.81+AS26 -> 9.75 | AN26: 4 | AO26: =AL26*AN26 -> 78 | AQ26: 19 | AR26: =AS26*$N$35 -> 13.88 | AS26: =2.73+AY26 -> 6.94 | AT26: 4 | AU26: =AR26*AT26 -> 55.52 | AW26: 19 | AX26: =AY26*$N$35 -> 8.42 | AY26: =2.48+BE26 -> 4.21 | AZ26: 4 | BA26: =AX26*AZ26 -> 33.68 | BC26: 19 | BD26: =BE26*$N$35 -> 3.46 | BE26: =1.03+BK26 -> 1.73 | BF26: 4 | BG26: =BD26*BF26 -> 13.84 | BI26: 19 | BJ26: =BK26*$N$35 -> 1.4 | BK26: 0.7 | BL26: 4 | BM26: =BJ26*BL26 -> 5.6
A27: FP | B27: =C27*$N$35 -> 0 | C27: 0 | D27: 1 | E27: =B27*D27 -> 0 | G27: FP | H27: =I27*$N$35 -> 0 | I27: 0 | J27: 1 | K27: =H27*J27 -> 0 | M27: FP | N27: =O27*$N$35 -> 0 | O27: 0 | P27: 1 | Q27: =N27*P27 -> 0 | S27: FP | T27: =U27*$N$35 -> 0 | U27: 0 | V27: 1 | W27: =T27*V27 -> 0 | Y27: FP | Z27: =AA27*$N$35 -> 0 | AA27: 0 | AB27: 1 | AC27: =Z27*AB27 -> 0 | AE27: FP | AF27: =AG27*$N$35 -> 0 | AG27: 0 | AH27: 1 | AI27: =AF27*AH27 -> 0 | AK27: FP | AL27: =AM27*$N$35 -> 0 | AM27: 0 | AN27: 1 | AO27: =AL27*AN27 -> 0 | AQ27: FP | AR27: =AS27*$N$35 -> 0 | AS27: 0 | AT27: 1 | AU27: =AR27*AT27 -> 0 | AW27: FP | AX27: =AY27*$N$35 -> 0 | AY27: 0 | AZ27: 1 | BA27: =AX27*AZ27 -> 0 | BC27: FP | BD27: =BE27*$N$35 -> 0 | BE27: =0+BK27 -> 0 | BF27: 1 | BG27: =BD27*BF27 -> 0 | BI27: FP | BJ27: =BK27*$N$35 -> 0 | BK27: 0 | BL27: 1 | BM27: =BJ27*BL27 -> 0
A28: ∑ A x Fs | D28: =SUM(E5:E27) -> 12296.976 | G28: ∑ A x Fs | J28: =SUM(K5:K27) -> 10081.824 | M28: ∑ A x Fs | P28: =SUM(Q5:Q27) -> 8810.035 | S28: ∑ A x Fs | V28: =SUM(W5:W27) -> 7637.222 | Y28: ∑ A x Fs | AB28: =SUM(AC5:AC27) -> 6490.18 | AE28: ∑ A x Fs | AH28: =SUM(AI5:AI27) -> 5361.22 | AK28: ∑ A x Fs | AN28: =SUM(AO5:AO27) -> 4244.5 | AQ28: ∑ A x Fs | AT28: =SUM(AU7:AU27) -> 3137.2 | AW28: ∑ A x Fs | AZ28: =SUM(BA7:BA27) -> 2041 | BC28: ∑ A x Fs | BF28: =SUM(BG7:BG27) -> 972 | BI28: ∑ A x Fs | BL28: =SUM(BM7:BM27) -> 463.24
A29: V Displacement | D29: =1/3*D28*N33 -> 28662.202 | G29: V Displacement | J29: =1/3*J28*N33 -> 23499.051 | M29: V Displacement | P29: =1/3*P28*N33 -> 20534.723 | S29: V Displacement | V29: =1/3*V28*N33 -> 17801.092 | Y29: V Displacement | AB29: =1/3*AB28*N33 -> 15127.528 | AE29: V Displacement | AH29: =1/3*AH28*N33 -> 12496.11 | AK29: V Displacement | AN29: =1/3*AN28*N33 -> 9893.2221 | AQ29: V Displacement | AT29: =1/3*AT28*N33 -> 7312.2903 | AW29: V Displacement | AZ29: =1/3*AZ28*N33 -> 4757.2308 | BC29: V Displacement | BF29: =1/3*BF28*N33 -> 2265.57 | BI29: V Displacement | BL29: =1/3*BL28*N33 -> 1079.7352
A30: Displacement | D30: =D29*N34 -> 29378.757 | G30: Displacement | J30: =J29*N34 -> 24086.528 | M30: Displacement | P30: =P29*N34 -> 21048.091 | S30: Displacement | V30: =V29*N34 -> 18246.119 | Y30: Displacement | AB30: =AB29*N34 -> 15505.716 | AE30: Displacement | AH30: =AH29*N34 -> 12808.513 | AK30: Displacement | AN30: =AN29*N34 -> 10140.553 | AQ30: Displacement | AT30: =AT29*N34 -> 7495.0976 | AW30: Displacement | AZ30: =AZ29*N34 -> 4876.1616 | BC30: Displacement | BF30: =BF29*N34 -> 2322.2092 | BI30: Displacement | BL30: =BL29*N34 -> 1106.7286
M32: lpp | N32: 139.85
A33: Main Deck | M33: h lpp | N33: =N32/20 -> 6.9925
M34: ρ air laut | N34: 1.025
A35: Station | B35: Area | C35: Area/2 | D35: Fs | E35: A x Fs | N35: 2
A36: -2 | B36: 0 | C36: 0 | D36: 0.3 | E36: =C36*D36 -> 0
A37: -1 | B37: =C37*$N$35 -> 5.3 | C37: =2.65+I37 -> 2.65 | D37: 1.2 | E37: =C37*D37 -> 3.18
A38: AP | B38: =C38*$N$35 -> 8.1 | C38: =4.05+I38 -> 4.05 | D38: 1.3 | E38: =B38*D38 -> 10.53
A39: 1 | B39: =C39*$N$35 -> 13.2 | C39: =6.6+I39 -> 6.6 | D39: 4 | E39: =B39*D39 -> 52.8
A40: 2 | B40: =C40*$N$35 -> 17.82 | C40: =8.91+I40 -> 8.91 | D40: 2 | E40: =B40*D40 -> 35.64
A41: 3 | B41: =C41*$N$35 -> 21.22 | C41: =10.61+I41 -> 10.61 | D41: 4 | E41: =B41*D41 -> 84.88
A42: 4 | B42: =C42*$N$35 -> 23.42 | C42: =11.71+I42 -> 11.71 | D42: 2 | E42: =B42*D42 -> 46.84
A43: 5 | B43: =C43*$N$35 -> 24.28 | C43: =12.14+I43 -> 12.14 | D43: 4 | E43: =B43*D43 -> 97.12
...

Sheet GT
I5: 247.18
I6: 264.04
H14: 2954.541 | P14: 42.98
P15: 66.8
F16: 23499.051

Sheet DOC 1 ATTACH
A1: Detail of Calculation on Ship Resistance
A3: Type of Ship | G3: OIL TANKER
A4: LPP | G4: =HOLTROP!G4 -> 137 | H4: m
A5: LWL | G5: =HOLTROP!G5 -> 142.48 | H5: m
A6: B | G6: =HOLTROP!G6 -> 23.7 | H6: m
A7: H | G7: =HOLTROP!G7 -> 13.34 | H7: m
A8: T | G8: =HOLTROP!G8 -> 9.947 | H8: m | J8: Lpp(B+T)+ 0.85 Lpp(H-T)+0.85{(L1.h1)+0.75(L2.h2)}
A9: Vs | G9: =HOLTROP!G9 -> 16 | H9: knot
A10: Cb | G10: =HOLTROP!G10 -> 0.68
A11: Cm | G11: =HOLTROP!G11 -> 0.982
A12: Cp | G12: =HOLTROP!G12 -> 0.69
A13: Volume Displacement | G13: =G27 -> 22401.14 | H13: m3
K14: =G5*G6*G8*G10 -> 22840.378 | M14: =K14-G27 -> 439.23803
A16: Using Data From Design 1
A18: Cb | G18: =G10 -> 0.68
A19: Cm | G19: =G11 -> 0.982 | K19: B/T = | L19: =G6/G8 -> 2.3826279
A20: Cp | G20: =G12 -> 0.69
A21: Am | G21: =G19*G6*G8 -> 231.50051
A22: L Displacement | G22: =1/2*(G4+G5) -> 139.74 | H22: m | K22: 3.28084
G23: =G22*3.28084 -> 458.46458 | H23: ft
A24: Speed Length Ratio | G24: =G9/G23^(1/2) -> 0.747252
A26: Am | G26: =G19*G6*G8 -> 231.50051 | H26: m² | M26: =K28/17500 -> 0.31206676
A27: Volume Displacement | G27: =G18*G22*G6*G8 -> 22401.14 | H27: m3
A28: Displacement Weight | G28: =G27*1.025 -> 22961.168 | H28: ton | J28: lwt = | K28: =G28-17500 -> 5461.1683
A29: Wetted Surface (S) | G29: =1.025*G4*((G10*G6)+(1.7*G8)) -> 4637.662 | H29: m²
A30: Faktor Bentuk (K) | G30: =19*(G10*(G6/G5))^2 -> 0.2430862
A32: LCB | G32: 0.005
A33: Assumptions
A35: Sea Water Temp (Standart Indonesian Sea Temperature) | G35: 25 | H35: ⁰C
A36: Viscosity Kinematics | G36: 8.93e-07
A37: Density of sea water | G37: 1.025 | H37: ton/m3
A47: HOLTROP EQUATION:
A52: Holtrop Limitation
A53: Fn <= | B53: 1
A54: Cp = | B54: 0.785
A55: B/T = | B55: =G6/G8 -> 2.3826279
A56: L/B = | B56: =G5/G6 -> 6.0118143
A58: Froude Number
A61: Requirements for Holtrop calculations are Success
A62: Because There is no Froude Number that exceeds the value of 1
...

Sheet DOC 2 ATTACH
A1: Calculation of Gross Tonnage, Amount of Crew, Fresh Water, Fuel Oil and Lubricants
B3: SHIP DATA
B4: Name : MV. Minyak
B5: Type : Oil Tanker
B7: LPP | D7: = | E7: =HOLTROP!G4 -> 137 | G7: m | I7: Main Engine Power | N7: = | O7: =E109 -> 8400 | Q7: kW
B8: LWL | D8: = | E8: =HOLTROP!G5 -> 142.48 | G8: m | I8: Volume Disp | N8: = | O8: =HOLTROP!G13 -> 22401.14 | Q8: m3
B9: Ldisp | D9: = | E9: =(E8+E7)/2 -> 139.74 | G9: m | I9: Endurance | N9: = | O9: 3 | Q9: days
B10: B | D10: = | E10: =HOLTROP!G6 -> 23.7 | G10: m | I10: Displacement | N10: = | O10: =1.025*O8 -> 22961.168 | Q10: ton
B11: H | D11: = | E11: =HOLTROP!G7 -> 13.34 | G11: m | I11: Weight Tonnage | N11: = | O11: =H194 -> 840.45309 | Q11: ton
B12: T | D12: = | E12: =HOLTROP!G8 -> 9.947 | G12: m
B13: Vs | D13: = | E13: =HOLTROP!G9 -> 16 | G13: Knot
B14: Cb | D14: = | E14: =HOLTROP!G10 -> 0.68
B15: Cp | D15: = | E15: =HOLTROP!G12 -> 0.69
B16: L Main Deck | D16: = | E16: 144.4434 | G16: m
A18: A. Calculation of Gross Tonnage
B20: 1. Calculation of the Volume Displacement below WL
C21: Using Simpson rules from Design 2:
C22: Vol | D22: = | E22: LWL * B * T * Cb | J22: m3
D23: = | E23: =E8 *E10 *E12 *E14 -> 22840.378 | J23: m^3
B25: 2. Calculation volume displacement from LWL until main deck
C26: Using Simpson rules:
C27: Vol | D27: = | E27: Lmain * B * (H-T) * Cb
E28: =E16 * E10 * (E11-E12) *E14 -> 7898.3945 | H28: m3
B30: 3. Calculation volume of the poop deck
C31: wl | D31: Area | I31: Fs | L31: A x Fs
C32: =E12 -> 9.947 | D32: 209.0116 | I32: 0.5 | J32: 1 | L32: =D32*I32 -> 104.5058 | M32: =D32*J32 -> 209.0116
J33: 4 | M33: =D33*J33 -> 0
C34: =E11 -> 13.34 | D34: 264.04 | I34: 0.5 | J34: 1 | L34: =D34*I34 -> 132.02 | M34: =D34*J34 -> 264.04
H35: Total | L35: =SUM(L32:L34) -> 236.5258 | M35: =SUM(M32:M34) -> 473.0516
H36: Volume | L36: = | M36: h x Total
L37: = | M37: =(C34-C32)*L35 -> 802.53204 | P37: m3
B39: 4. Calculation volume of the forecastle deck
C40: wl | D40: Area | H40: Fs | L40: A x Fs
C41: 9.947 | D41: 42.98 | H41: 0.5 | L41: =D41*H41 -> 21.49
C42: 13.34 | D42: 66.8 | H42: 0.5 | L42: =D42*H42 -> 33.4
H43: Total | L43: =SUM(L41:N42) -> 54.89
H44: Volume | L44: = | M44: h x Total
L45: = | M45: =2.5*L43 -> 137.225 | P45: m3
B47: 5. Calculation volume of superstructure
B48: wl | E48: Area | H48: t | J48: volume
...

Sheet DOC 3 ATTACH
A1: TANK CAPACITY AND PAYLOAD
B3: SHIP DATA
B4: Name : MV. Minyak
B5: Type : Oil Tanker
B7: LPP | D7: = | E7: =HOLTROP!G4 -> 137 | G7: m | I7: Main Engine Power | N7: = | O7: 8400 | Q7: kW
B8: LWL | D8: = | E8: =HOLTROP!G5 -> 142.48 | G8: m | I8: Volume Disp | N8: = | O8: =HOLTROP!G13 -> 22401.14 | Q8: m3
B9: Ldisp | D9: = | E9: =(E8+E7)/2 -> 139.74 | G9: m | I9: Endurance | N9: = | O9: 10 | Q9: days
B10: B | D10: = | E10: =HOLTROP!G6 -> 23.7 | G10: m | I10: Displacement | N10: = | O10: =1.026*O8 -> 22983.569 | Q10: ton
B11: H | D11: = | E11: =HOLTROP!G7 -> 13.34 | G11: m | I11: W. Total of Consumable | N11: = | O11: ='DOC 2 ATTACH'!H194 -> 840.45309 | Q11: ton
B12: T | D12: = | E12: =HOLTROP!G8 -> 9.947 | G12: m
B13: Vs | D13: = | E13: =HOLTROP!G9 -> 16 | G13: Knot
B14: Cb | D14: = | E14: =HOLTROP!G10 -> 0.68
B15: Cp | D15: = | E15: =HOLTROP!G12 -> 0.69
B16: Cm | D16: = | E16: =HOLTROP!G11 -> 0.982
A18: A. LWT Calculation
B20: 1. Ship Steel Weight
B21: The calculation of ship steel weight based on the formula from Watson, RINA(Practical Ship Design, DGM Watson):
B24: E(Llyod's equipment num) = Lpp(B+T)+ 0.85 Lpp(H-T)+0.85{(L1.h1)+0.75(L2.h2)}
B26: In which: | E26: L1 | F26: = | G26: Forecastle deck length | L26: = | M26: 15 | O26: m
E27: h1 | F27: = | G27: Forecastle height | L27: = | M27: 2.5 | O27: m
E28: L2 | F28: = | G28: Poopdeck length | L28: = | M28: 30.68 | O28: m
E29: h2 | F29: = | G29: Poopdeck height | L29: = | M29: 2.5 | O29: m
B31: So, the value of E | F31: = | G31: =(E7*(E10+E12))+(0.85*E7*(E11-E12))+0.85*((M26*M27)+0.75*(M28*M29)) -> 5085.5251 | I31: m2
B33: Ship Steel Weight(Wst)
B34: Wst = K x E^1.36
B36: Which K value can be obtained from the table which is stated in practical ship design page 85
E53: based on the table on Practical Ship Design by Watson
E54: page
C55: Wst | D55: = | E55: K x E^1.36 | H55: k = | I55: 0.035 | K55: (estimated)
D56: = | E56: =I55*(G31)^(1.36) -> 3843.127 | G56: Ton
B58: 2. Outfit and Accomodation
C59: WOA | D59: = | E59: 0.4 x Lpp x B
D60: = | E60: =0.4*E7*E10 -> 1298.76 | G60: Ton | H60: (Practical Ship Design Page. 100 DGM Watson)
B62: 3. Engine Installation Weight
C63: Wmt | D63: = | E63: 0.72 x MCR^0.78
D64: = | E64: =0.72*(O7)^0.78 -> 828.4577 | G64: Ton
B66: 4. Reserved Weight (WRes)
C67: Wres | D67: = | E67: 2.5%(Wst+WOA+Wmt)
D68: = | E68: =2.5%*(E56+E60+E64) -> 149.25862 | G68: Ton
B70: 5. Total LWT | O70: 2.142
...

Sheet SARAT KOSONG
A2: Type of Ship | G2: OIL TANKER
A3: LPP | G3: =HOLTROP!G4 -> 137 | H3: m
A4: LWL | G4: =HOLTROP!G5 -> 142.48 | H4: m
A5: B | G5: =HOLTROP!G6 -> 23.7 | H5: m
A6: H | G6: =HOLTROP!G7 -> 13.34 | H6: m | K6: Lpp(B+T)+ 0.85 Lpp(H-T)+0.85{(L1.h1)+0.75(L2.h2)}
A7: T | G7: =HOLTROP!G8 -> 9.947 | H7: m
A8: Vs | G8: =HOLTROP!G9 -> 16 | H8: knot
A9: Cb | G9: =HOLTROP!G10 -> 0.68
A10: Cm | G10: =HOLTROP!G11 -> 0.982
A11: Cp | G11: =HOLTROP!G12 -> 0.69
A12: Volume Displacement | G12: =G27 -> 22401.14 | H12: m3
A14: Calculation of Ship Dimension
A16: Using Data From Design 1
A18: Cb | G18: =G9 -> 0.68
A19: Cm | G19: =G10 -> 0.982
A20: Cp | G20: =G11 -> 0.69
A21: Am | G21: =G19*G5*G7 -> 231.50051
A22: L Displacement | G22: =1/2*(G3+G4) -> 139.74 | H22: m
G23: =G22*3.28084 -> 458.46458 | H23: ft
A24: Speed Length Ratio | G24: =G8/G23^(1/2) -> 0.747252
A26: Am | G26: =G19*G5*G7 -> 231.50051 | H26: m²
A27: Volume Displacement | G27: =G18*G22*G5*G7 -> 22401.14 | H27: m3
A28: Displacement Weight | G28: =G27*1.025 -> 22961.168 | H28: ton
A29: Wetted Surface (S) | G29: =1.025*G3*((G9*G5)+(1.7*G7)) -> 4637.662 | H29: m²
A30: Faktor Bentuk (K) | G30: =19*(G9*(G5/G4))^2 -> 0.2430862
J31: BUSAN
A32: LCB | G32: 0.005
A36: SARAT KAPAL KOSONG ENGINE MAN L32/44CR | AM36: SARAT KAPAL KOSONG ENGINE CAT M 32 C | BF36: SARAT KAPAL KOSONG ENGINE WARTSILA 7L32
A37: Perhitungan Berat Kebutuhan Tangki | AM37: Perhitungan Berat Kebutuhan Tangki | BF37: Perhitungan Berat Kebutuhan Tangki
A38: 1. | B38: Berat Bahan Bakar Mesin Induk | T38: Volume HFO Settling Tank | W38: 24 jam | AM38: 1. | AN38: Berat Bahan Bakar Mesin Induk | BF38: 1. | BG38: Berat Bahan Bakar Mesin Induk
B39: WFO | C39: = | D39: BHPME . bME . (S/Vs) . 10-6 . C | G39: (Ton) | T39: W = | U39: =4800*178*24*10^-6 *1.5 -> 30.7584 | V39: ton | X39: Dimana ρ diesel = | Z39: 0.95 | AA39: ton/m3 | AN39: WFO | AO39: = | AP39: BHPME . bME . (S/Vs) . 10-6 . C | AS39: (Ton) | BG39: WFO | BH39: = | BI39: BHPME . bME . (S/Vs) . 10-6 . C | BL39: (Ton)
B40: Keterangan : | E40: BHPME | G40: = | H40: BHP Mesin utama dari catalog (kW) | N40: waktu tempuh | O40: =O45/K46 -> 260.84615 | P40: jam | T40: Vol = | U40: =U39/Z39 -> 32.377263 | V40: m3 | AN40: Keterangan : | AQ40: BHPME | AS40: = | AT40: BHP Mesin utama dari catalog (kW) | AZ40: waktu tempuh | BA40: =BA45/AW46 -> 260.84615 | BB40: jam | BG40: Keterangan : | BJ40: BHPME | BL40: = | BM40: BHP Mesin utama dari catalog (kW) | BS40: waktu tempuh | BT40: =BT45/BP46 -> 260.84615 | BU40: jam
E41: bME | G41: = | H41: Spesifik konsumsi bahan bakar mesin induk =178 g/kWh | O41: =O44/K45 -> 260.84615 | AQ41: bME | AS41: = | AT41: Spesifik konsumsi bahan bakar mesin induk =178 g/kWh | BA41: =BA44/AW45 -> 260.84615 | BJ41: bME | BL41: = | BM41: Spesifik konsumsi bahan bakar mesin induk =178 g/kWh | BT41: =BT44/BP45 -> 260.84615
E42: S | G42: = | H42: Rute Pelayaran (Nautical Miles) | O42: =O41/24 -> 10.86859 | P42: days | T42: Volume HFO Service Tank | W42: 8 jam | AQ42: S | AS42: = | AT42: Rute Pelayaran (Nautical Miles) | BA42: =BA41/24 -> 10.86859 | BB42: days | BJ42: S | BL42: = | BM42: Rute Pelayaran (Nautical Miles) | BT42: =BT41/24 -> 10.86859 | BU42: days
E43: Vs | G43: = | H43: Kecepatan Kapal (Knots) | T43: W= | U43: =4800*178*8*10^-6 *1.5 -> 10.2528 | AQ43: Vs | AS43: = | AT43: Kecepatan Kapal (Knots) | BJ43: Vs | BL43: = | BM43: Kecepatan Kapal (Knots)
E44: C | G44: = | H44: Koreksi Cadangan (1.3-1.5) | N44: S = | O44: 3391 | P44: nm | T44: Vol= | U44: =U43/Z39 -> 10.792421 | V44: m3 | AQ44: C | AS44: = | AT44: Koreksi Cadangan (1.3-1.5) | AZ44: S = | BA44: 3391 | BB44: nm | BJ44: C | BL44: = | BM44: Koreksi Cadangan (1.3-1.5) | BS44: S = | BT44: 3391 | BU44: nm
B45: WFO | C45: = | D45: BHPME . bME . (S/Vs) . 10-6 . C | J45: Vs = | K45: 13 | L45: knot | N45: = | O45: =O44*1.852 -> 6280.132 | P45: km | AN45: WFO | AO45: = | AP45: BHPME . bME . (S/Vs) . 10-6 . C | AV45: Vs = | AW45: 13 | AX45: knot | AZ45: = | BA45: =BA44*1.852 -> 6280.132 | BB45: km | BG45: WFO | BH45: = | BI45: BHPME . bME . (S/Vs) . 10-6 . C | BO45: Vs = | BP45: 13 | BQ45: knot | BS45: = | BT45: =BT44*1.852 -> 6280.132 | BU45: km
C46: = | D46: 4480 . 178 . 3391/13 . 10-6 . 1,5 | J46: = | K46: =K45*1.852 -> 24.076 | L46: km/h | AO46: = | AP46: 3840 . 177 . 3391/13 . 10-6 . 1,5 | AV46: = | AW46: =AW45*1.852 -> 24.076 | AX46: km/h | BH46: = | BI46: 4060 . 185. 3391/13 . 10-6 . 1,5 | BO46: = | BP46: =BP45*1.852 -> 24.076 | BQ46: km/h
C47: = | D47: =4800*178*(O44/K45)*10^-6 *1.5 -> 334.30043 | F47: Ton | H47: =4480*178*(24)*10^-6 *1.5 -> 28.70784 | AO47: = | AP47: =3840*177*(BA44/AW45)*10^-6 *1.5 -> 265.93787 | AR47: Ton | BH47: = | BI47: =4060*185*(BT44/BP45)*10^-6 *1.5 -> 293.88232 | BK47: Ton
M48: "Tentang Rencana Umum" Gaguk Suhardjito 2006 hal 16 | AY48: "Tentang Rencana Umum" Gaguk Suhardjito 2006 hal 16 | BR48: "Tentang Rencana Umum" Gaguk Suhardjito 2006 hal 16
...

Sheet Tank
A1: payload
A2: volume | B2: 18974.457 | C2: m3 | D2: =B2/0.98 -> 19361.691
A4: ballast
A5: volume | B5: 5028.0073 | C5: m3
A7: total | B7: =B2+B5 -> 24002.464 | C7: m3
A9: total cargo+doubel bottom+wing tank | H9: Ballast double bottom | M9: vol double bottom + wing tank | P9: =K15+H81 -> 5713.1537 | Q9: m3
A10: wl | B10: 1/2 area | C10: fs | D10: area x fs | H10: wl | I10: 1/2 area | J10: fs | K10: area x fs
A11: 0 | B11: 922.49 | C11: 1 | D11: =B11*C11 -> 922.49 | H11: 0 | I11: 872.09 | J11: 1 | K11: =I11*J11 -> 872.09 | M11: vol cargo tank | O11: =D29-P9 -> 21947.283 | P11: m3
A12: 1 | B12: 1077.69 | C12: 3 | D12: =B12*C12 -> 3233.07 | H12: 0.67 | I12: 1050.46 | J12: 4 | K12: =I12*J12 -> 4201.84
A13: 2 | B13: 1116.54 | C13: 3 | D13: =B13*C13 -> 3349.62 | H13: 1.33 | I13: 1096.64 | J13: 1 | K13: =I13*J13 -> 1096.64 | M13: cargo tank lebih | O13: =O11-B2 -> 2972.8261 | P13: m3
A14: 3 | B14: 1116.72 | C14: 2 | D14: =B14*C14 -> 2233.44 | K14: =SUM(K11:K13) -> 6170.57
A15: 4 | B15: 1128.03 | C15: 3 | D15: =B15*C15 -> 3384.09 | J15: vol | K15: =2*1/3*(1.33/2)*K14 -> 2735.6194 | L15: m3 | M15: slop tank | O15: =0.03*B2 -> 569.2337 | P15: m3
A16: 5 | B16: 1130.65 | C16: 3 | D16: =B16*C16 -> 3391.95
A17: 6 | B17: 1132.88 | C17: 2 | D17: =B17*C17 -> 2265.76 | M17: HFO bunker | O17: 341.70431 | P17: m3
A18: 7 | B18: 1135.52 | C18: 3 | D18: =B18*C18 -> 3406.56 | M18: HFO Settling | O18: 30.218779 | P18: m3 | Q18: X | R18: =2*3.75*3*2 -> 45
A19: 8 | B19: 1138.92 | C19: 3 | D19: =B19*C19 -> 3416.76 | M19: HFO Service | O19: ='SARAT KOSONG'!U44 -> 10.792421 | P19: m3 | Q19: X | R19: =3*4*2.1 -> 25.2 | S19: =R19/2 -> 12.6
A20: 9 | B20: 1143.07 | C20: 1 | D20: =B20*C20 -> 1143.07
D21: =SUM(D11:D20) -> 26746.81 | M21: MDO Storage | O21: =0.15*O17 -> 51.255646 | P21: m3
C22: vol | D22: =2*3/8*1*D21 -> 20060.107 | E22: m3 | M22: MDO Service | O22: =0.2*O19 -> 2.1584842 | P22: m3 | Q22: X | R22: =2*1*1*2 -> 4
A24: 9.05 | B24: 1143.07 | C24: 0.5 | D24: =B24*C24 -> 571.535 | M24: LO Tank | O24: 1.4043864 | P24: m3 | Q24: x | R24: =2*1.5*1*1 -> 3
A25: 12.35 | B25: 1160.06 | C25: 0.5 | D25: =B25*C25 -> 580.03
D26: =SUM(D24:D25) -> 1151.565 | M26: Fresh Water Tank | O26: 52.496158 | P26: m3 | Q26: X | R26: =3.75*10.5 -> 39.375
C27: vol | D27: =3.3*D26*2 -> 7600.329 | E27: m3
M28: Sludge Tank | O28: 5.742 | P28: m3 | R28: =2*1.325*4.2*1.5 -> 16.695
C29: vol total | D29: =D27+D22 -> 27660.436 | E29: m3
M30: Oily Bilge Tank | O30: =4480/250 -> 17.92 | P30: m3
A32: Engine room bulkhead ke cargo bulkhead | M32: Sewage | O32: 6 | P32: m3
A33: wl | B33: 1/2 area | C33: fs | D33: area x fs
A34: 0 | B34: 15.79 | C34: 1 | D34: =B34*C34 -> 15.79 | M34: Sea Chest | O34: =4800/750 -> 6.4 | P34: m3
A35: 1 | B35: 24.64 | C35: 3 | D35: =B35*C35 -> 73.92
A36: 2 | B36: 26.55 | C36: 3 | D36: =B36*C36 -> 79.65
A37: 3 | B37: 27.52 | C37: 2 | D37: =B37*C37 -> 55.04
A38: 4 | B38: 28.17 | C38: 3 | D38: =B38*C38 -> 84.51
A39: 5 | B39: 28.77 | C39: 3 | D39: =B39*C39 -> 86.31
A40: 6 | B40: 29.45 | C40: 2 | D40: =B40*C40 -> 58.9
A41: 7 | B41: 30.25 | C41: 3 | D41: =B41*C41 -> 90.75
A42: 8 | B42: 31.19 | C42: 3 | D42: =B42*C42 -> 93.57
A43: 9 | B43: 32.29 | C43: 1 | D43: =B43*C43 -> 32.29
D44: =SUM(D34:D43) -> 670.73
C45: vol | D45: =2*3/8*1*D44 -> 503.0475 | E45: m3
...

Sheet HOLTROP
A1: Principle Dimension
A3: Type of Ship | G3: {=[5]HARVARLD!$F$4:$G$4} -> Product Oil Tanker | H3: 0
A4: LPP | G4: =[5]HARVARLD!$F$6 -> 137 | H4: m
A5: LWL | G5: =[5]HARVARLD!$F$8 -> 142.48 | H5: m
A6: B | G6: =[5]HARVARLD!$F$16 -> 23.7 | H6: m
A7: H | G7: =[5]HARVARLD!$F$25 -> 13.34 | H7: m
A8: T | G8: =[5]HARVARLD!$F$23 -> 9.947 | H8: m | J8: Lpp(B+T)+ 0.85 Lpp(H-T)+0.85{(L1.h1)+0.75(L2.h2)}
A9: Vs | G9: =[5]HARVARLD!$F$27 -> 16 | H9: knot
A10: Cb | G10: =[5]HARVARLD!$F$31 -> 0.68
A11: Cm | G11: =[5]HARVARLD!$F$30 -> 0.982
