Workbook

Sheet JARAK
B2: GENERAL ARRANGEMENT
B4: Nama Mahasiswa | E4: : Daffa Gabillah Maulana Gapur
B5: Dosen
B6: DATA KAPAL
B8: Tipe Kapal | D8: Tanker
B9: IMO-N
B10: Klasifikasi
B11: Panjang (Lpp) | C11: = | D11: =HARVARLD!F6 -> #REF! | E11: m
B12: Lebar (B) | C12: = | D12: 23.7 | E12: m
B13: Tinggi Geladak (H) | C13: = | D13: 13.34 | E13: m
B14: Sarat Air (T) | C14: = | D14: 9.947 | E14: m
B15: Kecepatan Dinas (Vs) | C15: = | D15: 16 | E15: knot
B17: LWL | C17: = | D17: =0.04 * D11 + D11 -> #REF! | E17: m
B19: Cb | C19: = | D19: 0.68
B21: Vdisplacement | D21: =D17 * D12 * D14 * D19 -> #REF! | E21: mᶟ
B22: Jarak Gading (frame spacing)
B24: (Lpp) Panjang | C24: =D11 -> #REF!
B25: (B) Lebar | C25: =D12 -> 23.7
B26: (H) Tinggi Geladak | C26: =D13 -> 13.34
B27: (T) Sarat Air | C27: =D14 -> 9.947
B29: A0 | C29: =(C24/500)+0.48 -> #REF! | D29: meter
C30: 800 | D30: mm
B32: Harga Jarak gading :
B33: Pada sekat ceruk buritan | C33: < 600 | D33: mm
B34: Pada kamar mesin | C34: < 1000 | D34: mm
B35: Pada ruang muat | C35: < 1000 | D35: mm
B36: Pada sekat ceruk haluan | C36: < 600 | D36: mm
B38: Ap ke 0.35T
B39: Panjang Awal 0.35T = | C39: =0.35*C27 -> 3.48145 | D39: m
B40: Jarak Gading = | C40: 600 | D40: mm
B41: Jumlah = | C41: =(C39*1000)/C40 -> 5.8024167 | D41: Jarak Gading
B42: Pembulatan Menjadi = | C42: 4 | D42: Jarak Gading
B43: Panjang Sebenarnya = | C43: =C42*C40 -> 2400 | D43: mm
B44: Nomor Gading = | C44: 4
B46: Sekat Ceruk Buritan (streamtube bulkhead)
B47: Minimal 3 Jarak gading dari 0.35T
B48: Jumlah Jarak Gading = | C48: 3
B49: Jarak Gading = | C49: 600 | D49: mm
B50: Panjang dari 0.35T = | C50: 1800 | D50: mm
B51: Nomor Jarak Gading = | C51: 7
...

Sheet HARVARLD
B2: Data Utama Kapal | F2: Metode Harvald
D4: Jenis Kapal | F4: Product Oil Tanker
D6: Lpp | E6: = | F6: ='[1]General Arrangement'!$D$6 -> #REF! | G6: m | K6: m_to_ft | L6: = | M6: 3.28084 | N6: ft
E7: = | F7: =F6*$M$6 -> #REF! | G7: ft
D8: Lwl | E8: = | F8: =4/100*F6+F6 -> #REF! | G8: m
F9: =F8*$M$6 -> #REF! | G9: ft
D10: 0.96 * LWL | E10: = | F10: =0.96 * F8 -> #REF! | G10: m
D12: 0.97 * LWL | E12: = | F12: =0.97 * F8 -> #REF! | G12: m
D14: Ldisplacement | E14: = | F14: =(F6+F8)*0.5 -> #REF! | G14: m | K14: Perhitungan Data Secondary
F15: =F14*$M$6 -> #REF! | G15: ft
D16: Lebar (B) | E16: = | F16: 23.7 | G16: m | K16: Kecepatan dalam m/s
E17: = | F17: =F16*$M$6 -> 77.755908 | G17: ft
D19: B/2 | E19: = | F19: =F16/2 -> 11.85 | G19: m
E20: = | F20: =F17/2 -> 38.877954 | G20: ft
D23: Sarat Air (T) | E23: = | F23: 9.947 | G23: m | K23: 1 knot = | N23: 0.514444 | O23: m/s
F24: =F23*$M$6 -> 32.634515 | G24: ft
D25: Tinggi Geladak (H) | E25: = | F25: 13.34 | G25: m | K25: =F27 -> 16 | L25: knot | M25: = | N25: =F27*N23 -> 8.231104 | O25: m/s
F26: =F25*$M$6 -> 43.766406 | G26: ft
D27: Kecepatan (Vs) | E27: = | F27: 16 | G27: knot
D28: Vdisplacement | E28: = | F28: =F8*F16*F23*F31 -> #REF! | G28: mᶟ | K28: g = | N28: 9.81 | O28: m/s²
D29: Displacement | E29: = | F29: =F28 * N29 -> #REF! | G29: ton | K29: \rho | M29: = | N29: 1.026 | O29: ton/m^3
D30: Koefisien midship/Cm (β) | E30: = | F30: 0.982 | K30: e% = | N30: 0.005 | O30: didepan midship
D31: Koefisien blok/Cb (δ) | E31: = | F31: 0.68
D32: Koefisien prismatik/Cp (ϕ) | E32: = | F32: 0.69
B33: Tahanan Kapal Metode Harvald
B34: 1 | C34: Menghitung Reynold Number (Rn)
C35: Rn = | D35: (𝑉 𝑥 𝐿𝑤𝑙)/𝑣
G36: Dengan viskositas kinematic air laut pada temperatur 22C adalah 0.978875*10^-6
C37: Rn = | D37: =N25*F8/(0.978875*10^-6) -> #REF!
B38: 2 | C38: Menghitung Froude Number (Fn)
C39: Fn =
C41: Fn = | D41: =N25/(N28*F8)^(1/2) -> #REF!
B42: 3 | C42: Mencari Nilai Luas Permukaan Basah
C43: Luas permukaan basah adalah bagian luas permukaan kapal yang tercelup di air, untuk menghitungnya dilakukan
C44: pendekatan dengan rumus sebagai berikut :
C45: S = | D45: 1.026 * Lwl * (Cb * B + 1.7 * T)
C46: = | D46: =1.026*F8*((F31*F16)+(1.7*F23)) -> #REF! | F46: m³
B48: 4 | C48: Menghitung Koefisien Tahanan Kapal
C49: a. | D49: Menghitung Koefisien Gesek (T)
D50: Untuk menghitung tahanan gesek kapal perlu untuk dicari terlebih dahulu nilai dari koefisien geseknya, dalam
...

Sheet HOLTROP
B2: Data Utama Kapal | E2: Metode Holtrop | I2: Perhitungan Data Secondary
I3: Kecepatan dalam m/s
B4: Jenis Kapal | E4: CHEMICAL TANKER | I4: 1 knot = | J4: 0.514444 | K4: m/s
B5: Lpp | E5: =HARVARLD!F6 -> #REF! | G5: m | I5: 12.99 knot= | J5: =E11*J4 -> 8.231104 | K5: m/s
B6: Lwl | E6: =HARVARLD!F8 -> #REF! | G6: m
B7: Ldisplacement | E7: =HARVARLD!F14 -> #REF! | G7: m | I7: g = | J7: 9.81 | K7: m/s²
B8: Lebar (B) | E8: =HARVARLD!F16 -> 23.7 | G8: m | I8: e% = | J8: =HARVARLD!N30 -> 0.005 | K8: didepan
B9: Sarat Air (T) | E9: =HARVARLD!F23 -> 9.947 | G9: m | I9: ρ air laut | J9: 1.026
B10: Tinggi Geladak (H) | E10: =HARVARLD!F25 -> 13.34 | G10: m | I10: 1 kW = | J10: =HARVARLD!I184 -> 1.3596193 | K10: HP
B11: Kecepatan (Vs) | E11: =HARVARLD!F27 -> 16 | G11: knot
B12: Vdisplacement | E12: =HARVARLD!F28 -> #REF! | G12: mᶟ
B13: Koefisien midship/Cm (β) | E13: =HARVARLD!F30 -> 0.982
B14: Koefisien blok/Cb (δ) | E14: =HARVARLD!F31 -> 0.68 | I14: =E7*E8*E9*E14 -> #REF! | J14: =I14*J9 -> #REF!
B15: Koefisien prismatik/Cp (ϕ) | E15: =HARVARLD!F32 -> 0.69
B16: LCB | E16: =J8*E7 -> #REF!
B17: LOA | E17: ='[2]Lines Plan'!$B$9 -> #REF!
B18: Langkah Perhitungan
B19: 1 | C19: Menghitung Froude Number (Fn)
C20: Fn = | D20: 𝑉/(√𝑔 𝑥 𝐿pp)
C21: = | D21: =J5/(J7*E5)^(1/2) -> #REF!
C23: CWP = | D23: 0.180+0.860∙CPdisp
C24: = | D24: =(0.18)+(0.86*E15) -> 0.7734
B26: 2 | C26: Menghitung Volume Displacement
C27: Vdisp = | D27: Lwl x B x T x Cb wl
C28: = | D28: =E6*E8*E9*E14 -> #REF!
B30: 3 | C30: Menghitung Berat Displacement
C31: Ldisp = | D31: Vdisp x ρ air laut
C32: = | D32: =D28*J9 -> #REF!
B34: 4 | C34: Luas Permukaan Basah (S)
C35: S = | D35: L (2T + B)(Cm0,5) (0,453 + 0,4425 Cb - 0,2862 Cm - 0,003467 (B/T)
C36: = | D36: =E6*(2*(E9)+E8)*(E13^0.5)*(0.453+0.4425*(E14)-0.2862*(E13)-0.003467*(E8/E9)+0.396*(D24))+0 -> #REF!
B38: 5 | C38: Menghitung Frictional Ressistance According to the ITTC Formula (Rf)
B39: a | C39: Menghitung Reynold Number
C40: Rn = | D40: (Vs x Lwl)/υ
C41: = | D41: =(J5*E6)/(0.8847*10^-6) -> #REF!
B43: b | C43: Menghitung LR
C44: LR = | D44: L (1 - Cp + 0.06 x Cp x Lcb /(4 x Cp -1)) | G44: υ = | H44: viskositas kinematis air laut pada 280
C45: = | D45: =E6*(1-E15+0.06*E15*E16/(4*E15-1)) -> #REF! | G45: υ = | H45: 0,8847 x 10^-6
G46: υ = | H46: =0.8847*10^-6 -> 8.847e-07 | I46: m2/s
B47: c | C47: Koefisien Gesek (CF)
...

Sheet EN & GEAR
B2: Data Engine
B3: Merk = | C3: Wartsila | E3: 1 kW = | F3: 1.359619 | G3: HP
B4: Type = | C4: 7L46F | E4: 1 HP = | F4: 0.7355 | G4: kW
B5: Cycle = | C5: 4 stroke
B6: Power max = | C6: 8400 | D6: kW
C7: =C6/F4 -> 11420.802 | D7: HP
B8: Cylinder = | C8: 7
B9: Bore = | C9: 460 | D9: mm
B10: Piston Stroke = | C10: 580 | D10: mm
B11: Dimension = | J11: LE3 | K11: = | L11: 1550 | M11: mm
B12: Length = | C12: =SUM(L11:L13) -> 10005 | D12: mm | J12: LE2 | K12: = | L12: 6990 | M12: mm
B13: Width = | C13: 3130 | D13: mm | J13: LE3* | K13: = | L13: 1465 | M13: mm
B14: Height = | C14: =SUM(L14:L16) -> 5230 | D14: mm | J14: HE3 | K14: = | L14: 1430 | M14: mm
B15: Weight =
B16: Rpm = | C16: 600 | D16: rpm | J16: HE1 | K16: = | L16: 3800 | M16: mm
B17: Displacement | C17: 96.4 | D17: l/cyl
B18: Power factor = | C18: =C6/C16 -> 14
B20: Perhitungan Daya Engine MAK 6M32C
B21: a) BHPMCR = | C21: 8400 | D21: Kw | E21: 1 kW = | F21: 1.359619 | G21: HP
B22: = | C22: =C21/F4 -> 11420.802 | D22: HP
B24: b) BHPSCR = | C24: BHPMCR x 0,9
B25: = | C25: =C21*0.9 -> 7560 | D25: kW
B26: = | C26: =C25/F4 -> 10278.722 | D26: HP
B28: c) SHP = | C28: BHPSCR x ηG
B29: = | C29: =C25*0.98 -> 7408.8 | D29: kW
B30: = | C30: =C29/F4 -> 10073.148 | D30: HP
B32: d) DHP = | C32: SHP x ηSηB
B33: = | C33: =C29*0.98 -> 7260.624 | D33: kW
B34: = | C34: =C33/F4 -> 9871.6846 | D34: HP
B36: e) EHP = | C36: DHP x Pc
B37: = | C37: =C33*HARVARLD!F223 -> 5562.5839 | D37: kW
B38: = | C38: =C37*F21 -> 7562.9948 | D38: HP
B40: f) THP = | C40: EHP x ƞh
B41: = | C41: =C37*HARVARLD!F221 -> 6244.1963 | D41: kW
B42: = | C42: =C41*F21 -> 8489.7279 | D42: HP
B44: Pemilihan gear Box
B46: Merk = | C46: ZF Marine Gearbox
B47: Type = | C47: ZF W43100 NC
B48: Power Factor = | C48: =C18 -> 14
B49: Reduction Ratio = | C49: 4.41
...

Sheet PROPELL (0.969)
B2: Data Utama Kapal | I2: Perhitungan Data Secondary
I3: Kecepatan dalam m/s
B4: Jenis Kapal | E4: CHEMICAL TANKER | I4: 1 knot = | J4: =HARVARLD!N23 -> 0.514444 | K4: m/s
B5: Lpp | E5: =HARVARLD!F6 -> #REF! | G5: m | I5: 1 m/s = | J5: 1.94384 | K5: knot
B6: Lwl | E6: =HARVARLD!F8 -> #REF! | G6: m | I6: 1 kW = | J6: ='EN & GEAR'!F3 -> 1.359619 | K6: HP
B7: Ldisplacement | E7: =HARVARLD!F14 -> #REF! | G7: m | I7: 1 HP = | J7: =HARVARLD!I183 -> 0.7355 | K7: KW
B8: Lebar (B) | E8: =HARVARLD!F16 -> 23.7 | G8: m | I8: 16 knot = | J8: =E11*J4 -> 8.231104 | K8: m/s
B9: Sarat Air (T) | E9: =HARVARLD!F23 -> 9.947 | G9: m | I9: g = | J9: 9.8 | K9: m/s²
B10: Tinggi Geladak (H) | E10: =HARVARLD!F25 -> 13.34 | G10: m | I10: e% = | J10: 0.005 | K10: didepan midship
B11: Kecepatan (Vs) | E11: =HARVARLD!F27 -> 16 | G11: knot
B12: Vdisplacement | E12: =HARVARLD!F28 -> #REF! | G12: mᶟ
B13: Koefisien midship/Cm (β) | E13: =HARVARLD!F30 -> 0.982
B14: Koefisien blok/Cb (δ) | E14: =HARVARLD!F31 -> 0.68
B15: Koefisien prismatik/Cp (ϕ) | E15: =HARVARLD!F32 -> 0.69
B17: Data Utama Engine
B18: Merk | D18: ='EN & GEAR'!C3 -> Wartsila
B19: Type | D19: ='EN & GEAR'!C4 -> 7L46F
B20: Cycle | D20: ='EN & GEAR'!C5 -> 4 stroke
B21: Power max | D21: ='EN & GEAR'!C6 -> 8400 | E21: kW
D22: =D21*J6 -> 11420.8 | E22: HP
B23: Cylinder | D23: ='EN & GEAR'!C8 -> 7
B24: Bore | D24: ='EN & GEAR'!C9 -> 460 | E24: mm
B25: Piston Stroke | D25: ='EN & GEAR'!C10 -> 580 | E25: mm
B27: Dimension
B28: Length | D28: ='EN & GEAR'!C12 -> 10005 | E28: mm
B29: Width | D29: ='EN & GEAR'!C13 -> 3130 | E29: mm
B30: Height | D30: ='EN & GEAR'!C14 -> 5230 | E30: mm
B31: Rpm | D31: ='EN & GEAR'!C16 -> 600
B32: Displacement | D32: ='EN & GEAR'!C17 -> 96.4 | E32: ='EN & GEAR'!D17 -> l/cyl
B33: Power factor | D33: =D21/D31 -> 14
B36: Pemilihan gear Box
G37: tr
B38: Merk | D38: ='EN & GEAR'!C46 -> ZF Marine Gearbox
B39: Type | D39: ='EN & GEAR'!C47 -> ZF W43100 NC
B40: Power Factor | D40: ='EN & GEAR'!C48 -> 14
B41: Ratio | D41: ='EN & GEAR'!C49 -> 4.41 | H41: 335.66642 | I41: 0.005267134
B42: Rpm | D42: ='EN & GEAR'!C50 -> 136.05442 | E42: rpm | H42: =H41*I41 -> 1.768
B43: Input Power | D43: ='EN & GEAR'!C51 -> 0 | E43: kW
B45: Dimension
B46: Length | D46: ='EN & GEAR'!C54 -> 0 | E46: mm | F46: L1+L2
...

Sheet EN & GEAR (2)
B2: Data Engine
B3: Merk = | C3: Wartsila | E3: 1 kW = | F3: 1.359619 | G3: HP
B4: Type = | C4: 7L46F | E4: 1 HP = | F4: 0.7355 | G4: kW
B5: Cycle = | C5: 4 stroke
B6: Power max = | C6: 8400 | D6: kW
C7: =C6/F4 -> 11420.802 | D7: HP
B8: Cylinder = | C8: 7
B9: Bore = | C9: 460 | D9: mm
B10: Piston Stroke = | C10: 580 | D10: mm
B11: Dimension = | J11: LE3 | K11: = | L11: 1550 | M11: mm
B12: Length = | C12: =SUM(L11:L13) -> 10005 | D12: mm | J12: LE2 | K12: = | L12: 6990 | M12: mm
B13: Width = | C13: 3130 | D13: mm | J13: LE3* | K13: = | L13: 1465 | M13: mm
B14: Height = | C14: =SUM(L14:L16) -> 3585 | D14: mm | J14: HE6 | K14: = | L14: 470 | M14: mm
B15: Weight = | D15: ton | J15: HE5 | L15: 1905 | M15: mm
B16: Rpm = | C16: 600 | D16: rpm | J16: HE3 | K16: = | L16: 1210 | M16: mm
B17: Displacement | C17: 96.4 | D17: l/cyl
B18: Power factor = | C18: =C6/C16 -> 14
B20: Perhitungan Daya Engine MAK 6M32C
B21: a) BHPMCR = | C21: =C6 -> 8400 | D21: Kw | E21: 1 kW = | F21: 1.359619 | G21: HP
B22: = | C22: =C21/F4 -> 11420.802 | D22: HP
B24: b) BHPSCR = | C24: BHPMCR x 0,9
B25: = | C25: =C21*0.9 -> 7560 | D25: kW
B26: = | C26: =C25/F4 -> 10278.722 | D26: HP
B28: c) SHP = | C28: BHPSCR x ηG
B29: = | C29: =C25*0.98 -> 7408.8 | D29: kW
B30: = | C30: =C29/F4 -> 10073.148 | D30: HP
B32: d) DHP = | C32: SHP x ηSηB
B33: = | C33: =C29*0.98 -> 7260.624 | D33: kW
B34: = | C34: =C33/F4 -> 9871.6846 | D34: HP
B36: e) EHP = | C36: DHP x Pc
B37: = | C37: =C33*HARVARLD!F223 -> 5562.5839 | D37: kW
B38: = | C38: =C37*F21 -> 7562.9948 | D38: HP
B40: f) THP = | C40: EHP x ƞh
B41: = | C41: =C37*HARVARLD!F221 -> 6244.1963 | D41: kW
B42: = | C42: =C41*F21 -> 8489.7279 | D42: HP
B44: Pemilihan gear Box
B46: Merk = | C46: ZF Marine Gearbox
B47: Type = | C47: ZF W43100 NC
B48: Power Factor =
B49: Reduction Ratio = | C49: 4.41
...

Sheet EPM
B2: Data Utama
B3: diambil dari perhitungan kapal dengan metode harvarld
C4: t = | D4: =HARVARLD!F197 -> 0.203
C5: w = | D5: =HARVARLD!F193 -> 0.29
C6: Vs = | D6: ='PROPELL (0.969)'!$E$11 -> 16 | E6: knot
C7: = | D7: ='PROPELL (0.969)'!$J$8 -> 8.231104 | E7: m/s
C8: ρ air laut = | D8: 1025 | E8: kg/m3
C9: S = | D9: =HARVARLD!D46 -> #REF! | E9: m³
C10: Ct = | D10: =HARVARLD!F166 -> #REF!
B12: Data Propeller
B13: diambil dari pemilihan propeller
B14: Tipe Propeller = | D14: ='PROPELL (0.969)'!$D$273 -> B3-35
B15: Db(m) = | D15: ='PROPELL (0.969)'!D274 -> 5.5048235
B16: (P/Db) = | D16: ='PROPELL (0.969)'!D275 -> 0.7
B17: η propeller = | D17: ='PROPELL (0.969)'!$D$276 -> 0.593
B18: Rpm Propeller = | D18: ='PROPELL (0.969)'!$D$277 -> 136.05442
B20: Tahanan total pada saat clean hull
C21: Rt trial = | D21: =HARVARLD!F171 -> #REF!
B23: Tahanan total pada saat service lambuung telah di fouling
C24: Rt dinas = | D24: =HARVARLD!G178 -> #REF!
B25: Symbol
C26: a = | D26: Konstanta
C27: β = | D27: konstanta
C28: KT = | D28: Koefisien Gaya Dorong (thrust) Baling-baling
C29: J = | D29: Koefisien Gaya Advanced Baling-baling
C30: KQ = | D30: Koefisien Torsi Baling-Baling
C31: Q = | D31: Torsi
B33: Langkah Perhitungan
B34: 1 | C34: Menghitung Koefisien α
C35: Rt = | D35: 0.5 x ρ x Ct x S x vs2
C36: = | D36: a x vs2
C38: α trial = | D38: Rt / Vs2
C39: = | D39: =D21*1000/(D7^2) -> #REF!
C41: α service = | D41: Rt / Vs2
C42: = | D42: =D24*1000/(D7^2) -> #REF!
B44: 2 | C44: Menghitung Koefisien β
C45: β = | D45: α / {(1-t) (1-w)2 ρ D2}
C47: β trial = | D47: =D39/((1-D4)*((1-D5)^2)*D8*(D15^2)) -> #REF!
C49: β service = | D49: =D42/((1-D4)*((1-D5)^2)*D8*(D15^2)) -> #REF!
B51: 3 | C51: Membuat Kurva hubungan KT-J
...

Sheet Poros Prop
A2: 1 | B2: Perencanaan Poros Propeller
A4: 1.1 | B4: Perencanaan Diameter Poros Propeller
B5: Ds = | C5: [(5.1 / τa) * Kt * Cb * T] / 3
B6: Ds = | C6: Diameter Poros Propeller (mm)
B7: τa = | C7: Tegangan geser yang diijinkan (Kg/mm2)
B8: Kt = | C8: Faktor Konsentrasi Tegangan
B9: Cb = | C9: Faktor Beban Lentur
B10: T = | C10: Momen puntir rencana (kg mm)
A12: a | B12: Daya Perencanaan (Pd)
B13: Pd = | C13: fc * p
B14: fc = | C14: Faktor koreksi daya
B15: p = | C15: Daya pada poros (SHP) dalam kw
B17: tabel faktor-faktor koreksi daya yang akan ditransmisikan fc
C18: daya yang akan ditransmisikan | F18: fc
C19: (Daya Rata - Rata) | F19: 1.2 - 2.0
C20: (Daya Maksimum) | F20: 0.8 - 1.2
C21: (Daya normal) | F21: 1.0 - 1.5
B23: diambil fc = | D23: 1
B24: nilai SHP diambil dari perhitungan sebelumnya
B25: SHP = | C25: ='EN & GEAR (2)'!C30 -> 10073.148 | D25: HP
C26: =C25*HARVARLD!F223 -> 7717.3433 | D26: kW
B27: jadi Pd = | C27: =D23*C26 -> 7717.3433 | D27: kW
A29: b | B29: Momen Puntir Rencana (T)
B30: T = | C30: 9.74 * 105 * (Pd / N)
C31: T = | D31: Momen puntir rencana (kg mm)
C32: N = | D32: putaran poros (rpm)
C33: Pd = | D33: Daya perencanaan (kW)
B34: nilai N adalah putaran propeller dalam rpm
B35: N = | C35: ='EN & GEAR (2)'!C50 -> 136.05442 | D35: rpm
B36: jadi T = | C36: =9.74*10^5*(C27/C35) -> 55247689 | D36: kg mm
A38: c | B38: Tegangan Geser yang Diijinkan (τa)
B39: τa = | C39: σb/(sf1 * sf2)
C40: material poros adalah:
C41: S 35 C,σb= | D41: ='PROPELL (0.969)'!L243 * 1000 -> 246.85526 | E41: kg/mm2
C42: sf1 = untuk material baja karbon= | F42: 6
C43: sf2 = 1.3 ~ 3 diambil= | F43: 2
B44: jadi τa = | C44: =D41/(F42*F43) -> 20.571272 | D44: Kg/mm2
A46: d | B46: Faktor Konsentrasi Tegangan (kt)
B47: Kt = | C47: 1 | D47: ( Tumbukan halus )
B48: Kt = | C48: 1.0-1.5 | D48: ( Sedikit tumbukan )
...

Sheet Propeller Gambar
A1: Data Propeller
A3: Propeller
A4: Tipe | B4: Diameter (m) | C4: n (rps) | D4: P/D | E4: η | F4: Ae/A0 | G4: Pitch | H4: Z | I4: Tr
A5: B3-35 | B5: =EPM!D15 -> 5.5048235 | C5: ='PROPELL (0.969)'!F277 -> 2.2675737 | D5: ='PROPELL (0.969)'!D275 -> 0.7 | E5: ='PROPELL (0.969)'!D276 -> 0.593 | F5: 0.35 | G5: =D5*B5 -> 3.8533764 | H5: 3 | I5: =0.045*B5 -> 0.24771706
A6: R = | B6: =B5/2 -> 2.7524117
A7: Dimension of 3 Bladed Propellers Wageningen B-Series
A9: r/R | B9: crZ | C9: ar/cr | D9: br/cr | E9: Sr/D = Ar - BrZ
B10: DAE/Ao | E10: Ar | F10: Br
A11: 0.2 | B11: 1.663 | C11: 0.616 | D11: 0.35 | E11: 0.0526 | F11: 0.004
A12: 0.3 | B12: 1.832 | C12: 0.611 | D12: 0.35 | E12: 0.0464 | F12: 0.0035
A13: 0.4 | B13: 2 | C13: 0.599 | D13: 0.351 | E13: 0.0402 | F13: 0.003
A14: 0.5 | B14: 2.12 | C14: 0.583 | D14: 0.355 | E14: 0.034 | F14: 0.0025
A15: 0.6 | B15: 2.186 | C15: 0.558 | D15: 0.389 | E15: 0.0278 | F15: 0.002
A16: 0.7 | B16: 2.168 | C16: 0.526 | D16: 0.442 | E16: 0.0216 | F16: 0.0015
A17: 0.8 | B17: 2.127 | C17: 0.481 | D17: 0.478 | E17: 0.0154 | F17: 0.001
A18: 0.9 | B18: 1.657 | C18: 0.4 | D18: 0.5 | E18: 0.0092 | F18: 0.0005
A19: 1 | B19: 0 | C19: 0 | D19: 0 | E19: 0.003 | F19: 0
A33: Keterangan :
A34: R | B34: : | C34: Radius propeller
A35: r/R | B35: : | C35: Rasio jarak tebal blade (pitch)
A36: Z | B36: : | C36: Jumlah blade
A37: Cr | B37: : | C37: Panjang antara trailling edge ke leading edge pada r/R
A38: D | B38: : | C38: Diameter propeller
A39: AE/Ao | B39: : | C39: Perbandingan luasan daun propeller dengan seluruh lingkaran propeller
A40: ar | B40: : | C40: Jarak antara generator line ke leading edge
A41: br | B41: : | C41: Jarak maksimum tebal ke leading edge
A42: Sr | B42: : | C42: Tebal maksimum
A44: Perhitungan dengan Metode Wageningen
A46: r/R | B46: crZ | C46: cr | D46: ar/cr | E46: ar | F46: br/cr | G46: br | H46: Sr/D = Ar - BrZ | J46: Sr | M46: r/R | N46: cr | O46: ar | P46: br | Q46: Sr | R46: Dr | S46: Ar-Br
B47: DAE/Ao | C47: (m) | E47: (m) | G47: (m) | H47: Ar | I47: Br | J47: (m) | N47: (m) | O47: (m) | P47: (m) | Q47: (m) | R47: (m) | S47: (m)
A48: 0.2 | B48: =B11 -> 1.663 | C48: =(B48*$B$5*$F$5)/$H$5 -> 1.0680275 | D48: =C11 -> 0.616 | E48: =C48*D48 -> 0.65790494 | F48: =D11 -> 0.35 | G48: =F48*C48 -> 0.37380963 | H48: =E11 -> 0.0526 | I48: =F11 -> 0.004 | J48: =(H48-(I48*$H$5))*$B$5 -> 0.22349583 | M48: 0.2 | N48: =C48 -> 1.0680275 | O48: =E48 -> 0.65790494 | P48: =G48 -> 0.37380963 | Q48: =J48 -> 0.22349583 | R48: =-(N48-O48) -> -0.41012256 | S48: =O48-P48 -> 0.28409532
A49: 0.3 | B49: =B12 -> 1.832 | C49: =(B49*$B$5*$F$5)/$H$5 -> 1.1765643 | D49: =C12 -> 0.611 | E49: =C49*D49 -> 0.71888077 | F49: =D12 -> 0.35 | G49: =F49*C49 -> 0.4117975 | H49: =E12 -> 0.0464 | I49: =F12 -> 0.0035 | J49: =(H49-(I49*$H$5))*$B$5 -> 0.19762316 | M49: 0.3 | N49: =C49 -> 1.1765643 | O49: =E49 -> 0.71888077 | P49: =G49 -> 0.4117975 | Q49: =J49 -> 0.19762316 | R49: =-(N49-O49) -> -0.4576835 | S49: =O49-P49 -> 0.30708328
A50: 0.4 | B50: =B13 -> 2 | C50: =(B50*$B$5*$F$5)/$H$5 -> 1.2844588 | D50: =C13 -> 0.599 | E50: =C50*D50 -> 0.76939083 | F50: =D13 -> 0.351 | G50: =F50*C50 -> 0.45084504 | H50: =E13 -> 0.0402 | I50: =F13 -> 0.003 | J50: =(H50-(I50*$H$5))*$B$5 -> 0.17175049 | M50: 0.4 | N50: =C50 -> 1.2844588 | O50: =E50 -> 0.76939083 | P50: =G50 -> 0.45084504 | Q50: =J50 -> 0.17175049 | R50: =-(N50-O50) -> -0.51506798 | S50: =O50-P50 -> 0.31854579
A51: 0.5 | B51: =B14 -> 2.12 | C51: =(B51*$B$5*$F$5)/$H$5 -> 1.3615263 | D51: =C14 -> 0.583 | E51: =C51*D51 -> 0.79376986 | F51: =D14 -> 0.355 | G51: =F51*C51 -> 0.48334185 | H51: =E14 -> 0.034 | I51: =F14 -> 0.0025 | J51: =(H51-(I51*$H$5))*$B$5 -> 0.14587782 | M51: 0.5 | N51: =C51 -> 1.3615263 | O51: =E51 -> 0.79376986 | P51: =G51 -> 0.48334185 | Q51: =J51 -> 0.14587782 | R51: =-(N51-O51) -> -0.56775649 | S51: =O51-P51 -> 0.31042801
A52: 0.6 | B52: =B15 -> 2.186 | C52: =(B52*$B$5*$F$5)/$H$5 -> 1.4039135 | D52: =C15 -> 0.558 | E52: =C52*D52 -> 0.78338372 | F52: =D15 -> 0.389 | G52: =F52*C52 -> 0.54612235 | H52: =E15 -> 0.0278 | I52: =F15 -> 0.002 | J52: =(H52-(I52*$H$5))*$B$5 -> 0.12000515 | M52: 0.6 | N52: =C52 -> 1.4039135 | O52: =E52 -> 0.78338372 | P52: =G52 -> 0.54612235 | Q52: =J52 -> 0.12000515 | R52: =-(N52-O52) -> -0.62052976 | S52: =O52-P52 -> 0.23726138
A53: 0.7 | B53: =B16 -> 2.168 | C53: =(B53*$B$5*$F$5)/$H$5 -> 1.3923534 | D53: =C16 -> 0.526 | E53: =C53*D53 -> 0.73237786 | F53: =D16 -> 0.442 | G53: =F53*C53 -> 0.61542018 | H53: =E16 -> 0.0216 | I53: =F16 -> 0.0015 | J53: =(H53-(I53*$H$5))*$B$5 -> 0.094132482 | M53: 0.7 | N53: =C53 -> 1.3923534 | O53: =E53 -> 0.73237786 | P53: =G53 -> 0.61542018 | Q53: =J53 -> 0.094132482 | R53: =-(N53-O53) -> -0.65997549 | S53: =O53-P53 -> 0.11695768
A54: 0.8 | B54: =B17 -> 2.127 | C54: =(B54*$B$5*$F$5)/$H$5 -> 1.3660219 | D54: =C17 -> 0.481 | E54: =C54*D54 -> 0.65705656 | F54: =D17 -> 0.478 | G54: =F54*C54 -> 0.65295849 | H54: =E17 -> 0.0154 | I54: =F17 -> 0.001 | J54: =(H54-(I54*$H$5))*$B$5 -> 0.068259811 | M54: 0.8 | N54: =C54 -> 1.3660219 | O54: =E54 -> 0.65705656 | P54: =G54 -> 0.65295849 | Q54: =J54 -> 0.068259811 | R54: =-(N54-O54) -> -0.70896539 | S54: =O54-P54 -> 0.0040980658
A55: 0.9 | B55: =B18 -> 1.657 | C55: =(B55*$B$5*$F$5)/$H$5 -> 1.0641741 | D55: =C18 -> 0.4 | E55: =C55*D55 -> 0.42566965 | F55: =D18 -> 0.5 | G55: =F55*C55 -> 0.53208706 | H55: =E18 -> 0.0092 | I55: =F18 -> 0.0005 | J55: =(H55-(I55*$H$5))*$B$5 -> 0.042387141 | M55: 0.9 | N55: =C55 -> 1.0641741 | O55: =E55 -> 0.42566965 | P55: =G55 -> 0.53208706 | Q55: =J55 -> 0.042387141 | R55: =-(N55-O55) -> -0.63850448 | S55: =O55-P55 -> -0.10641741
A56: 1 | B56: =B19 -> 0 | C56: =(B56*$B$5*$F$5)/$H$5 -> 0 | D56: =C19 -> 0 | E56: =C56*D56 -> 0 | F56: =D19 -> 0 | G56: =F56*C56 -> 0 | H56: =E19 -> 0.003 | I56: =F19 -> 0 | J56: =(H56-(I56*$H$5))*$B$5 -> 0.01651447 | M56: 1 | N56: =C56 -> 0 | O56: =E56 -> 0 | P56: =G56 -> 0 | Q56: =J56 -> 0.01651447 | R56: =-(N56-O56) -> 0 | S56: =O56-P56 -> 0
A58: Tabel V1 untuk Y Face Propeller | N58: Untuk Perhitungan Propeller Nose Radius mengacu pada rumusan di Buku The Design of Marine Screw Propeller hal. 72.
...

Sheet VRM
B2: Jenis Kapal | E2: CHEMICAL TANKER
B3: Lpp | E3: =HARVARLD!F6 -> #REF! | G3: m
B4: Lwl | E4: =HARVARLD!F8 -> #REF! | G4: m
B5: Ldisplacement | E5: =HARVARLD!F14 -> #REF! | G5: m
B6: Lebar (B) | E6: =HARVARLD!F16 -> 23.7 | G6: m | I6: e% = | J6: 0.005
B7: Sarat Air (T) | E7: =HARVARLD!F23 -> 9.947 | G7: m
B8: Tinggi Geladak (H) | E8: =HARVARLD!F25 -> 13.34 | G8: m
B9: Kecepatan (Vs) | E9: =HARVARLD!F27 -> 16 | G9: knot
B10: Ddisplacement | E10: =HARVARLD!F29 -> #REF! | G10: ton
B11: Vdisplacement | E11: =HARVARLD!F28 -> #REF! | G11: mᶟ
B12: Koefisien midship/Cm (β) | E12: =HARVARLD!F30 -> 0.982
B13: Koefisien blok/Cb (δ) | E13: =HARVARLD!F31 -> 0.68
B14: Koefisien prismatik/Cp (ϕ) | E14: =HARVARLD!F32 -> 0.69
B15: LCB | E15: =J6*E5 -> #REF!
B16: LOA | E16: ='[2]Lines Plan'!$B$9 -> #REF!
B18: PERHITUNGAN VOLUME RUANG MUAT
B19: 1 | C19: Berat Bahan Bakar
C20: Wfo = | D20: BHPmc x bmc x S/Vs x 10-6 x C ( ton )
C21: Dimana :
C22: BHPmc = | D22: Bhp mesin induk ( katalog mesin ) kW
C23: = | D23: ='EN & GEAR (2)'!C6 -> 8400 | E23: kW
C24: bmc = | D24: spesifik konsumsi bahan bakar mesin induk ( g/kWh )
C25: = | D25: 183.4 | E25: g/kWh
C26: S = | D26: jarak pelayaran ( mil )
C27: = | D27: 2910 | E27: miles
C28: Vs = | D28: kecepatan dinas ( knot )
C29: = | D29: =E9 -> 16 | E29: knot
C30: C = | D30: koreksi cadangan ( 1,3 - 1,5 )
C31: = | D31: 1.4
C33: Wfo = | D33: =D23*D25*(D27/D29)*(10^-6)*D31 -> 392.26509 | E33: ton
C35: Menentukan volume bahan bakar mesin induk
C37: Vfo = | D37: Wfo/ρ ( m3 )
C38: Dimana :
C39: ρ = | D39: 0.95 | E39: ton/m3
C41: Vfo = | D41: =D33/D39 -> 412.91062 | E41: m3
C43: Volume bahan bakar mesin induk terdapat penambahan karena:
C44: > Double bottom ( 2% )
C45: Vfo x 2% = | D45: =D41*2% -> 8.2582124 | E45: m3
C47: > Ekspansi karena panas ( 2% )
C48: Vfo x 2% = | D48: =D41*2% -> 8.2582124 | E48: m3
...

Sheet SIMPSON
A4: profile | B4: HFO Tank
C5: No. Frame | D5: Faktor simpson | E5: A | F5: FS * A
C6: 34 | D6: 1 | E6: 21.5739 | F6: =D6 * E6 -> 21.5739
C7: 36 | D7: 4 | E7: 23.4357 | F7: =D7 * E7 -> 93.7428
C8: 38 | D8: 2 | E8: 24.9782 | F8: =D8 * E8 -> 49.9564
C9: 40 | D9: 4 | E9: 26.2258 | F9: =D9 * E9 -> 104.9032
C10: 42 | D10: 2 | E10: 27.2351 | F10: =D10 * E10 -> 54.4702
C11: 44 | D11: 4 | E11: 28.0577 | F11: =D11 * E11 -> 112.2308
C12: 46 | D12: 2 | E12: 28.7412 | F12: =D12 * E12 -> 57.4824
C13: 48 | D13: 4 | E13: 29.3298 | F13: =D13 * E13 -> 117.3192
E14: sum = | F14: =SUM(F6:F13) -> 611.6789
C15: First frame | D15: = | E15: 38
C16: end frame | D16: = | E16: 50 | G16: =(E15+E16)/2 -> 44
C17: Total fame | D17: = | E17: =E16-E15 -> 12
D18: = | E18: 7
C19: jarak antar frame | D19: = | E19: 2 | F19: m
C20: V | D20: = | E20: 1/3 * h * (Fs*A)
D21: = | E21: =1/3 * E19 * F14 -> 407.78593 | F21: m^3
A24: half-breadth | B24: HFO Tank
B25: High end | C25: = | D25: 13.34 | E25: m
B26: high first | C26: = | D26: 1.41 | E26: m
B27: delta high | C27: = | D27: =D25-D26 -> 11.93 | E27: m
B28: dH / 4 | C28: = | D28: =D27/4 -> 2.9825 | E28: m
B29: Prediksi panjang | C29: = | D29: V/(t*l) | E29: m
C30: = | D30: =VRM!D51/(D27*(HARVARLD!F16-1.5352*2)) -> 1.7448502 | E30: m
C31: WL | D31: Faktor simpson | E31: A | F31: FS * A
B32: =$D$28 -> 2.9825 | C32: =D26 -> 1.41 | D32: 1 | E32: 19.0875 | F32: =D32 * E32 -> 19.0875
B33: =$D$28 -> 2.9825 | C33: =C32+B33 -> 4.3925 | D33: 4 | E33: 17.8113 | F33: =D33 * E33 -> 71.2452
B34: =$D$28 -> 2.9825 | C34: =C33+B34 -> 7.375 | D34: 2 | E34: 18.1855 | F34: =D34 * E34 -> 36.371
B35: =$D$28 -> 2.9825 | C35: =C34+B35 -> 10.3575 | D35: 4 | E35: 19.6488 | F35: =D35 * E35 -> 78.5952
B36: =$D$28 -> 2.9825 | C36: =C35+B36 -> 13.34 | D36: 1 | E36: 22.4154 | F36: =D36 * E36 -> 22.4154
B37: =$D$28 -> 2.9825 | C37: =C36+B37 -> 16.3225 | F37: =D37 * E37 -> 0
B38: =$D$28 -> 2.9825 | C38: =C37+B38 -> 19.305 | F38: =D38 * E38 -> 0
E39: sum = | F39: =SUM(F32:F38) -> 227.7143
C40: First frame | D40: = | E40: 38
C41: end frame | D41: = | E41: 40
C42: Total fame | D42: = | E42: =E41-E40 -> 2
D43: = | E43: 7
C44: jarak antar frame | D44: = | E44: =D28 -> 2.9825 | F44: m
C45: V (P) | D45: = | E45: 1/3 * h * (Fs*A)
...

Sheet BALLAST
C1: PERHITUNGAN BALLAST | H1: Nama | I1: : Daffa Gabillah Maulana Gapur
H2: No. Doc | I2: : 0
H3: No. Rev | I3: : 01
H4: Halaman | I4: : 01
B6: Data Utama Kapal
B8: Jenis Kapal | E8: CHEMICAL TANKER
B9: Lpp | E9: =HARVARLD!F6 -> #REF! | G9: m
B10: Lwl | E10: =HARVARLD!F8 -> #REF! | G10: m
B11: Ldisplacement | E11: =HARVARLD!F14 -> #REF! | G11: m
B12: Lebar (B) | E12: =HARVARLD!F16 -> 23.7 | G12: m
B13: Sarat Air (T) | E13: =HARVARLD!F23 -> 9.947 | G13: m
B14: Tinggi Geladak (H) | E14: =HARVARLD!F25 -> 13.34 | G14: m
B15: Kecepatan (Vs) | E15: =HARVARLD!F27 -> 16 | G15: knot
B16: Vdisplacement | E16: =HARVARLD!F28 -> #REF! | G16: mᶟ
B17: Koefisien midship/Cm (β) | E17: =HARVARLD!F30 -> 0.982
B18: Koefisien blok/Cb (δ) | E18: =HARVARLD!F31 -> 0.68
B19: Koefisien prismatik/Cp (ϕ) | E19: =HARVARLD!F32 -> 0.69
B20: l1 | E20: 19.6
B21: l | E21: 28
B23: Perhitungan Kapasitas Ballast System
B24: a | C24: Volume Displacement | G24: RL 2007 Rules and Regulation, Part 3 Definition
C25: ∇ = | D25: L x B X T x Cb
C26: Dimana :
C27: L = | D27: =E10 -> #REF!
C28: =
C29: B = | D29: Lebar
C30: D = | D30: Sarat
C31: Cb = | D31: Koefisien blok
C33: ∇ = | D33: L x B X T x Cb
D34: =D27*E12*E13*E18 -> #REF! | E34: m3
B35: b | C35: Ship Displacement
C36: ∆ = | D36: ∇ x ρ | G36: ρ = | H36: =HARVARLD!N29 -> 1.026 | I36: ton/m3
C37: = | D37: =D34*H36 -> #REF! | E37: ton
C40: Berat air ballast
C41: Wb = | D41: (10% - 20% ) x ∆
C42: = | D42: =0.1*D37 -> #REF! | E42: ton
B44: c | C44: Volume ballast
C45: Vb = | D45: Wb / ρ
C46: = | D46: =D42/H36 -> #REF! | E46: m3
B48: d | C48: Kapasitas ballast
...

Sheet ABK
B2: Mencari Jumlah ABK
B3: Jumlah ABK yang direncanakan Harus kurang dari atau sama dengan hasil dari persamaan berikut
B5: Zc = Cst x [ Cdk (CN/1000)^0.16 + Ceng ( BHP/10 )^0.33 + Cadets ]
B7: dimana :
B8: Cst | C8: : Koefisien Steward Deck ( 1,2 - 1,33 ) | H8: 1.2
B9: Cdk | C9: : Koefisien Deck Departement ( 11,5 - 14,5 ) | H9: 11.5
B10: Ceng | C10: : Koefisien Engine Departement ( 8,5 - 11 ) | H10: 8.5
B11: BHP | C11: : Tenaga Mesin
B12: Cadets | C12: : Perwira Tambahan
B13: CN | C13: : ( L.B.H ) / 1000
B15: Zc = | C15: Cst x [ Cdk (CN/1000)^1/6 + Ceng ( BHP/10 )^1/3 + Cadets ]
C16: =H8*(H9*((HARVARLD!F6*HARVARLD!F16*HARVARLD!F25/1000)/1000)^(1/6)+H10*(HARVARLD!G250/1000)^(1/3)+1) -> #REF!
C17: 33
B19: Maka Jumlah Crew Sebagai Berikut :
B21: No | D21: Jabatan | F21: Jumlah
B22: Master
B23: 1 | D23: Captain | F23: 1 | G23: Person
B24: Deck Departement
B25: 2 | D25: Chief Officer | F25: 1 | G25: Person
B26: 3 | D26: Medic | F26: 1 | G26: Person
B27: 4 | D27: Quarter Master | F27: 1 | G27: Person | H27: ooo
B28: 5 | D28: Radio Operator | F28: 1 | G28: person
B29: 5 | D29: Boatswain | F29: 1 | G29: Person | H29: ooo
B30: Engine Departement
B31: 7 | D31: Chief Engineer | F31: 1 | G31: Person
B32: 8 | D32: Second Engineer | F32: 2 | G32: Person | H32: ooo
B33: 9 | D33: Electrician | F33: 2 | G33: Person | H33: ooo
B34: 10 | D34: Fireman | F34: 1 | G34: Person | H34: ooo
B35: 11 | D35: Oiler | F35: 2 | G35: Person | H35: ooo
B36: 12 | D36: Pumpman | F36: 3 | G36: Person | H36: ooo
B37: Catering Departement
B38: 13 | D38: Chief Cook | F38: 1 | G38: Person | H38: ooo
B39: 14 | D39: Assistant Cook | F39: 1 | G39: Person | H39: ooo
B40: 15 | D40: Boys | F40: 1 | G40: Person | H40: ooo
D41: Total | F41: =SUM(F23:F40) -> 20 | G41: Person

Sheet PIPA
B2: Data Utama Kapal
B4: Jenis Kapal | E4: CHEMICAL TANKER
B5: Lpp | E5: =HARVARLD!F6 -> #REF! | G5: m
B6: Lwl | E6: =HARVARLD!F8 -> #REF! | G6: m
B7: Ldisplacement | E7: =(E5+E6)*0.5 -> #REF! | G7: m
B8: Lebar (B) | E8: =HARVARLD!F16 -> 23.7 | G8: m
B9: Sarat Air (T) | E9: =HARVARLD!F23 -> 9.947 | G9: m
B10: Tinggi Geladak (H) | E10: =HARVARLD!F25 -> 13.34 | G10: m
B11: Kecepatan (Vs) | E11: =HARVARLD!F27 -> 16 | G11: knot
B12: Vdisplacement | E12: =HARVARLD!F28 -> #REF! | G12: mᶟ
B13: Koefisien midship/Cm (β) | E13: =HARVARLD!F30 -> 0.982
B14: Koefisien blok/Cb (δ) | E14: =HARVARLD!F31 -> 0.68
B15: Koefisien prismatik/Cp (ϕ) | E15: =HARVARLD!F32 -> 0.69
B16: l1 | E16: 19.6
B17: l | E17: 28
B19: Perhitungan Diameter Utama Pipa Bilga
B20: a | C20: Untuk Kapal Tankers
C23: Dh = | D23: =3*((E8+E10)*E16)^0.5+35 -> 115.83227
C24: Dimana:
C25: dH = | D25: Diameter dalam pipa utama bilga (mm)
C26: L = | D26: Lpp (mm)
C27: B = | D27: Lebar kapal dg kulit (lebar maksimum)
C28: H = | D28: Tinggi kapal (m)
C29: l1 = | D29: Total panjang ruangan antara cofferdam/sekat pump room dan sekat stern tube (m)
B31: b | C31: Perhitungan Diameter Cabang Pipa Bilga
C34: Dz = | D34: =2.15*((E8+E10)*E17)^0.5 -> 69.239347
C35: Dimana:
C36: Dz = | D36: Diameter dalam pipa cabang bilga (mm)
C37: l = | D37: Panjang dari kompartment yang memiliki sekat kedap (m)
B39: c | C39: Perhitungan Pompa Bilga
C41: Q kapasitas
C42: dan Head wajib dihitung
C43: Q = | D43: =5.75*(10^-3)*(D23^2) -> 77.148411
B45: 4 | C45: Calculation of main bilge line
C46: dm : | D46: 1.68 √L(B + D) + 25 | F46: mm | G46: RL 2007 Rules and Regulation, part 5, chapter 13.5
C48: Where :
C49: L : | D49: 97% Lwl | E49: , Lwl : | F49: =E6 -> #REF! | G49: m
C50: : | D50: =97%*F49 -> #REF! | E50: m
C51: B : | D51: =E8 -> 23.7 | E51: m
C52: D : | D52: =E9 -> 9.947 | E52: m
...

Sheet OILY BILGE
B2: Data Utama Kapal
B4: Jenis Kapal | E4: CHEMICAL TANKER
B5: Lpp | E5: =HARVARLD!F6 -> #REF! | G5: m
B6: Lwl | E6: =HARVARLD!F8 -> #REF! | G6: m
B7: Ldisplacement | E7: =HARVARLD!F14 -> #REF! | G7: m
B8: Lebar (B) | E8: =HARVARLD!F16 -> 23.7 | G8: m
B9: Sarat Air (T) | E9: =HARVARLD!F23 -> 9.947 | G9: m
B10: Tinggi Geladak (H) | E10: =HARVARLD!F25 -> 13.34 | G10: m
B11: Kecepatan (Vs) | E11: =HARVARLD!F27 -> 16 | G11: knot
B12: Vdisplacement | E12: =HARVARLD!F28 -> #REF! | G12: mᶟ
B13: Koefisien midship/Cm (β) | E13: =HARVARLD!F30 -> 0.982
B14: Koefisien blok/Cb (δ) | E14: =HARVARLD!F31 -> 0.68
B15: Koefisien prismatik/Cp (ϕ) | E15: =HARVARLD!F32 -> 0.69
B16: l1 | E16: 19.6
B17: l | E17: 28
B19: Perhitungan Kapasitas Oily Bilge System
B20: a | C20: Volume dari bilge well lebih dari 2.5 m3
C25: Dimana :
C26: Panjang = | E26: 1.7 | F26: m
C27: Lebar = | E27: 1.47 | F27: m
C28: Tinggi = | E28: 1 | F28: m
C29: Volume = | E29: =E26*E27*E28 -> 2.499 | F29: m3
B31: b | C31: waktu yang dibutuhkan selama pengeringan bilge well selama 75 menit
C32: oily bilge well kapasitas V/t | G32: v = total volume bilge well
C33: Q = | D33: Volume bilge well/t | G33: t = waktu pengeringan
C34: Q = | D34: 2.5/(75/60)
C35: Q = | D35: =E29/1.5 -> 1.666 | E35: m3/hr
C37: diameter pipa oil bilge system
C38: A = | D38: Q/velocity
C39: A = | D39: =(D35/3600)/2 -> 0.00023138889 | E39: m3
C41: perhitungan diameter pipa :
C42: A = | D42: 0.25 x π x dz^2
C43: dz = | D43: =SQRT(D39/((1/4)*(22/7))) -> 0.017160855 | E43: m
D44: =D43*1000 -> 17.160855 | E44: mm
C46: Untuk pipa pada oil bilge, yang akan digunakan yaitu ASME Section III - ASME QSC 467
C47: Inside diameter (dm) = | F47: 18.88 | G47: mm
C48: thickness = | F48: 3.91 | G48: mm
C49: Outside diameter = | F49: 26.7 | G49: mm
C50: Nominal pipe size = | F50: 20XS | G50: sch 80
B52: Calculation of oily waste collecting tank volume
...

Sheet HAHAHU
A1: A. Perhitungan Panas Total (Qt)
A3: BEBAN PANS TRANSMISI (Qtr)
A4: Room | B4: Dimension | E4: Volume (m^3) | F4: Ouside Coondition | H4: Insiede Condition | J4: ΔT (°C) | K4: Wall | P4: Qtr
B5: Panjang | C5: Lebar | D5: Tinggi | F5: Temp | G5: RH | H5: Temp | I5: RH | K5: Koeff Heat | L5: F-A Wall | M5: Side Wall | N5: Roof | O5: Area
B6: m | C6: m | D6: m | F6: (°C) | G6: (%) | H6: (°C) | I6: (%) | K6: (W/m^2 °C ) | L6: (m^2) | M6: (m^2) | N6: (m^2) | O6: (m^2) | P6: (watt)
A7: Mess Room | B7: 4.2 | C7: 5.4439 | D7: 2.5 | E7: =B7*C7*D7 -> 57.16095 | F7: 33 | G7: 60 | H7: 27 | I7: 50 | J7: =F7-H7 -> 6 | K7: 6.46 | L7: =(C7*D7) -> 13.60975 | M7: =2*(B7*D7) -> 21 | N7: =B7*C7 -> 22.86438 | O7: =L7+M7+N7 -> 57.47413 | P7: =K7*O7 -> 371.28288
A8: Galley | B8: 4.2 | C8: 5.6255 | D8: 2.5 | E8: =B8*C8*D8 -> 59.06775 | F8: 33 | G8: 60 | H8: 27 | I8: 50 | J8: =F8-H8 -> 6 | K8: 6.46 | L8: 0 | M8: =2*(B8*D8) -> 21 | N8: 0 | O8: =L8+M8+N8 -> 21 | P8: =K8*O8 -> 135.66
A9: Musholla | B9: 4.2 | C9: 5.7702 | D9: 2.5 | E9: =B9*C9*D9 -> 60.5871 | F9: 33 | G9: 60 | H9: 27 | I9: 50 | J9: =F9-H9 -> 6 | K9: 6.46 | L9: =2*(C9*D9) -> 28.851 | M9: =2*(B9*D9) -> 21 | N9: 0 | O9: =L9+M9+N9 -> 49.851 | P9: =K9*O9 -> 322.03746
A10: Library | B10: 4.2 | C10: 5.7702 | D10: 2.5 | E10: =B10*C10*D10 -> 60.5871 | F10: 33 | G10: 60 | H10: 27 | I10: 50 | J10: =F10-H10 -> 6 | K10: 6.46 | L10: 0 | M10: =2*(B10*D10) -> 21 | N10: 0 | O10: =L10+M10+N10 -> 21 | P10: =K10*O10 -> 135.66
A11: Tally Office | B11: 3.5 | C11: 5.8723 | D11: 2.5 | E11: =B11*C11*D11 -> 51.382625 | F11: 33 | G11: 60 | H11: 27 | I11: 50 | J11: =F11-H11 -> 6 | K11: 6.46 | L11: =(C11*D11) -> 14.68075 | M11: =2*(B11*D11) -> 17.5 | N11: 0 | O11: =L11+M11+N11 -> 32.18075 | P11: =K11*O11 -> 207.88765
A12: Chief Cook | B12: 4.9 | C12: 2.8101 | D12: 2.5 | E12: =B12*C12*D12 -> 34.423725 | F12: 33 | G12: 60 | H12: 27 | I12: 50 | J12: =F12-H12 -> 6 | K12: 6.46 | L12: 0 | M12: =2*(B12*D12) -> 24.5 | N12: 0 | O12: =L12+M12+N12 -> 24.5 | P12: =K12*O12 -> 158.27
A13: Boatswain | B13: 4.2 | C13: 2.8831 | D13: 2.5 | E13: =B13*C13*D13 -> 30.27255 | F13: 33 | G13: 60 | H13: 27 | I13: 50 | J13: =F13-H13 -> 6 | K13: 6.46 | L13: =(C13*D13) -> 7.20775 | M13: =2*(B13*D13) -> 21 | N13: 0 | O13: =L13+M13+N13 -> 28.20775 | P13: =K13*O13 -> 182.22207
A14: Oiler | B14: 2.8 | C14: 2.5 | D14: 2.5 | E14: =B14*C14*D14 -> 17.5 | F14: 33 | G14: 60 | H14: 27 | I14: 50 | J14: =F14-H14 -> 6 | K14: 6.46 | L14: =2*(C14*D14) -> 12.5 | M14: 0 | N14: 0 | O14: =L14+M14+N14 -> 12.5 | P14: =K14*O14 -> 80.75
A15: Fireman | B15: 2.8 | C15: 2.5 | D15: 2.5 | E15: =B15*C15*D15 -> 17.5 | F15: 33 | G15: 60 | H15: 27 | I15: 50 | J15: =F15-H15 -> 6 | K15: 6.46 | L15: =2*(C15*D15) -> 12.5 | M15: =(B15*D15) -> 7 | N15: 0 | O15: =L15+M15+N15 -> 19.5 | P15: =K15*O15 -> 125.97
A16: Pumpman | B16: 2.8 | C16: 2.5 | D16: 2.5 | E16: =B16*C16*D16 -> 17.5 | F16: 33 | G16: 60 | H16: 27 | I16: 50 | J16: =F16-H16 -> 6 | K16: 6.46 | L16: =2*(C16*D16) -> 12.5 | M16: =(B16*D16) -> 7 | N16: 0 | O16: =L16+M16+N16 -> 19.5 | P16: =K16*O16 -> 125.97
A17: Asistant Cook | B17: 2.8 | C17: 2.5 | D17: 2.5 | E17: =B17*C17*D17 -> 17.5 | F17: 33 | G17: 60 | H17: 27 | I17: 50 | J17: =F17-H17 -> 6 | K17: 6.46 | L17: =2*(C17*D17) -> 12.5 | M17: 0 | N17: 0 | O17: =L17+M17+N17 -> 12.5 | P17: =K17*O17 -> 80.75
A18: Boys | B18: 2.8 | C18: 2.8831 | D18: 2.5 | E18: =B18*C18*D18 -> 20.1817 | F18: 33 | G18: 60 | H18: 27 | I18: 50 | J18: =F18-H18 -> 6 | K18: 6.46 | L18: =(C18*D18) -> 7.20775 | M18: =2*(B18*D18) -> 14 | N18: 0 | O18: =L18+M18+N18 -> 21.20775 | P18: =K18*O18 -> 137.00207
A19: Total | P19: =SUM(P7:P18) -> 2063.4621
A21: BEBAN PANAS AKIBAT PENGHUNI RUANGAN (Qperson = Qp)
A22: Room | B22: Qty | C22: Sensible | D22: Latent | E22: Total | F22: Q Penghuni
B23: (Person) | C23: (Watt) | D23: (Watt) | E23: (Watt) | F23: (Watt)
A24: Mess Room | B24: 10 | C24: 64 | D24: 97 | E24: 161 | F24: =B24*E24 -> 1610
A25: Galley | B25: 2 | C25: 59 | D25: 73 | E25: 132 | F25: =B25*E25 -> 264
A26: Musholla | B26: 7 | C26: 64 | D26: 97 | E26: 161 | F26: =B26*E26 -> 1127
A27: Library | B27: 4 | C27: 59 | D27: 73 | E27: 117 | F27: =B27*E27 -> 468
A28: Tally Office | B28: 1 | C28: 59 | D28: 73 | E28: 132 | F28: =B28*E28 -> 132
A29: Chief Cook | B29: 1 | C29: 57 | D29: 60 | E29: 117 | F29: =B29*E29 -> 117
A30: Boatswain | B30: 1 | C30: 57 | D30: 60 | E30: 117 | F30: =B30*E30 -> 117
A31: Oiler | B31: 1 | C31: 57 | D31: 60 | E31: 117 | F31: =B31*E31 -> 117
A32: Fireman | B32: 1 | C32: 57 | D32: 60 | E32: 117 | F32: =B32*E32 -> 117 | G32: Kecepatan Angin Rata - Rata real madrid
A33: Pumpman | B33: 1 | C33: 57 | D33: 60 | E33: 117 | F33: =B33*E33 -> 117
A34: Asistant Cook | B34: 1 | C34: 57 | D34: 60 | E34: 117 | F34: =B34*E34 -> 117 | G34: 1 kph = | H34: 0.2778 | I34: m/s
A35: Boys | B35: 1 | C35: 57 | D35: 60 | E35: 117 | F35: =B35*E35 -> 117 | G35: Kecepatan angin rata - rata = | J35: 16.2 | K35: kph
A36: Total | F36: =SUM(F24:F35) -> 4420 | I36: = | J36: =J35*H34 -> 4.50036 | K36: m/s
P37: 0.4 | Q37: 0.4
A38: BEBAN PANAS AKIBAT RAMBAT DARI JENDELA (Qwindow = Qw)
A39: Room | B39: Ouside Coondition | C39: Insiede Condition | D39: ΔT | E39: Jumlah Jendela | F39: U Factor Double Kaca | G39: Luas Jendela | H39: Qw
B41: (°C) | C41: (°C) | D41: (°C) | E41: (buah) | F41: (W/m.°K) | G41: (m^2) | H41: (watt)
A42: Mess Room | B42: 33 | C42: 27 | D42: =B42-C42 -> 6 | E42: 2 | F42: 3.6 | G42: 0.1256 | H42: =E42*F42*G42 -> 0.90432
A43: Galley | B43: 33 | C43: 27 | D43: =B43-C43 -> 6 | E43: 2 | F43: 3.6 | G43: 0.1256 | H43: =E43*F43*G43 -> 0.90432
...

Sheet STORAGE
A1: Perancangan sistem ruang pendinginin cargo / Akomodasi
A2: Maulana Muslim Dianto/0319040065/D4 ME 7B
J3: Data Utama Kapal
J4: Jenis Kapal | M4: CHEMICAL TANKER
J5: Lpp | M5: =HARVARLD!F6 -> #REF! | O5: m
J6: Lwl | M6: =HARVARLD!F8 -> #REF! | O6: m
J7: Ldisplacement | M7: =HARVARLD!F14 -> #REF! | O7: m
J8: Lebar (B) | M8: =HARVARLD!F16 -> 23.7 | O8: m
J9: Sarat Air (T) | M9: =HARVARLD!F23 -> 9.947 | O9: m
J10: Tinggi Geladak (H) | M10: =HARVARLD!F25 -> 13.34 | O10: m
J11: Kecepatan (Vs) | M11: =HARVARLD!F27 -> 16 | O11: knot
J12: Awak Kapal (N) | M12: =ABK!F41 -> 20 | O12: orang
J13: D | M13: 9.5 | O13: days
J14: P | M14: 4.5 | O14: freighters
J15: F | M15: 2.8 | O15: mᶟ
A17: N | B17: =ABK!F41 -> 20 | C17: orang
A18: D | B18: 9.5 | C18: days
A19: P | B19: 4.5 | C19: for freighters
A20: F | B20: 2.8
A21: V | B21: =(B17*B19*B18*B20)/1000 -> 2.394
E22: 1m3= | F22: 35.3147 | G22: ft3
A23: Volume Ruang
A24: P | B24: =1.5 -> 1.5 | C24: m | I24: =B24*$F$22 -> 52.97205 | J24: ft
A25: L | B25: 2.5 | C25: m | I25: =B25*$F$22 -> 88.28675 | J25: ft
A26: High Celling (T) | B26: 2.5 | C26: m | I26: =B27*$F$22 -> 132.43013 | J26: ft
A27: Net Floor | B27: =B24*B25 -> 3.75 | I27: =B26*$F$22 -> 88.28675 | J27: ft
A28: gross volume | B28: =B27*B26 -> 9.375 | I28: =B28*$F$22 -> 331.07531 | J28: ft
B29: =B28*F22 -> 331.07531
L33: =B37*3 -> 0
B40: Density (pcf) | C40: Beban Produk (lb)
A41: Fish Store | B41: 35 | C41: =B41*B29 -> 11587.636
A42: Vegetable Store | B42: 30 | C42: =B29*B42 -> 9932.2594
A43: Meat Store | B43: 35 | C43: =B29*B43 -> 11587.636
A44: Total | C44: =SUM(C41:C43) -> 33107.531
A46: Item | B46: Meat and Fish | C46: Fruit and Vegetables | D46: Dairy Product
A47: Specific heat in Btu/lb F | B47: 0.45 | C47: 0.9 | D47: 0.7
B48: 35 | C48: 30 | D48: 22
B49: 15 | C49: 30 | D49: 25
B50: 48 | C50: 48 | D50: 48

Sheet Sheet2
A2: A. Perhitungan Panas Total (Qt)
A3: BEBAN PANS TRANSMISI (Qtr)
A4: Room | B4: Dimension | E4: Volume (m^3) | F4: Ouside Coondition | H4: Insiede Condition | J4: ΔT (°C) | K4: Wall | P4: Qtr
B5: Panjang | C5: Lebar | D5: Tinggi | F5: Temp | G5: RH | H5: Temp | I5: RH | K5: Koeff Heat | L5: F-A Wall | M5: Side Wall | N5: Roof | O5: Area
B6: m | C6: m | D6: m | F6: (°C) | G6: (%) | H6: (°C) | I6: (%) | K6: (W/m^2 °C ) | L6: (m^2) | M6: (m^2) | N6: (m^2) | O6: (m^2) | P6: (watt)
A7: Quarter Master+assistant cook+electrican man+fireman | B7: 4.039 | C7: 2.95 | D7: 2.4 | E7: =B7*C7*D7 -> 28.59612 | F7: 35 | G7: 70 | H7: 27 | I7: 50 | J7: =F7-H7 -> 8 | K7: 0.92 | L7: =2*(C7*D7) -> 14.16 | M7: =2*(B7*D7) -> 19.3872 | N7: =B7*C7 -> 11.91505 | O7: =L7+M7+N7 -> 45.46225 | P7: =K7*O7 -> 41.82527
A8: seaman+oiler | B8: 4.6 | C8: 3.836 | D8: 2.4 | E8: =B8*C8*D8 -> 42.34944 | F8: 35 | G8: 70 | H8: 27 | I8: 50 | J8: =F8-H8 -> 8 | K8: 0.92 | L8: =2*(C8*D8) -> 18.4128 | M8: =2*(B8*D8) -> 22.08 | N8: =B8*C8 -> 17.6456 | O8: =L8+M8+N8 -> 58.1384 | P8: =K8*O8 -> 53.487328
A9: oiler+seaman | B9: 2.999 | C9: 2.702 | D9: 2.4 | E9: =B9*C9*D9 -> 19.447915 | F9: 35 | G9: 70 | H9: 27 | I9: 50 | J9: =F9-H9 -> 8 | K9: 0.92 | L9: =2*(C9*D9) -> 12.9696 | M9: =2*(B9*D9) -> 14.3952 | N9: =B9*C9 -> 8.103298 | O9: =L9+M9+N9 -> 35.468098 | P9: =K9*O9 -> 32.63065
A10: boys+steward | B10: 3.596 | C10: 3.6 | D10: 2.4 | E10: =B10*C10*D10 -> 31.06944 | F10: 35 | G10: 70 | H10: 27 | I10: 50 | J10: =F10-H10 -> 8 | K10: 0.92 | L10: =2*(C10*D10) -> 17.28 | M10: =2*(B10*D10) -> 17.2608 | N10: =B10*C10 -> 12.9456 | O10: =L10+M10+N10 -> 47.4864 | P10: =K10*O10 -> 43.687488
A11: galley | B11: 3.194 | C11: 3.458 | D11: 2.4 | E11: =B11*C11*D11 -> 26.507645 | F11: 35 | G11: 70 | H11: 27 | I11: 50 | J11: =F11-H11 -> 8 | K11: 0.92 | L11: =2*(C11*D11) -> 16.5984 | M11: =2*(B11*D11) -> 15.3312 | N11: =B11*C11 -> 11.044852 | O11: =L11+M11+N11 -> 42.974452 | P11: =K11*O11 -> 39.536496
A12: office | B12: 2.999 | C12: 4.06 | D12: 2.4 | E12: =B12*C12*D12 -> 29.222256 | F12: 35 | G12: 70 | H12: 27 | I12: 50 | J12: =F12-H12 -> 8 | K12: 0.92 | L12: =2*(C12*D12) -> 19.488 | M12: =2*(B12*D12) -> 14.3952 | N12: =B12*C12 -> 12.17594 | O12: =L12+M12+N12 -> 46.05914 | P12: =K12*O12 -> 42.374409
A13: Total | P13: =SUM(P7:P12) -> 253.54164
J18: Kecepatan Angin Rata - Rata Jeddah
J19: 1 kph = | K19: 0.2778 | L19: m/s
J20: Kecepatan angin rata - rata = | M20: =(17.1+12.5+14.8)/3 -> 14.8 | N20: kph
L21: = | M21: =M20*K19 -> 4.11144 | N21: m/s
A40: BEBAN PANAS AKIBAT PENGHUNI RUANGAN (Qperson = Qp)
A41: Room | B41: Qty | C41: Sensible | D41: Latent | E41: Q Penghuni
B42: (Person) | C42: (Watt) | D42: (Watt) | E42: (Watt)
A43: Quarter Master+assistant cook+electrican man+fireman | B43: 4 | C43: 64 | D43: 97 | E43: =15*161 -> 2415
A44: seaman+oiler | B44: 2 | C44: 57 | D44: 60 | E44: =2*(C44+D44) -> 234
A45: oiler+seaman | B45: 2 | C45: 73 | D45: 149 | E45: =2*(C45+D45) -> 444
A46: boys+steward | B46: 2 | C46: 57 | D46: 60 | E46: =2*(C46+D46) -> 234
A47: galley | B47: 3 | C47: 57 | D47: 60 | E47: =2*(C47+D47) -> 234
A48: office | B48: 2 | C48: 57 | D48: 60 | E48: =1*(C48+D48) -> 117
A49: Total | E49: =SUM(E43:E48) -> 3678
A51: BEBAN PANAS AKIBAT RAMBAT DARI JENDELA (Qwindow = Qw)
A52: Room | B52: Ouside Coondition | D52: Insiede Condition | F52: ΔT (°C) | G52: Jumlah | H52: U Factor | I52: Luas | J52: Qw
B53: Temp | D53: Temp | G53: Jendela | H53: Double Kaca | I53: Jendela
B54: (°C) | D54: (°C) | G54: (buah) | H54: (W/m.°K) | I54: (m^2) | J54: (watt)
A55: Quarter Master+assistant cook+electrican man+fireman | B55: 35 | D55: 27 | F55: =B55-D55 -> 8 | G55: 4 | H55: 3.6 | I55: 0.2 | J55: =G55*H55*I55 -> 2.88
A56: seaman+oiler | B56: 35 | D56: 27 | F56: =B56-D56 -> 8 | G56: 2 | H56: 3.6 | I56: 0.2 | J56: =G56*H56*I56 -> 1.44
A57: oiler+seaman | B57: 35 | D57: 27 | F57: =B57-D57 -> 8 | G57: 2 | H57: 3.6 | I57: 0.2 | J57: =G57*H57*I57 -> 1.44
A58: boys+steward | B58: 35 | D58: 27 | F58: =B58-D58 -> 8 | G58: 2 | H58: 3.6 | I58: 0.2 | J58: =G58*H58*I58 -> 1.44
A59: galley | B59: 35 | D59: 27 | F59: =B59-D59 -> 8 | G59: 2 | H59: 3.6 | I59: 0.2 | J59: =G59*H59*I59 -> 1.44
A60: office | B60: 35 | D60: 27 | F60: =B60-D60 -> 8 | G60: 2 | H60: 3.6 | I60: 0.2 | J60: =G60*H60*I60 -> 1.44
A61: Total | J61: =SUM(J55:J60) -> 10.08
A63: BEBAN PANAS DARI PENGGUNAAN LAMPU PENERANGAN (Qlampu = Ql)
A64: Room | B64: Dimension | E64: Area | F64: Load | G64: Ql
B65: Panjang | C65: Lebar | D65: Tinggi | F65: Constant
...

Sheet JEJANGKARAN
B1: JANGKAR
A2: Data Utama Kapal
A3: Jenis Kapal | D3: CHEMICAL TANKER
A4: Lpp | D4: =HARVARLD!F6 -> #REF! | F4: m
A5: Lwl | D5: =HARVARLD!F8 -> #REF! | F5: m
A6: Ldisplacement | D6: =HARVARLD!F14 -> #REF! | F6: m
A7: Lebar (B) | D7: =HARVARLD!F16 -> 23.7 | F7: m
A8: Sarat Air (T) | D8: =HARVARLD!F23 -> 9.947 | F8: m
A9: Tinggi Geladak (H) | D9: =HARVARLD!F25 -> 13.34 | F9: m
A10: Kecepatan (Vs) | D10: =HARVARLD!F27 -> 16 | F10: knot
A11: Vdisplacement | D11: =HARVARLD!F28 -> #REF! | F11: mᶟ
A12: Koefisien midship/Cm (β) | D12: =HARVARLD!F30 -> 0.982
A13: Koefisien blok/Cb (δ) | D13: =HARVARLD!F31 -> 0.68
A14: Koefisien prismatik/Cp (ϕ) | D14: =HARVARLD!F32 -> 0.69
A15: Cbwl | D15: =D5/(D7*D8) -> #REF!
A17: Penentuan jangkar berdasarkan peraturan BKI 1996 Vol. III
A18: Z = D^2/3 + 2.H.B + A/10
A19: Dimana :
A20: D = Displacement kapal
A21: B = Lebar kapal
A22: H = fb + ƩH
A23: fb = Lambung timbul (H-T)
A24: ƩH = jumlah bangunan atas x tinggi masing-masing bangunan atas tsb
A25: A = Luas penampang membujur dr bangunan atas di atas garis air pd center line
A27: Z = D^2/3 + 2.H.B + A/10
A29: Dimana :
A30: D= | B30: Lwl x B x T x Cbwl x ρ | E30: 1.026
A31: = | B31: =D5*D7*D8*D15*E30 -> #REF!
A33: H= | B33: fb + ƩH
A34: = | B34: (H-T) + (jumlah lt x tinggi) | F34: deck | G34: tinggi | H34: lebar
A35: = | B35: =(D9-D8)+((G35)+(4*G36)) -> 15.893 | F35: main | G35: 2.5 | H35: =D7 -> 23.7
F36: poop | G36: 2.5 | H36: 16.2486
F37: boat | G37: 2.5 | H37: 13.9963
A38: A= | B38: (LWL x T) + (luas bangunan atas) | F38: bridge | G38: 2.5 | H38: 13.9963
A39: = | B39: =(D5*D8)+((G35*H35)+(G36*H36)+(G37*H37)+(G39*H39)+(G38*H38)) -> #REF! | F39: navigation | G39: 2.5 | H39: 11.998
A42: Z= | B42: D^2/3 + 2.H.B + A/10
A43: = | B43: =B31^(2/3) + (2*B35*D7) + (B39/10) -> #REF!
A45: BKI - Part1 - Vol II - 2022 - Rules for Hull
A46: Berdasarkan pada tabel BKI jilid II tahun 2006 section 18, maka dengan nilai | H46: Z = | I46: =B43 -> #REF!
A47: diperoleh data jangkar sebagai berikut :
...
