Workbook

Sheet List of Room
C1: PERHITUNGAN KEBUTUHAN AIR HANDLING UNIT (AHU) PADA AKOMODASI KAPAL
C5: Halaman :
C6: LIST RUANGAN AKOMODASI & DIMENSI
B8: NO. | C8: DECK | E8: ROOM | I8: P (m) | J8: L (m) | K8: T (m) | L8: A (m2) | M8: V (m3)
C10: Main Deck
B11: 1 | E11: Mess Room | I11: 4.64 | J11: 3.98 | K11: 2.5 | L11: =I11*J11 -> 18.4672 | M11: =L11*K11 -> 46.168
B12: 2 | E12: Quarter Master & Steward Room | I12: 3 | J12: 4.1 | K12: 2.5 | L12: =I12*J12 -> 12.3 | M12: =L12*K12 -> 30.75
B13: 3 | E13: Boatswain & Seaman Room | I13: 3 | J13: 4.24 | K13: 2.5 | L13: =I13*J13 -> 12.72 | M13: =L13*K13 -> 31.8
B14: 4 | E14: Oiler (2p) Room | I14: 3 | J14: 4.1 | K14: 2.5 | L14: =I14*J14 -> 12.3 | M14: =L14*K14 -> 30.75
B15: 5 | E15: Pumpman (2p) Room | I15: 3 | J15: 4.2 | K15: 2.5 | L15: =I15*J15 -> 12.6 | M15: =L15*K15 -> 31.5
B16: 6 | E16: Fireman (2p) Room | I16: 3 | J16: 4.24 | K16: 2.5 | L16: =I16*J16 -> 12.72 | M16: =L16*K16 -> 31.8
B17: 7 | E17: Boys (2p) Room | I17: 3 | J17: 4.2 | K17: 2.5 | L17: =I17*J17 -> 12.6 | M17: =L17*K17 -> 31.5
C19: Poop Deck
B20: 1 | E20: Chief Cook Room | I20: 3 | J20: 3.4 | K20: 2.4 | L20: =I20*J20 -> 10.2 | M20: =L20*K20 -> 24.48
B21: 2 | E21: Second Engineer Room | I21: 3 | J21: 3.4 | K21: 2.4 | L21: =I21*J21 -> 10.2 | M21: =L21*K21 -> 24.48
B22: 3 | E22: Musholla | I22: 3 | J22: 3.4 | K22: 2.4 | L22: =I22*J22 -> 10.2 | M22: =L22*K22 -> 24.48
B23: 4 | E23: Electrician Room | I23: 3 | J23: 3.4 | K23: 2.4 | L23: =I23*J23 -> 10.2 | M23: =L23*K23 -> 24.48
B24: 5 | E24: Smoking Room | I24: 3.5 | J24: 4 | K24: 2.4 | L24: =I24*J24 -> 14 | M24: =L24*K24 -> 33.6
B25: 6 | E25: Mess Room | I25: 3.5 | J25: 3.4 | K25: 2.4 | L25: =I25*J25 -> 11.9 | M25: =L25*K25 -> 28.56
C27: Boat Deck
B28: 1 | E28: Chief Officer % Engineer Office | I28: 3.55 | J28: 5 | K28: 2.4 | L28: =I28*J28 -> 17.75 | M28: =L28*K28 -> 42.6
B29: 2 | E29: Chief Officer Room | I29: 4.4 | J29: 3.41 | K29: 2.4 | L29: =I29*J29 -> 15.004 | M29: =L29*K29 -> 36.0096
B30: 3 | E30: Chief Engineer Room | I30: 4.4 | J30: 3.41 | K30: 2.4 | L30: =I30*J30 -> 15.004 | M30: =L30*K30 -> 36.0096
B31: 4 | E31: Second Officer Room | I31: 4 | J31: 3.41 | K31: 2.4 | L31: =I31*J31 -> 13.64 | M31: =L31*K31 -> 32.736
B32: 5 | E32: Medical Room | I32: 4 | J32: 3.41 | K32: 2.4 | L32: =I32*J32 -> 13.64 | M32: =L32*K32 -> 32.736
C34: Bridge Deck
B35: 1 | E35: Master Room | I35: 6.6 | J35: 3.23 | K35: 2.4 | L35: =I35*J35 -> 21.318 | M35: =L35*K35 -> 51.1632
B36: 2 | E36: Master Office | I36: 3.55 | J36: 2.98 | K36: 2.4 | L36: =I36*J36 -> 10.579 | M36: =L36*K36 -> 25.3896
B37: 3 | E37: Meeting Room | I37: 3.55 | J37: 3.2 | K37: 2.4 | L37: =I37*J37 -> 11.36 | M37: =L37*K37 -> 27.264
B38: 4 | E38: Radio Operator Room | I38: 4.35 | J38: 3.41 | K38: 2.4 | L38: =I38*J38 -> 14.8335 | M38: =L38*K38 -> 35.6004
B39: 5 | E39: Library | I39: 2.25 | J39: 3.41 | K39: 2.4 | L39: =I39*J39 -> 7.6725 | M39: =L39*K39 -> 18.414
C41: Navigation Deck
B42: 1 | E42: Navigation Room | I42: 6.925 | J42: 3.717 | K42: 2.5 | L42: =I42*J42 -> 25.740225 | M42: =K42*L42 -> 64.350562
B43: 2 | E43: Radio Room | I43: 6.925 | J43: 3.717 | K43: 2.5 | L43: =I43*J43 -> 25.740225 | M43: =K43*L43 -> 64.350562

Sheet Summary
D1: PERHITUNGAN KEBUTUHAN AIR HANDLING UNIT (AHU) PADA AKOMODASI KAPAL
D5: Halaman :
D6: COOLING SUMMARY
B8: SPACE | D8: DECK | E8: SIDE | F8: FRAMES | G8: Volume (ft3) | H8: Heat Area (ft2) | I8: BTU/HR | L8: SHF | M8: OUTSIDE AIR BASED ON * | P8: CFM | Q8: R/C TOTAL AIR | R8: Air Quantity (l/s) | S8: Friction Loss (Pa/mm) | T8: Duct Diameter (mm) | U8: Rect. Duct Size (mm) | W8: Uk. Diffuser | X8: l/s | Y8: Jumlah Diffuser
E9: SIDE | F9: FRAMES | I9: SENS. | J9: LATENT | K9: TOTAL | M9: R/C | N9: PERS. | O9: EXH. | U9: L x W
B10: Galley | D10: Main Deck | E10: P | F10: =[1]Galley!$H$3 -> 0 to 06 | G10: =[1]Galley!$J$38 -> 744.28379 | H10: =[1]Galley!$J$36 -> 674.09784 | I10: =[1]Galley!$J$40 -> 6295.4151 | J10: =[1]Galley!$M$36 -> 790 | K10: =I10+J10 -> 7085.4151 | L10: =[1]Galley!$J$41 -> 0.88850336 | M10: =[1]Galley!$G$33 -> 24.80946 | N10: =[1]Galley!$E$33 -> 15 | O10: =[1]Galley!$J$29 -> 15 | P10: =[1]Galley!$K$31 -> 234 | Q10: =MAX(M10:O10) -> 24.80946 | R10: =0.472*P10 -> 110.448
B11: Mess Room | E11: P | F11: ='[1]Mess Room '!$H$3 -> 04 to 11 | G11: ='[1]Mess Room '!$J$37 -> 1630.4091 | H11: ='[1]Mess Room '!$J$35 -> 1185.9092 | I11: ='[1]Mess Room '!$J$39 -> 12719.505 | J11: ='[1]Mess Room '!$M$35 -> 5000 | K11: =I11+J11 -> 17719.505 | L11: ='[1]Mess Room '!$J$40 -> 0.71782507 | M11: ='[1]Mess Room '!$G$32 -> 54.346969 | N11: ='[1]Mess Room '!$E$32 -> 150 | O11: ='[1]Mess Room '!$J$28 -> 150 | P11: ='[1]Mess Room '!$K$30 -> 472 | Q11: =MAX(M11:O11) -> 150 | R11: =0.472*P11 -> 222.784
B12: Quarter Master & Steward Room | E12: P | F12: ='[1]Quarter Master & Steward '!$H$3 -> 11 to 16 | G12: ='[1]Quarter Master & Steward '!$J$37 -> 1050.6123 | H12: ='[1]Quarter Master & Steward '!$J$35 -> 777.26767 | I12: ='[1]Quarter Master & Steward '!$J$39 -> 3687.0942 | J12: ='[1]Quarter Master & Steward '!$M$35 -> 1000 | K12: =I12+J12 -> 4687.0942 | L12: ='[1]Quarter Master & Steward '!$J$40 -> 0.7866482 | M12: ='[1]Quarter Master & Steward '!$G$32 -> 35.020411 | N12: ='[1]Quarter Master & Steward '!$E$32 -> 30 | O12: ='[1]Quarter Master & Steward '!$J$28 -> 30 | P12: ='[1]Quarter Master & Steward '!$K$30 -> 137 | Q12: =MAX(M12:O12) -> 35.020411 | R12: =0.472*P12 -> 64.664
B13: Boys (2p) Room | E13: P | F13: ='[1]Boys (2p)'!H3 -> 15 to 20 | G13: ='[1]Boys (2p)'!$J$37 -> 1109.7644 | H13: ='[1]Boys (2p)'!$J$35 -> 666.82214 | I13: ='[1]Boys (2p)'!$J$39 -> 3519.3369 | J13: ='[1]Boys (2p)'!$M$35 -> 1000 | K13: =I13+J13 -> 4519.3369 | L13: ='[1]Boys (2p)'!$J$40 -> 0.7787286 | M13: ='[1]Boys (2p)'!$G$32 -> 36.992148 | N13: ='[1]Boys (2p)'!$E$32 -> 30 | O13: ='[1]Boys (2p)'!$J$28 -> 30 | P13: ='[1]Boys (2p)'!$K$30 -> 131 | Q13: =MAX(M13:O13) -> 36.992148 | R13: =0.472*P13 -> 61.832
B14: Boatswain & Seaman Room | E14: P | F14: ='[1]Boatswain & Seaman'!H3 -> 20 to 25 | G14: ='[1]Boatswain & Seaman'!$J$37 -> 1123.0075 | H14: ='[1]Boatswain & Seaman'!$J$35 -> 806.00728 | I14: ='[1]Boatswain & Seaman'!$J$39 -> 4944.9238 | J14: ='[1]Boatswain & Seaman'!$M$35 -> 1000 | K14: =I14+J14 -> 5944.9238 | L14: ='[1]Boatswain & Seaman'!$J$40 -> 0.83178926 | M14: ='[1]Boatswain & Seaman'!$G$32 -> 37.433582 | N14: ='[1]Boatswain & Seaman'!$E$32 -> 30 | O14: ='[1]Boatswain & Seaman'!$J$28 -> 30 | P14: ='[1]Boatswain & Seaman'!$K$30 -> 184 | Q14: =MAX(M14:O14) -> 37.433582 | R14: =0.472*P14 -> 86.848
B15: Oiler (2p) Room | E15: S | F15: ='[1]Oiler (2p)'!H3 -> 11 to 16 | G15: ='[1]Oiler (2p)'!$J$37 -> 1085.927 | H15: ='[1]Oiler (2p)'!$J$35 -> 786.14789 | I15: ='[1]Oiler (2p)'!$J$39 -> 4285.9023 | J15: ='[1]Oiler (2p)'!$M$35 -> 1000 | K15: =I15+J15 -> 5285.9023 | L15: ='[1]Oiler (2p)'!$J$40 -> 0.81081754 | M15: ='[1]Oiler (2p)'!$G$32 -> 36.197567 | N15: ='[1]Oiler (2p)'!$E$32 -> 30 | O15: ='[1]Oiler (2p)'!$J$28 -> 30 | P15: ='[1]Oiler (2p)'!$K$30 -> 159 | Q15: =MAX(M15:O15) -> 36.197567 | R15: =0.472*P15 -> 75.048
B16: Pumpman (2p) Room | E16: S | F16: ='[1]Pumpman 2p)'!H3 -> 16 to 20 | G16: ='[1]Pumpman 2p)'!$J$37 -> 1112.4131 | H16: ='[1]Pumpman 2p)'!$J$35 -> 798.52637 | I16: ='[1]Pumpman 2p)'!$J$39 -> 3797.0892 | J16: ='[1]Pumpman 2p)'!$M$35 -> 1000 | K16: =I16+J16 -> 4797.0892 | L16: ='[1]Pumpman 2p)'!$J$40 -> 0.79154025 | M16: ='[1]Pumpman 2p)'!$G$32 -> 37.080435 | N16: ='[1]Pumpman 2p)'!$E$32 -> 30 | O16: ='[1]Pumpman 2p)'!$J$28 -> 30 | P16: ='[1]Pumpman 2p)'!$K$30 -> 141 | Q16: =MAX(M16:O16) -> 37.080435 | R16: =0.472*P16 -> 66.552
B17: Fireman (2p) Room | E17: S | F17: ='[1]Fireman (2P)'!H3 -> 20 to 25 | G17: ='[1]Fireman (2P)'!$J$37 -> 1123.0075 | H17: ='[1]Fireman (2P)'!$J$35 -> 802.29374 | I17: ='[1]Fireman (2P)'!$J$39 -> 4914.6042 | J17: ='[1]Fireman (2P)'!$M$35 -> 1000 | K17: =I17+J17 -> 5914.6042 | L17: ='[1]Fireman (2P)'!$J$40 -> 0.83092698 | M17: ='[1]Fireman (2P)'!$G$32 -> 37.433582 | N17: ='[1]Fireman (2P)'!$E$32 -> 30 | O17: ='[1]Fireman (2P)'!$J$28 -> 30 | P17: ='[1]Fireman (2P)'!$K$30 -> 183 | Q17: =MAX(M17:O17) -> 37.433582 | R17: =0.472*P17 -> 86.376
B18: Pantry | D18: Poop Deck | E18: P | F18: =[2]Pantry!$H$3 -> 06 to 11 | G18: =[2]Pantry!$J$37 -> 867.04651 | H18: =[2]Pantry!$J$35 -> 664.23165 | I18: =[2]Pantry!$J$39 -> 4077.055 | J18: =[2]Pantry!$M$35 -> 790 | K18: =I18+J18 -> 4867.055 | L18: =[2]Pantry!$J$40 -> 0.83768419 | M18: =[2]Pantry!$G$32 -> 28.90155 | N18: =[2]Pantry!$E$32 -> 15 | O18: =[2]Pantry!$J$28 -> 15 | P18: =[2]Pantry!$K$30 -> 152 | Q18: =MAX(M18:O18) -> 28.90155 | R18: =0.472*P18 -> 71.744
B19: Mess Room | E19: P | F19: ='[2]Mess Room '!$H$3 -> 11 to 16 | G19: ='[2]Mess Room '!$J$37 -> 1008.5878 | H19: ='[2]Mess Room '!$J$35 -> 769.3885 | I19: ='[2]Mess Room '!$J$39 -> 5347.1072 | J19: ='[2]Mess Room '!$M$35 -> 4000 | K19: =I19+J19 -> 9347.1072 | L19: ='[2]Mess Room '!$J$40 -> 0.57206011 | M19: ='[2]Mess Room '!$G$32 -> 33.619594 | N19: ='[2]Mess Room '!$E$32 -> 120 | O19: ='[2]Mess Room '!$J$28 -> 120 | P19: ='[2]Mess Room '!$K$30 -> 199 | Q19: =MAX(M19:O19) -> 120 | R19: =0.472*P19 -> 93.928
B20: Chief Cook Room | E20: P | F20: ='[2]Chief Cook Room'!$H$3 -> 20 to 24 | G20: ='[2]Chief Cook Room'!$J$37 -> 867.04651 | H20: ='[2]Chief Cook Room'!$J$35 -> 662.87971 | I20: ='[2]Chief Cook Room'!$J$39 -> 2171.0295 | J20: ='[2]Chief Cook Room'!$M$35 -> 500 | K20: =I20+J20 -> 2671.0295 | L20: ='[2]Chief Cook Room'!$J$40 -> 0.81280626 | M20: ='[2]Chief Cook Room'!$G$32 -> 28.90155 | N20: ='[2]Chief Cook Room'!$E$32 -> 15 | O20: ='[2]Chief Cook Room'!$J$28 -> 15 | P20: ='[2]Chief Cook Room'!$K$30 -> 81 | Q20: =MAX(M20:O20) -> 28.90155 | R20: =0.472*P20 -> 38.232
B21: Musholla | E21: S | F21: =[2]Musholla!$H$3 -> 11 to 16 | G21: =[2]Musholla!$J$37 -> 867.04651 | H21: =[2]Musholla!$J$35 -> 732.75895 | I21: =[2]Musholla!$J$39 -> 2473.1104 | J21: =[2]Musholla!$M$35 -> 1000 | K21: =I21+J21 -> 3473.1104 | L21: =[2]Musholla!$J$40 -> 0.71207365 | M21: =[2]Musholla!$G$32 -> 28.90155 | N21: =[2]Musholla!$E$32 -> 30 | O21: =[2]Musholla!$J$28 -> 30 | P21: =[2]Musholla!$K$30 -> 92 | Q21: =MAX(M21:O21) -> 30 | R21: =0.472*P21 -> 43.424
B22: Electrician Room | E22: S | F22: =[2]Electrician!$H$3 -> 16 to 20 | G22: =[2]Electrician!$J$37 -> 867.04651 | H22: =[2]Electrician!$J$35 -> 728.10894 | I22: =[2]Electrician!$J$39 -> 1399.0661 | J22: =[2]Electrician!$M$35 -> 500 | K22: =I22+J22 -> 1899.0661 | L22: =[2]Electrician!$J$40 -> 0.7367127 | M22: =[2]Electrician!$G$32 -> 28.90155 | N22: =[2]Electrician!$E$32 -> 15 | O22: =[2]Electrician!$J$28 -> 15 | P22: =[2]Electrician!$K$30 -> 52 | Q22: =MAX(M22:O22) -> 28.90155 | R22: =0.472*P22 -> 24.544
B23: Second Engineer Room | E23: S | F23: ='[2]Second Engineer'!$H$3 -> 20 to 25 | G23: ='[2]Second Engineer'!$J$37 -> 867.04651 | H23: ='[2]Second Engineer'!$J$35 -> 693.68599 | I23: ='[2]Second Engineer'!$J$39 -> 2154.4182 | J23: ='[2]Second Engineer'!$M$35 -> 500 | K23: =I23+J23 -> 2654.4182 | L23: ='[2]Second Engineer'!$J$40 -> 0.81163481 | M23: ='[2]Second Engineer'!$G$32 -> 28.90155 | N23: ='[2]Second Engineer'!$E$32 -> 15 | O23: ='[2]Second Engineer'!$J$28 -> 15 | P23: ='[2]Second Engineer'!$K$30 -> 80 | Q23: =MAX(M23:O23) -> 28.90155 | R23: =0.472*P23 -> 37.76
B24: Smoking Room | E24: C | F24: ='[2]Smoking Room'!$H$3 -> 20 to 25 | G24: ='[2]Smoking Room'!$J$37 -> 1186.5739 | H24: ='[2]Smoking Room'!$J$35 -> 879.96173 | I24: ='[2]Smoking Room'!$J$39 -> 4612.8964 | J24: ='[2]Smoking Room'!$M$35 -> 2000 | K24: =I24+J24 -> 6612.8964 | L24: ='[2]Smoking Room'!$J$40 -> 0.69756066 | M24: ='[2]Smoking Room'!$G$32 -> 39.552464 | N24: ='[2]Smoking Room'!$E$32 -> 60 | O24: ='[2]Smoking Room'!$J$28 -> 60 | P24: ='[2]Smoking Room'!$K$30 -> 171 | Q24: =MAX(M24:O24) -> 60 | R24: =0.472*P24 -> 80.712
B25: Second Officer Room | D25: Boat Deck | E25: P | F25: ='[3]Second Engineer'!$H$3 -> 12 to 18 | G25: ='[3]Second Engineer'!$J$37 -> 1156.062 | H25: ='[3]Second Engineer'!$J$35 -> 824.14446 | I25: ='[3]Second Engineer'!$J$39 -> 3903.9395 | J25: ='[3]Second Engineer'!$M$35 -> 500 | K25: =I25+J25 -> 4403.9395 | L25: ='[3]Second Engineer'!$J$40 -> 0.88646529 | M25: ='[3]Second Engineer'!$G$32 -> 38.535401 | N25: ='[3]Second Engineer'!$E$32 -> 15 | O25: ='[3]Second Engineer'!$J$28 -> 15 | P25: ='[3]Second Engineer'!$K$30 -> 145 | Q25: =MAX(M25:O25) -> 38.535401 | R25: =0.472*P25 -> 68.44
B26: Chief Engineer Room | E26: P | F26: ='[3]Chief Engineer'!$H$3 -> 18 to 25 | G26: ='[3]Chief Engineer'!$J$37 -> 1149.6206 | H26: ='[3]Chief Engineer'!$J$35 -> 890.72563 | I26: ='[3]Chief Engineer'!$J$39 -> 5332.9627 | J26: ='[3]Chief Engineer'!$M$35 -> 500 | K26: =I26+J26 -> 5832.9627 | L26: ='[3]Chief Engineer'!$J$40 -> 0.91428027 | M26: ='[3]Chief Engineer'!$G$32 -> 38.320687 | N26: ='[3]Chief Engineer'!$E$32 -> 15 | O26: ='[3]Chief Engineer'!$J$28 -> 15 | P26: ='[3]Chief Engineer'!$K$30 -> 198 | Q26: =MAX(M26:O26) -> 38.320687 | R26: =0.472*P26 -> 93.456
B27: Chief Officer & Engineer Office | E27: P | F27: ='[3]Chief Officer & Engineer Office'!$H$3 -> 19 to 25 | G27: ='[3]Chief Officer & Engineer Office'!$J$37 -> 1504.4062 | H27: ='[3]Chief Officer & Engineer Office'!$J$35 -> 1018.984 | I27: ='[3]Chief Officer & Engineer Office'!$J$39 -> 5244.8819 | J27: ='[3]Chief Officer & Engineer Office'!$M$35 -> 1000 | K27: =I27+J27 -> 6244.8819 | L27: ='[3]Chief Officer & Engineer Office'!$J$40 -> 0.83986887 | M27: ='[3]Chief Officer & Engineer Office'!$G$32 -> 50.146874 | N27: ='[3]Chief Officer & Engineer Office'!$E$32 -> 30 | O27: ='[3]Chief Officer & Engineer Office'!$J$28 -> 30 | P27: ='[3]Chief Officer & Engineer Office'!$K$30 -> 195 | Q27: =MAX(M27:O27) -> 50.146874 | R27: =0.472*P27 -> 92.04
B28: Medical Room | E28: S | F28: ='[3]Medical Room'!$H$3 -> 12 to 19 | G28: ='[3]Medical Room'!$J$37 -> 1034.0144 | H28: ='[3]Medical Room'!$J$35 -> 824.66112 | I28: ='[3]Medical Room'!$J$39 -> 5548.1094 | J28: ='[3]Medical Room'!$M$35 -> 1000 | K28: =I28+J28 -> 6548.1094 | L28: ='[3]Medical Room'!$J$40 -> 0.84728416 | M28: ='[3]Medical Room'!$G$32 -> 34.467147 | N28: ='[3]Medical Room'!$E$32 -> 30 | O28: ='[3]Medical Room'!$J$28 -> 30 | P28: ='[3]Medical Room'!$K$30 -> 206 | Q28: =MAX(M28:O28) -> 34.467147 | R28: =0.472*P28 -> 97.232
B29: Chief Officer Room | E29: S | F29: ='[3]Chief Officer'!$H$3 -> 128to 25 | G29: ='[3]Chief Officer'!$J$37 -> 1271.6682 | H29: ='[3]Chief Officer'!$J$35 -> 912.68399 | I29: ='[3]Chief Officer'!$J$39 -> 5169.157 | J29: ='[3]Chief Officer'!$M$35 -> 500 | K29: =I29+J29 -> 5669.157 | L29: ='[3]Chief Officer'!$J$40 -> 0.91180347 | M29: ='[3]Chief Officer'!$G$32 -> 42.388941 | N29: ='[3]Chief Officer'!$E$32 -> 15 | O29: ='[3]Chief Officer'!$J$28 -> 15 | P29: ='[3]Chief Officer'!$K$30 -> 192 | Q29: =MAX(M29:O29) -> 42.388941 | R29: =0.472*P29 -> 90.624
B30: Library | D30: Bridge Deck | E30: P | F30: =[4]Library!$H$3 -> 15 to 18 | G30: =[4]Library!$J$37 -> 650.28489 | H30: =[4]Library!$J$35 -> 476.62656 | I30: =[4]Library!$J$39 -> 3269.3285 | J30: =[4]Library!$M$35 -> 1000 | K30: =I30+J30 -> 4269.3285 | L30: =[4]Library!$J$40 -> 0.76577113 | M30: =[4]Library!$G$32 -> 21.676163 | N30: =[4]Library!$E$32 -> 30 | O30: =[4]Library!$J$28 -> 30 | P30: =[4]Library!$K$30 -> 122 | Q30: =MAX(M30:O30) -> 30 | R30: =0.472*P30 -> 57.584
B31: Radio Operator Room | E31: P | F31: ='[4]Radio Operator Room'!$H$3 -> 18 to 25 | G31: ='[4]Radio Operator Room'!$J$37 -> 1135.1698 | H31: ='[4]Radio Operator Room'!$J$35 -> 758.12408 | I31: ='[4]Radio Operator Room'!$J$39 -> 3188.8261 | J31: ='[4]Radio Operator Room'!$M$35 -> 500 | K31: =I31+J31 -> 3688.8261 | L31: ='[4]Radio Operator Room'!$J$40 -> 0.86445552 | M31: ='[4]Radio Operator Room'!$G$32 -> 37.838995 | N31: ='[4]Radio Operator Room'!$E$32 -> 15 | O31: ='[4]Radio Operator Room'!$J$28 -> 15 | P31: ='[4]Radio Operator Room'!$K$30 -> 119 | Q31: =MAX(M31:O31) -> 37.838995 | R31: =0.472*P31 -> 56.168
B32: Meeting Room | E32: S | F32: ='[4]Meeting Room'!$H$3 -> 19 to 25 | G32: ='[4]Meeting Room'!$J$37 -> 902.64373 | H32: ='[4]Meeting Room'!$J$35 -> 705.65221 | I32: ='[4]Meeting Room'!$J$39 -> 4453.5467 | J32: ='[4]Meeting Room'!$M$35 -> 3000 | K32: =I32+J32 -> 7453.5467 | L32: ='[4]Meeting Room'!$J$40 -> 0.59750705 | M32: ='[4]Meeting Room'!$G$32 -> 30.088124 | N32: ='[4]Meeting Room'!$E$32 -> 90 | O32: ='[4]Meeting Room'!$J$28 -> 90 | P32: ='[4]Meeting Room'!$K$30 -> 165 | Q32: =MAX(M32:O32) -> 90 | R32: =0.472*P32 -> 77.88
B33: Master Office | E33: S | F33: ='[4]Master Office'!$H$3 -> 19 to 25 | G33: ='[4]Master Office'!$J$37 -> 965.82879 | H33: ='[4]Master Office'!$J$35 -> 719.95098 | I33: ='[4]Master Office'!$J$39 -> 3521.6719 | J33: ='[4]Master Office'!$M$35 -> 500 | K33: =I33+J33 -> 4021.6719 | L33: ='[4]Master Office'!$J$40 -> 0.8756736 | M33: ='[4]Master Office'!$G$32 -> 32.194293 | N33: ='[4]Master Office'!$E$32 -> 15 | O33: ='[4]Master Office'!$J$28 -> 15 | P33: ='[4]Master Office'!$K$30 -> 131 | Q33: =MAX(M33:O33) -> 32.194293 | R33: =0.472*P33 -> 61.832
B34: Master Room | E34: C | F34: =[4]Master!$H$3 -> 15 to 25 | G34: =[4]Master!$J$37 -> 1593.2298 | H34: =[4]Master!$J$35 -> 1198.9822 | I34: =[4]Master!$J$39 -> 6489.7381 | J34: =[4]Master!$M$35 -> 500 | K34: =I34+J34 -> 6989.7381 | L34: =[4]Master!$J$40 -> 0.92846656 | M34: =[4]Master!$G$32 -> 53.107658 | N34: =[4]Master!$E$32 -> 15 | O34: =[4]Master!$J$28 -> 15 | P34: =[4]Master!$K$30 -> 241 | Q34: =MAX(M34:O34) -> 53.107658 | R34: =0.472*P34 -> 113.752
B35: Navigation Room | D35: Navigation Deck | E35: C | F35: ='[5]Nav Room'!$H$3 -> 15 to 25 | G35: ='[5]Nav Room'!$J$40 -> 7171.3138 | H35: ='[5]Nav Room'!$J$38 -> 2755.4234 | I35: ='[5]Nav Room'!$J$42 -> 34930.508 | J35: ='[5]Nav Room'!$M$38 -> 2000 | K35: =I35+J35 -> 36930.508 | L35: ='[5]Nav Room'!$J$43 -> 0.94584423 | M35: ='[5]Nav Room'!$G$35 -> 239.04379 | N35: ='[5]Nav Room'!$E$35 -> 60 | O35: ='[5]Nav Room'!$J$31 -> 60 | P35: ='[5]Nav Room'!$K$33 -> 1294 | Q35: =MAX(M35:O35) -> 239.04379 | R35: =0.472*P35 -> 610.768
I38: =SUM(I10:I36) -> 147451.22 | J38: =SUM(J10:J36) -> 32080 | K38: =SUM(K10:K36) -> 179531.22 | P38: =SUM(P10:P36) -> 5476
D40: Room | E40: Air Out
D41: Main Deck | E41: =SUM(P10:P17) -> 1641 | H41: =SUM(E43:E45) -> 2802
D42: Poop Deck | E42: =SUM(P18:P24) -> 827 | H42: =E41+E45+E42 -> 3762
D43: Boat Deck | E43: =SUM(P25:P27)+P29 -> 730
D44: Bridge Deck | E44: =SUM(P30:P34) -> 778
D45: Navigation Deck | E45: =P35 -> 1294
D46: Total | E46: =SUM(E41:E45) -> 5270 | F46: CFM = | G46: =E46*0.472 -> 2487.44 | H46: l/s

Sheet Main Deck
B2: 1 | C2: 2 | D2: 3 | E2: 4 | F2: 5 | G2: 6 | H2: 7 | I2: 8 | J2: 9 | L2: 10 | M2: 11 | N2: 12 | Q2: 1 | R2: 2 | S2: 3 | T2: 4 | U2: 5 | V2: 6 | W2: 7 | X2: 8 | Y2: 9 | AA2: 10 | AB2: 11 | AC2: 12
B3: BRANCH SECT. NO. | C3: AIR QUANTITY Q (cfm) | D3: EQUIV. DUCT LENGTH L (ft) | E3: PRESSURE READING (in.wg) | G3: TAKE OFF TO TAKE OFF S.P. (in.wg) | H3: S.P. AHEAD OF TAKE OFF (in.wg) | I3: AIR TERMINAL PRESS. (in.wg) | J3: DUCT SIZE | L3: VELOCITY V (fpm) | M3: Loses Branch to Terminal (in.wg) | N3: DUCT Terminal Size | Q3: BRANCH SECT. NO. | R3: AIR QUANTITY Q (cfm) | S3: EQUIV. DUCT LENGTH L (ft) | T3: PRESSURE READING (in.wg) | V3: TAKE OFF TO TAKE OFF S.P. (in.wg) | W3: S.P. AHEAD OF TAKE OFF (in.wg) | X3: AIR TERMINAL PRESS. (in.wg) | Y3: DUCT SIZE (in.) | AA3: VELOCITY V (fpm) | AB3: Loses Branch to Terminal (in.wg) | AC3: DUCT Terminal Size
E4: Initial | F4: Selected | J4: (in.) | K4: (m) | N4: (in.) | O4: (mm) | T4: Initial | U4: Selected | Y4: (in.) | Z4: (m) | AC4: (in.) | AD4: (mm)
B5: =B19 -> MD (B-01) | C5: =H14 -> 1641 | D5: =C20+C45 -> 20.36544 | G5: 1.25 | H5: =G5+G6 -> 1.942425 | I5: 1.5 | J5: 8 | K5: =J5*$AH$8 -> 0.2032 | L5: 4500 | Q5: =B5 -> MD (B-01) | R5: =C5 -> 1641 | S5: =D5 -> 20.36544 | V5: =G5 -> 1.25 | W5: =V5+V6 -> 1.942425 | X5: 1.5 | Y5: 8 | Z5: =Y5*$AH$8 -> 0.2032 | AA5: 4500
G6: =AK7 -> 0.69242496 | I6: 1.5 | V6: =G6 -> 0.69242496 | X6: 1.5 | AF6: 1 | AG6: m = | AH6: 3.28 | AI6: ft | AJ6: Friction Lose | AK6: 3.4 | AL6: in.wg
B7: =B21 -> MD (01-02) | C7: =D14 -> 843 | D7: =C22 -> 7.544 | E7: 1.25 | F7: 0.92 | G7: =E7-F7 -> 0.33 | H7: =H5-G7 -> 1.612425 | I7: 1.5 | J7: 7 | K7: =J7*$AH$8 -> 0.1778 | L7: 3200 | M7: 0.34 | N7: 4 | O7: =N7*$AH$9 -> 101.6 | Q7: =Q22 -> MD (01-05) | R7: =T15 -> 798 | S7: =R23 -> 2.296 | T7: 1.25 | U7: 1.5 | V7: =T7-U7 -> -0.25 | W7: =W5-V7 -> 2.192425 | X7: 1.5 | Y7: 6 | Z7: =Y7*$AH$8 -> 0.1524 | AA7: 3900 | AB7: 0.32 | AC7: 4 | AD7: =AC7*$AH$9 -> 101.6 | AF7: 1 | AG7: inch | AH7: 0.0834 | AI7: ft | AJ7: Pressure Drop | AK7: =(D5*AK6)/100 -> 0.69242496 | AL7: in.wg
B8: =B23 -> MD (02-03) | C8: =D15 -> 706 | D8: =C24 -> 12.4312 | E8: 0.55 | F8: 0.88 | G8: =E8-F8 -> -0.33 | H8: =H7-G8 -> 1.942425 | I8: 1.5 | J8: 7 | K8: =J8*$AH$8 -> 0.1778 | L8: 2600 | M8: 0.7 | N8: 6 | O8: =N8*$AH$9 -> 152.4 | Q8: =Q24 -> MD (05-06) | R8: =T16 -> 667 | S8: =R25 -> 9.5776 | T8: 0.92 | U8: 1.1 | V8: =T8-U8 -> -0.18 | W8: =W7-V8 -> 2.372425 | X8: 1.5 | Y8: 6 | Z8: =Y8*$AH$8 -> 0.1524 | AA8: 3300 | AB8: 0.61 | AC8: 4 | AD8: =AC8*$AH$9 -> 101.6 | AF8: 1 | AG8: inch | AH8: 0.0254 | AI8: m
B9: =B25 -> MD (03-04) | C9: =C16 -> 234 | D9: =C26 -> 12.628 | E9: 3.8 | F9: 3 | G9: =E9-F9 -> 0.8 | H9: =H8-G9 -> 1.142425 | I9: 1.5 | J9: 5 | K9: =J9*$AH$8 -> 0.127 | L9: 1600 | M9: 0.36 | N9: 5 | O9: =N9*$AH$9 -> 127 | Q9: =Q26 -> MD (06-07) | R9: =T17 -> 483 | S9: =R27+(R33*2) -> 38.2832 | T9: 0.26 | U9: 0.3 | V9: =T9-U9 -> -0.04 | W9: =W8-V9 -> 2.412425 | X9: 1.5 | Y9: 7 | Z9: =Y9*$AH$8 -> 0.1778 | AA9: 1800 | AB9: 0.6 | AC9: 4 | AD9: =AC9*$AH$9 -> 101.6 | AE9: =W9+X9+AB9 -> 4.512425 | AF9: 1 | AG9: inch | AH9: =AH8*1000 -> 25.4 | AI9: mm
Q10: =Q28 -> MD (07-08) | R10: =T18 -> 300 | S10: =R29 -> 9.676 | T10: 0.19 | U10: 0.225 | V10: =T10-U10 -> -0.035 | W10: =W9-V10 -> 2.447425 | X10: 1.5 | Y10: 6 | Z10: =Y10*$AH$8 -> 0.1524 | AA10: 1460 | AB10: 0.35 | AC10: 4 | AD10: =AC10*$AH$9 -> 101.6 | AE10: =W10+X10+AB10 -> 4.297425
Q11: =Q30 -> MD (08-09) | R11: =S19 -> 159 | S11: =R31 -> 10.3648 | T11: 0.12 | U11: 0.15 | V11: =T11-U11 -> -0.03 | W11: =W10-V11 -> 2.477425 | X11: 1.5 | Y11: 5 | Z11: =Y11*$AH$8 -> 0.127 | AA11: 1100 | AB11: 0.47 | AC11: 4 | AD11: =AC11*$AH$9 -> 101.6 | AE11: =W11+X11+AB11 -> 4.447425
R12: Maximum S.P. at Section MD (06-07) | V12: =W9 -> 2.412425 | W12: + | X12: =+X9 -> 1.5 | Y12: + | AA12: =+AB9 -> 0.6 | AB12: = | AC12: =+V12+X12+AA12 -> 4.512425
B13: Jalur Kiri | E13: l/s | G13: Urutan Section
B14: Quarter Master & Steward | C14: =Summary!P12 -> 137 | D14: =SUM(C14:C16) -> 843 | E14: =C14*0.472 -> 64.664 | G14: =B5 -> MD (B-01) | H14: =D14+T15 -> 1641 | Q14: Jalur Kanan | V14: l/s | Y14: Urutan Section
B15: MessRoom | C15: =Summary!P11 -> 472 | D15: =C15+C16 -> 706 | E15: =C15*0.472 -> 222.784 | G15: =B7 -> MD (01-02) | H15: =C7 -> 843 | Q15: Boys (2p) Room | S15: =Summary!P13 -> 131 | T15: =SUM(S15:S19) -> 798 | V15: =S15*0.472 -> 61.832 | Y15: =Q5 -> MD (B-01) | Z15: =R5 -> 1641
B16: GalleyRoom | C16: =Summary!P10 -> 234 | E16: =C16*0.472 -> 110.448 | G16: =B7 -> MD (01-02) | H16: =C8 -> 706 | Q16: Boatswain & Seaman Room | S16: =Summary!P14 -> 184 | T16: =SUM(S16:S19) -> 667 | V16: =S16*0.472 -> 86.848 | Y16: =Q7 -> MD (01-05) | Z16: =R7 -> 798
G17: =B9 -> MD (03-04) | H17: =C9 -> 234 | Q17: Fireman (2p) Room | S17: =Summary!P17 -> 183 | T17: =SUM(S17:S19) -> 483 | V17: =S17*0.472 -> 86.376 | Y17: =Q8 -> MD (05-06) | Z17: =R8 -> 667
B18: Panjang line | Q18: Pumpman (2p) Room | S18: =Summary!P16 -> 141 | T18: =S18+S19 -> 300 | V18: =S18*0.472 -> 66.552 | Y18: =Q9 -> MD (06-07) | Z18: =R9 -> 483
B19: MD (B-01) | C19: 3.768 | D19: m | Q19: Oiler (2p) Room | S19: =Summary!P15 -> 159 | V19: =S19*0.472 -> 75.048 | Y19: =Q10 -> MD (07-08) | Z19: =R10 -> 300
C20: =C19*AH6 -> 12.35904 | D20: ft | Y20: =Q11 -> MD (08-09) | Z20: =R11 -> 159
B21: MD (01-02) | C21: 2.3 | D21: m | Q21: Panjang line
C22: =C21*AH6 -> 7.544 | D22: ft | Q22: MD (01-05) | R22: 0.7 | S22: m
B23: MD (02-03) | C23: 3.79 | D23: m | R23: =R22*AH6 -> 2.296 | S23: ft
C24: =C23*AH6 -> 12.4312 | D24: ft | Q24: MD (05-06) | R24: 2.92 | S24: m
B25: MD (03-04) | C25: 3.85 | D25: m | R25: =R24*AH6 -> 9.5776 | S25: ft
C26: =C25*AH6 -> 12.628 | D26: ft | Q26: MD (06-07) | R26: =0.62+7.24+0.58 -> 8.44 | S26: m | T26: =0.62*AH6 -> 2.0336 | U26: =7.24*AH6 -> 23.7472 | V26: =0.58*AH6 -> 1.9024
B27: Panjang Terminal = | D27: 2 | E27: m | R27: =R26*AH6 -> 27.6832 | S27: ft
D28: =D27*AH6 -> 6.56 | E28: ft | Q28: MD (07-08) | R28: 2.95 | S28: m
B29: Tinggi Deck = | D29: 2.5 | E29: m | R29: =R28*AH6 -> 9.676 | S29: ft
D30: =D29*AH6 -> 8.2 | E30: ft | Q30: MD (08-09) | R30: 3.16 | S30: m
R31: =R30*AH6 -> 10.3648 | S31: ft
B32: Le/D = | C32: K/f
B33: f = | C33: K/(Le/D) | Q33: Le Smooth Elbow 7 inch = | R33: 5.3 | S33: ft
B34: f = | C34: =0.24/12 -> 0.02
B35: Le/D = | C35: K/f | H35: Sebelum | K35: DUCT Terminal Size | N35: Damper | P35: Sesudah
B36: Le = | C36: (K*D)/f | H36: CFM pipe flow | I36: CFM Excel | J36: eror | K36: Sebelum | L36: Sesudah | N36: Deck | O36: Room | P36: CFM pipe flow | Q36: CFM Excel | R36: eror
B37: Le = | C37: =(0.24*J5)/C34 -> 96 | D37: Inch | G37: MD (01-02) | H37: 179 | I37: =C14 -> 137 | J37: =(H37-I37)/I37 -> 0.30656934 | K37: =N7 -> 4 | L37: 2.5 | M37: =L37*$AH$8 -> 0.0635 | N37: Yes | O37: No | P37: 143 | Q37: =I37 -> 137 | R37: =(P37-Q37)/Q37 -> 0.04379562
C38: =C37*AH7 -> 8.0064 | D38: ft | G38: MD (02-03) | H38: 453 | I38: =C15 -> 472 | J38: =(H38-I38)/I38 -> -0.040254237 | K38: =N8 -> 6 | L38: 5 | M38: =L38*$AH$8 -> 0.127 | O38: No | P38: 499 | Q38: =I38 -> 472 | R38: =(P38-Q38)/Q38 -> 0.05720339
G39: MD (03-04) | H39: 274 | I39: =C16 -> 234 | J39: =(H39-I39)/I39 -> 0.17094017 | K39: =N9 -> 5 | L39: 3 | M39: =L39*$AH$8 -> 0.0762 | O39: No | P39: 253 | Q39: =I39 -> 234 | R39: =(P39-Q39)/Q39 -> 0.081196581
B40: Le/D = | C40: 12 | G40: MD (01-05) | H40: 163 | I40: =S15 -> 131 | J40: =(H40-I40)/I40 -> 0.24427481 | K40: =AC7 -> 4 | L40: 2.5 | M40: =L40*$AH$8 -> 0.0635 | O40: No | P40: 127 | Q40: =I40 -> 131 | R40: =(P40-Q40)/Q40 -> -0.030534351
B41: Le = | C41: Le/D*D | G41: MD (05-06) | H41: 146 | I41: =S16 -> 184 | J41: =(H41-I41)/I41 -> -0.20652174 | K41: =AC8 -> 4 | L41: 4 | M41: =L41*$AH$8 -> 0.1016 | O41: No | P41: 179 | Q41: =I41 -> 184 | R41: =(P41-Q41)/Q41 -> -0.027173913
...

Sheet Poop Deck 
B2: 1 | C2: 2 | D2: 3 | E2: 4 | F2: 5 | G2: 6 | H2: 7 | I2: 8 | J2: 9 | L2: 10 | M2: 11 | N2: 12
B3: BRANCH SECT. NO. | C3: AIR QUANTITY Q (cfm) | D3: EQUIV. DUCT LENGTH L (ft) | E3: PRESSURE READING (in.wg) | G3: TAKE OFF TO TAKE OFF S.P. (in.wg) | H3: S.P. AHEAD OF TAKE OFF (in.wg) | I3: AIR TERMINAL PRESS. (in.wg) | J3: DUCT SIZE | L3: VELOCITY V (fpm) | M3: Loses Branch to Terminal (in.wg) | N3: DUCT Terminal Size
E4: Initial | F4: Selected | J4: (in.) | K4: (m) | N4: (in.) | O4: (mm)
B5: =B24 -> PD (A-01) | C5: =D15 -> 827 | D5: =C25 -> 11.3324 | G5: 1.2 | H5: =G5+G6 -> 1.6759608 | I5: 1.5 | J5: 6 | K5: =J5*$S$8 -> 0.1524 | L5: 4300 | M5: 0.175 | N5: 4 | O5: =N5*$S$9 -> 101.6
G6: =V7 -> 0.4759608 | I6: 1.5 | Q6: 1 | R6: m = | S6: 3.28 | T6: ft | U6: Friction Lose | V6: 4.2 | W6: in.wg
B7: =B26 -> PD (01-02) | C7: =D16 -> 735 | D7: =C27+C39 -> 8.2392 | E7: 1.1 | F7: 1.3 | G7: =E7-F7 -> -0.2 | H7: =H5-G7 -> 1.8759608 | I7: 1.5 | J7: 6 | K7: =J7*$S$8 -> 0.1524 | L7: 3700 | M7: 0.225 | N7: 3 | O7: =N7*$S$9 -> 76.2 | Q7: 1 | R7: inch | S7: 0.0834 | T7: ft | U7: Pressure Drop | V7: =(D5*V6)/100 -> 0.4759608 | W7: in.wg
B8: =B28 -> PD (02-03) | C8: =D17 -> 683 | D8: =C29+C39 -> 11.1584 | E8: 0.82 | F8: 1.2 | G8: =E8-F8 -> -0.38 | H8: =H7-G8 -> 2.2559608 | I8: 1.5 | J8: 6 | K8: =J8*$S$8 -> 0.1524 | L8: 3400 | M8: 0.45 | N8: 3 | O8: =N8*$S$9 -> 76.2 | Q8: 1 | R8: inch | S8: 0.0254 | T8: m
B9: =B30 -> PD (03-04) | C9: =D18 -> 603 | D9: =C31 -> 11.316 | E9: 0.7 | F9: 0.9 | G9: =E9-F9 -> -0.2 | H9: =H8-G9 -> 2.4559608 | I9: 1.5 | J9: 6 | K9: =J9*$S$8 -> 0.1524 | L9: 3000 | M9: 0.575 | N9: 4 | O9: =N9*$S$9 -> 101.6 | P9: =H9+I9+M9 -> 4.5309608 | Q9: 1 | R9: inch | S9: =S8*1000 -> 25.4 | T9: mm
B10: =B32 -> PD (04-05) | C10: =D19 -> 432 | D10: =C33 -> 11.808 | E10: 0.55 | F10: 0.45 | G10: =E10-F10 -> 0.1 | H10: =H9-G10 -> 2.3559608 | I10: 1.5 | J10: 6 | K10: =J10*$S$8 -> 0.1524 | L10: 2200 | M10: 0.46 | N10: 3 | O10: =N10*$S$9 -> 76.2 | P10: =H10+I10+M10 -> 4.3159608
B11: =B34 -> PD (05-06) | C11: =D20 -> 351 | D11: =C35+C40 -> 22.0936 | E11: 0.215 | F11: 0.185 | G11: =E11-F11 -> 0.03 | H11: =H10-G11 -> 2.3259608 | I11: 1.5 | J11: 7 | K11: =J11*$S$8 -> 0.1778 | L11: 1400 | M11: 0.28 | N11: 5 | O11: =N11*$S$9 -> 127
B12: =B36 -> PD (06-07) | C12: =C21 -> 152 | D12: =C37 -> 10.8568 | E12: 0.115 | F12: 0.141 | G12: =E12-F12 -> -0.026 | H12: =H11-G12 -> 2.3519608 | I12: 1.5 | J12: 5 | K12: =J12*$S$8 -> 0.127 | L12: 1100 | M12: 0.45 | N12: 4 | O12: =N12*$S$9 -> 101.6 | P12: =+H12+I12+M12 -> 4.3019608
C13: Maximum S.P. at Section PD (03-04) | G13: =H9 -> 2.4559608 | H13: + | I13: =I9 -> 1.5 | J13: + | L13: =M9 -> 0.575 | M13: = | N13: =G13+I13+L13 -> 4.5309608
F14: l/s
B15: =Summary!B21 -> Musholla | C15: =Summary!P21 -> 92 | D15: =SUM(C15:C21) -> 827 | F15: =C15*0.472 -> 43.424 | J15: Urutan Section
B16: =Summary!B22 -> Electrician Room | C16: =Summary!P22 -> 52 | D16: =SUM(C16:C21) -> 735 | F16: =C16*0.472 -> 24.544 | J16: =B5 -> PD (A-01) | L16: =D15 -> 827 | O16: Sebelum | R16: DUCT Terminal Size | U16: Damper | V16: Sesudah
B17: =Summary!B23 -> Second Engineer Room | C17: =Summary!P23 -> 80 | D17: =SUM(C17:C21) -> 683 | F17: =C17*0.472 -> 37.76 | J17: =B7 -> PD (01-02) | L17: =C7 -> 735 | O17: CFM pipe flow | P17: CFM Excel | Q17: eror | R17: Sebelum | S17: Sesudah | V17: CFM pipe flow | W17: CFM Excel | X17: eror
B18: =Summary!B24 -> Smoking Room | C18: =Summary!P24 -> 171 | D18: =SUM(C18:C21) -> 603 | F18: =C18*0.472 -> 80.712 | J18: =B7 -> PD (01-02) | L18: =C8 -> 683 | N18: PD (A-01) | O18: 328 | P18: =C15 -> 92 | Q18: =(O18-P18)/P18 -> 2.5652174 | R18: =N5 -> 4 | S18: 4 | T18: =S18*$S$8 -> 0.1016 | U18: Yes | V18: 92 | W18: =P18 -> 92 | X18: =(V18-W18)/W18 -> 0
B19: =Summary!B20 -> Chief Cook Room | C19: =Summary!P20 -> 81 | D19: =SUM(C19:C21) -> 432 | F19: =C19*0.472 -> 38.232 | J19: =B9 -> PD (03-04) | L19: =C9 -> 603 | N19: PD (01-02) | O19: 206 | P19: =C16 -> 52 | Q19: =(O19-P19)/P19 -> 2.9615385 | R19: =N7 -> 3 | S19: 3 | T19: =S19*$S$8 -> 0.0762 | U19: Yes | V19: 52 | W19: =P19 -> 52 | X19: =(V19-W19)/W19 -> 0
B20: =Summary!B19 -> Mess Room | C20: =Summary!P19 -> 199 | D20: =SUM(C20:C21) -> 351 | F20: =C20*0.472 -> 93.928 | J20: =B10 -> PD (04-05) | L20: =C10 -> 432 | N20: PD (02-03) | O20: 51.5 | P20: =C17 -> 80 | Q20: =(O20-P20)/P20 -> -0.35625 | R20: =N8 -> 3 | S20: 2 | T20: =S20*$S$8 -> 0.0508 | U20: No | V20: 78.78 | W20: =P20 -> 80 | X20: =(V20-W20)/W20 -> -0.01525
B21: =Summary!B18 -> Pantry | C21: =Summary!P18 -> 152 | F21: =C21*0.472 -> 71.744 | J21: =B11 -> PD (05-06) | L21: =C11 -> 351 | N21: PD (03-04) | O21: 51.14 | P21: =C18 -> 171 | Q21: =(O21-P21)/P21 -> -0.70093567 | R21: =N9 -> 4 | S21: 4 | T21: =S21*$S$8 -> 0.1016 | U21: No | V21: 159 | W21: =P21 -> 171 | X21: =(V21-W21)/W21 -> -0.070175439
J22: =B12 -> PD (06-07) | L22: =C12 -> 152 | N22: PD (04-05) | O22: 34.99 | P22: =C19 -> 81 | Q22: =(O22-P22)/P22 -> -0.56802469 | R22: =N10 -> 3 | S22: 2.5 | T22: =S22*$S$8 -> 0.0635 | U22: No | V22: 84.35 | W22: =P22 -> 81 | X22: =(V22-W22)/W22 -> 0.041358025
B23: Panjang line | E23: Panjang Terminal = | G23: 2 | H23: m | N23: PD (05-06) | O23: 75.24 | P23: =C20 -> 199 | Q23: =(O23-P23)/P23 -> -0.62190955 | R23: =N11 -> 5 | S23: 4 | T23: =S23*$S$8 -> 0.1016 | U23: No | V23: 210 | W23: =P23 -> 199 | X23: =(V23-W23)/W23 -> 0.055276382
B24: PD (A-01) | C24: 3.455 | D24: m | G24: =G23*S6 -> 6.56 | H24: ft | N24: PD (06-07) | O24: 41.24 | P24: =C21 -> 152 | Q24: =(O24-P24)/P24 -> -0.72868421 | R24: =N12 -> 4 | S24: 4 | T24: =S24*$S$8 -> 0.1016 | U24: No | V24: 143 | W24: =P24 -> 152 | X24: =(V24-W24)/W24 -> -0.059210526
C25: =C24*S6 -> 11.3324 | D25: ft | E25: Tinggi Deck = | G25: 2.4 | H25: m
B26: PD (01-02) | C26: =0.37+0.77 -> 1.14 | D26: m | G26: =G25*S6 -> 7.872 | H26: ft
C27: =C26*S6 -> 3.7392 | D27: ft | N27: Total Panjang Pipa | S27: Total Elbow
B28: PD (02-03) | C28: =1.66+0.37 -> 2.03 | D28: m | N28: Ukuran (inch) | O28: Panjang (ft) | P28: Panjang (m) | Q28: Total (m) | S28: Ukuran (inch) | T28: Jumlah
C29: =C28*S6 -> 6.6584 | D29: ft | N29: 8 | O29: =D11 -> 22.0936 | P29: =O29/$S$6 -> 6.7358537 | Q29: 7 | S29: 8 | T29: 1
B30: PD (03-04) | C30: 3.45 | D30: m | N30: 6 | O30: =D5+D7+D8+D9+D10 -> 53.854 | P30: =O30/$S$6 -> 16.418902 | Q30: 16.5 | S30: 6 | T30: 1
C31: =C30*S6 -> 11.316 | D31: ft | N31: 5 | O31: =D12 -> 10.8568 | P31: =O31/$S$6 -> 3.31 | Q31: 3.5
B32: PD (04-05) | C32: 3.6 | D32: m | N32: 4 | O32: =G24*4 -> 26.24 | P32: =O32/$S$6 -> 8 | Q32: 8
C33: =C32*S6 -> 11.808 | D33: ft | N33: 3 | O33: =G24 -> 6.56 | P33: =O33/$S$6 -> 2 | Q33: 2
B34: PD (05-06) | C34: =0.6+4.52 -> 5.12 | D34: m | N34: 2.5 | O34: =G24 -> 6.56 | P34: =O34/$S$6 -> 2 | Q34: 2
C35: =C34*S6 -> 16.7936 | D35: ft | N35: 2 | O35: =G24 -> 6.56 | P35: =O35/$S$6 -> 2 | Q35: 2
B36: PD (06-07) | C36: 3.31 | D36: m
C37: =C36*S6 -> 10.8568 | D37: ft
B39: Le Smooth Elbow 6 inch = | C39: 4.5 | D39: ft
B40: Le Smooth Elbow 7 inch = | C40: 5.3 | D40: ft

Sheet Boat Deck 
B2: 1 | C2: 2 | D2: 3 | E2: 4 | F2: 5 | G2: 6 | H2: 7 | I2: 8 | J2: 9 | L2: 10 | M2: 11 | N2: 12
B3: BRANCH SECT. NO. | C3: AIR QUANTITY Q (cfm) | D3: EQUIV. DUCT LENGTH L (ft) | E3: PRESSURE READING (in.wg) | G3: TAKE OFF TO TAKE OFF S.P. (in.wg) | H3: S.P. AHEAD OF TAKE OFF (in.wg) | I3: AIR TERMINAL PRESS. (in.wg) | J3: DUCT SIZE | L3: VELOCITY V (fpm) | M3: Loses Branch to Terminal (in.wg) | N3: DUCT Terminal Size
E4: Initial | F4: Selected | J4: (in.) | K4: (m) | N4: (in.) | O4: (m)
B5: =B23 -> BD (C-01) | C5: =D15 -> 730 | D5: =C24 -> 10.88304 | G5: 1.35 | H5: =G5+G6 -> 1.883269 | I5: 1.5 | J5: 6 | K5: =J5*$S$8 -> 0.1524 | L5: 4650 | M5: 0.41 | N5: 4 | O5: =N5*$S$9 -> 101.6
G6: =V7 -> 0.53326896 | I6: 1.5 | Q6: 1 | R6: m = | S6: 3.28 | T6: ft | U6: Friction Lose | V6: 4.9 | W6: in.wg
B7: =B25 -> BD (01-02) | C7: =D16 -> 585 | D7: =C26+(C35*2) -> 19.9552 | E7: 1.15 | F7: 1.4 | G7: =E7-F7 -> -0.25 | H7: =H5-G7 -> 2.133269 | I7: 1.5 | J7: 6 | K7: =J7*$S$8 -> 0.1524 | L7: 3800 | M7: 0.74 | N7: 4 | O7: =N7*$S$9 -> 101.6 | P7: =H7+I7+M7 -> 4.373269 | Q7: 1 | R7: inch | S7: 0.0834 | T7: ft | U7: Pressure Drop | V7: =(D5*V6)/100 -> 0.53326896 | W7: in.wg
B8: =B27 -> BD (02-03) | C8: =D17 -> 387 | D8: =C28 -> 12.2672 | E8: 0.82 | F8: 0.88 | G8: =E8-F8 -> -0.06 | H8: =H7-G8 -> 2.193269 | I8: 1.5 | J8: 6 | K8: =J8*$S$8 -> 0.1524 | L8: 3000 | M8: 0.72 | N8: 4 | O8: =N8*$S$9 -> 101.6 | P8: =H8+I8+M8 -> 4.413269 | Q8: 1 | R8: inch | S8: 0.0254 | T8: m
B9: =B29 -> BD (03-04) | C9: =C18 -> 192 | D9: =C30 -> 8.8888 | E9: 0.55 | F9: 0.4 | G9: =E9-F9 -> 0.15 | H9: =H8-G9 -> 2.043269 | I9: 1.5 | J9: 6 | K9: =J9*$S$8 -> 0.1524 | L9: 1950 | M9: 0.7 | N9: 4 | O9: =N9*$S$9 -> 101.6 | Q9: 1 | R9: inch | S9: =S8*1000 -> 25.4 | T9: mm
C13: Maximum S.P. at Section BD (02-03) | G13: =H8 -> 2.193269 | H13: + | I13: =I8 -> 1.5 | J13: + | L13: =M8 -> 0.72 | M13: = | N13: =G13+I13+L13 -> 4.413269
F14: l/s
B15: =Summary!B25 -> Second Officer Room | C15: =Summary!P25 -> 145 | D15: =SUM(C15:C19) -> 730 | F15: =C15*0.472 -> 68.44 | J15: Urutan Section | O15: Sebelum | R15: DUCT Terminal Size | U15: Damper | W15: Sesudah
B16: =Summary!B26 -> Chief Engineer Room | C16: =Summary!P26 -> 198 | D16: =SUM(C16:C19) -> 585 | F16: =C16*0.472 -> 93.456 | J16: =B5 -> BD (C-01) | L16: =D15 -> 730 | O16: CFM pipe flow | P16: CFM Excel | Q16: eror | R16: Sebelum | S16: Sesudah | U16: Deck | V16: Roomj | W16: CFM pipe flow | X16: CFM Excel | Y16: eror
B17: =Summary!B27 -> Chief Officer & Engineer Office | C17: =Summary!P27 -> 195 | D17: =SUM(C17:C19) -> 387 | F17: =C17*0.472 -> 92.04 | J17: =B7 -> BD (01-02) | L17: =C7 -> 585 | N17: BD (C-01) | O17: 280 | P17: =C15 -> 145 | Q17: =(O17-P17)/P17 -> 0.93103448 | R17: =N5 -> 4 | S17: 2.5 | T17: =S17*$S$8 -> 0.0635 | U17: Yes | V17: No | W17: 159 | X17: =P17 -> 145 | Y17: =(W17-X17)/X17 -> 0.096551724
B18: =Summary!B29 -> Chief Officer Room | C18: =Summary!P29 -> 192 | F18: =C18*0.472 -> 90.624 | J18: =B7 -> BD (01-02) | L18: =C8 -> 387 | N18: BD (01-02) | O18: 219 | P18: =C16 -> 198 | Q18: =(O18-P18)/P18 -> 0.10606061 | R18: =N7 -> 4 | S18: 3 | T18: =S18*$S$8 -> 0.0762 | V18: No | W18: 228 | X18: =P18 -> 198 | Y18: =(W18-X18)/X18 -> 0.15151515
J19: =B9 -> BD (03-04) | L19: =C9 -> 192 | N19: BD (02-03) | O19: 148 | P19: =C17 -> 195 | Q19: =(O19-P19)/P19 -> -0.24102564 | R19: =N8 -> 4 | S19: 3 | T19: =S19*$S$8 -> 0.0762 | V19: No | W19: 208 | X19: =P19 -> 195 | Y19: =(W19-X19)/X19 -> 0.066666667
N20: BD (03-04) | O20: 238 | P20: =C18 -> 192 | Q20: =(O20-P20)/P20 -> 0.23958333 | R20: =N9 -> 4 | S20: 2.5 | T20: =S20*$S$8 -> 0.0635 | V20: No | W20: 176 | X20: =P20 -> 192 | Y20: =(W20-X20)/X20 -> -0.083333333
B22: Panjang line | E22: Panjang Terminal = | G22: 2 | H22: m | N22: Total Panjang Pipa | S22: Total Elbow
B23: BD (C-01) | C23: 3.318 | D23: m | G23: =G22*S6 -> 6.56 | H23: ft | N23: Ukuran (inch) | O23: Panjang (ft) | P23: Panjang (m) | Q23: Total (m) | S23: Ukuran (inch) | T23: Jumlah
C24: =C23*S6 -> 10.88304 | D24: ft | E24: Tinggi Deck = | G24: 2.4 | H24: m | N24: 6 | O24: =D5+D7+D8+D9 -> 51.99424 | P24: =O24/$S$6 -> 15.851902 | Q24: 16 | S24: 6 | T24: 2
B25: BD (01-02) | C25: =0.54+2.26+0.54 -> 3.34 | D25: m | G25: =G24*S6 -> 7.872 | H25: ft | N25: 3 | O25: =G23*2 -> 13.12 | P25: =O25/$S$6 -> 4 | Q25: 4
C26: =C25*S6 -> 10.9552 | D26: ft | N26: 2.5 | O26: =G23*2 -> 13.12 | P26: =O26/$S$6 -> 4 | Q26: 4
B27: BD (02-03) | C27: 3.74 | D27: m
C28: =C27*S6 -> 12.2672 | D28: ft
B29: BD (03-04) | C29: 2.71 | D29: m
C30: =C29*S6 -> 8.8888 | D30: ft
B34: Le Smooth Elbow 5 inch = | C34: 3.8 | D34: ft
B35: Le Smooth Elbow 6 inch = | C35: 4.5 | D35: ft

Sheet Bridge Deck
B2: 1 | C2: 2 | D2: 3 | E2: 4 | F2: 5 | G2: 6 | H2: 7 | I2: 8 | J2: 9 | L2: 10 | M2: 11 | N2: 12
B3: BRANCH SECT. NO. | C3: AIR QUANTITY Q (cfm) | D3: EQUIV. DUCT LENGTH L (ft) | E3: PRESSURE READING (in.wg) | G3: TAKE OFF TO TAKE OFF S.P. (in.wg) | H3: S.P. AHEAD OF TAKE OFF (in.wg) | I3: AIR TERMINAL PRESS. (in.wg) | J3: DUCT SIZE | L3: VELOCITY V (fpm) | M3: Loses Branch to Terminal (in.wg) | N3: DUCT Terminal Size
E4: Initial | F4: Selected | J4: (in.) | K4: (m) | N4: (in.) | O4: (mm)
B5: =B23 -> BRD (D-01) | C5: =D15 -> 778 | D5: =C24+C35 -> 22.41864 | G5: 1.25 | H5: =G5+G6 -> 2.3260947 | I5: 1.5 | J5: 6 | K5: =J5*$S$8 -> 0.1524 | L5: 4500 | M5: 0.38 | N5: 5 | O5: =N5*$S$9 -> 127
G6: =V7 -> 1.0760947 | I6: 1.5 | Q6: 1 | R6: m = | S6: 3.28 | T6: ft | U6: Friction Lose | V6: 4.8 | W6: in.wg
B7: =B25 -> BRD (01-02) | C7: =D16 -> 537 | D7: =C26+C34 -> 13.3776 | E7: 1.2 | F7: 1.51 | G7: =E7-F7 -> -0.31 | H7: =H5-G7 -> 2.6360947 | I7: 1.5 | J7: 5 | K7: =J7*$S$8 -> 0.127 | L7: 3850 | M7: 0.33 | N7: 4 | O7: =N7*$S$9 -> 101.6 | Q7: 1 | R7: inch | S7: 0.0834 | T7: ft | U7: Pressure Drop | V7: =(D5*V6)/100 -> 1.0760947 | W7: in.wg
B8: =B27 -> BRD (02-03) | C8: =D17 -> 406 | D8: =C28 -> 10.496 | E8: 0.92 | F8: 0.92 | G8: =E8-F8 -> 0 | H8: =H7-G8 -> 2.6360947 | I8: 1.5 | J8: 5 | K8: =J8*$S$8 -> 0.127 | L8: 3000 | M8: 0.55 | N8: 4 | O8: =N8*$S$9 -> 101.6 | Q8: 1 | R8: inch | S8: 0.0254 | T8: m
B9: =B29 -> BRD (03-04) | C9: =D18 -> 241 | D9: =C30+C34 -> 13.3448 | E9: 0.54 | F9: 0.32 | G9: =E9-F9 -> 0.22 | H9: =H8-G9 -> 2.4160947 | I9: 1.5 | J9: 5 | K9: =J9*$S$8 -> 0.127 | L9: 1700 | M9: 0.31 | N9: 4 | O9: =N9*$S$9 -> 101.6 | Q9: 1 | R9: inch | S9: =S8*1000 -> 25.4 | T9: mm
B10: =B31 -> BRD (04-05) | C10: =C19 -> 122 | D10: =C32 -> 7.544 | E10: 0.17 | F10: 0.22 | G10: =E10-F10 -> -0.05 | H10: =H9-G10 -> 2.4660947 | I10: 1.5 | J10: 4 | K10: =J10*$S$8 -> 0.1016 | L10: 1300 | M10: 0.3 | N10: 4 | O10: =N10*$S$9 -> 101.6
C13: Maximum S.P. at Section BRD (02-03) | G13: =H8 -> 2.6360947 | H13: + | I13: =I8 -> 1.5 | J13: + | L13: =M8 -> 0.55 | M13: = | N13: =G13+I13+L13 -> 4.6860947
F14: l/s
B15: =Summary!B34 -> Master Room | C15: =Summary!P34 -> 241 | D15: =SUM(C15:C19) -> 778 | F15: =C15*0.472 -> 113.752 | J15: Urutan Section | O15: Sebelum | R15: DUCT Terminal Size | T15: Damper | V15: Sesudah
B16: =Summary!B33 -> Master Office | C16: =Summary!P33 -> 131 | D16: =SUM(C16:C19) -> 537 | F16: =C16*0.472 -> 61.832 | J16: =B5 -> BRD (D-01) | L16: =D15 -> 778 | O16: CFM pipe flow | P16: CFM Excel | Q16: eror | R16: Sebelum | S16: Sesudah | T16: Deck | U16: Room | V16: CFM pipe flow | W16: CFM Excel | X16: eror
B17: =Summary!B32 -> Meeting Room | C17: =Summary!P32 -> 165 | D17: =SUM(C17:C19) -> 406 | F17: =C17*0.472 -> 77.88 | J17: =B7 -> BRD (01-02) | L17: =C7 -> 537 | N17: BRD (D-01) | O17: 310 | P17: =C15 -> 241 | Q17: =(O17-P17)/P17 -> 0.28630705 | R17: =N5 -> 5 | S17: 3 | T17: Yes | U17: No | V17: 286 | W17: =P17 -> 241 | X17: =(V17-W17)/W17 -> 0.18672199
B18: =Summary!B31 -> Radio Operator Room | C18: =Summary!P31 -> 119 | D18: =SUM(C18:C19) -> 241 | F18: =C18*0.472 -> 56.168 | J18: =B7 -> BRD (01-02) | L18: =C8 -> 406 | N18: BRD (01-02) | O18: 136 | P18: =C16 -> 131 | Q18: =(O18-P18)/P18 -> 0.038167939 | R18: =N7 -> 4 | S18: 2.5 | U18: No | V18: 145 | W18: =P18 -> 131 | X18: =(V18-W18)/W18 -> 0.10687023
B19: =Summary!B30 -> Library | C19: =Summary!P30 -> 122 | F19: =C19*0.472 -> 57.584 | J19: =B9 -> BRD (03-04) | L19: =C9 -> 241 | N19: BRD (02-03) | O19: 111 | P19: =C17 -> 165 | Q19: =(O19-P19)/P19 -> -0.32727273 | R19: =N8 -> 4 | S19: 3 | U19: No | V19: 169 | W19: =P19 -> 165 | X19: =(V19-W19)/W19 -> 0.024242424
J20: =B10 -> BRD (04-05) | L20: =C10 -> 122 | N20: BRD (03-04) | O20: 98.74 | P20: =C18 -> 119 | Q20: =(O20-P20)/P20 -> -0.1702521 | R20: =N9 -> 4 | S20: 2.5 | U20: No | V20: 119 | W20: =P20 -> 119 | X20: =(V20-W20)/W20 -> 0
N21: BRD (04-05) | O21: 98.84 | P21: =C19 -> 122 | Q21: =(O21-P21)/P21 -> -0.18983607 | R21: =N10 -> 4 | S21: 2.5 | U21: No | V21: 131 | W21: =P21 -> 122 | X21: =(V21-W21)/W21 -> 0.073770492
B22: Panjang line | E22: Panjang Terminal = | G22: 2 | H22: m
B23: BRD (D-01) | C23: =3.713+1.75 -> 5.463 | D23: m | G23: =G22*S6 -> 6.56 | H23: ft | N23: Total Panjang Pipa | S23: Total Elbow
C24: =C23*S6 -> 17.91864 | D24: ft | E24: Tinggi Deck = | G24: 2.4 | H24: m | N24: Ukuran (inch) | O24: Panjang (ft) | P24: Panjang (m) | Q24: Total (m) | S24: Ukuran (inch) | T24: Jumlah
B25: BRD (01-02) | C25: =0.81+2.11 -> 2.92 | D25: m | G25: =G24*S6 -> 7.872 | H25: ft | N25: 6 | O25: =D5 -> 22.41864 | P25: =O25/$S$6 -> 6.8349512 | Q25: 7 | S25: 6 | T25: 1
C26: =C25*S6 -> 9.5776 | D26: ft | N26: 5 | O26: =D7+D8+D9 -> 37.2184 | P26: =O26/$S$6 -> 11.347073 | Q26: 11.5 | S26: 5 | T26: 1
B27: BRD (02-03) | C27: 3.2 | D27: m | N27: 4 | O27: =D10 -> 7.544 | P27: =O27/$S$6 -> 2.3 | Q27: 2.5
C28: =C27*S6 -> 10.496 | D28: ft | N28: 3 | O28: =G23*2 -> 13.12 | P28: =O28/$S$6 -> 4 | Q28: 4
B29: BRD (03-04) | C29: =2.35+0.56 -> 2.91 | D29: m | N29: 2.5 | O29: =G23*3 -> 19.68 | P29: =O29/$S$6 -> 6 | Q29: 6
C30: =C29*S6 -> 9.5448 | D30: ft
B31: BRD (04-05) | C31: 2.3 | D31: m
C32: =C31*S6 -> 7.544 | D32: ft
B34: Le Smooth Elbow 5 inch = | C34: 3.8 | D34: ft
B35: Le Smooth Elbow 6 inch = | C35: 4.5 | D35: ft

Sheet Nav Deck
B2: 1 | C2: 2 | D2: 3 | E2: 4 | F2: 5 | G2: 6 | H2: 7 | I2: 8 | J2: 9 | L2: 10 | M2: 11 | N2: 12
B3: BRANCH SECT. NO. | C3: AIR QUANTITY Q (cfm) | D3: EQUIV. DUCT LENGTH L (ft) | E3: PRESSURE READING (in.wg) | G3: TAKE OFF TO TAKE OFF S.P. (in.wg) | H3: S.P. AHEAD OF TAKE OFF (in.wg) | I3: AIR TERMINAL PRESS. (in.wg) | J3: DUCT SIZE | L3: VELOCITY V (fpm) | M3: Loses Branch to Terminal (in.wg) | N3: DUCT Terminal Size
E4: Initial | F4: Selected | J4: (in.) | K4: (m) | N4: (in.) | O4: (mm)
B5: =B18 -> ND (E-01) | C5: =C15 -> 1294 | D5: =C19 -> 8.90848 | G5: 1.4 | H5: =G5+G6 -> 1.8008816 | I5: 1.5 | J5: 7 | K5: =J5*R8 -> 0.1778 | L5: 4800 | M5: 0.75 | N5: 7 | O5: =N5*R9 -> 177.8
G6: =U7 -> 0.4008816 | I6: 1.5 | P6: 1 | Q6: m = | R6: 3.28 | S6: ft | T6: Friction Lose | U6: 4.5 | V6: in.wg
P7: 1 | Q7: inch | R7: 0.0834 | S7: ft | T7: Pressure Drop | U7: =(D5*U6)/100 -> 0.4008816 | V7: in.wg
B8: =B18 -> ND (E-01) | C8: =C15 -> 1294 | D8: =C19 -> 8.90848 | G8: 1.4 | H8: =G8+G9 -> 1.8008816 | I8: 1.5 | J8: 7 | K8: =J8*R8 -> 0.1778 | L8: 4800 | M8: 0.18 | N8: 5 | O8: =N8*R9 -> 127 | P8: 1 | Q8: inch | R8: 0.0254 | S8: m
G9: =U7 -> 0.4008816 | I9: 1.5 | P9: 1 | Q9: inch | R9: =R8*1000 -> 25.4 | S9: mm
C13: Maximum S.P. at Section ND (E-01) | G13: =H5 -> 1.8008816 | H13: + | I13: =I5 -> 1.5 | J13: + | L13: =M5 -> 0.75 | M13: = | N13: =G13+I13+L13 -> 4.0508816
G14: l/s
B15: =Summary!B35 -> Navigation Room | C15: =Summary!P35 -> 1294 | D15: 2 Diffuser | E15: =C15/2 -> 647 | G15: =E15*0.472 -> 305.384 | J15: Urutan Section | O15: Sebelum | R15: DUCT Terminal Size | T15: Damper | U15: Sesudah
D16: 4 Diffuser | E16: =C15/4 -> 323.5 | G16: =E16*0.472 -> 152.692 | J16: =B5 -> ND (E-01) | L16: =C15 -> 1294 | O16: CFM pipe flow | P16: CFM Excel | Q16: eror | R16: Sebelum | S16: Sesudah | U16: CFM pipe flow | V16: CFM Excel | W16: eror
B17: Panjang line | N17: ND (E-01) | O17: 346 | P17: =E16 -> 323.5 | Q17: =(O17-P17)/P17 -> 0.069551777 | R17: =N8 -> 5 | S17: 5 | T17: Yes | U17: =324 -> 324 | V17: =P17 -> 323.5 | W17: =(U17-V17)/V17 -> 0.0015455951
B18: ND (E-01) | C18: 2.716 | D18: m
C19: =C18*R6 -> 8.90848 | D19: ft
B21: Panjang Terminal = | D21: 1 | E21: m
D22: =D21*R6 -> 3.28 | E22: ft | F22: (untuk 1 terminal) | N22: Total Panjang Pipa | S22: Total Tee
D23: 3.511 | E23: m | N23: Ukuran (inch) | O23: Panjang (ft) | P23: Panjang (m) | Q23: Total (m) | S23: Ukuran (inch) | T23: Jumlah
D24: =D23*R6 -> 11.51608 | E24: ft | F24: (untuk 2 cabang terminal) | N24: 8 | O24: =D8 -> 8.90848 | P24: =O24/$R$6 -> 2.716 | Q24: 3 | S24: 5 | T24: 3
B25: Tinggi Deck = | D25: 2.4 | E25: m | N25: 5 | O25: =D22*4+(D24*2) -> 36.15216 | P25: =O25/$R$6 -> 11.022 | Q25: 11.5
D26: =D25*R6 -> 7.872 | E26: ft

Sheet Main Header 12 Jam
B2: 1 | C2: 2 | D2: 3 | E2: 4 | F2: 5 | G2: 6 | H2: 7 | I2: 8 | J2: 9 | K2: 10 | O2: 1 | P2: 2 | Q2: 3 | R2: 4 | S2: 5 | T2: 6 | U2: 7 | V2: 8 | W2: 9 | X2: 10
B3: BRANCH SECT. NO. | C3: AIR QUANTITY Q (cfm) | D3: EQUIV. DUCT LENGTH L (ft) | E3: PRESSURE READING (in.wg) | G3: TAKE OFF TO TAKE OFF S.P. (in.wg) | H3: S.P. AHEAD OF TAKE OFF (in.wg) | I3: BRANCH PRESS. (in.wg) | J3: DUCT SIZE (in.) | K3: VELOCITY V (fpm) | O3: BRANCH SECT. NO. | P3: AIR QUANTITY Q (cfm) | Q3: EQUIV. DUCT LENGTH L (ft) | R3: PRESSURE READING (in.wg) | T3: TAKE OFF TO TAKE OFF S.P. (in.wg) | U3: S.P. AHEAD OF TAKE OFF (in.wg) | V3: BRANCH. (in.wg) | W3: DUCT SIZE (in.) | X3: VELOCITY V (fpm)
E4: Initial | F4: Selected | R4: Initial | S4: Selected
B5: =B19 -> H (01-02) | C5: =K14 -> 5270 | D5: =C20+C39 -> 21.82824 | H5: =AG7 -> 0.24011064 | J5: 16 | K5: 3800 | O5: =B5 -> H (01-02) | P5: =C5 -> 5270 | Q5: =D5 -> 21.82824 | U5: =H5 -> 0.24011064 | W5: =J5 -> 16 | X5: =K5 -> 3800
AB6: 1 | AC6: m = | AD6: 3.28 | AE6: ft | AF6: Friction Lose | AG6: 1.1 | AH6: in.wg
B7: =B21 -> H (02-B) | C7: =C14 -> 1641 | D7: =C22 -> 5.8384 | E7: 0.9 | F7: 0.8 | G7: =E7-F7 -> 0.1 | H7: =H5-G7 -> 0.14011064 | I7: ='Main Deck'!AC12 -> 4.512425 | J7: 10 | K7: 2700 | O7: =O22 -> H (02-A) | P7: =R15 -> 3629 | Q7: =P23 -> 2.0336 | R7: 0.9 | S7: 0.95 | T7: =R7-S7 -> -0.05 | U7: =U5-T7 -> 0.29011064 | V7: ='Poop Deck '!N13 -> 4.5309608 | W7: 14 | X7: 3400 | AB7: 1 | AC7: inch | AD7: 0.0834 | AE7: ft | AF7: Pressure Drop | AG7: =(D5*AG6)/100 -> 0.24011064 | AH7: in.wg
O8: =O24 -> H (A-C) | P8: =R16 -> 2802 | Q8: =P25 -> 7.872 | R8: 0.75 | S8: 0.65 | T8: =R8-S8 -> 0.1 | U8: =U7-T8 -> 0.19011064 | V8: ='Boat Deck '!N13 -> 4.413269 | W8: 14 | X8: 2800 | AB8: 1 | AC8: inch | AD8: 0.0254 | AE8: m
O9: =O26 -> H (C-D) | P9: =R17 -> 2072 | Q9: =P27 -> 7.872 | R9: 0.45 | S9: 0.6 | T9: =R9-S9 -> -0.15 | U9: =U8-T9 -> 0.34011064 | V9: ='Bridge Deck'!N13 -> 4.6860947 | W9: 12 | X9: 2600 | AA9: =U9+V9+Y9 -> 5.0262054 | AD9: =AD8*8 -> 0.2032
O10: =O28 -> H (D-E) | P10: =Q18 -> 1294 | Q10: =P29 -> 7.872 | R10: 0.42 | S10: 0.36 | T10: =R10-S10 -> 0.06 | U10: =U9-T10 -> 0.28011064 | V10: ='Nav Deck'!N13 -> 4.0508816 | W10: 11 | X10: 1900 | AA10: =U10+V10+Y10 -> 4.3309922
P12: Maximum S.P. at Section H (C-D) | T12: =U9 -> 0.34011064 | U12: + | V12: =+V9 -> 4.6860947 | W12: = | X12: =T12+V12 -> 5.0262054
B13: Jalur Kebawah | J13: Urutan Section
B14: Main Deck | C14: ='Main Deck'!H14 -> 1641 | J14: =B5 -> H (01-02) | K14: =C14+R15 -> 5270 | O14: Jalur Keatas | T14: Urutan Section
J15: =B7 -> H (02-B) | K15: =C7 -> 1641 | O15: Poop Deck | Q15: ='Poop Deck '!L16 -> 827 | R15: =SUM(Q15:Q18) -> 3629 | T15: =O5 -> H (01-02) | U15: =P5 -> 5270
O16: Boat Deck | Q16: ='Boat Deck '!L16 -> 730 | R16: =SUM(Q16:Q18) -> 2802 | T16: =O7 -> H (02-A) | U16: =P7 -> 3629
O17: Bridge Deck | Q17: ='Bridge Deck'!L16 -> 778 | R17: =SUM(Q17:Q18) -> 2072 | T17: =O8 -> H (A-C) | U17: =P8 -> 2802
B18: Panjang line | O18: Nav Deck | Q18: ='Nav Deck'!L16 -> 1294 | T18: =O9 -> H (C-D) | U18: =P9 -> 2072
B19: H (01-02) | C19: =0.623+1.15 -> 1.773 | D19: m | E19: 0.263 | F19: =E19*AD6 -> 0.86264 | T19: =O10 -> H (D-E) | U19: =P10 -> 1294
C20: =C19*AD6 -> 5.81544 | D20: ft | E20: 1.15 | F20: =E20*AD6 -> 3.772
B21: H (02-B) | C21: 1.78 | D21: m | O21: Panjang line
C22: =C21*AD6 -> 5.8384 | D22: ft | O22: H (02-A) | P22: 0.62 | Q22: m
P23: =P22*AD6 -> 2.0336 | Q23: ft
O24: H (A-C) | P24: 2.4 | Q24: m
B25: Le/D = | C25: K/f | P25: =P24*AD6 -> 7.872 | Q25: ft
B26: f = | C26: K/(Le/D) | O26: H (C-D) | P26: 2.4 | Q26: m
B27: f = | C27: =0.24/12 -> 0.02 | P27: =P26*AD6 -> 7.872 | Q27: ft
O28: H (D-E) | P28: 2.4 | Q28: m
B29: Le/D = | C29: K/f | P29: =P28*AD6 -> 7.872 | Q29: ft
B30: Le = | C30: (K*D)/f
B31: Le = | C31: =(0.24*J5)/C27 -> 192 | D31: Inch
C32: =C31*AD7 -> 16.0128 | D32: ft
B34: Le/D = | C34: 12
B35: Le = | C35: Le/D*D
B36: Le = | C36: =C34*J5 -> 192 | D36: Inch
C37: =C36*AD7 -> 16.0128 | D37: ft
B39: Le Tee 16 inch | C39: =C32 -> 16.0128 | D39: ft

Sheet Main Header 24 Jam
B2: 1 | C2: 2 | D2: 3 | E2: 4 | F2: 5 | G2: 6 | H2: 7 | I2: 8 | J2: 9 | L2: 10 | P2: 1 | Q2: 2 | R2: 3 | S2: 4 | T2: 5 | U2: 6 | V2: 7 | W2: 8 | X2: 9 | Z2: 10
B3: BRANCH SECT. NO. | C3: AIR QUANTITY Q (cfm) | D3: EQUIV. DUCT LENGTH L (ft) | E3: PRESSURE READING (in.wg) | G3: TAKE OFF TO TAKE OFF S.P. (in.wg) | H3: S.P. AHEAD OF TAKE OFF (in.wg) | I3: BRANCH PRESS. (in.wg) | J3: DUCT SIZE | L3: VELOCITY V (fpm) | P3: BRANCH SECT. NO. | Q3: AIR QUANTITY Q (cfm) | R3: EQUIV. DUCT LENGTH L (ft) | S3: PRESSURE READING (in.wg) | U3: TAKE OFF TO TAKE OFF S.P. (in.wg) | V3: S.P. AHEAD OF TAKE OFF (in.wg) | W3: BRANCH. (in.wg) | X3: DUCT SIZE | Z3: VELOCITY V (fpm)
E4: Initial | F4: Selected | J4: (in.) | K4: (m) | S4: Initial | T4: Selected | X4: (in.) | Y4: (m)
B5: =B19 -> H (01-02) | C5: =L14 -> 5270 | D5: =C20+C39 -> 23.830824 | H5: =AI7 -> 0.14060186 | J5: 18 | K5: =J5*$AF$8 -> 0.4572 | L5: 3000 | P5: =B5 -> H (01-02) | Q5: =C5 -> 5270 | R5: =D5 -> 23.830824 | V5: =H5 -> 0.14060186 | X5: =J5 -> 18 | Y5: =X5*$AF$8 -> 0.4572 | Z5: =L5 -> 3000
AD6: 1 | AE6: m = | AF6: 3.28 | AG6: ft | AH6: Friction Lose | AI6: 0.59 | AJ6: in.wg
B7: =B21 -> H (02-B) | C7: =C15 -> 1641 | D7: =C22 -> 5.8384 | E7: 0.58 | F7: 0.55 | G7: =E7-F7 -> 0.03 | H7: =H5-G7 -> 0.11060186 | I7: ='Main Deck'!AC12 -> 4.512425 | J7: 11 | K7: =J7*$AF$8 -> 0.2794 | L7: 2100 | P7: =P22 -> H (02-A) | Q7: =S16 -> 3629 | R7: =Q23 -> 2.0336 | S7: 0.56 | T7: 0.58 | U7: =S7-T7 -> -0.02 | V7: =V5-U7 -> 0.16060186 | W7: ='Poop Deck '!N13 -> 4.5309608 | X7: 16 | Y7: =X7*$AF$8 -> 0.4064 | Z7: 2500 | AD7: 1 | AE7: inch | AF7: 0.0834 | AG7: ft | AH7: Pressure Drop | AI7: =(D5*AI6)/100 -> 0.14060186 | AJ7: in.wg
P8: =P24 -> H (A-C) | Q8: =S17 -> 2802 | R8: =Q25 -> 7.872 | S8: 0.4 | T8: 0.34 | U8: =S8-T8 -> 0.06 | V8: =V7-U8 -> 0.10060186 | W8: ='Boat Deck '!N13 -> 4.413269 | X8: 16 | Y8: =X8*$AF$8 -> 0.4064 | Z8: 2000 | AD8: 1 | AE8: inch | AF8: 0.0254 | AG8: m
P9: =P26 -> H (C-D) | Q9: =S18 -> 2072 | R9: =Q27 -> 7.872 | S9: 0.25 | T9: 0.32 | U9: =S9-T9 -> -0.07 | V9: =V8-U9 -> 0.17060186 | W9: ='Bridge Deck'!N13 -> 4.6860947 | X9: 14 | Y9: =X9*$AF$8 -> 0.3556 | Z9: 1900 | AC9: =V9+W9+AA9 -> 4.8566966
P10: =P28 -> H (D-E) | Q10: =R19 -> 1294 | R10: =Q29 -> 7.872 | S10: 0.22 | T10: 0.24 | U10: =S10-T10 -> -0.02 | V10: =V9-U10 -> 0.19060186 | W10: ='Nav Deck'!N13 -> 4.0508816 | X10: 12 | Y10: =X10*$AF$8 -> 0.3048 | Z10: 1600 | AC10: =V10+W10+AA10 -> 4.2414835
Q12: Maximum S.P. at Section H (C-D) | U12: =V9 -> 0.17060186 | V12: + | W12: =+W9 -> 4.6860947 | X12: = | Z12: =U12+W12 -> 4.8566966
J13: Urutan Section
B14: Jalur Kebawah | J14: =B5 -> H (01-02) | L14: =C15+S16 -> 5270 | U14: Urutan Section
B15: Main Deck | C15: ='Main Deck'!H14 -> 1641 | J15: =B7 -> H (02-B) | L15: =C7 -> 1641 | P15: Jalur Keatas | U15: =P5 -> H (01-02) | V15: =Q5 -> 5270
P16: Poop Deck | R16: ='Poop Deck '!L16 -> 827 | S16: =SUM(R16:R19) -> 3629 | U16: =P7 -> H (02-A) | V16: =Q7 -> 3629
P17: Boat Deck | R17: ='Boat Deck '!L16 -> 730 | S17: =SUM(R17:R19) -> 2802 | U17: =P8 -> H (A-C) | V17: =Q8 -> 2802
B18: Panjang line | P18: Bridge Deck | R18: ='Bridge Deck'!L16 -> 778 | S18: =SUM(R18:R19) -> 2072 | U18: =P9 -> H (C-D) | V18: =Q9 -> 2072
B19: H (01-02) | C19: =0.6233+1.15 -> 1.7733 | D19: m | E19: 0.263 | F19: =E19*AD6 -> 0.263 | H19: Elbow 90º 5 Piece 18 inch= | K19: 18 | L19: ft | P19: Nav Deck | R19: ='Nav Deck'!L16 -> 1294 | U19: =P10 -> H (D-E) | V19: =Q10 -> 1294
C20: =C19*AF6 -> 5.816424 | D20: ft | E20: 1.15 | F20: =E20*AD6 -> 1.15
B21: H (02-B) | C21: 1.78 | D21: m | P21: Panjang line
C22: =C21*AF6 -> 5.8384 | D22: ft | P22: H (02-A) | Q22: 0.62 | R22: m
Q23: =Q22*AF6 -> 2.0336 | R23: ft
P24: H (A-C) | Q24: 2.4 | R24: m
B25: Le/D = | C25: K/f | Q25: =Q24*AF6 -> 7.872 | R25: ft | S25: =Q23+Q25 -> 9.9056
B26: f = | C26: K/(Le/D) | P26: H (C-D) | Q26: 2.4 | R26: m
B27: f = | C27: =0.24/12 -> 0.02 | Q27: =Q26*AF6 -> 7.872 | R27: ft | S27: =S25+Q27 -> 17.7776
P28: H (D-E) | Q28: 2.4 | R28: m
B29: Le/D = | C29: K/f | Q29: =Q28*AF6 -> 7.872 | R29: ft | S29: =S27+Q29 -> 25.6496
B30: Le = | C30: (K*D)/f
B31: Le = | C31: =(0.24*J5)/C27 -> 216 | D31: Inch
C32: =C31*AF7 -> 18.0144 | D32: ft
B34: Le/D = | C34: 12
B35: Le = | C35: Le/D*D
B36: Le = | C36: =C34*J5 -> 216 | D36: Inch
C37: =C36*AF7 -> 18.0144 | D37: ft
B39: Le Tee 18 inch | C39: =C32 -> 18.0144 | D39: ft

Sheet Main Header 24 Jam Type 2
B2: 1 | C2: 2 | D2: 3 | E2: 4 | F2: 5 | G2: 6 | H2: 7 | I2: 8 | J2: 9 | L2: 10 | P2: 1 | Q2: 2 | R2: 3 | S2: 4 | T2: 5 | U2: 6 | V2: 7 | W2: 8 | X2: 9 | Z2: 10
B3: BRANCH SECT. NO. | C3: AIR QUANTITY Q (cfm) | D3: EQUIV. DUCT LENGTH L (ft) | E3: PRESSURE READING (in.wg) | G3: TAKE OFF TO TAKE OFF S.P. (in.wg) | H3: S.P. AHEAD OF TAKE OFF (in.wg) | I3: BRANCH PRESS. (in.wg) | J3: DUCT SIZE | L3: VELOCITY V (fpm) | M3: Friction Loss (In.wg) | N3: Pressure Drop (In.wg) | P3: BRANCH SECT. NO. | Q3: AIR QUANTITY Q (cfm) | R3: EQUIV. DUCT LENGTH L (ft) | S3: PRESSURE READING (in.wg) | U3: TAKE OFF TO TAKE OFF S.P. (in.wg) | V3: S.P. AHEAD OF TAKE OFF (in.wg) | W3: BRANCH. (in.wg) | X3: DUCT SIZE | Z3: VELOCITY V (fpm) | AA3: Friction Loss (In.wg) | AB3: Pressure Drop (In.wg)
E4: Initial | F4: Selected | J4: (in.) | K4: (m) | S4: Initial | T4: Selected | X4: (in.) | Y4: (m)
AD6: 1 | AE6: m = | AF6: 3.28 | AG6: ft
B7: =B21 -> H (01-B) | C7: =C15 -> 1641 | D7: =C22 -> 31.654824 | I7: ='Main Deck'!AC12 -> 4.512425 | J7: 10 | K7: =J7*$AF$8 -> 0.254 | L7: 2800 | M7: 1.1 | N7: =(D7*M7)/100 -> 0.34820306 | P7: =P22 -> H (01-A) | Q7: =R16 -> 827 | R7: =Q23 -> 19.850024 | W7: ='Poop Deck '!N13 -> 4.5309608 | X7: 7 | Y7: =X7*$AF$8 -> 0.1778 | Z7: 3200 | AA7: 2.1 | AB7: =(R7*AA7)/100 -> 0.4168505 | AD7: 1 | AE7: inch | AF7: 0.0834 | AG7: ft
P8: =P24 -> H (01-C) | Q8: =R17 -> 730 | R8: =Q25 -> 27.722024 | W8: ='Boat Deck '!N13 -> 4.413269 | X8: 7 | Y8: =X8*$AF$8 -> 0.1778 | Z8: 2800 | AA8: 1.7 | AB8: =(R8*AA8)/100 -> 0.47127441 | AD8: 1 | AE8: inch | AF8: 0.0254 | AG8: m
P9: =P26 -> H (01-D) | Q9: =R18 -> 778 | R9: =Q27 -> 35.594024 | W9: ='Bridge Deck'!N13 -> 4.6860947 | X9: 7 | Y9: =X9*$AF$8 -> 0.1778 | Z9: 3000 | AA9: 1.9 | AB9: =(R9*AA9)/100 -> 0.67628646 | AC9: =V9+W9+AA9 -> 6.5860947
P10: =P28 -> H (01-E) | Q10: =R19 -> 1294 | R10: =Q29 -> 51.466024 | W10: ='Nav Deck'!N13 -> 4.0508816 | X10: 10 | Y10: =X10*$AF$8 -> 0.254 | Z10: 2400 | AA10: 0.8 | AB10: =(R10*AA10)/100 -> 0.41172819 | AC10: =V10+W10+AA10 -> 4.8508816
Q12: Maximum S.P. at Section H (C-D) | U12: =V9 -> 0 | V12: + | W12: =+W9 -> 4.6860947 | X12: = | Z12: =U12+W12 -> 4.6860947
J13: Urutan Section
B14: Jalur Kebawah | U14: Urutan Section
B15: Main Deck | C15: ='Main Deck'!H14 -> 1641 | J15: =B7 -> H (01-B) | L15: =C7 -> 1641 | P15: Jalur Keatas
P16: Poop Deck | R16: ='Poop Deck '!L16 -> 827 | U16: =P7 -> H (01-A) | V16: =Q7 -> 827
P17: Boat Deck | R17: ='Boat Deck '!L16 -> 730 | U17: =P8 -> H (01-C) | V17: =Q8 -> 730
B18: Panjang line | P18: Bridge Deck | R18: ='Bridge Deck'!L16 -> 778 | U18: =P9 -> H (01-D) | V18: =Q9 -> 778
P19: Nav Deck | R19: ='Nav Deck'!L16 -> 1294 | U19: =P10 -> H (01-E) | V19: =Q10 -> 1294
B21: H (01-B) | C21: =0.6233+1.15+1.78 -> 3.5533 | D21: m | P21: Panjang line
C22: =C21*AF6+(2*10) -> 31.654824 | D22: ft | P22: H (01-A) | Q22: =0.6233+1.15+0.62 -> 2.3933 | R22: m
Q23: =Q22*AF6+(2*6) -> 19.850024 | R23: ft
P24: H (01-C) | Q24: =0.6233+1.15+0.62+2.4 -> 4.7933 | R24: m
Q25: =Q24*AF6+(2*6) -> 27.722024 | R25: ft
P26: H (01-D) | Q26: =0.6233+1.15+0.62+2.4+2.4 -> 7.1933 | R26: m
Q27: =Q26*AF6+(2*6) -> 35.594024 | R27: ft
P28: H (01-E) | Q28: =0.6233+1.15+0.62+2.4+2.4+2.4 -> 9.5933 | R28: m
Q29: =Q28*AF6+(2*10) -> 51.466024 | R29: ft
P49: Total Panjang Pipa | U49: Total Tee | X49: Total Elbow
P50: Ukuran (inch) | Q50: Panjang (ft) | R50: Panjang (m) | S50: Total (m) | U50: Ukuran (inch) | V50: Jumlah | X50: Ukuran (inch) | Y50: Jumlah
P51: 10 | Q51: =D7+R10 -> 83.120848 | R51: =Q51/$AF$6 -> 25.341722 | S51: 25.5 | U51: 10 | V51: 2 | X51: 10 | Y51: 4
P52: 8 | Q52: =R7+R8+R9 -> 83.166072 | R52: =Q52/$AF$6 -> 25.35551 | S52: 25.5 | U52: 8 | V52: 3 | X52: 8 | Y52: 6

Sheet Ducting & Insulation
A1: HARGA DUCTING & INSULATION
B3: DUCTING | X3: ELBOW | AI3: TEE
B4: Ducting (inch) | C4: Panjang (m) | D4: Harga | L4: 5. | M4: Ducting 4 inch | X4: Ukuran (inch) | Y4: Junlah | Z4: Harga | AI4: Ukuran (inch) | AJ4: Junlah | AK4: Harga
B5: 10 | C5: ='Main Header 24 Jam Type 2'!S51 -> 25.5 | D5: =I18 -> 5312500 | R5: = | S5: 396000 | T5: per 1,2 m | X5: 10 | Y5: ='Main Header 24 Jam Type 2'!Y51 -> 4 | Z5: =AE14 -> 976000 | AI5: 10 | AJ5: ='Main Header 24 Jam Type 2'!V51 -> 2 | AK5: =AO17 -> 550000
B6: 8 | C6: ='Main Deck'!L49+'Poop Deck '!Q29+'Nav Deck'!Q24+'Main Header 24 Jam Type 2'!S52 -> 48 | D6: =I29 -> 8400000 | R6: = | S6: =S5/1.2 -> 330000 | T6: per 1 m | X6: 8 | Y6: ='Main Deck'!O49+'Poop Deck '!T29+'Main Header 24 Jam Type 2'!Y52 -> 9 | Z6: =AE25 -> 1854000 | AI6: 8 | AJ6: ='Main Deck'!Q49+'Main Header 24 Jam Type 2'!V52 -> 4 | AK6: =AO28 -> 856000
B7: 6 | C7: ='Poop Deck '!Q30+'Boat Deck '!Q24+'Bridge Deck'!Q25 -> 39.5 | D7: =I40 -> 6586625 | R7: = | S7: =S6*C9 -> 6105000 | T7: total | X7: 6 | Y7: ='Poop Deck '!T30+'Boat Deck '!T24+'Bridge Deck'!T25 -> 4 | Z7: =AE36 -> 548000 | AI7: 5 | AJ7: ='Nav Deck'!T24 -> 3 | AK7: =AO39 -> 465000
B8: 5 | C8: ='Main Deck'!L50+'Poop Deck '!Q31+'Bridge Deck'!Q26+'Nav Deck'!Q25 -> 32.5 | D8: =I52 -> 3872916.7 | X8: 5 | Y8: ='Bridge Deck'!T26 -> 1 | Z8: =AE48 -> 137000 | AJ8: Total | AK8: =SUM(AK5:AK7) -> 1871000
B9: 4 | C9: ='Main Deck'!K51+'Poop Deck '!Q32+'Bridge Deck'!Q27 -> 18.5 | D9: =S7 -> 6105000 | Y9: Total | Z9: =SUM(Z5:Z8) -> 3515000
B10: 3 | C10: ='Main Deck'!L52+'Poop Deck '!Q33+'Boat Deck '!Q25+'Bridge Deck'!Q28 -> 12 | D10: =S18 -> 1800000
B11: 2.5 | C11: ='Main Deck'!L53+'Poop Deck '!Q34+'Boat Deck '!Q26+'Bridge Deck'!Q29 -> 16 | D11: =S18 -> 1800000
B12: 2 | C12: ='Poop Deck '!Q35 -> 2 | D12: =S29 -> 1587200 | W12: 1. | X12: Elbow 10 inch
