Workbook

Sheet List of Room
C1: PERHITUNGAN KEBUTUHAN AIR HANDLING UNIT (AHU) PADA AKOMODASI KAPAL
C5: Halaman :
C6: LIST RUANGAN AKOMODASI & DIMENSI
B8: NO. | C8: DECK | E8: ROOM | I8: P (m) | J8: L (m) | K8: T (m) | L8: A (m2) | M8: V (m3)
C10: Main Deck
B11: 1 | E11: Mess Room | I11: 4.64 | J11: 3.98 | K11: 2.5 | L11: =I11*J11 -> 18.4672 | M11: =L11*K11 -> 46.168
B12: 2 | E12: Quarter Master & Steward Room | I12: 3 | J12: 4.1 | K12: 2.5 | L12: =I12*J12 -> 12.3 | M12: =L12*K12 -> 30.75
B13: 3 | E13: Boatswain & Seaman Room | I13: 3 | J13: 4.24 | K13: 2.5 | L13: =I13*J13 -> 12.72 | M13: =L13*K13 -> 31.8
B14: 4 | E14: Oiler (2p) Room | I14: 3 | J14: 4.1 | K14: 2.5 | L14: =I14*J14 -> 12.3 | M14: =L14*K14 -> 30.75
B15: 5 | E15: Pumpman (2p) Room | I15: 3 | J15: 4.2 | K15: 2.5 | L15: =I15*J15 -> 12.6 | M15: =L15*K15 -> 31.5
B16: 6 | E16: Fireman (2p) Room | I16: 3 | J16: 4.24 | K16: 2.5 | L16: =I16*J16 -> 12.72 | M16: =L16*K16 -> 31.8
B17: 7 | E17: Boys (2p) Room | I17: 3 | J17: 4.2 | K17: 2.5 | L17: =I17*J17 -> 12.6 | M17: =L17*K17 -> 31.5
C19: Poop Deck
B20: 1 | E20: Chief Cook Room | I20: 3 | J20: 3.4 | K20: 2.4 | L20: =I20*J20 -> 10.2 | M20: =L20*K20 -> 24.48
B21: 2 | E21: Second Engineer Room | I21: 3 | J21: 3.4 | K21: 2.4 | L21: =I21*J21 -> 10.2 | M21: =L21*K21 -> 24.48
B22: 3 | E22: Musholla | I22: 3 | J22: 3.4 | K22: 2.4 | L22: =I22*J22 -> 10.2 | M22: =L22*K22 -> 24.48
B23: 4 | E23: Electrician Room | I23: 3 | J23: 3.4 | K23: 2.4 | L23: =I23*J23 -> 10.2 | M23: =L23*K23 -> 24.48
B24: 5 | E24: Smoking Room | I24: 3.5 | J24: 4 | K24: 2.4 | L24: =I24*J24 -> 14 | M24: =L24*K24 -> 33.6
B25: 6 | E25: Mess Room | I25: 3.5 | J25: 3.4 | K25: 2.4 | L25: =I25*J25 -> 11.9 | M25: =L25*K25 -> 28.56
C27: Boat Deck
B28: 1 | E28: Chief Officer % Engineer Office | I28: 3.55 | J28: 5 | K28: 2.4 | L28: =I28*J28 -> 17.75 | M28: =L28*K28 -> 42.6
B29: 2 | E29: Chief Officer Room | I29: 4.4 | J29: 3.41 | K29: 2.4 | L29: =I29*J29 -> 15.004 | M29: =L29*K29 -> 36.0096
B30: 3 | E30: Chief Engineer Room | I30: 4.4 | J30: 3.41 | K30: 2.4 | L30: =I30*J30 -> 15.004 | M30: =L30*K30 -> 36.0096
B31: 4 | E31: Second Officer Room | I31: 4 | J31: 3.41 | K31: 2.4 | L31: =I31*J31 -> 13.64 | M31: =L31*K31 -> 32.736
B32: 5 | E32: Medical Room | I32: 4 | J32: 3.41 | K32: 2.4 | L32: =I32*J32 -> 13.64 | M32: =L32*K32 -> 32.736
C34: Bridge Deck
B35: 1 | E35: Master Room | I35: 6.6 | J35: 3.23 | K35: 2.4 | L35: =I35*J35 -> 21.318 | M35: =L35*K35 -> 51.1632
B36: 2 | E36: Master Office | I36: 3.55 | J36: 2.98 | K36: 2.4 | L36: =I36*J36 -> 10.579 | M36: =L36*K36 -> 25.3896
B37: 3 | E37: Meeting Room | I37: 3.55 | J37: 3.2 | K37: 2.4 | L37: =I37*J37 -> 11.36 | M37: =L37*K37 -> 27.264
B38: 4 | E38: Radio Operator Room | I38: 4.35 | J38: 3.41 | K38: 2.4 | L38: =I38*J38 -> 14.8335 | M38: =L38*K38 -> 35.6004
B39: 5 | E39: Library | I39: 2.25 | J39: 3.41 | K39: 2.4 | L39: =I39*J39 -> 7.6725 | M39: =L39*K39 -> 18.414
C41: Navigation Deck
B42: 1 | E42: Navigation Room | I42: 6.925 | J42: 3.717 | K42: 2.5 | L42: =I42*J42 -> 25.740225 | M42: =K42*L42 -> 64.350562
B43: 2 | E43: Radio Room | I43: 6.925 | J43: 3.717 | K43: 2.5 | L43: =I43*J43 -> 25.740225 | M43: =K43*L43 -> 64.350562

Sheet Summary
D1: PERHITUNGAN KEBUTUHAN AIR HANDLING UNIT (AHU) PADA AKOMODASI KAPAL
D5: Halaman :
D6: COOLING SUMMARY
B8: SPACE | D8: DECK | E8: SIDE | F8: FRAMES | G8: Volume (ft3) | H8: Heat Area (ft2) | I8: BTU/HR | L8: SHF | M8: OUTSIDE AIR BASED ON * | P8: CFM | Q8: R/C TOTAL AIR | R8: Air Quantity (l/s) | S8: Friction Loss (Pa/mm) | T8: Duct Diameter (mm) | U8: Rect. Duct Size (mm) | W8: Uk. Diffuser | X8: l/s | Y8: Jumlah Diffuser
E9: SIDE | F9: FRAMES | I9: SENS. | J9: LATENT | K9: TOTAL | M9: R/C | N9: PERS. | O9: EXH. | U9: L x W
B10: Pantry | D10: Poop Deck | E10: P | F10: =Pantry!$H$3 -> 06 to 11 | G10: =Pantry!$J$37 -> 867.04651 | H10: =Pantry!$J$35 -> 664.23165 | I10: =Pantry!$J$39 -> 4077.055 | J10: =Pantry!$M$35 -> 790 | K10: =I10+J10 -> 4867.055 | L10: =Pantry!$J$40 -> 0.83768419 | M10: =Pantry!$G$32 -> 28.90155 | N10: =Pantry!$E$32 -> 15 | O10: =Pantry!$J$28 -> 15 | P10: =Pantry!$K$30 -> 152 | Q10: =MAX(M10:O10) -> 28.90155 | R10: =0.472*P10 -> 71.744
B11: Mess Room | E11: P | F11: ='Mess Room '!$H$3 -> 11 to 16 | G11: ='Mess Room '!$J$37 -> 1008.5878 | H11: ='Mess Room '!$J$35 -> 769.3885 | I11: ='Mess Room '!$J$39 -> 5347.1072 | J11: ='Mess Room '!$M$35 -> 4000 | K11: =I11+J11 -> 9347.1072 | L11: ='Mess Room '!$J$40 -> 0.57206011 | M11: ='Mess Room '!$G$32 -> 33.619594 | N11: ='Mess Room '!$E$32 -> 120 | O11: ='Mess Room '!$J$28 -> 120 | P11: ='Mess Room '!$K$30 -> 199 | Q11: =MAX(M11:O11) -> 120 | R11: =0.472*P11 -> 93.928
B12: Chief Cook Room | E12: P | F12: ='Chief Cook Room'!$H$3 -> 20 to 24 | G12: ='Chief Cook Room'!$J$37 -> 867.04651 | H12: ='Chief Cook Room'!$J$35 -> 662.87971 | I12: ='Chief Cook Room'!$J$39 -> 2171.0295 | J12: ='Chief Cook Room'!$M$35 -> 500 | K12: =I12+J12 -> 2671.0295 | L12: ='Chief Cook Room'!$J$40 -> 0.81280626 | M12: ='Chief Cook Room'!$G$32 -> 28.90155 | N12: ='Chief Cook Room'!$E$32 -> 15 | O12: ='Chief Cook Room'!$J$28 -> 15 | P12: ='Chief Cook Room'!$K$30 -> 81 | Q12: =MAX(M12:O12) -> 28.90155 | R12: =0.472*P12 -> 38.232
B13: Musholla | E13: S | F13: =Musholla!$H$3 -> 11 to 16 | G13: =Musholla!$J$37 -> 867.04651 | H13: =Musholla!$J$35 -> 732.75895 | I13: =Musholla!$J$39 -> 2473.1104 | J13: =Musholla!$M$35 -> 1000 | K13: =I13+J13 -> 3473.1104 | L13: =Musholla!$J$40 -> 0.71207365 | M13: =Musholla!$G$32 -> 28.90155 | N13: =Musholla!$E$32 -> 30 | O13: =Musholla!$J$28 -> 30 | P13: =Musholla!$K$30 -> 92 | Q13: =MAX(M13:O13) -> 30 | R13: =0.472*P13 -> 43.424
B14: Electrician Room | E14: S | F14: =Electrician!$H$3 -> 16 to 20 | G14: =Electrician!$J$37 -> 867.04651 | H14: =Electrician!$J$35 -> 728.10894 | I14: =Electrician!$J$39 -> 1399.0661 | J14: =Electrician!$M$35 -> 500 | K14: =I14+J14 -> 1899.0661 | L14: =Electrician!$J$40 -> 0.7367127 | M14: =Electrician!$G$32 -> 28.90155 | N14: =Electrician!$E$32 -> 15 | O14: =Electrician!$J$28 -> 15 | P14: =Electrician!$K$30 -> 52 | Q14: =MAX(M14:O14) -> 28.90155 | R14: =0.472*P14 -> 24.544
B15: Second Engineer Room | E15: S | F15: ='Second Engineer'!$H$3 -> 20 to 25 | G15: ='Second Engineer'!$J$37 -> 867.04651 | H15: ='Second Engineer'!$J$35 -> 693.68599 | I15: ='Second Engineer'!$J$39 -> 2154.4182 | J15: ='Second Engineer'!$M$35 -> 500 | K15: =I15+J15 -> 2654.4182 | L15: ='Second Engineer'!$J$40 -> 0.81163481 | M15: ='Second Engineer'!$G$32 -> 28.90155 | N15: ='Second Engineer'!$E$32 -> 15 | O15: ='Second Engineer'!$J$28 -> 15 | P15: ='Second Engineer'!$K$30 -> 80 | Q15: =MAX(M15:O15) -> 28.90155 | R15: =0.472*P15 -> 37.76
B16: Smoking Room | E16: C | F16: ='Smoking Room'!$H$3 -> 20 to 25 | G16: ='Smoking Room'!$J$37 -> 1186.5739 | H16: ='Smoking Room'!$J$35 -> 879.96173 | I16: ='Smoking Room'!$J$39 -> 4612.8964 | J16: ='Smoking Room'!$M$35 -> 2000 | K16: =I16+J16 -> 6612.8964 | L16: ='Smoking Room'!$J$40 -> 0.69756066 | M16: ='Smoking Room'!$G$32 -> 39.552464 | N16: ='Smoking Room'!$E$32 -> 60 | O16: ='Smoking Room'!$J$28 -> 60 | P16: ='Smoking Room'!$K$30 -> 171 | Q16: =MAX(M16:O16) -> 60 | R16: =0.472*P16 -> 80.712
I43: =SUM(I10:I41) -> 22234.683 | J43: =SUM(J10:J41) -> 9290 | K43: =SUM(K10:K41) -> 31524.683 | P43: =SUM(P10:P41) -> 827

Sheet Pantry
B1: H | C1: U | D1: D | H1: 1 m = | I1: 3.28 | J1: ft
B2: SPACE | D2: SPACE NO. | F2: MAIN DECK | H2: FRAMES | I2: SPACE TEMP COOLING | M2: 78.8 | N2: °F | O2: SPACE TEMP HEATING | Q2: 70 | R2: °F
B3: Pantry | D3: MD/SB/4 | H3: 06 to 11 | T3: Kondisi Temperature udara yang didesain. | Y3: 26°C | Z3: 78,8°F
B4: ADJOINING SPACE | C4: LOAD | D4: INSUL | E4: U | F4: DIMENSION (m2) | H4: AREA (Ft ²) | I4: TO | J4: TD | K4: U | L4: QS | M4: QL | N4: QT | O4: TO | P4: TD | Q4: U | R4: Qw
C5: KEY | D5: TYPE | E5: KEY | F5: Panjang | G5: Tinggi/Lebar
B6: Depan = MessRoom | C6: 4 | D6: 10 | E6: H | F6: 3.41 | G6: 2.4 | H6: =(F6*G6)*10.7639 -> 88.091758 | I6: 78.8 | J6: =I6-$M$2 -> 0 | K6: 0.361 | L6: =K6*H6*J6 -> 0 | N6: =L6+M6 -> 0
B7: Belakang = Outside/Solar | C7: 5 | D7: 54 | E7: H | F7: 3.41 | G7: 2.4 | H7: =(F7*G7)*10.7639 -> 88.091758 | I7: 125 | J7: =I7-$M$2 -> 46.2 | K7: 0.212 | L7: =K7*H7*J7 -> 862.80591 | N7: =L7+M7 -> 862.80591 | AU7: Glass Solar Factor | AX7: saya pakai | AZ7: 95F | BD7: Equipment
B8: Kanan = Gangway | C8: 6 | D8: 54 | E8: H | F8: 3 | G8: 2.4 | H8: =(F8*G8)*10.7639 -> 77.50008 | I8: 80 | J8: =I8-$M$2 -> 1.2 | K8: 0.191 | L8: =K8*H8*J8 -> 17.763018 | N8: =L8+M8 -> 17.763018
B9: Kiri = Outdoor /Portside Weather | C9: 3 | D9: 54 | E9: H | F9: 3 | G9: 2.4 | H9: =(F9*G9)*10.7639 -> 77.50008 | I9: 95 | J9: =I9-$M$2 -> 16.2 | K9: 0.196 | L9: =K9*H9*J9 -> 246.07825 | N9: =L9+M9 -> 246.07825
B10: Solar (window) | C10: 3 | E10: GLASS | G10: =O44 -> 0.4 | H10: =((1/4*PI()*G10^2)*(I1^2)*M45) -> 2.7038808 | L10: =160*H10 -> 432.62093 | N10: =L10+M10 -> 432.62093
B11: atas = Outdoor/ Weather | C11: 1 | D11: 54 | E11: D | F11: 3 | G11: 3.41 | H11: =(F11*G11)*10.7639 -> 110.1147 | I11: 95 | J11: =I11-$M$2 -> 16.2 | K11: 0.176 | L11: =K11*H11*J11 -> 313.95902 | N11: =L11+M11 -> 313.95902
B12: bawah = Messroom | C12: 2 | D12: 10 | E12: U | F12: 3 | G12: 3.41 | H12: =(F12*G12)*10.7639 -> 110.1147 | I12: 78.8 | J12: =I12-$M$2 -> 0 | K12: 0.435 | L12: =K12*H12*J12 -> 0 | N12: =L12+M12 -> 0 | BJ12: ql = q ,dl ×U F
B13: lampu | C13: 7 | F13: 3 | G13: 3.41 | H13: =(F13*G13)*10.7639 -> 110.1147 | L13: =7*H13 -> 770.80288 | N13: =L13+M13 -> 770.80288
BJ15: qs = q ,ds ×U F × H F
B16: Equipment : | C16: 8 | Z16: Udara Luar
B17: Dishwasher | C17: 8 | L17: =0.5*0.5*1120 -> 280 | M17: =0.5*580 -> 290 | N17: =L17+M17 -> 570
B18: Electric Stove (250 Watt) | C18: 8 | L18: =250*I54 -> 853.025 | N18: =L18+M18 -> 853.025 | BJ18: Jika tudung buang dipasang di atas peralatan, gunakan Faktor Tudung, H.F., 0,5. Beban laten untuk peralatan tersebut dianggap nol. Gunakan H.F. = 1,0 dalam Persamaan 3-6 ketika tudung buang tidak dipasang di atas peralatan. Lihat Tabel 3-6 untuk Faktor Penggunaan yang direkomendasikan, U.F
B19: Personel
B20: manusia (latent & sensibel) | C20: 9 | L20: =C32*300 -> 300 | M20: =C32*500 -> 500 | N20: =L20+M20 -> 800 | T20: Pemilihan Insulation
B22: TOTAL HEAT | L22: =SUM(L6:L20) -> 4077.055 | M22: =SUM(M6:M20) -> 790 | N22: =L22+M22 -> 4867.055 | AU22: Lighting Loads
BA25: q=A x LC
BK27: Occupancy
B28: ΔT = | C28: 25 | D28: °F | E28: Vol. = | G28: =J51 -> 867.04651 | H28: Ft³ | I28: Out. Air = | J28: =E32 -> 15 | K28: cfm | M28: `
B29: NOTES : GLASS SOLAR LOAD = 160 BTU/HR/ft² x 8,79 ft² = BTU/HR
B30: SHF (Sensible Heat factor)= | C30: Qs/Qt = | D30: =L22/N22 -> 0.83768419 | G30: Q = | H30: Qs/1.08 x ΔT | I30: =L22/(1.08*C28) -> 151.00204 | J30: use | K30: =ROUNDUP(I30,0) -> 152 | L30: Cfm
B32: Min. Out. Air (1) Occupancy = | C32: 1 | D32: 15 | E32: =C32*D32 -> 15 | F32: (2) R/C = | G32: =G28/30 -> 28.90155 | I32: (3) Exhaust throuht Rad. Equip. = | M32: - | O32: HULL or JOB Numnber :
O33: Check by : GEK/MAM
B34: KEY | D34: SYMBOLS | I34: SUMMARY | O34: Calculated by : Vieri Pramudya Dirgantara
B35: 1 = Deck Over | D35: Qs = Heat Load, BTU/Hr, Sensible | I35: Sq. Ft. | J35: =SUM(H6:H13) -> 664.23165 | L35: ƩQL | M35: =M22 -> 790 | O35: HEATING & COOLING LOAD CALCULATIONS | AU35: Heat Gain Personal
B36: 2 = Deck Under | D36: QL = Heat Load, BTU/Hr, Latent | I36: Height | J36: =J49 -> 2.4 | L36: ƩQT | M36: =N22 -> 4867.055 | BL36: Hunian Udara luar ruangan minimum berdasarkan hunian kamar adalah 12 CFM / orang untuk ruang hunian tinggi (misalnya, ruang rekreasi, ruang makan dan kamar mess) dan 15 CFM / orang untuk ruang ber-AC dengan hunian rendah (misalnya, kabin dan kantor). Tarif ini hanya akan ditingkatkan untuk mencapai keseimbangan udara dalam setiap subdivisi, tetapi tidak boleh melebihi 50 CFM / orang.
B37: 3 = Outboard Bhd or Shell | D37: QT = Heat Load, BTU/Hr, Total | I37: Volume | J37: =G28 -> 867.04651 | L37: Q | M37: =K30 -> 152
B38: 4 = Forward Bulkhead | D38: QW = Heat Load, BTU/Hr, Winter | I38: R or C | J38: =G32 -> 28.90155
B39: 5 = After Bulkhead | D39: U = Transmittance, BTU/Sq. Ft. Hr. °F | I39: ƩQs | J39: =L22 -> 4077.055
B40: 6 = Inboard Bulkhead | D40: TD = Temperature Differences | I40: SHF | J40: =D30 -> 0.83768419 | O40: REV | Q40: SHEET NO OF
B41: 7 = Lights | D41: TO = Temp of Adjoining Space or Outside
B42: 8 = Equipment
B43: 9= Personnel
B44: Kode | K44: Uk.Jendela | M44: 400 | N44: mm | O44: 0.4 | P44: m
B45: 10 | C45: Tidak mengalami perpindahan panas | K45: Jumalah Jendela | M45: 2 | BL45: Infiltrasi Untuk ruang seperti Ruang Kemudi (Rumah Percontohan) dengan pintu yang terbuka langsung ke cuaca, laju perubahan udara luar ruangan minimum adalah 60 menit, tetapi tidak boleh melebihi 50 CFM / orang.
B46: 54 | C46: Mengalami perpindahan panas | I46: Volume Ruangan
...

Sheet Mess Room 
B1: H | C1: U | D1: D | H1: 1 m = | I1: 3.28 | J1: ft
B2: SPACE | D2: SPACE NO. | F2: MAIN DECK | H2: FRAMES | I2: SPACE TEMP COOLING | M2: 78.8 | N2: °F | O2: SPACE TEMP HEATING | Q2: 70 | R2: °F
B3: Mess Room | D3: MD/SB/4 | H3: 11 to 16 | T3: Kondisi Temperature udara yang didesain. | Y3: 26°C | Z3: 78,8°F
B4: ADJOINING SPACE | C4: LOAD | D4: INSUL | E4: U | F4: DIMENSION (m2) | H4: AREA (Ft ²) | I4: TO | J4: TD | K4: U | L4: QS | M4: QL | N4: QT | O4: TO | P4: TD | Q4: U | R4: Qw
C5: KEY | D5: TYPE | E5: KEY | F5: Panjang | G5: Tinggi/Lebar
B6: Depan = Locker Room | C6: 4 | D6: 54 | E6: H | F6: 3.41 | G6: 2.4 | H6: =(F6*G6)*10.7639 -> 88.091758 | I6: 110 | J6: =I6-$M$2 -> 31.2 | K6: 0.191 | L6: =K6*H6*J6 -> 524.9564 | N6: =L6+M6 -> 524.9564
B7: Belakang = Pamtry | C7: 5 | D7: 10 | E7: H | F7: 3.41 | G7: 2.4 | H7: =(F7*G7)*10.7639 -> 88.091758 | I7: 78.8 | J7: =I7-$M$2 -> 0 | K7: 0.328 | L7: =K7*H7*J7 -> 0 | N7: =L7+M7 -> 0 | AU7: Glass Solar Factor | AX7: saya pakai | AZ7: 95F | BD7: Equipment
B8: Kanan = Gangway | C8: 6 | D8: 54 | E8: H | F8: 3.5 | G8: 2.4 | H8: =(F8*G8)*10.7639 -> 90.41676 | I8: 80 | J8: =I8-$M$2 -> 1.2 | K8: 0.191 | L8: =K8*H8*J8 -> 20.723521 | N8: =L8+M8 -> 20.723521
B9: Kiri = Outdoor/Portside Weather | C9: 3 | D9: 54 | E9: H | F9: 3.5 | G9: 2.4 | H9: =(F9*G9)*10.7639 -> 90.41676 | I9: 95 | J9: =I9-$M$2 -> 16.2 | K9: 0.196 | L9: =K9*H9*J9 -> 287.0913 | N9: =L9+M9 -> 287.0913
B10: Solar (window) | C10: 3 | E10: GLASS | G10: =O44 -> 0.4 | H10: =(1/4*PI()*G10^2)*(I1^2) -> 1.3519404 | L10: =160*H10 -> 216.31047 | N10: =L10+M10 -> 216.31047
B11: atas = Second Officer Room | C11: 1 | D11: 10 | E11: D | F11: 2.9 | G11: 3.41 | H11: =(F11*G11)*10.7639 -> 106.44421 | I11: 78.8 | J11: =I11-$M$2 -> 0 | K11: 0.272 | L11: =K11*H11*J11 -> 0 | N11: =L11+M11 -> 0
B12: atas = Outdoor/Weather | C12: 1 | D12: 54 | E12: D | F12: 0.6 | G12: 3.41 | H12: =(F12*G12)*10.7639 -> 22.022939 | I12: 95 | J12: =I12-$M$2 -> 16.2 | K12: 0.176 | L12: =K12*H12*J12 -> 62.791805 | N12: =L12+M12 -> 62.791805 | BJ12: ql = q ,dl ×U F
B13: bawah = Quarter Master & Steward Room | C13: 2 | D13: 10 | E13: U | F13: 3 | G13: 4.1 | H13: =(F13*G13)*10.7639 -> 132.39597 | I13: 78.8 | J13: =I13-$M$2 -> 0 | K13: 0.435 | L13: =K13*H13*J13 -> 0 | N13: =L13+M13 -> 0
B14: bawah = Boys (2p) | C14: 2 | D14: 10 | E14: U | F14: 0.5 | G14: 4.1 | H14: =(F14*G14)*10.7639 -> 22.065995 | I14: 78.8 | J14: =I14-$M$2 -> 0 | K14: 0.435 | L14: =K14*H14*J14 -> 0 | N14: =L14+M14 -> 0
B15: lampu | C15: 7 | F15: 3.5 | G15: 3.4 | H15: =(F15*G15)*10.7639 -> 128.09041 | L15: =9*H15 -> 1152.8137 | N15: =L15+M15 -> 1152.8137 | BJ15: qs = q ,ds ×U F × H F
Z16: Udara Luar
B17: Equipment : | C17: 8
B18: TV (200 Watt) | C18: 8 | L18: =200*I54 -> 682.42 | N18: =L18+M18 -> 682.42 | BJ18: Jika tudung buang dipasang di atas peralatan, gunakan Faktor Tudung, H.F., 0,5. Beban laten untuk peralatan tersebut dianggap nol. Gunakan H.F. = 1,0 dalam Persamaan 3-6 ketika tudung buang tidak dipasang di atas peralatan. Lihat Tabel 3-6 untuk Faktor Penggunaan yang direkomendasikan, U.F
B19: Personel
B20: manusia (latent & sensibel) | C20: 9 | L20: =C32*300 -> 2400 | M20: =C32*500 -> 4000 | N20: =L20+M20 -> 6400 | T20: Pemilihan Insulation
B22: TOTAL HEAT | L22: =SUM(L6:L20) -> 5347.1072 | M22: =SUM(M6:M20) -> 4000 | N22: =L22+M22 -> 9347.1072 | AU22: Lighting Loads
BA25: q=A x LC
BK27: Occupancy
B28: ΔT = | C28: 25 | D28: °F | E28: Vol. = | G28: =J51 -> 1008.5878 | H28: Ft³ | I28: Out. Air = | J28: =E32 -> 120 | K28: cfm | M28: `
B29: NOTES : GLASS SOLAR LOAD = 160 BTU/HR/ft² x 8,79 ft² = BTU/HR
B30: SHF (Sensible Heat factor)= | C30: Qs/Qt = | D30: =L22/N22 -> 0.57206011 | G30: Q = | H30: Qs/1.08 x ΔT | I30: =L22/(1.08*C28) -> 198.04101 | J30: use | K30: =ROUNDUP(I30,0) -> 199 | L30: Cfm
B32: Min. Out. Air (1) Occupancy = | C32: 8 | D32: 15 | E32: =C32*D32 -> 120 | F32: (2) R/C = | G32: =G28/30 -> 33.619594 | I32: (3) Exhaust throuht Rad. Equip. = | M32: - | O32: HULL or JOB Numnber :
O33: Check by : GEK/MAM
B34: KEY | D34: SYMBOLS | I34: SUMMARY | O34: Calculated by : Vieri Pramudya Dirgantara
B35: 1 = Deck Over | D35: Qs = Heat Load, BTU/Hr, Sensible | I35: Sq. Ft. | J35: =SUM(H6:H15) -> 769.3885 | L35: ƩQL | M35: =M22 -> 4000 | O35: HEATING & COOLING LOAD CALCULATIONS | AU35: Heat Gain Personal
B36: 2 = Deck Under | D36: QL = Heat Load, BTU/Hr, Latent | I36: Height | J36: =J49 -> 2.4 | L36: ƩQT | M36: =N22 -> 9347.1072 | BL36: Hunian Udara luar ruangan minimum berdasarkan hunian kamar adalah 12 CFM / orang untuk ruang hunian tinggi (misalnya, ruang rekreasi, ruang makan dan kamar mess) dan 15 CFM / orang untuk ruang ber-AC dengan hunian rendah (misalnya, kabin dan kantor). Tarif ini hanya akan ditingkatkan untuk mencapai keseimbangan udara dalam setiap subdivisi, tetapi tidak boleh melebihi 50 CFM / orang.
B37: 3 = Outboard Bhd or Shell | D37: QT = Heat Load, BTU/Hr, Total | I37: Volume | J37: =G28 -> 1008.5878 | L37: Q | M37: =K30 -> 199
B38: 4 = Forward Bulkhead | D38: QW = Heat Load, BTU/Hr, Winter | I38: R or C | J38: =G32 -> 33.619594
B39: 5 = After Bulkhead | D39: U = Transmittance, BTU/Sq. Ft. Hr. °F | I39: ƩQs | J39: =L22 -> 5347.1072
B40: 6 = Inboard Bulkhead | D40: TD = Temperature Differences | I40: SHF | J40: =D30 -> 0.57206011 | O40: REV | Q40: SHEET NO OF
B41: 7 = Lights | D41: TO = Temp of Adjoining Space or Outside
B42: 8 = Equipment
B43: 9= Personnel
B44: Kode | K44: Uk.Jendela | M44: 400 | N44: mm | O44: 0.4 | P44: m
B45: 10 | C45: Tidak mengalami perpindahan panas | K45: Jumlah Jendela | M45: 3 | BL45: Infiltrasi Untuk ruang seperti Ruang Kemudi (Rumah Percontohan) dengan pintu yang terbuka langsung ke cuaca, laju perubahan udara luar ruangan minimum adalah 60 menit, tetapi tidak boleh melebihi 50 CFM / orang.
...

Sheet Chief Cook Room
B1: H | C1: U | D1: D | H1: 1 m = | I1: 3.28 | J1: ft
B2: SPACE | D2: SPACE NO. | F2: MAIN DECK | H2: FRAMES | I2: SPACE TEMP COOLING | M2: 78.8 | N2: °F | O2: SPACE TEMP HEATING | Q2: 70 | R2: °F
B3: Chief Cook Room | D3: MD/SB/4 | H3: 20 to 24 | T3: Kondisi Temperature udara yang didesain. | Y3: 26°C | Z3: 78,8°F
B4: ADJOINING SPACE | C4: LOAD | D4: INSUL | E4: U | F4: DIMENSION (m2) | H4: AREA (Ft ²) | I4: TO | J4: TD | K4: U | L4: QS | M4: QL | N4: QT | O4: TO | P4: TD | Q4: U | R4: Qw
C5: KEY | D5: TYPE | E5: KEY | F5: Panjang | G5: Tinggi/Lebar
B6: Depan = Outdoor/Solar | C6: 4 | D6: 54 | E6: H | F6: 3.41 | G6: 2.4 | H6: =(F6*G6)*10.7639 -> 88.091758 | I6: 125 | J6: =I6-$M$2 -> 46.2 | K6: 0.212 | L6: =K6*H6*J6 -> 862.80591 | N6: =L6+M6 -> 862.80591
B7: Belakang = Gangway | C7: 5 | D7: 54 | E7: H | F7: 3.41 | G7: 2.4 | H7: =(F7*G7)*10.7639 -> 88.091758 | I7: 80 | J7: =I7-$M$2 -> 1.2 | K7: 0.191 | L7: =K7*H7*J7 -> 20.190631 | N7: =L7+M7 -> 20.190631 | AU7: Glass Solar Factor | AX7: saya pakai | AZ7: 95F | BD7: Equipment
B8: Kanan = Gangway | C8: 6 | D8: 54 | E8: H | F8: 3 | G8: 2.4 | H8: =(F8*G8)*10.7639 -> 77.50008 | I8: 80 | J8: =I8-$M$2 -> 1.2 | K8: 0.191 | L8: =K8*H8*J8 -> 17.763018 | N8: =L8+M8 -> 17.763018
B9: Kiri = Outdoor/Portside Weather | C9: 3 | D9: 54 | E9: H | F9: 3 | G9: 2.4 | H9: =(F9*G9)*10.7639 -> 77.50008 | I9: 95 | J9: =I9-$M$2 -> 16.2 | K9: 0.196 | L9: =K9*H9*J9 -> 246.07825 | N9: =L9+M9 -> 246.07825
B10: Solar (window) | C10: 3 | E10: GLASS | G10: =O44 -> 0.4 | H10: =(1/4*PI()*G10^2)*(I1^2) -> 1.3519404 | L10: =160*H10 -> 216.31047 | N10: =L10+M10 -> 216.31047
B11: atas =Chief Engineer Room | C11: 1 | D11: 10 | E11: D | F11: 3 | G11: 3.41 | H11: =(F11*G11)*10.7639-H12 -> 94.614681 | I11: 78.8 | J11: =I11-$M$2 -> 0 | K11: 0.272 | L11: =K11*H11*J11 -> 0 | N11: =L11+M11 -> 0
B12: atas =Toilet Chief Engineer Room | C12: 1 | D12: 54 | E12: D | F12: 1.2 | G12: 1.2 | H12: =(F12*G12)*10.7639 -> 15.500016 | I12: 85 | J12: =I12-$M$2 -> 6.2 | K12: 0.169 | L12: =K12*H12*J12 -> 16.240917 | N12: =L12+M12 -> 16.240917 | BJ12: ql = q ,dl ×U F
B13: bawah = Boatswain & Seaman Room | C13: 2 | D13: 10 | E13: U | F13: 3 | G13: 3.41 | H13: =(F13*G13)*10.7639 -> 110.1147 | I13: 78.8 | J13: =I13-$M$2 -> 0 | K13: 0.435 | L13: =K13*H13*J13 -> 0 | N13: =L13+M13 -> 0
B14: lampu | C14: 7 | F14: 3 | G14: 3.41 | H14: =(F14*G14)*10.7639 -> 110.1147 | L14: =4*H14 -> 440.45879 | N14: =L14+M14 -> 440.45879
BJ15: qs = q ,ds ×U F × H F
Z16: Udara Luar
B17: Equipment : | C17: 8
B18: Handphone (15 Watt) | C18: 8 | L18: =15*I54 -> 51.1815 | BJ18: Jika tudung buang dipasang di atas peralatan, gunakan Faktor Tudung, H.F., 0,5. Beban laten untuk peralatan tersebut dianggap nol. Gunakan H.F. = 1,0 dalam Persamaan 3-6 ketika tudung buang tidak dipasang di atas peralatan. Lihat Tabel 3-6 untuk Faktor Penggunaan yang direkomendasikan, U.F
B19: Personel
B20: manusia (latent & sensibel) | C20: 9 | L20: =C32*300 -> 300 | M20: =C32*500 -> 500 | N20: =L20+M20 -> 800 | T20: Pemilihan Insulation
B22: TOTAL HEAT | L22: =SUM(L6:L20) -> 2171.0295 | M22: =SUM(M6:M20) -> 500 | N22: =L22+M22 -> 2671.0295 | AU22: Lighting Loads
BA25: q=A x LC
BK27: Occupancy
B28: ΔT = | C28: 25 | D28: °F | E28: Vol. = | G28: =J51 -> 867.04651 | H28: Ft³ | I28: Out. Air = | J28: =E32 -> 15 | K28: cfm | M28: `
B29: NOTES : GLASS SOLAR LOAD = 160 BTU/HR/ft² x 8,79 ft² = BTU/HR
B30: SHF (Sensible Heat factor)= | C30: Qs/Qt = | D30: =L22/N22 -> 0.81280626 | G30: Q = | H30: Qs/1.08 x ΔT | I30: =L22/(1.08*C28) -> 80.408499 | J30: use | K30: =ROUNDUP(I30,0) -> 81 | L30: Cfm
B32: Min. Out. Air (1) Occupancy = | C32: 1 | D32: 15 | E32: =C32*D32 -> 15 | F32: (2) R/C = | G32: =G28/30 -> 28.90155 | I32: (3) Exhaust throuht Rad. Equip. = | M32: - | O32: HULL or JOB Numnber :
O33: Check by : GEK/MAM
B34: KEY | D34: SYMBOLS | I34: SUMMARY | O34: Calculated by : Vieri Pramudya Dirgantara
B35: 1 = Deck Over | D35: Qs = Heat Load, BTU/Hr, Sensible | I35: Sq. Ft. | J35: =SUM(H6:H14) -> 662.87971 | L35: ƩQL | M35: =M22 -> 500 | O35: HEATING & COOLING LOAD CALCULATIONS | AU35: Heat Gain Personal
B36: 2 = Deck Under | D36: QL = Heat Load, BTU/Hr, Latent | I36: Height | J36: =J49 -> 2.4 | L36: ƩQT | M36: =N22 -> 2671.0295 | BL36: Hunian Udara luar ruangan minimum berdasarkan hunian kamar adalah 12 CFM / orang untuk ruang hunian tinggi (misalnya, ruang rekreasi, ruang makan dan kamar mess) dan 15 CFM / orang untuk ruang ber-AC dengan hunian rendah (misalnya, kabin dan kantor). Tarif ini hanya akan ditingkatkan untuk mencapai keseimbangan udara dalam setiap subdivisi, tetapi tidak boleh melebihi 50 CFM / orang.
B37: 3 = Outboard Bhd or Shell | D37: QT = Heat Load, BTU/Hr, Total | I37: Volume | J37: =G28 -> 867.04651 | L37: Q | M37: =K30 -> 81
B38: 4 = Forward Bulkhead | D38: QW = Heat Load, BTU/Hr, Winter | I38: R or C | J38: =G32 -> 28.90155
B39: 5 = After Bulkhead | D39: U = Transmittance, BTU/Sq. Ft. Hr. °F | I39: ƩQs | J39: =L22 -> 2171.0295
B40: 6 = Inboard Bulkhead | D40: TD = Temperature Differences | I40: SHF | J40: =D30 -> 0.81280626 | O40: REV | Q40: SHEET NO OF
B41: 7 = Lights | D41: TO = Temp of Adjoining Space or Outside
B42: 8 = Equipment
B43: 9= Personnel
B44: Kode | K44: Uk.Jendela | M44: 400 | N44: mm | O44: 0.4 | P44: m
B45: 10 | C45: Tidak mengalami perpindahan panas | BL45: Infiltrasi Untuk ruang seperti Ruang Kemudi (Rumah Percontohan) dengan pintu yang terbuka langsung ke cuaca, laju perubahan udara luar ruangan minimum adalah 60 menit, tetapi tidak boleh melebihi 50 CFM / orang.
...

Sheet Musholla
B1: H | C1: U | D1: D | H1: 1 m = | I1: 3.28 | J1: ft
B2: SPACE | D2: SPACE NO. | F2: MAIN DECK | H2: FRAMES | I2: SPACE TEMP COOLING | M2: 78.8 | N2: °F | O2: SPACE TEMP HEATING | Q2: 70 | R2: °F
B3: Musholla | D3: MD/SB/4 | H3: 11 to 16 | T3: Kondisi Temperature udara yang didesain. | Y3: 26°C | Z3: 78,8°F
B4: ADJOINING SPACE | C4: LOAD | D4: INSUL | E4: U | F4: DIMENSION (m2) | H4: AREA (Ft ²) | I4: TO | J4: TD | K4: U | L4: QS | M4: QL | N4: QT | O4: TO | P4: TD | Q4: U | R4: Qw
C5: KEY | D5: TYPE | E5: KEY | F5: Panjang | G5: Tinggi/Lebar
B6: Depan = Electrician Room | C6: 4 | D6: 10 | E6: H | F6: 3.4 | G6: 2.4 | H6: =(F6*G6)*10.7639 -> 87.833424 | I6: 78.8 | J6: =I6-$M$2 -> 0 | K6: 0.361 | L6: =K6*H6*J6 -> 0 | N6: =L6+M6 -> 0
B7: Belakang = Toilet | C7: 5 | D7: 54 | E7: H | F7: 3.4 | G7: 2.4 | H7: =(F7*G7)*10.7639 -> 87.833424 | I7: 105 | J7: =I7-$M$2 -> 26.2 | K7: 0.191 | L7: =K7*H7*J7 -> 439.53602 | N7: =L7+M7 -> 439.53602 | AU7: Glass Solar Factor | AX7: saya pakai | AZ7: 95F | BD7: Equipment
B8: Kanan = Outdoor/Starboard Weather | C8: 6 | D8: 54 | E8: H | F8: 3.49 | G8: 3 | H8: =(F8*G8)*10.7639 -> 112.69803 | I8: 95 | J8: =I8-$M$2 -> 16.2 | K8: 0.196 | L8: =K8*H8*J8 -> 357.83879 | N8: =L8+M8 -> 357.83879
B9: Kiri = Gangway | C9: 3 | D9: 54 | E9: H | F9: 3.49 | G9: 3 | H9: =(F9*G9)*10.7639 -> 112.69803 | I9: 80 | J9: =I9-$M$2 -> 1.2 | K9: 0.191 | L9: =K9*H9*J9 -> 25.830389 | N9: =L9+M9 -> 25.830389
B10: Solar (window) | C10: 3 | E10: GLASS | G10: =O44 -> 0.4 | H10: =(1/4*PI()*G10^2)*(I1^2) -> 1.3519404 | L10: =160*H10 -> 216.31047 | N10: =L10+M10 -> 216.31047
B11: atas = Medical Room | C11: 1 | D11: 10 | E11: D | F11: 2.4 | G11: 3.41 | H11: =(F11*G11)*10.7639 -> 88.091758 | I11: 78.8 | J11: =I11-$M$2 -> 0 | K11: 0.272 | L11: =K11*H11*J11 -> 0 | N11: =L11+M11 -> 0
B12: atas = Outdoor/Weather | C12: 1 | D12: 54 | E12: D | F12: 0.6 | G12: 3.41 | H12: =(F12*G12)*10.7639 -> 22.022939 | I12: 95 | J12: =I12-$M$2 -> 16.2 | K12: 0.176 | L12: =K12*H12*J12 -> 62.791805 | N12: =L12+M12 -> 62.791805 | BJ12: ql = q ,dl ×U F
B13: bawah = Oiler (2p)Room | C13: 2 | D13: 10 | E13: U | F13: 3 | G13: 3.41 | H13: =(F13*G13)*10.7639 -> 110.1147 | I13: 78.8 | J13: =I13-$M$2 -> 0 | K13: 0.435 | L13: =K13*H13*J13 -> 0 | N13: =L13+M13 -> 0
B14: lampu | C14: 7 | F14: 3 | G14: 3.41 | H14: =(F14*G14)*10.7639 -> 110.1147 | L14: =7*H14 -> 770.80288 | N14: =L14+M14 -> 770.80288
BJ15: qs = q ,ds ×U F × H F
Z16: Udara Luar
B17: Equipment : | C17: 8
BJ18: Jika tudung buang dipasang di atas peralatan, gunakan Faktor Tudung, H.F., 0,5. Beban laten untuk peralatan tersebut dianggap nol. Gunakan H.F. = 1,0 dalam Persamaan 3-6 ketika tudung buang tidak dipasang di atas peralatan. Lihat Tabel 3-6 untuk Faktor Penggunaan yang direkomendasikan, U.F
B19: Personel
B20: manusia (latent & sensibel) | C20: 9 | L20: =C32*300 -> 600 | M20: =C32*500 -> 1000 | N20: =L20+M20 -> 1600 | T20: Pemilihan Insulation
B22: TOTAL HEAT | L22: =SUM(L6:L20) -> 2473.1104 | M22: =SUM(M6:M20) -> 1000 | N22: =L22+M22 -> 3473.1104 | AU22: Lighting Loads
BA25: q=A x LC
BK27: Occupancy
B28: ΔT = | C28: 25 | D28: °F | E28: Vol. = | G28: =J51 -> 867.04651 | H28: Ft³ | I28: Out. Air = | J28: =E32 -> 30 | K28: cfm | M28: `
B29: NOTES : GLASS SOLAR LOAD = 160 BTU/HR/ft² x 8,79 ft² = BTU/HR
B30: SHF (Sensible Heat factor)= | C30: Qs/Qt = | D30: =L22/N22 -> 0.71207365 | G30: Q = | H30: Qs/1.08 x ΔT | I30: =L22/(1.08*C28) -> 91.59668 | J30: use | K30: =ROUNDUP(I30,0) -> 92 | L30: Cfm
B32: Min. Out. Air (1) Occupancy = | C32: 2 | D32: 15 | E32: =C32*D32 -> 30 | F32: (2) R/C = | G32: =G28/30 -> 28.90155 | I32: (3) Exhaust throuht Rad. Equip. = | M32: - | O32: HULL or JOB Numnber :
O33: Check by : GEK/MAM
B34: KEY | D34: SYMBOLS | I34: SUMMARY | O34: Calculated by : Vieri Pramudya Dirgantara
B35: 1 = Deck Over | D35: Qs = Heat Load, BTU/Hr, Sensible | I35: Sq. Ft. | J35: =SUM(H6:H14) -> 732.75895 | L35: ƩQL | M35: =M22 -> 1000 | O35: HEATING & COOLING LOAD CALCULATIONS | AU35: Heat Gain Personal
B36: 2 = Deck Under | D36: QL = Heat Load, BTU/Hr, Latent | I36: Height | J36: =J49 -> 2.4 | L36: ƩQT | M36: =N22 -> 3473.1104 | BL36: Hunian Udara luar ruangan minimum berdasarkan hunian kamar adalah 12 CFM / orang untuk ruang hunian tinggi (misalnya, ruang rekreasi, ruang makan dan kamar mess) dan 15 CFM / orang untuk ruang ber-AC dengan hunian rendah (misalnya, kabin dan kantor). Tarif ini hanya akan ditingkatkan untuk mencapai keseimbangan udara dalam setiap subdivisi, tetapi tidak boleh melebihi 50 CFM / orang.
B37: 3 = Outboard Bhd or Shell | D37: QT = Heat Load, BTU/Hr, Total | I37: Volume | J37: =G28 -> 867.04651 | L37: Q | M37: =K30 -> 92
B38: 4 = Forward Bulkhead | D38: QW = Heat Load, BTU/Hr, Winter | I38: R or C | J38: =G32 -> 28.90155
B39: 5 = After Bulkhead | D39: U = Transmittance, BTU/Sq. Ft. Hr. °F | I39: ƩQs | J39: =L22 -> 2473.1104
B40: 6 = Inboard Bulkhead | D40: TD = Temperature Differences | I40: SHF | J40: =D30 -> 0.71207365 | O40: REV | Q40: SHEET NO OF
B41: 7 = Lights | D41: TO = Temp of Adjoining Space or Outside
B42: 8 = Equipment
B43: 9= Personnel
B44: Kode | K44: Uk.Jendela | M44: 400 | N44: mm | O44: 0.4 | P44: m
B45: 10 | C45: Tidak mengalami perpindahan panas | BL45: Infiltrasi Untuk ruang seperti Ruang Kemudi (Rumah Percontohan) dengan pintu yang terbuka langsung ke cuaca, laju perubahan udara luar ruangan minimum adalah 60 menit, tetapi tidak boleh melebihi 50 CFM / orang.
...

Sheet Electrician
B1: H | C1: U | D1: D | H1: 1 m = | I1: 3.28 | J1: ft
B2: SPACE | D2: SPACE NO. | F2: MAIN DECK | H2: FRAMES | I2: SPACE TEMP COOLING | M2: 78.8 | N2: °F | O2: SPACE TEMP HEATING | Q2: 70 | R2: °F
B3: Electrician | D3: MD/SB/4 | H3: 16 to 20 | T3: Kondisi Temperature udara yang didesain. | Y3: 26°C | Z3: 78,8°F
B4: ADJOINING SPACE | C4: LOAD | D4: INSUL | E4: U | F4: DIMENSION (m2) | H4: AREA (Ft ²) | I4: TO | J4: TD | K4: U | L4: QS | M4: QL | N4: QT | O4: TO | P4: TD | Q4: U | R4: Qw
C5: KEY | D5: TYPE | E5: KEY | F5: Panjang | G5: Tinggi/Lebar
B6: Depan = Second Engineer Room | C6: 4 | D6: 10 | E6: H | F6: 3.41 | G6: 2.4 | H6: =(F6*G6)*10.7639 -> 88.091758 | I6: 78.8 | J6: =I6-$M$2 -> 0 | K6: 0.361 | L6: =K6*H6*J6 -> 0 | N6: =L6+M6 -> 0
B7: Belakang = Musholla | C7: 5 | D7: 10 | E7: H | F7: 3.41 | G7: 2.4 | H7: =(F7*G7)*10.7639 -> 88.091758 | I7: 78.8 | J7: =I7-$M$2 -> 0 | K7: 0.361 | L7: =K7*H7*J7 -> 0 | N7: =L7+M7 -> 0 | AU7: Glass Solar Factor | AX7: saya pakai | AZ7: 95F | BD7: Equipment
B8: Kanan = Outdoor/Starboard Weather | C8: 6 | D8: 54 | E8: H | F8: 3 | G8: 3.41 | H8: =(F8*G8)*10.7639 -> 110.1147 | I8: 95 | J8: =I8-$M$2 -> 16.2 | K8: 0.196 | L8: =K8*H8*J8 -> 349.63619 | N8: =L8+M8 -> 349.63619
B9: Kiri = Gangway | C9: 3 | D9: 54 | E9: H | F9: 3 | G9: 3.41 | H9: =(F9*G9)*10.7639 -> 110.1147 | I9: 80 | J9: =I9-$M$2 -> 1.2 | K9: 0.191 | L9: =K9*H9*J9 -> 25.238289 | N9: =L9+M9 -> 25.238289
B10: Solar (window) | C10: 3 | E10: GLASS | G10: =O44 -> 0.4 | H10: =(1/4*PI()*G10^2)*(I1^2) -> 1.3519404 | L10: =160*H10 -> 216.31047 | N10: =L10+M10 -> 216.31047
B11: atas = Medical Room | C11: 1 | D11: 10 | E11: D | F11: 1.6 | G11: 3.41 | H11: =(F11*G11)*10.7639-H13 -> 43.227822 | I11: 78.8 | J11: =I11-$M$2 -> 0 | K11: 0.272 | L11: =K11*H11*J11 -> 0 | N11: =L11+M11 -> 0
B12: atas = Chief Officerl Room | C12: 1 | D12: 10 | E12: D | F12: 1.4 | G12: 3.41 | H12: =(F12*G12)*10.7639 -> 51.386859 | I12: 78.8 | J12: =I12-$M$2 -> 0 | K12: 0.272 | L12: =K12*H12*J12 -> 0 | N12: =L12+M12 -> 0 | BJ12: ql = q ,dl ×U F
B13: atas = Toilet Medical Room | C13: 1 | D13: 54 | E13: D | F13: 1.2 | G13: 1.2 | H13: =(F13*G13)*10.7639 -> 15.500016 | I13: 85 | J13: =I13-$M$2 -> 6.2 | K13: 0.169 | L13: =K13*H13*J13 -> 16.240917 | N13: =L13+M13 -> 16.240917
B14: bawah = Pumpman (2p) Room | C14: 2 | D14: 10 | E14: U | F14: 3 | G14: 3.41 | H14: =(F14*G14)*10.7639 -> 110.1147 | I14: 78.8 | J14: =I14-$M$2 -> 0 | K14: 0.435 | L14: =K14*H14*J14 -> 0 | N14: =L14+M14 -> 0
B15: lampu | C15: 7 | F15: 3 | G15: 3.41 | H15: =(F15*G15)*10.7639 -> 110.1147 | L15: =4*H15 -> 440.45879 | N15: =L15+M15 -> 440.45879 | BJ15: qs = q ,ds ×U F × H F
Z16: Udara Luar
B17: Equipment : | C17: 8
B18: Handphone (15 Watt) | C18: 8 | L18: =15*I54 -> 51.1815 | BJ18: Jika tudung buang dipasang di atas peralatan, gunakan Faktor Tudung, H.F., 0,5. Beban laten untuk peralatan tersebut dianggap nol. Gunakan H.F. = 1,0 dalam Persamaan 3-6 ketika tudung buang tidak dipasang di atas peralatan. Lihat Tabel 3-6 untuk Faktor Penggunaan yang direkomendasikan, U.F
B19: Personel
B20: manusia (latent & sensibel) | C20: 9 | L20: =C32*300 -> 300 | M20: =C32*500 -> 500 | N20: =L20+M20 -> 800 | T20: Pemilihan Insulation
B22: TOTAL HEAT | L22: =SUM(L6:L20) -> 1399.0661 | M22: =SUM(M6:M20) -> 500 | N22: =L22+M22 -> 1899.0661 | AU22: Lighting Loads
BA25: q=A x LC
BK27: Occupancy
B28: ΔT = | C28: 25 | D28: °F | E28: Vol. = | G28: =J51 -> 867.04651 | H28: Ft³ | I28: Out. Air = | J28: =E32 -> 15 | K28: cfm | M28: `
B29: NOTES : GLASS SOLAR LOAD = 160 BTU/HR/ft² x 8,79 ft² = BTU/HR
B30: SHF (Sensible Heat factor)= | C30: Qs/Qt = | D30: =L22/N22 -> 0.7367127 | G30: Q = | H30: Qs/1.08 x ΔT | I30: =L22/(1.08*C28) -> 51.817265 | J30: use | K30: =ROUNDUP(I30,0) -> 52 | L30: Cfm
B32: Min. Out. Air (1) Occupancy = | C32: 1 | D32: 15 | E32: =C32*D32 -> 15 | F32: (2) R/C = | G32: =G28/30 -> 28.90155 | I32: (3) Exhaust throuht Rad. Equip. = | M32: - | O32: HULL or JOB Numnber :
O33: Check by : GEK/MAM
B34: KEY | D34: SYMBOLS | I34: SUMMARY | O34: Calculated by : Vieri Pramudya Dirgantara
B35: 1 = Deck Over | D35: Qs = Heat Load, BTU/Hr, Sensible | I35: Sq. Ft. | J35: =SUM(H6:H15) -> 728.10894 | L35: ƩQL | M35: =M22 -> 500 | O35: HEATING & COOLING LOAD CALCULATIONS | AU35: Heat Gain Personal
B36: 2 = Deck Under | D36: QL = Heat Load, BTU/Hr, Latent | I36: Height | J36: =2.5 -> 2.5 | L36: ƩQT | M36: =N22 -> 1899.0661 | BL36: Hunian Udara luar ruangan minimum berdasarkan hunian kamar adalah 12 CFM / orang untuk ruang hunian tinggi (misalnya, ruang rekreasi, ruang makan dan kamar mess) dan 15 CFM / orang untuk ruang ber-AC dengan hunian rendah (misalnya, kabin dan kantor). Tarif ini hanya akan ditingkatkan untuk mencapai keseimbangan udara dalam setiap subdivisi, tetapi tidak boleh melebihi 50 CFM / orang.
B37: 3 = Outboard Bhd or Shell | D37: QT = Heat Load, BTU/Hr, Total | I37: Volume | J37: =G28 -> 867.04651 | L37: Q | M37: =K30 -> 52
B38: 4 = Forward Bulkhead | D38: QW = Heat Load, BTU/Hr, Winter | I38: R or C | J38: =G32 -> 28.90155
B39: 5 = After Bulkhead | D39: U = Transmittance, BTU/Sq. Ft. Hr. °F | I39: ƩQs | J39: =L22 -> 1399.0661
B40: 6 = Inboard Bulkhead | D40: TD = Temperature Differences | I40: SHF | J40: =D30 -> 0.7367127 | O40: REV | Q40: SHEET NO OF
B41: 7 = Lights | D41: TO = Temp of Adjoining Space or Outside
B42: 8 = Equipment
B43: 9= Personnel
B44: Kode | K44: Uk.Jendela | M44: 400 | N44: mm | O44: 0.4 | P44: m
B45: 10 | C45: Tidak mengalami perpindahan panas | BL45: Infiltrasi Untuk ruang seperti Ruang Kemudi (Rumah Percontohan) dengan pintu yang terbuka langsung ke cuaca, laju perubahan udara luar ruangan minimum adalah 60 menit, tetapi tidak boleh melebihi 50 CFM / orang.
...

Sheet Second Engineer
B1: H | C1: U | D1: D | H1: 1 m = | I1: 3.28 | J1: ft
B2: SPACE | D2: SPACE NO. | F2: MAIN DECK | H2: FRAMES | I2: SPACE TEMP COOLING | M2: 78.8 | N2: °F | O2: SPACE TEMP HEATING | Q2: 70 | R2: °F
B3: Second Engineer | D3: MD/SB/4 | H3: 20 to 25 | T3: Kondisi Temperature udara yang didesain. | Y3: 26°C | Z3: 78,8°F
B4: ADJOINING SPACE | C4: LOAD | D4: INSUL | E4: U | F4: DIMENSION (m2) | H4: AREA (Ft ²) | I4: TO | J4: TD | K4: U | L4: QS | M4: QL | N4: QT | O4: TO | P4: TD | Q4: U | R4: Qw
C5: KEY | D5: TYPE | E5: KEY | F5: Panjang | G5: Tinggi/Lebar
B6: Depan = Outdoor/Solar | C6: 4 | D6: 54 | E6: H | F6: 3.4 | G6: 2.4 | H6: =(F6*G6)*10.7639 -> 87.833424 | I6: 125 | J6: =I6-$M$2 -> 46.2 | K6: 0.212 | L6: =K6*H6*J6 -> 860.27569 | N6: =L6+M6 -> 860.27569
B7: Belakang = Electrician Room | C7: 5 | D7: 10 | E7: H | F7: 3.4 | G7: 2.4 | H7: =(F7*G7)*10.7639 -> 87.833424 | I7: 78.8 | J7: =I7-$M$2 -> 0 | K7: 0.361 | L7: =K7*H7*J7 -> 0 | N7: =L7+M7 -> 0 | AU7: Glass Solar Factor | AX7: saya pakai | AZ7: 95F | BD7: Equipment
B8: Kanan = Outdoor/Starboard Weather | C8: 6 | D8: 54 | E8: H | F8: 3 | G8: 2.4 | H8: =(F8*G8)*10.7639 -> 77.50008 | I8: 95 | J8: =I8-$M$2 -> 16.2 | K8: 0.196 | L8: =K8*H8*J8 -> 246.07825 | N8: =L8+M8 -> 246.07825
B9: Kiri = Gangway | C9: 3 | D9: 54 | E9: H | F9: 3 | G9: 3.4 | H9: =(F9*G9)*10.7639 -> 109.79178 | I9: 80 | J9: =I9-$M$2 -> 1.2 | K9: 0.191 | L9: =K9*H9*J9 -> 25.164276 | N9: =L9+M9 -> 25.164276
B10: Solar (window) | C10: 3 | E10: GLASS | G10: =O44 -> 0.4 | H10: =(1/4*PI()*G10^2)*(I1^2) -> 1.3519404 | L10: =160*H10 -> 216.31047 | N10: =L10+M10 -> 216.31047
B11: atas = Chief Officer Room | C11: 1 | D11: 10 | E11: D | F11: 3 | G11: 3.4 | H11: =(F11*G11)*10.7639-H12 -> 94.291764 | I11: 78.8 | J11: =I11-$M$2 -> 0 | K11: 0.272 | L11: =K11*H11*J11 -> 0 | N11: =L11+M11 -> 0
B12: atas = Toilet Chief Officer Room | C12: 1 | D12: 54 | E12: D | F12: 1.2 | G12: 1.2 | H12: =(F12*G12)*10.7639 -> 15.500016 | I12: 85 | J12: =I12-$M$2 -> 6.2 | K12: 0.169 | L12: =K12*H12*J12 -> 16.240917 | N12: =L12+M12 -> 16.240917 | BJ12: ql = q ,dl ×U F
B13: bawah = Fireman (2p) Room | C13: 2 | D13: 10 | E13: U | F13: 3 | G13: 3.4 | H13: =(F13*G13)*10.7639 -> 109.79178 | I13: 78.8 | J13: =I13-$M$2 -> 0 | K13: 0.435 | L13: =K13*H13*J13 -> 0 | N13: =L13+M13 -> 0
B14: lampu | C14: 7 | F14: 3 | G14: 3.4 | H14: =(F14*G14)*10.7639 -> 109.79178 | L14: =4*H14 -> 439.16712 | N14: =L14+M14 -> 439.16712
BJ15: qs = q ,ds ×U F × H F
Z16: Udara Luar
B17: Equipment : | C17: 8
B18: Handphone (15 Watt) | C18: 8 | L18: =15*I54 -> 51.1815 | BJ18: Jika tudung buang dipasang di atas peralatan, gunakan Faktor Tudung, H.F., 0,5. Beban laten untuk peralatan tersebut dianggap nol. Gunakan H.F. = 1,0 dalam Persamaan 3-6 ketika tudung buang tidak dipasang di atas peralatan. Lihat Tabel 3-6 untuk Faktor Penggunaan yang direkomendasikan, U.F
B19: Personel
B20: manusia (latent & sensibel) | C20: 9 | L20: =C32*300 -> 300 | M20: =C32*500 -> 500 | N20: =L20+M20 -> 800 | T20: Pemilihan Insulation
B22: TOTAL HEAT | L22: =SUM(L6:L20) -> 2154.4182 | M22: =SUM(M6:M20) -> 500 | N22: =L22+M22 -> 2654.4182 | AU22: Lighting Loads
BA25: q=A x LC
BK27: Occupancy
B28: ΔT = | C28: 25 | D28: °F | E28: Vol. = | G28: =J51 -> 867.04651 | H28: Ft³ | I28: Out. Air = | J28: =E32 -> 15 | K28: cfm | M28: `
B29: NOTES : GLASS SOLAR LOAD = 160 BTU/HR/ft² x 8,79 ft² = BTU/HR
B30: SHF (Sensible Heat factor)= | C30: Qs/Qt = | D30: =L22/N22 -> 0.81163481 | G30: Q = | H30: Qs/1.08 x ΔT | I30: =L22/(1.08*C28) -> 79.793267 | J30: use | K30: =ROUNDUP(I30,0) -> 80 | L30: Cfm
B32: Min. Out. Air (1) Occupancy = | C32: 1 | D32: 15 | E32: =C32*D32 -> 15 | F32: (2) R/C = | G32: =G28/30 -> 28.90155 | I32: (3) Exhaust throuht Rad. Equip. = | M32: - | O32: HULL or JOB Numnber :
O33: Check by : GEK/MAM
B34: KEY | D34: SYMBOLS | I34: SUMMARY | O34: Calculated by : Vieri Pramudya Dirgantara
B35: 1 = Deck Over | D35: Qs = Heat Load, BTU/Hr, Sensible | I35: Sq. Ft. | J35: =SUM(H6:H14) -> 693.68599 | L35: ƩQL | M35: =M22 -> 500 | O35: HEATING & COOLING LOAD CALCULATIONS | AU35: Heat Gain Personal
B36: 2 = Deck Under | D36: QL = Heat Load, BTU/Hr, Latent | I36: Height | J36: =2.5 -> 2.5 | L36: ƩQT | M36: =N22 -> 2654.4182 | BL36: Hunian Udara luar ruangan minimum berdasarkan hunian kamar adalah 12 CFM / orang untuk ruang hunian tinggi (misalnya, ruang rekreasi, ruang makan dan kamar mess) dan 15 CFM / orang untuk ruang ber-AC dengan hunian rendah (misalnya, kabin dan kantor). Tarif ini hanya akan ditingkatkan untuk mencapai keseimbangan udara dalam setiap subdivisi, tetapi tidak boleh melebihi 50 CFM / orang.
B37: 3 = Outboard Bhd or Shell | D37: QT = Heat Load, BTU/Hr, Total | I37: Volume | J37: =G28 -> 867.04651 | L37: Q | M37: =K30 -> 80
B38: 4 = Forward Bulkhead | D38: QW = Heat Load, BTU/Hr, Winter | I38: R or C | J38: =G32 -> 28.90155
B39: 5 = After Bulkhead | D39: U = Transmittance, BTU/Sq. Ft. Hr. °F | I39: ƩQs | J39: =L22 -> 2154.4182
B40: 6 = Inboard Bulkhead | D40: TD = Temperature Differences | I40: SHF | J40: =D30 -> 0.81163481 | O40: REV | Q40: SHEET NO OF
B41: 7 = Lights | D41: TO = Temp of Adjoining Space or Outside
B42: 8 = Equipment
B43: 9= Personnel
B44: Kode | K44: Uk.Jendela | M44: 400 | N44: mm | O44: 0.4 | P44: m
B45: 10 | C45: Tidak mengalami perpindahan panas | BL45: Infiltrasi Untuk ruang seperti Ruang Kemudi (Rumah Percontohan) dengan pintu yang terbuka langsung ke cuaca, laju perubahan udara luar ruangan minimum adalah 60 menit, tetapi tidak boleh melebihi 50 CFM / orang.
...

Sheet Smoking Room
B1: H | C1: U | D1: D | H1: 1 m = | I1: 3.28 | J1: ft
B2: SPACE | D2: SPACE NO. | F2: MAIN DECK | H2: FRAMES | I2: SPACE TEMP COOLING | M2: 78.8 | N2: °F | O2: SPACE TEMP HEATING | Q2: 70 | R2: °F
B3: Smoking Room | D3: MD/SB/4 | H3: 20 to 25 | T3: Kondisi Temperature udara yang didesain. | Y3: 26°C | Z3: 78,8°F
B4: ADJOINING SPACE | C4: LOAD | D4: INSUL | E4: U | F4: DIMENSION (m2) | H4: AREA (Ft ²) | I4: TO | J4: TD | K4: U | L4: QS | M4: QL | N4: QT | O4: TO | P4: TD | Q4: U | R4: Qw
C5: KEY | D5: TYPE | E5: KEY | F5: Panjang | G5: Tinggi/Lebar
B6: Depan = Outdoor/Solar | C6: 4 | D6: 54 | E6: H | F6: 4 | G6: 2.4 | H6: =(F6*G6)*10.7639 -> 103.33344 | I6: 125 | J6: =I6-$M$2 -> 46.2 | K6: 0.212 | L6: =K6*H6*J6 -> 1012.089 | N6: =L6+M6 -> 1012.089
B7: Belakang = Gangway | C7: 5 | D7: 54 | E7: H | F7: 4 | G7: 2.4 | H7: =(F7*G7)*10.7639 -> 103.33344 | I7: 80 | J7: =I7-$M$2 -> 1.2 | K7: 0.191 | L7: =K7*H7*J7 -> 23.684024 | N7: =L7+M7 -> 23.684024 | AU7: Glass Solar Factor | AX7: saya pakai | AZ7: 95F | BD7: Equipment
B8: Kanan = Gangway | C8: 6 | D8: 54 | E8: H | F8: 3.5 | G8: 2.4 | H8: =(F8*G8)*10.7639 -> 90.41676 | I8: 80 | J8: =I8-$M$2 -> 1.2 | K8: 0.191 | L8: =K8*H8*J8 -> 20.723521 | N8: =L8+M8 -> 20.723521
B9: Kiri = Gangway | C9: 3 | D9: 54 | E9: H | F9: 3.5 | G9: 3.4 | H9: =(F9*G9)*10.7639 -> 128.09041 | I9: 80 | J9: =I9-$M$2 -> 1.2 | K9: 0.191 | L9: =K9*H9*J9 -> 29.358322 | N9: =L9+M9 -> 29.358322
B10: Solar (window) | C10: 3 | E10: GLASS | G10: =O44 -> 0.4 | H10: =((1/4*PI()*G10^2)*(I1^2)*M45) -> 2.7038808 | L10: =160*H10 -> 432.62093 | N10: =L10+M10 -> 432.62093
B11: atas = Chief Officer & Engineer Office | C11: 1 | D11: 10 | E11: D | F11: 3.5 | G11: 4 | H11: =(F11*G11)*10.7639 -> 150.6946 | I11: 78.8 | J11: =I11-$M$2 -> 0 | K11: 0.272 | L11: =K11*H11*J11 -> 0 | N11: =L11+M11 -> 0
B12: bawah = Dry Provision Room | C12: 2 | D12: 54 | E12: U | F12: 3 | G12: 4 | H12: =(F12*G12)*10.7639 -> 129.1668 | I12: 110 | J12: =I12-$M$2 -> 31.2 | K12: 0.207 | L12: =K12*H12*J12 -> 834.21086 | N12: =L12+M12 -> 834.21086 | BJ12: ql = q ,dl ×U F
B13: bawah = Gangway | C13: 2 | D13: 54 | E13: U | F13: 0.5 | G13: 4 | H13: =(F13*G13)*10.7639 -> 21.5278 | I13: 80 | J13: =I13-$M$2 -> 1.2 | K13: 0.207 | L13: =K13*H13*J13 -> 5.3475055 | N13: =L13+M13 -> 5.3475055
B14: lampu | C14: 7 | F14: 3.5 | G14: 4 | H14: =(F14*G14)*10.7639 -> 150.6946 | L14: =7*H14 -> 1054.8622 | N14: =L14+M14 -> 1054.8622
BJ15: qs = q ,ds ×U F × H F
Z16: Udara Luar
B17: Equipment : | C17: 8
BJ18: Jika tudung buang dipasang di atas peralatan, gunakan Faktor Tudung, H.F., 0,5. Beban laten untuk peralatan tersebut dianggap nol. Gunakan H.F. = 1,0 dalam Persamaan 3-6 ketika tudung buang tidak dipasang di atas peralatan. Lihat Tabel 3-6 untuk Faktor Penggunaan yang direkomendasikan, U.F
B19: Personel
B20: manusia (latent & sensibel) | C20: 9 | L20: =C32*300 -> 1200 | M20: =C32*500 -> 2000 | N20: =L20+M20 -> 3200 | T20: Pemilihan Insulation
B22: TOTAL HEAT | L22: =SUM(L6:L20) -> 4612.8964 | M22: =SUM(M6:M20) -> 2000 | N22: =L22+M22 -> 6612.8964 | AU22: Lighting Loads
BA25: q=A x LC
BK27: Occupancy
B28: ΔT = | C28: 25 | D28: °F | E28: Vol. = | G28: =J51 -> 1186.5739 | H28: Ft³ | I28: Out. Air = | J28: =E32 -> 60 | K28: cfm | M28: `
B29: NOTES : GLASS SOLAR LOAD = 160 BTU/HR/ft² x 8,79 ft² = BTU/HR
B30: SHF (Sensible Heat factor)= | C30: Qs/Qt = | D30: =L22/N22 -> 0.69756066 | G30: Q = | H30: Qs/1.08 x ΔT | I30: =L22/(1.08*C28) -> 170.84802 | J30: use | K30: =ROUNDUP(I30,0) -> 171 | L30: Cfm
B32: Min. Out. Air (1) Occupancy = | C32: 4 | D32: 15 | E32: =C32*D32 -> 60 | F32: (2) R/C = | G32: =G28/30 -> 39.552464 | I32: (3) Exhaust throuht Rad. Equip. = | M32: - | O32: HULL or JOB Numnber :
O33: Check by : GEK/MAM
B34: KEY | D34: SYMBOLS | I34: SUMMARY | O34: Calculated by : Vieri Pramudya Dirgantara
B35: 1 = Deck Over | D35: Qs = Heat Load, BTU/Hr, Sensible | I35: Sq. Ft. | J35: =SUM(H6:H14) -> 879.96173 | L35: ƩQL | M35: =M22 -> 2000 | O35: HEATING & COOLING LOAD CALCULATIONS | AU35: Heat Gain Personal
B36: 2 = Deck Under | D36: QL = Heat Load, BTU/Hr, Latent | I36: Height | J36: =2.5 -> 2.5 | L36: ƩQT | M36: =N22 -> 6612.8964 | BL36: Hunian Udara luar ruangan minimum berdasarkan hunian kamar adalah 12 CFM / orang untuk ruang hunian tinggi (misalnya, ruang rekreasi, ruang makan dan kamar mess) dan 15 CFM / orang untuk ruang ber-AC dengan hunian rendah (misalnya, kabin dan kantor). Tarif ini hanya akan ditingkatkan untuk mencapai keseimbangan udara dalam setiap subdivisi, tetapi tidak boleh melebihi 50 CFM / orang.
B37: 3 = Outboard Bhd or Shell | D37: QT = Heat Load, BTU/Hr, Total | I37: Volume | J37: =G28 -> 1186.5739 | L37: Q | M37: =K30 -> 171
B38: 4 = Forward Bulkhead | D38: QW = Heat Load, BTU/Hr, Winter | I38: R or C | J38: =G32 -> 39.552464
B39: 5 = After Bulkhead | D39: U = Transmittance, BTU/Sq. Ft. Hr. °F | I39: ƩQs | J39: =L22 -> 4612.8964
B40: 6 = Inboard Bulkhead | D40: TD = Temperature Differences | I40: SHF | J40: =D30 -> 0.69756066 | O40: REV | Q40: SHEET NO OF
B41: 7 = Lights | D41: TO = Temp of Adjoining Space or Outside
B42: 8 = Equipment
B43: 9= Personnel
B44: Kode | K44: Uk.Jendela | M44: 400 | N44: mm | O44: 0.4 | P44: m
B45: 10 | C45: Tidak mengalami perpindahan panas | K45: Jumlah Jendela | M45: 2 | BL45: Infiltrasi Untuk ruang seperti Ruang Kemudi (Rumah Percontohan) dengan pintu yang terbuka langsung ke cuaca, laju perubahan udara luar ruangan minimum adalah 60 menit, tetapi tidak boleh melebihi 50 CFM / orang.
...
