Workbook

Sheet SUMMARY
B2: TOTAL JUMLAH RUANGAN yg DIKONDISIKAN
B4: Nama Kapal : | C4: MTM Antwerp
B5: Jenis Kapal : | C5: Product Oil Tanker
B6: Nama Mahasiswa : | C6: Daffa Gabillah Maulana Gapur
B7: NRP : | C7: 0322040051
B9: No | C9: Room Name | D9: Jumlah Ruangan
B10: 1 | C10: Main Deck | D10: ='MAIN DK'!B24 -> 4
B11: 2 | C11: Poop Deck | D11: ='POOP DK'!B24 -> 8
B12: 3 | C12: A Deck | D12: ='A DK'!B24 -> 10
B13: 4 | C13: B Deck | D13: ='B DK'!B24 -> 10
B14: 5 | C14: C Deck | D14: ='C DK'!B24 -> 11
B15: 6 | C15: Bridge Deck | D15: ='BRIDGE DK'!B24 -> 1

Sheet MAIN DK
B2: List Ruangan yg Perlu Dikondisikan dengan Sistem Air Handling Unit (AHU)
B4: No | C4: Room Name | D4: Dimension in Meter | G4: Area [ft2] | H4: Volume [ft3] | I4: Cooling Capacity [Btu/hr]
D5: Length | E5: Width | F5: Height
B6: 1 | C6: Vegetable Store | D6: =9*0.6 + 0.2 -> 5.6 | E6: 2.8 | F6: 3 | G6: ='VEGETABLE STORE'!F35 -> 165.19745 | H6: ='VEGETABLE STORE'!F37 -> 1463.3633 | I6: ='VEGETABLE STORE'!F43 -> 637.92502
B7: 2 | C7: Meat/Fish Store | D7: 4.2 | E7: 2.8 | F7: 3 | G7: ='MEET FISH STORE'!F35 -> 113.02095 | H7: ='MEET FISH STORE'!F37 -> 1001.1699
B8: 3 | C8: Engine Control Room | D8: 5 | E8: 10.7 | F8: 3 | G8: ='ENGINE CONTROL ROOM'!F35 -> 704.92781 | H8: ='ENGINE CONTROL ROOM'!F37 -> 6244.4395
B9: 4 | C9: Dry Provision Store | D9: 10.9 | E9: 3.55 | F9: 3 | G9: ='DRY PROVISION STORE'!F35 -> 519.66818 | H9: ='DRY PROVISION STORE'!F37 -> 4603.36
B24: =COUNTA(C6:C22) -> 4 | C24: Total Jumlah Ruangan

Sheet POOP DK
B2: List Ruangan yg Perlu Dikondisikan dengan Sistem Air Handling Unit (AHU)
B4: No | C4: Room Name | D4: Dimension in Meter | G4: Area [ft2] | H4: Volume [ft3] | I4: Cooling Capacity [Btu/hr]
D5: Length | E5: Width | F5: Height
B6: 1 | C6: Cargo Control Room | D6: 5.55 | E6: 3.9 | F6: 2.7 | G6: ='CARGO CONTROL ROOM'!F35 -> 254.88915 | H6: ='CARGO CONTROL ROOM'!F37 -> 2257.8764 | I6: ='CARGO CONTROL ROOM'!F43 -> 214.87687
B7: 2 | C7: Ship Office | D7: 5.5 | E7: 4.95 | F7: 2.7 | G7: ='SHIP OFFICE'!F35 -> 318.39616 | H7: ='SHIP OFFICE'!F37 -> 2820.4385
B8: 3 | C8: Deck Change Room | D8: 2.2 | E8: 2.6 | F8: 2.7 | G8: ='DECK CHANGE ROOM'!F35 -> 67.166736 | H8: ='DECK CHANGE ROOM'!F37 -> 594.98095
B9: 4 | C9: Store | D9: 2.2 | E9: 0.95 | F9: 2.7 | G9: =STORE!F35 -> 31.000032 | H9: =STORE!F37 -> 274.60659
B10: 5 | C10: Galley | D10: 6.1 | E10: 6 | F10: 2.7 | G10: =GALLEY!F35 -> 300.52809 | H10: =GALLEY!F37 -> 2662.1583
B11: 6 | C11: Pantry | D11: 5.3 | E11: 2.8 | F11: 2.7 | G11: =D11*E11 -> 14.84 | H11: =D11*E11*F11 -> 40.068
B12: 7 | C12: Crew Mess | D12: 7.6 | E12: 6 | F12: 2.7 | G12: ='CREW MESS'!F35 -> 404.29208 | H12: ='CREW MESS'!F37 -> 3581.3276
B13: 8 | C13: Office Mess | D13: 5.5 | E13: 6.2 | F13: 2.7 | G13: ='OFFICE MESS'!F35 -> 392.45179 | H13: ='OFFICE MESS'!F37 -> 3476.4432
B24: =COUNTA(C6:C22) -> 8 | C24: Total Jumlah Ruangan

Sheet A DK
B2: List Ruangan yg Perlu Dikondisikan dengan Sistem Air Handling Unit (AHU)
B4: No | C4: Room Name | D4: Dimension in Meter | G4: Area [ft2] | H4: Volume [ft3] | I4: Cooling Capacity
D5: Length | E5: Width | F5: Height
B6: 1 | C6: Motorman 2 Cabin | D6: 4.45 | E6: 3 | F6: 2.7 | G6: ='MOTORMAN 2 CABIN'!F35 -> 139.50014 | H6: ='MOTORMAN 2 CABIN'!F37 -> 1235.7297
B7: 2 | C7: Motorman 1 Cabin | D7: 4.45 | E7: 3 | F7: 2.7 | G7: ='MOTORMAN 1 CABIN'!$F$35 -> 134.22583 | H7: ='MOTORMAN 1 CABIN'!$F$37 -> 1189.0084
B8: 3 | C8: AB 2 Cabin | D8: 4.9 | E8: 3.3 | F8: 2.7 | G8: ='AB 2 CABIN'!$F$35 -> 156.39947 | H8: ='AB 2 CABIN'!$F$37 -> 1385.4284
B9: 4 | C9: AB 1 Cabin | D9: 3.4 | E9: 4.8 | F9: 2.7 | G9: ='AB 1 CABIN'!$F$35 -> 154.46196 | H9: ='AB 1 CABIN'!$F$37 -> 1368.2655
B10: 5 | C10: Hospital | D10: 3.2 | E10: 6 | F10: 2.7 | G10: =HOSPITAL!$F$35 -> 185.03144 | H10: =HOSPITAL!$F$37 -> 1639.0581
B11: 6 | C11: OS Cabin | D11: 4.45 | E11: 3 | F11: 2.7 | G11: ='OS CABIN'!$F$35 -> 134.22583 | H11: ='OS CABIN'!$F$37 -> 1189.0084
B12: 7 | C12: Messman Cabin | D12: 4.45 | E12: 3 | F12: 2.7 | G12: ='MESSMAN CABIN'!$F$35 -> 134.22583 | H12: ='MESSMAN CABIN'!$F$37 -> 1189.0084
B13: 8 | C13: Fitter Cabin | D13: 4.45 | E13: 3 | F13: 2.7 | G13: ='FITTER CABIN'!$F$35 -> 144.77445 | H13: ='FITTER CABIN'!$F$37 -> 1282.4509
B14: 9 | C14: Suez Crew Room | D14: 5.3 | E14: 2.9 | F14: 2.7 | G14: ='SUEZ CREW'!$F$35 -> 145.52793 | H14: ='SUEZ CREW'!$F$37 -> 1289.1254
B15: 10 | C15: Hospital Bath Room | D15: 1.3 | E15: 2.2 | F15: 2.7 | G15: ='HOSPITAL TOILET'!$F$35 -> 38.75004 | H15: ='HOSPITAL TOILET'!$F$37 -> 343.25824
B24: =COUNTA(C6:C22) -> 10 | C24: Total Jumlah Ruangan

Sheet B DK
B2: List Ruangan yg Perlu Dikondisikan dengan Sistem Air Handling Unit (AHU)
B4: No | C4: Room Name | D4: Dimension in Meter | G4: Area [ft2] | H4: Volume [ft3] | I4: Cooling Capacity
D5: Length | E5: Width | F5: Height
B6: 1 | C6: 2nd Engineer Cabin | D6: =0.9+1.3+2 -> 4.2 | E6: =1.15+1.4+3.6 -> 6.15 | F6: 2.7 | G6: ='2ND ENGINEER CABIN'!$F$35 -> 242.72594 | H6: ='2ND ENGINEER CABIN'!$F$37 -> 2150.1315
B7: 2 | C7: 3rd Engineer Cabin | D7: =2+1.35 -> 3.35 | E7: =3.6+1.4 -> 5 | F7: 2.7 | G7: ='3RD ENGINEER CABIN'!$F$35 -> 162.85781 | H7: ='3RD ENGINEER CABIN'!$F$37 -> 1442.6381
B8: 3 | C8: Electrician Crew Cabin | D8: 3.35 | E8: 5 | F8: 2.7 | G8: ='ELECTRICIANMAN CABIN'!$F$35 -> 38.75004 | H8: ='ELECTRICIANMAN CABIN'!$F$37 -> 343.25824
B9: 4 | C9: Bosun Crew Cabin | D9: 3.35 | E9: 5 | F9: 2.7 | G9: ='BOSUN CABIN'!F35 -> 168.3474 | H9: ='BOSUN CABIN'!$F$37 -> 1491.2664
B10: 5 | C10: Owner Cabin | D10: =0.9+1.4+1.9 -> 4.2 | E10: 5.25 | F10: 2.7 | G10: ='2ND ENGINEER CABIN'!$F$35 -> 242.72594 | H10: ='2ND ENGINEER CABIN'!$F$37 -> 2150.1315
B11: 6 | C11: Gym Room | D11: 2.15 | E11: 2.65 | F11: 2.7 | G11: ='GYM ROOM'!$F$35 -> 889.81665 | H11: ='GYM ROOM'!$F$37 -> 7882.2344
B12: 7 | C12: 2nd Officer Cabin | D12: 4.2 | E12: 6.15 | F12: 2.7 | G12: ='2ND OFFICER CABIN'!$F$35 -> 234.11482 | H12: ='2ND OFFICER CABIN'!$F$37 -> 2073.8519
B13: 8 | C13: 3rd Officer Cabin | D13: 3.35 | E13: 5 | F13: 2.7 | G13: ='3RD OFFICER CABIN'!$F$35 -> 162.85781 | H13: ='3RD OFFICER CABIN'!$F$37 -> 1442.6381
B14: 9 | C14: Pumpman Cabin | D14: 3.35 | E14: 5 | F14: 2.7 | G14: ='PUMPMAN CABIN'!$F$35 -> 162.85781 | H14: ='PUMPMAN CABIN'!$F$37 -> 1442.6381
B15: 10 | C15: Cook Crew Cabin | D15: 3.35 | E15: 5 | F15: 2.7 | G15: ='COOKMAN CABIN'!$F$35 -> 168.3474 | H15: ='COOKMAN CABIN'!$F$37 -> 1491.2664
B24: =COUNTA(C6:C22) -> 10 | C24: Total Jumlah Ruangan

Sheet C DK
B2: List Ruangan yg Perlu Dikondisikan dengan Sistem Air Handling Unit (AHU)
B4: No | C4: Room Name | D4: Dimension in Meter | G4: Area [ft2] | H4: Volume [ft3] | I4: Cooling Capacity
D5: Length | E5: Width | F5: Height
B6: 1 | C6: Captain Cabin | D6: 5.5 | E6: 3.2 | F6: =26.6-23.9 -> 2.7 | G6: ='MASTER CABIN'!$F$35 -> 206.88216 | H6: ='MASTER CABIN'!$F$37 -> 1832.6176
B7: 2 | C7: Captain Bedroom | D7: 2 | E7: 3.45 | F7: =26.6-23.9 -> 2.7 | G7: ='MASTER BEDROOM'!$F$35 -> 86.730124 | H7: ='MASTER BEDROOM'!$F$37 -> 768.27868
B8: 3 | C8: Chief Officer Cabin | D8: 4.9651 | E8: 3.7016 | F8: =26.6-23.9 -> 2.7 | G8: ='CHIEF OFFICER CABIN'!$F$35 -> 196.11826 | H8: ='CHIEF OFFICER CABIN'!$F$37 -> 1737.2681
B9: 4 | C9: Chief Officer Bedroom | D9: 2.0554 | E9: 3.5503 | F9: =26.6-23.9 -> 2.7 | G9: ='CHIEF OFFICER BEDROOM'!$F$35 -> 89.986204 | H9: ='CHIEF OFFICER BEDROOM'!$F$37 -> 797.12191
B10: 5 | C10: Pilot Cabin | D10: 3.1766 | E10: 4.9651 | F10: =26.6-23.9 -> 2.7 | G10: ='PILOT CABIN'!$F$35 -> 145.95848 | H10: ='PILOT CABIN'!$F$37 -> 1292.9394
B11: 6 | C11: Office Room | D11: 4.4223 | E11: 7.1006 | F11: =26.6-23.9 -> 2.7 | G11: =OFFICE!$F$35 -> 324.26249 | H11: =OFFICE!$F$37 -> 2872.404
B12: 7 | C12: Instrumentation Room | D12: 3.6571 | E12: 2.8563 | F12: =26.6-23.9 -> 2.7 | G12: ='INSTRUMENTATION ROOM'!$F$35 -> 107.639 | H12: ='INSTRUMENTATION ROOM'!$F$37 -> 953.49511
B13: 8 | C13: 1st Engineer Cabin | D13: 3.7016 | E13: 4.9651 | F13: =26.6-23.9 -> 2.7 | G13: ='1ST ENGINEER CABIN'!$F$35 -> 196.11826 | H13: ='1ST ENGINEER CABIN'!$F$37 -> 1737.2681
B14: 9 | C14: 1st Engineer Bedroom | D14: 2.0821 | E14: 3.5503 | F14: =26.6-23.9 -> 2.7 | G14: ='1ST ENGINEER BEDROOM'!$F$35 -> 89.986204 | H14: ='1ST ENGINEER BEDROOM'!$F$37 -> 797.12191
B15: 10 | C15: Chief Engineer Cabin | D15: 4.5736 | E15: 6.1129 | F15: =26.6-23.9 -> 2.7 | G15: ='CHIEF ENGINEER CABIN'!$F$35 -> 206.88216 | H15: ='CHIEF ENGINEER CABIN'!$F$37 -> 1832.6176
B16: 11 | C16: Chief Engineer Bedroom | D16: 2.1088 | E16: 3.5236 | F16: =26.6-23.9 -> 2.7 | G16: ='CHIEF ENGINEER BEDROOM'!$F$35 -> 86.730124 | H16: ='CHIEF ENGINEER BEDROOM'!$F$37 -> 768.27868
B24: =COUNTA(C6:C22) -> 11 | C24: Total Jumlah Ruangan

Sheet BRIDGE DK
B2: List Ruangan yg Perlu Dikondisikan dengan Sistem Air Handling Unit (AHU)
B4: No | C4: Room Name | D4: Dimension in Meter | G4: Area [ft2] | H4: Volume [ft3] | I4: Cooling Capacity
D5: Length | E5: Width | F5: Height
B6: 1 | C6: Wheel House | D6: 11.2382 | E6: 22.4675 | F6: =29.5-26.6 -> 2.9 | G6: ='WHEEL HOUSE'!$F$35 -> 1883.5749 | H6: ='WHEEL HOUSE'!$F$37 -> 16685.211
B24: =COUNTA(C6:C22) -> 1 | C24: Total Jumlah Ruangan

Sheet VEGETABLE STORE
A1: SPACE | C1: SPACE NO. | E1: DECK | F1: FRAMES | G1: SPACE TEMP COOLING 78 °F | O1: SPACE TEMP HEATING 70 °F
A2: VEGETABLE STORE | C2: 4001 | E2: MAIN DECK | F2: -8 - 2
A3: ADJOINING SPACE | B3: LOAD KEY | C3: INSUL TYPE | D3: U KEY | E3: DIMENSION | F3: AREA [ft2] | G3: T | H3: T0 | I3: ΔT | J3: U | L3: QS | M3: QL | N3: QT | O3: T | P3: T0 | Q3: ΔT | R3: U | T3: QW
J4: COEFF | K4: DIR | R4: COEFF | S4: DIR
A5: ELECTRICIAN WORKSHOP | B5: 6 | C5: 0"-0 | D5: H | E5: 5.4812 m x 3 m | F5: =10.7639 * (5.4812*3) -> 176.99727 | G5: 78 | H5: 105 | I5: =H5-G5 -> 27 | J5: 0.93 | K5: =_xlfn.UNICHAR(8596) -> ↔ | L5: =F5*I5*J5 -> 4444.4014 | N5: =L5+M5 -> 4444.4014 | O5: 78 | P5: 78 | Q5: =O5-P5 -> 0 | R5: =J5 -> 0.93 | S5: =K5 -> ↔ | T5: =F5*Q5*R5 -> 0
A6: MEAT/FISH STORE | B6: 6 | C6: 0"-0 | D6: H | E6: 2.8 m x 3 m | F6: =10.7639 *(2.8*3) -> 90.41676 | G6: 78 | H6: 78 | I6: =H6-G6 -> 0 | J6: 0.93 | K6: =_xlfn.UNICHAR(8596) -> ↔ | L6: =F6*I6*J6 -> 0 | N6: =L6+M6 -> 0 | O6: 78 | P6: 40 | Q6: =O6-P6 -> 38 | R6: =J6 -> 0.93 | S6: =K6 -> ↔ | T6: =F6*Q6*R6 -> 3195.3283
A7: DRY PROVISION STORE | B7: 6 | C7: 0"-6 | D7: H | E7: 5.4812 m x 3 m | F7: =10.7639 *(5.4812*3) -> 176.99727 | G7: 78 | H7: 78 | I7: =H7-G7 -> 0 | J7: 0.313 | K7: =_xlfn.UNICHAR(8596) -> ↔ | L7: =F7*I7*J7 -> 0 | N7: =L7+M7 -> 0 | O7: 78 | P7: 78 | Q7: =O7-P7 -> 0 | R7: =J7 -> 0.313 | S7: =K7 -> ↔ | T7: =F7*Q7*R7 -> 0
A8: TECH. FW TK | B8: 2 | C8: 0"-0 | D8: D | E8: 5.4812 m x 2.8 m | F8: =10.7639 *(5.4812*2.8) -> 165.19745 | G8: 78 | H8: 120 | I8: =H8-G8 -> 42 | J8: 0.801 | K8: =_xlfn.UNICHAR(8595) -> ↓ | L8: =F8*I8*J8 -> 5557.5726 | N8: =L8+M8 -> 5557.5726 | O8: 78 | P8: 78 | Q8: =O8-P8 -> 0 | R8: =J8 -> 0.801 | S8: =K8 -> ↓ | T8: =F8*Q8*R8 -> 0
A9: OUTDOOR SPACE | B9: 3 | C9: 0"-0 | D9: U | E9: 5.4812 m x 2.8 m | F9: =10.7639 *(5.4812*2.8) -> 165.19745 | G9: 78 | H9: 95 | I9: =H9-G9 -> 17 | J9: 1.491 | K9: =_xlfn.UNICHAR(8593) -> ↑ | L9: =F9*I9*J9 -> 4187.2597 | N9: =L9+M9 -> 4187.2597 | O9: 78 | P9: 78 | Q9: =O9-P9 -> 0 | R9: =J9 -> 1.491 | S9: =K9 -> ↑ | T9: =F9*Q9*R9 -> 0
A10: OUTDOOR SPACE | B10: 3 | C10: 0"-0 | D10: H | E10: 2.8 m x 3 m | F10: =10.7639 *(2.8*3) -> 90.41676 | G10: 78 | H10: 95 | I10: =H10-G10 -> 17 | J10: 1.32 | K10: =_xlfn.UNICHAR(8596) -> ↔ | L10: =F10*I10*J10 -> 2028.9521 | N10: =L10+M10 -> 2028.9521 | O10: 78 | P10: 78 | Q10: =O10-P10 -> 0 | R10: =J10 -> 1.32 | S10: =K10 -> ↔ | T10: =F10*Q10*R10 -> 0
A14: TRANSMISSION SUBTOTAL | N14: =SUM(N5:N10) -> 16218.186 | T14: =SUM(T5:T9) -> 3195.3283
A20: WINDOW | B20: 8 | F20: =(10.7639 * (0.6*0.5))*0 -> 0 | L20: =F20*160 -> 0 | N20: =L20+M20 -> 0
A21: LIGHTS | B21: 7 | F21: =F9 -> 165.19745 | L21: =F21*4 -> 660.78979 | N21: =L21+M21 -> 660.78979
A22: EQUIPMENT | B22: 8 | N22: =L22+M22 -> 0
A23: FOOD | L23: =30 -> 30 | M23: 30 | N23: =L23+M23 -> 60
A24: PERSONNEL | B24: 9 | L24: =1*315 -> 315 | M24: =1*485 -> 485 | N24: =L24+M24 -> 800
A29: TOTAL HEAT | N29: =SUM(N11:N24) -> 17738.976 | T29: =SUM(T11:T24) -> 3195.3283
A30: TOTAL HEAT | G30: =N29+T29 -> 20934.304
E33: ΔT = | F33: 25 | G33: °F
E34: OCCUPANCY | F34: =15*1 -> 15
E35: Sq. ft. | F35: =$F$21 -> 165.19745 | G35: sq. ft
E36: HEIGHT | F36: =3.28084 * 2.7 -> 8.858268 | G36: ft
E37: VOLUME | F37: =F35*F36 -> 1463.3633 | G37: cb. ft
E38: R of C | F38: =F37/30 -> 48.778776 | G38: CFM
E39: qS TOTAL | F39: =SUM($L$5:$L$28) -> 17223.976 | G39: Btu/hr
E40: qL TOTAL | F40: =SUM($M$5:$M$28) -> 515 | G40: Btu/hr
E41: qT TOTAL | F41: =N29 -> 17738.976 | G41: Btu/hr
E42: qW TOTAL | F42: =T29 -> 3195.3283 | G42: Btu/hr
E43: Q | F43: =F39/(1.08*F33) -> 637.92502 | G43: CFM
E44: CFM | F44: =ROUNDUP(F43,0) -> 638 | G44: CFM
E45: Q (kW) | F45: =F44*0.0002930711 -> 0.18697936 | G45: kW
E46: SHF | F46: =F39/F41 -> 0.97096788
A47: SYMBOLS | E47: KEY | G47: HEATING AND COOLING LOAD CALCULATION
A48: A = Boundary Area | B48: [ft2] | C48: U = Heat Transfer Coefficient | D48: [Btu/ft2/hr/°F] | E48: 1 = Deck Over | F48: 6 = Inboard Bulkhead
A49: qS = Heat Load, Sensible | B49: [Btu/hr] | C49: T = Space Design Temp. | D49: [°F] | E49: 2 = Deck Under | F49: 7 = Lights
A50: qL = Heat Load, Latent | B50: [Btu/hr] | C50: TO = Temperature of | D50: [°F] | E50: 3 = Outboard Bulkhead / Shell | F50: 8 = Equipment
A51: qT = Heat Load, Total | B51: [Btu/hr] | C51: Adjacent Space / Outside | E51: 4 = Forward Bulkhead | F51: 9 = Personnel
A52: qW = Heat Load, Winter | B52: [Btu/hr] | C52: ΔT = Temperature Difference | D52: [°F] | E52: 5 = After Bulkhead
A53: Q = Volumetric Flow Rate | B53: [CFM]
A54: R/C = Rate of Air Change | B54: [CFM]
...

Sheet MEET FISH STORE
A1: SPACE | C1: SPACE NO. | E1: DECK | F1: FRAMES | G1: SPACE TEMP COOLING 40 F | O1: SPACE TEMP HEATING 40 F
A2: MEAT/FISH STORE | C2: 4002 | E2: MAIN DECK
A3: ADJOINING SPACE | B3: LOAD KEY | C3: INSUL TYPE | D3: U KEY | E3: DIMENSION | F3: AREA [ft2] | G3: T | H3: T0 | I3: ΔT | J3: U | L3: QS | M3: QL | N3: QT | O3: T | P3: T0 | Q3: ΔT | R3: U | T3: QW
J4: COEFF | K4: DIR | R4: COEFF | S4: DIR
A5: VEGETABLE STORE | B5: 6 | C5: 6"-150 | D5: H | E5: 2.8 m x 3 m | F5: =10.7639 * (2.8 * 3) -> 90.41676 | G5: 40 | H5: 78 | I5: =H5-G5 -> 38 | J5: 0.063 | K5: =_xlfn.UNICHAR(8596) -> ↔ | L5: =F5*I5*J5 -> 216.45772 | N5: =L5+M5 -> 216.45772 | O5: 40 | P5: 40 | Q5: =P5-O5 -> 0 | R5: 0.1 | S5: =K5 -> ↔ | T5: =F5*Q5*R5 -> 0
A6: VENTILATION DUCT SPACE | B6: 6 | C6: 3"-94 | D6: H | E6: 0.7 m x 3 m + 1.8 m x 3 m | F6: =10.7639 * (0.7*3+1.8*3) -> 80.72925 | G6: 40 | H6: 120 | I6: =H6-G6 -> 80 | J6: 0.158 | K6: =_xlfn.UNICHAR(8596) -> ↔ | L6: =F6*I6*J6 -> 1020.4177 | N6: =L6+M6 -> 1020.4177 | O6: 40 | P6: 40 | Q6: =P6-O6 -> 0 | R6: 0.1 | S6: =K6 -> ↔ | T6: =F6*Q6*R6 -> 0
A7: DRY PROVISION STORE | B7: 6 | C7: 0"-6 | D7: H | E7: 3.6 m x 3 m | F7: =10.7639 *(3.6 * 3) -> 116.25012 | G7: 40 | H7: 78 | I7: =H7-G7 -> 38 | J7: 0.313 | K7: =_xlfn.UNICHAR(8596) -> ↔ | L7: =F7*I7*J7 -> 1382.6789 | N7: =L7+M7 -> 1382.6789 | O7: 40 | P7: 40 | Q7: =P7-O7 -> 0 | R7: 0.1 | S7: =K7 -> ↔ | T7: =F7*Q7*R7 -> 0
A8: ENGINE ROOM | B8: 6 | C8: 3"-94 | D8: H | E8: 2.4 m x 3 m | F8: =10.7639 * (2.4 * 3) -> 77.50008 | G8: 40 | H8: 130 | I8: =H8-G8 -> 90 | J8: 0.158 | K8: =_xlfn.UNICHAR(8596) -> ↔ | L8: =F8*I8*J8 -> 1102.0511 | N8: =L8+M8 -> 1102.0511 | O8: 40 | P8: 40 | Q8: =P8-O8 -> 0 | R8: 0.1 | S8: =K8 -> ↔ | T8: =F8*Q8*R8 -> 0
A9: WC | B9: 6 | C9: 0"-6 | D9: H | E9: 2.1 m x 3 m | F9: =10.7639 * (2.1*3) -> 67.81257 | G9: 40 | H9: 85 | I9: =H9-G9 -> 45 | J9: 0.313 | K9: =_xlfn.UNICHAR(8596) -> ↔ | L9: =F9*I9*J9 -> 955.14005 | N9: =L9+M9 -> 955.14005 | O9: 40 | P9: 40 | Q9: =P9-O9 -> 0 | R9: 0.1 | S9: =K9 -> ↔ | T9: =F9*Q9*R9 -> 0
A10: NO. 3 HFO STORE TANK | B10: 2 | C10: 3"-94 | D10: H | E10: 2.4 m x 0.7 m + 4.2 m x 2.1 m | F10: =10.7639 * (10.5) -> 113.02095 | G10: 40 | H10: 120 | I10: =H10-G10 -> 80 | J10: 0.158 | K10: =_xlfn.UNICHAR(8595) -> ↓ | L10: =F10*I10*J10 -> 1428.5848 | N10: =L10+M10 -> 1428.5848 | O10: 40 | P10: 40 | Q10: =P10-O10 -> 0 | R10: 0.1 | S10: =K10 -> ↓ | T10: =F10*Q10*R10 -> 0
A11: OUTDOOR SPACE | B11: 1 | C11: 0"-6 | D11: H | E11: 1.4 m x 4.2 m | F11: =10.7639 * (1.4*4.2) -> 63.291732 | G11: 40 | H11: 95 | I11: =H11-G11 -> 55 | J11: 0.313 | K11: =_xlfn.UNICHAR(8593) -> ↑ | L11: =F11*I11*J11 -> 1089.5672 | N11: =L11+M11 -> 1089.5672 | O11: 40 | P11: 40 | Q11: =P11-O11 -> 0 | R11: 0.1 | S11: =K11 -> ↑ | T11: =F11*Q11*R11 -> 0
A12: SAFETY EQUIPMENT STATION | B12: 1 | C12: 3"-94 | D12: D | E12: 1.4 m x 4.2 m | F12: =10.7639 * (1.4*4.2) -> 63.291732 | G12: 40 | H12: 110 | I12: =H12-G12 -> 70 | J12: 0.144 | K12: =_xlfn.UNICHAR(8593) -> ↑ | L12: =F12*I12*J12 -> 637.98066 | N12: =L12+M12 -> 637.98066 | O12: 40 | P12: 40 | Q12: =P12-O12 -> 0 | R12: 0.1 | S12: =K12 -> ↑ | T12: =F12*Q12*R12 -> 0
A13: VENTILATION SPACE | B13: 1 | C13: 3"-94 | D13: D | E13: 1.8 m x 0.7 m | F13: =10.7639 * (1.8 * 0.7) -> 13.562514 | G13: 40 | H13: 120 | I13: =H13-G13 -> 80 | J13: 0.144 | K13: =_xlfn.UNICHAR(8593) -> ↑ | L13: =F13*I13*J13 -> 156.24016 | N13: =L13+M13 -> 156.24016 | O13: 40 | P13: 40 | Q13: =P13-O13 -> 0 | R13: 0.1 | S13: =K13 -> ↑ | T13: =F13*Q13*R13 -> 0
A20: TRANSMISSION SUBTOTAL | N20: =SUM(N5:N13) -> 7989.1184 | T20: =SUM(T5:T13) -> 0
A21: LIGHTS | B21: 7 | F21: =F10 -> 113.02095 | L21: =F21*4 -> 452.0838 | N21: =L21+M21 -> 452.0838
A22: EQUIPMENT | B22: 8
A23: PERSONNEL | B23: 9 | L23: =1*315 -> 315 | M23: =1*485 -> 485 | N23: =L23+M23 -> 800
A24: TOTAL HEAT | N24: =SUM(N20:N23) -> 9241.2022 | T24: =SUM(T20:T23) -> 0
A25: TOTAL HEAT | G25: =N24+T24 -> 9241.2022
E33: ΔT = | F33: 25 | G33: °F
E34: OCCUPANCY | F34: =15*1 -> 15
E35: Sq. ft. | F35: =$F$21 -> 113.02095 | G35: sq. ft
E36: HEIGHT | F36: =3.28084 * 2.7 -> 8.858268 | G36: ft
E37: VOLUME | F37: =F35*F36 -> 1001.1699 | G37: cb. ft
E38: R of C | F38: =F37/30 -> 33.372329 | G38: CFM
E39: qS TOTAL | F39: =SUM($L$5:$L$28) -> 8756.2022 | G39: Btu/hr
E40: qL TOTAL | F40: =SUM($M$5:$M$28) -> 485 | G40: Btu/hr
E41: qT TOTAL | F41: =$N$24 -> 9241.2022 | G41: Btu/hr
E42: qW TOTAL | F42: =$T$29 -> 0 | G42: Btu/hr
E43: Q | F43: =F39/(1.08*F33) -> 324.30378 | G43: CFM
E44: CFM | F44: =ROUNDUP(F43,0) -> 325 | G44: CFM
E45: Q (kW) | F45: =F44*0.0002930711 -> 0.095248107 | G45: kW
E46: SHF | F46: =F39/F41 -> 0.94751765
A47: SYMBOLS | E47: KEY | G47: HEATING AND COOLING LOAD CALCULATION
A48: A = Boundary Area | B48: [ft2] | C48: U = Heat Transfer Coefficient | D48: [Btu/ft2/hr/°F] | E48: 1 = Deck Over | F48: 6 = Inboard Bulkhead
A49: qS = Heat Load, Sensible | B49: [Btu/hr] | C49: T = Space Design Temp. | D49: [°F] | E49: 2 = Deck Under | F49: 7 = Lights
A50: qL = Heat Load, Latent | B50: [Btu/hr] | C50: TO = Temperature of | D50: [°F] | E50: 3 = Outboard Bulkhead / Shell | F50: 8 = Equipment
A51: qT = Heat Load, Total | B51: [Btu/hr] | C51: Adjacent Space / Outside | E51: 4 = Forward Bulkhead | F51: 9 = Personnel
A52: qW = Heat Load, Winter | B52: [Btu/hr] | C52: ΔT = Temperature Difference | D52: [°F] | E52: 5 = After Bulkhead
A53: Q = Volumetric Flow Rate | B53: [CFM]
...

Sheet DRY PROVISION STORE
A1: SPACE | C1: SPACE NO. | E1: DECK | F1: FRAMES | G1: SPACE TEMP COOLING 78 °F | O1: SPACE TEMP HEATING 70 °F
A2: DRY PROVIISION STORE | C2: 4003 | E2: MAIN DECK | F2: -9 ~ 13
A3: ADJOINING SPACE | B3: LOAD KEY | C3: INSUL TYPE | D3: U KEY | E3: DIMENSION | F3: AREA [ft2] | G3: T | H3: T0 | I3: ΔT | J3: U | L3: QS | M3: QL | N3: QT | O3: T | P3: T0 | Q3: ΔT | R3: U | T3: QW
J4: COEFF | K4: DIR | R4: COEFF | S4: DIR
A5: PASSAGEWAY | B5: 6 | C5: 3"-94 | D5: H | E5: 1.1 m x 3 m | F5: =10.7639 *(11.1*3.34) -> 399.06083 | G5: 78 | H5: 105 | I5: =H5-G5 -> 27 | J5: 0.158 | K5: =_xlfn.UNICHAR(8596) -> ↔ | L5: =F5*I5*J5 -> 1702.3935 | N5: =L5+M5 -> 1702.3935 | O5: 70 | P5: 70 | Q5: =O5-P5 -> 0 | R5: =J5 -> 0.158 | S5: =K5 -> ↔ | T5: =F5*Q5*R5 -> 0
A6: LINEN ROOM | B6: 6 | C6: 3"-94 | D6: H | E6: 2.3776 m x 3 m | F6: =10.7639 *(5.9*3.34) -> 212.11341 | G6: 78 | H6: 105 | I6: =H6-G6 -> 27 | J6: 0.158 | K6: =_xlfn.UNICHAR(8596) -> ↔ | L6: =F6*I6*J6 -> 904.87582 | N6: =L6+M6 -> 904.87582 | O6: 70 | P6: 70 | Q6: =O6-P6 -> 0 | R6: =J6 -> 0.158 | S6: =K6 -> ↔ | T6: =F6*Q6*R6 -> 0
A7: ENGINE CHANGE ROOM | B7: 6 | C7: 3"-94 | D7: H | E7: 1.6 m x 3 m | F7: =10.7639 *((4.9+3.1)*3.34) -> 287.61141 | G7: 78 | H7: 105 | I7: =H7-G7 -> 27 | J7: 0.158 | K7: =_xlfn.UNICHAR(8596) -> ↔ | L7: =F7*I7*J7 -> 1226.9503 | N7: =L7+M7 -> 1226.9503 | O7: 70 | P7: 70 | Q7: =O7-P7 -> 0 | R7: =J7 -> 0.158 | S7: =K7 -> ↔ | T7: =F7*Q7*R7 -> 0
A8: WC | B8: 6 | C8: 3"-94 | D8: H | E8: 1.6 m x 3 m | F8: =10.7639 *(2.1*3.34) -> 75.497995 | G8: 78 | H8: 85 | I8: =H8-G8 -> 7 | J8: 0.158 | K8: =_xlfn.UNICHAR(8596) -> ↔ | L8: =F8*I8*J8 -> 83.500782 | N8: =L8+M8 -> 83.500782 | O8: 70 | P8: 70 | Q8: =O8-P8 -> 0 | R8: =J8 -> 0.158 | S8: =K8 -> ↔ | T8: =F8*Q8*R8 -> 0
A9: MEAT/FISH STORE | B9: 6 | C9: 0"-6 | D9: H | E9: 3.8 m x 3 m | F9: =10.7639 *(1*3.34) -> 35.951426 | G9: 78 | H9: 78 | I9: =H9-G9 -> 0 | J9: 0.313 | K9: =_xlfn.UNICHAR(8596) -> ↔ | L9: =F9*I9*J9 -> 0 | N9: =L9+M9 -> 0 | O9: 70 | P9: 70 | Q9: =O9-P9 -> 0 | R9: =J9 -> 0.313 | S9: =K9 -> ↔ | T9: =F9*Q9*R9 -> 0
A10: VEGETABLE STORE | B10: 6 | C10: 0"-6 | D10: H | F10: 0 | G10: 78 | H10: 78 | I10: =H10-G10 -> 0 | J10: 0.313 | K10: =_xlfn.UNICHAR(8596) -> ↔ | L10: =F10*I10*J10 -> 0 | N10: =L10+M10 -> 0 | O10: 70 | P10: 70 | Q10: =O10-P10 -> 0 | R10: =J10 -> 0.313 | S10: =K10 -> ↔ | T10: =F10*Q10*R10 -> 0
A11: OUTDOOR SPACE | B11: 3 | C11: 3"-94 | D11: H | E11: (3.052 m + 14.5 m) x 3 m | F11: =10.7639 *((1.3*1)+(2.2*1)) -> 37.67365 | G11: 78 | H11: 95 | I11: =H11-G11 -> 17 | J11: 0.158 | K11: =_xlfn.UNICHAR(8596) -> ↔ | L11: =F11*I11*J11 -> 101.19142 | N11: =L11+M11 -> 101.19142 | O11: 70 | P11: 70 | Q11: =O11-P11 -> 0 | R11: =J11 -> 0.158 | S11: =K11 -> ↔ | T11: =F11*Q11*R11 -> 0
A12: OUTDOOR SPACE | B12: 1 | C12: 0"-0 | D12: U | F12: =10.7639 *(52.6492-4.3704) -> 519.66818 | G12: 78 | H12: 95 | I12: =H12-G12 -> 17 | J12: 1.491 | K12: =_xlfn.UNICHAR(8593) -> ↑ | L12: =F12*I12*J12 -> 13172.029 | N12: =L12+M12 -> 13172.029 | O12: 70 | P12: 70 | Q12: =O12-P12 -> 0 | R12: =J12 -> 1.491 | S12: =K12 -> ↑ | T12: =F12*Q12*R12 -> 0
A13: VOID COFFERDAM | B13: 2 | C13: 0"-0 | D13: D | F13: =10.7639 *(5.9247) -> 63.772878 | G13: 78 | H13: 120 | I13: =H13-G13 -> 42 | J13: 0.801 | K13: =_xlfn.UNICHAR(8595) -> ↓ | L13: =F13*I13*J13 -> 2145.4472 | N13: =L13+M13 -> 2145.4472 | O13: 70 | P13: 70 | Q13: =O13-P13 -> 0 | R13: =J13 -> 0.801 | S13: =K13 -> ↓ | T13: =F13*Q13*R13 -> 0
A14: NO. 3 HFO STORAGE TANK (S) | B14: 2 | C14: 0"-0 | D14: D | F14: =10.7639 *(19.2478) -> 207.18139 | G14: 78 | H14: 120 | I14: =H14-G14 -> 42 | J14: 0.801 | K14: =_xlfn.UNICHAR(8595) -> ↓ | L14: =F14*I14*J14 -> 6969.9965 | N14: =L14+M14 -> 6969.9965 | O14: 70 | P14: 70 | Q14: =O14-P14 -> 0 | R14: =J14 -> 0.801 | S14: =K14 -> ↓ | T14: =F14*Q14*R14 -> 0
A15: TECHNICAL FW TANK | B15: 2 | C15: 0"-0 | D15: D | F15: =10.7639 *(23.0567) -> 248.18001 | G15: 78 | H15: 120 | I15: =H15-G15 -> 42 | J15: 0.801 | K15: =_xlfn.UNICHAR(8595) -> ↓ | L15: =F15*I15*J15 -> 8349.272 | N15: =L15+M15 -> 8349.272 | O15: 70 | P15: 70 | Q15: =O15-P15 -> 0 | R15: =J15 -> 0.801 | S15: =K15 -> ↓ | T15: =F15*Q15*R15 -> 0
A19: TRANSMISSION SUBTOTAL | N19: =SUM(N5:N18) -> 34655.657 | T19: =SUM(T5:T18) -> 0
A20: WINDOW | F20: =(10.7639 * (0.6*0.5))*0 -> 0 | L20: =F20*160 -> 0 | N20: =L20 -> 0
A21: LIGHTS | B21: 7 | F21: =10.7639 *(52.6492-4.3704) -> 519.66818 | L21: =F21*12 -> 6236.0181 | N21: =L21+M21 -> 6236.0181
A26: PERSONNEL | B26: 9 | L26: =1*315 -> 315 | M26: =1*485 -> 485 | N26: =L26+M26 -> 800
A27: INFILTRATION
A29: TOTAL HEAT | N29: =SUM(N19:N28) -> 41691.675 | T29: =SUM(T19:T28) -> 0
A30: TOTAL HEAT | G30: =N29+T29 -> 41691.675
E33: ΔT = | F33: 25 | G33: °F
E34: OCCUPANCY | F34: =15*1 -> 15
E35: Sq. ft. | F35: =$F$21 -> 519.66818 | G35: sq. ft
E36: HEIGHT | F36: =3.28084 * 2.7 -> 8.858268 | G36: ft
E37: VOLUME | F37: =F35*F36 -> 4603.36 | G37: cb. ft
E38: R of C | F38: =F37/30 -> 153.44533 | G38: CFM
E39: qS TOTAL | F39: =SUM($L$5:$L$28) -> 41206.675 | G39: Btu/hr
E40: qL TOTAL | F40: =SUM($M$5:$M$28) -> 485 | G40: Btu/hr
E41: qT TOTAL | F41: =$N$29 -> 41691.675 | G41: Btu/hr
E42: qW TOTAL | F42: =$T$29 -> 0 | G42: Btu/hr
E43: Q | F43: =F39/(1.08*F33) -> 1526.1731 | G43: CFM
E44: CFM | F44: =ROUNDUP(F43,0) -> 1527 | G44: CFM
E45: Q (kW) | F45: =F44*0.0002930711 -> 0.44751957 | G45: kW
E46: SHF | F46: =F39/F41 -> 0.98836698
A47: SYMBOLS | E47: KEY | G47: HEATING AND COOLING LOAD CALCULATION
A48: A = Boundary Area | B48: [ft2] | C48: U = Heat Transfer Coefficient | D48: [Btu/ft2/hr/°F] | E48: 1 = Deck Over | F48: 6 = Inboard Bulkhead
A49: qS = Heat Load, Sensible | B49: [Btu/hr] | C49: T = Space Design Temp. | D49: [°F] | E49: 2 = Deck Under | F49: 7 = Lights
A50: qL = Heat Load, Latent | B50: [Btu/hr] | C50: TO = Temperature of | D50: [°F] | E50: 3 = Outboard Bulkhead / Shell | F50: 8 = Equipment
...

Sheet ENGINE CONTROL ROOM
A1: SPACE | C1: SPACE NO. | E1: DECK | F1: FRAMES | G1: SPACE TEMP COOLING 78 °F | O1: SPACE TEMP HEATING 70 °F
A2: ENGINE CONTROL ROOM | C2: 4004 | E2: MAIN DECK | F2: 20 ~ 23
A3: ADJOINING SPACE | B3: LOAD KEY | C3: INSUL TYPE | D3: U KEY | E3: DIMENSION | F3: AREA [ft2] | G3: T | H3: T0 | I3: ΔT | J3: U | L3: QS | M3: QL | N3: QT | O3: T | P3: T0 | Q3: ΔT | R3: U | T3: QW
J4: COEFF | K4: DIR | R4: COEFF | S4: DIR
A5: COFFERDAM | B5: 3 | C5: 4"-129 | D5: H | E5: 11.1 m x 3 m | F5: =10.7639 *(11.1*3.34) -> 399.06083 | G5: 78 | H5: 120 | I5: =H5-G5 -> 42 | J5: 0.063 | K5: =_xlfn.UNICHAR(8596) -> ↔ | L5: =F5*I5*J5 -> 1055.915 | N5: =L5+M5 -> 1055.915 | O5: 70 | P5: 70 | Q5: =O5-P5 -> 0 | R5: =J5 -> 0.063 | S5: =K5 -> ↔ | T5: =F5*Q5*R5 -> 0
A6: VALVE CONTROL UNIT ROOM | B6: 6 | C6: 3"-94 | D6: H | E6: 5.9 m x 3 m | F6: =10.7639 *(5.9*3.34) -> 212.11341 | G6: 78 | H6: 110 | I6: =H6-G6 -> 32 | J6: 0.158 | K6: =_xlfn.UNICHAR(8596) -> ↔ | L6: =F6*I6*J6 -> 1072.4454 | N6: =L6+M6 -> 1072.4454 | O6: 70 | P6: 70 | Q6: =O6-P6 -> 0 | R6: =J6 -> 0.158 | S6: =K6 -> ↔ | T6: =F6*Q6*R6 -> 0
A7: ENGINE ROOM | B7: 6 | C7: 3"-94 | D7: H | E7: (4.9 m + 3.1 m) x 3 m | F7: =10.7639 *((4.9+3.1)*3.34) -> 287.61141 | G7: 78 | H7: 130 | I7: =H7-G7 -> 52 | J7: 0.158 | K7: =_xlfn.UNICHAR(8596) -> ↔ | L7: =F7*I7*J7 -> 2363.0153 | N7: =L7+M7 -> 2363.0153 | O7: 70 | P7: 70 | Q7: =O7-P7 -> 0 | R7: =J7 -> 0.158 | S7: =K7 -> ↔ | T7: =F7*Q7*R7 -> 0
A8: STAIRWAY | B8: 6 | C8: 3"-94 | D8: H | E8: 2.1 m x 3 m | F8: =10.7639 *(2.1*3.34) -> 75.497995 | G8: 78 | H8: 105 | I8: =H8-G8 -> 27 | J8: 0.171 | K8: =_xlfn.UNICHAR(8593) -> ↑ | L8: =F8*I8*J8 -> 348.57424 | N8: =L8+M8 -> 348.57424 | O8: 70 | P8: 70 | Q8: =O8-P8 -> 0 | R8: =J8 -> 0.171 | S8: =K8 -> ↑ | T8: =F8*Q8*R8 -> 0
A9: SERVICE DUCT TRUNK | B9: 6 | C9: 3"-94 | D9: H | E9: 1 m x 3 m | F9: =10.7639 *(1*3.34) -> 35.951426 | G9: 78 | H9: 120 | I9: =H9-G9 -> 42 | J9: 0.144 | K9: =_xlfn.UNICHAR(8595) -> ↓ | L9: =F9*I9*J9 -> 217.43422 | N9: =L9+M9 -> 217.43422 | O9: 70 | P9: 70 | Q9: =O9-P9 -> 0 | R9: =J9 -> 0.144 | S9: =K9 -> ↓ | T9: =F9*Q9*R9 -> 0
A10: FIRE/FOAM STATION | B10: 6 | C10: 3"-94 | D10: H | E10: 5.9 m x 3 m | F10: =10.7639 *(5.9*3.34) -> 212.11341 | G10: 78 | H10: 110 | I10: =H10-G10 -> 32 | J10: 0.144 | K10: =_xlfn.UNICHAR(8595) -> ↓ | L10: =F10*I10*J10 -> 977.41861 | N10: =L10+M10 -> 977.41861 | O10: 70 | P10: 70 | Q10: =O10-P10 -> 0 | R10: =J10 -> 0.144 | S10: =K10 -> ↓ | T10: =F10*Q10*R10 -> 0
A11: PASSAGE WAY | B11: 1 | C11: 3"-94 | D11: U | E11: (1.3 m x 1 m) + (2.2 m * 1 m) | F11: =10.7639 *((1.3*1)+(2.2*1)) -> 37.67365 | G11: 78 | H11: 80 | I11: =H11-G11 -> 2 | J11: 0.144 | K11: =_xlfn.UNICHAR(8595) -> ↓ | L11: =F11*I11*J11 -> 10.850011 | N11: =L11+M11 -> 10.850011 | O11: 70 | P11: 70 | Q11: =O11-P11 -> 0 | R11: =J11 -> 0.144 | S11: =K11 -> ↓ | T11: =F11*Q11*R11 -> 0
A12: ENGINE ROOM | B12: 2 | C12: 3"-94 | D12: D | E12: 5.9 m x 6.45 m | F12: =10.7639 *(5.9*6.45) - (F14+F15+F16) -> 227.92558 | G12: 78 | H12: 130 | I12: =H12-G12 -> 52 | J12: 0.144 | K12: =_xlfn.UNICHAR(8595) -> ↓ | L12: =F12*I12*J12 -> 1706.7068 | N12: =L12+M12 -> 1706.7068 | O12: 70 | P12: 70 | Q12: =O12-P12 -> 0 | R12: =J12 -> 0.144 | S12: =K12 -> ↓ | T12: =F12*Q12*R12 -> 0
A13: HYDRAULIC AGREGATES ROOM | B13: 2 | C13: 0"-0 | D13: D | E13: 5.9 m x 4.65 m | F13: =10.7639 *(5.9*4.65) -> 295.3076 | G13: 78 | H13: 110 | I13: =H13-G13 -> 32 | J13: 0.801 | K13: =_xlfn.UNICHAR(8595) -> ↓ | L13: =F13*I13*J13 -> 7569.3243 | N13: =L13+M13 -> 7569.3243 | O13: 70 | P13: 70 | Q13: =O13-P13 -> 0 | R13: =J13 -> 0.801 | S13: =K13 -> ↓ | T13: =F13*Q13*R13 -> 0
A14: G/E LO STORAGE TANK | B14: 2 | C14: 0"-0 | D14: D | E14: 2.4 m x 2.3 m | F14: =10.7639 *(2.4*2.3) -> 59.416728 | G14: 78 | H14: 120 | I14: =H14-G14 -> 42 | J14: 0.801 | K14: =_xlfn.UNICHAR(8595) -> ↓ | L14: =F14*I14*J14 -> 1998.8976 | N14: =L14+M14 -> 1998.8976 | O14: 70 | P14: 70 | Q14: =O14-P14 -> 0 | R14: =J14 -> 0.801 | S14: =K14 -> ↓ | T14: =F14*Q14*R14 -> 0
A15: MGO SERVICE TANK | B15: 2 | C15: 0"-0 | D15: D | E15: 2.1 m x 3.2 m | F15: =10.7639 *(2.1*3.2) -> 72.333408 | G15: 78 | H15: 120 | I15: =H15-G15 -> 42 | J15: 0.801 | K15: =_xlfn.UNICHAR(8595) -> ↓ | L15: =F15*I15*J15 -> 2433.4405 | N15: =L15+M15 -> 2433.4405 | O15: 70 | P15: 70 | Q15: =O15-P15 -> 0 | R15: =J15 -> 0.801 | S15: =K15 -> ↓ | T15: =F15*Q15*R15 -> 0
A16: MGO SETTLING TANK | B16: 2 | C16: 0"-0 | D16: D | E16: 1.45 m x 3.2 m | F16: =10.7639 *(1.45*3.2) -> 49.944496 | G16: 78 | H16: 120 | I16: =H16-G16 -> 42 | J16: 0.801 | K16: =_xlfn.UNICHAR(8595) -> ↓ | L16: =F16*I16*J16 -> 1680.2327 | N16: =L16+M16 -> 1680.2327 | O16: 70 | P16: 70 | Q16: =O16-P16 -> 0 | R16: =J16 -> 0.801 | S16: =K16 -> ↓ | T16: =F16*Q16*R16 -> 0
A19: TRANSMISSION SUBTOTAL | N19: =SUM(N5:N18) -> 21434.255 | T19: =SUM(T5:T18) -> 0
A20: WINDOW | F20: =(10.7639 * (0.6*0.5))*0 -> 0 | L20: =F20*160 -> 0 | N20: =L20 -> 0
A21: LIGHTS | B21: 7 | F21: =10.7639 *(5.9 * 11.1) -> 704.92781 | L21: =F21*12 -> 8459.1337 | N21: =L21+M21 -> 8459.1337
A22: EQUIPMENT: Control Panels | B22: 8 | L22: =3.412 * 400 * 8 * 0.9 -> 9826.56 | N22: =L22+M22 -> 9826.56
A23: EQUIPMENT: Computer Consoles | B23: 8 | L23: =3.412 * 300 * 2 * 0.95 -> 1944.84 | N23: =L23+M23 -> 1944.84
A24: EQUIPMENT: UCS System | B24: 8 | L24: =3.412 * 1200 * 1 * 0.9 -> 3684.96 | N24: =L24+M24 -> 3684.96
A25: EQUIPMENT: Communication Equipment | B25: 8 | L25: =3.412 * 200 * 1 * 0.9 -> 614.16 | N25: =L25+M25 -> 614.16
A26: PERSONNEL | B26: 9 | L26: =3*315 -> 945 | M26: =3*485 -> 1455 | N26: =L26+M26 -> 2400
A27: INFILTRATION
A29: TOTAL HEAT | N29: =SUM(N19:N28) -> 48363.908 | T29: =SUM(T19:T28) -> 0
A30: TOTAL HEAT | G30: =N29+T29 -> 48363.908
E33: ΔT = | F33: 25 | G33: °F
E34: OCCUPANCY | F34: =15*1 -> 15
E35: Sq. ft. | F35: =$F$21 -> 704.92781 | G35: sq. ft
E36: HEIGHT | F36: =3.28084 * 2.7 -> 8.858268 | G36: ft
E37: VOLUME | F37: =F35*F36 -> 6244.4395 | G37: cb. ft
E38: R of C | F38: =F37/30 -> 208.14798 | G38: CFM
E39: qS TOTAL | F39: =SUM($L$5:$L$28) -> 46908.908 | G39: Btu/hr
E40: qL TOTAL | F40: =SUM($M$5:$M$28) -> 1455 | G40: Btu/hr
E41: qT TOTAL | F41: =$N$29 -> 48363.908 | G41: Btu/hr
E42: qW TOTAL | F42: =$T$29 -> 0 | G42: Btu/hr
E43: Q | F43: =F39/(1.08*F33) -> 1737.367 | G43: CFM
E44: CFM | F44: =ROUNDUP(F43,0) -> 1738 | G44: CFM
E45: Q (kW) | F45: =F44*0.0002930711 -> 0.50935757 | G45: kW
...

Sheet GALLEY
A1: SPACE | C1: SPACE NO. | E1: DECK | F1: FRAMES | G1: SPACE TEMP COOLING 78 °F | O1: SPACE TEMP HEATING 70 °F
A2: GALLEY | C2: 5001 | E2: POOP DECK | F2: 16 ~ 24
A3: ADJOINING SPACE | B3: LOAD KEY | C3: INSUL TYPE | D3: U KEY | E3: DIMENSION | F3: AREA [ft2] | G3: T | H3: T0 | I3: ΔT | J3: U | L3: QS | M3: QL | N3: QT | O3: T | P3: T0 | Q3: ΔT | R3: U | T3: QW
J4: COEFF | K4: DIR | R4: COEFF | S4: DIR
A5: OUTDOOR SPACE | B5: 3 | C5: 4"-129 | D5: H | E5: 3 m x 2.7 m + 4.2 m x 2.7 m | F5: =10.7639 * (3*2.7 + 4.2*2.7) -> 209.25022 | G5: 78 | H5: 95 | I5: =H5-G5 -> 17 | J5: 0.063 | K5: =_xlfn.UNICHAR(8596) -> ↔ | L5: =F5*I5*J5 -> 224.10698 | N5: =L5+M5 -> 224.10698 | O5: 70 | P5: 70 | Q5: =O5-P5 -> 0 | T5: =F5*Q5*R5 -> 0
A6: STORE | B6: 6 | C6: 3"-94 | D6: H | E6: 1.2 m x 2.7 m + 0.8 m x 2.7 m | F6: =10.7639 *1.2*2.7 -> 34.875036 | G6: 78 | H6: 78 | I6: =H6-G6 -> 0 | J6: 0.158 | K6: =_xlfn.UNICHAR(8596) -> ↔ | L6: =F6*I6*J6 -> 0 | N6: =L6+M6 -> 0 | O6: 70 | P6: 70 | Q6: =O6-P6 -> 0 | T6: =F6*Q6*R6 -> 0
A7: DECK CHANGE ROOM | B7: 6 | C7: 3"-94 | D7: H | E7: 2.6 m x 2.7 m | F7: =10.7639 *2.6*2.7 -> 75.562578 | G7: 78 | H7: 78 | I7: =H7-G7 -> 0 | J7: 0.158 | K7: =_xlfn.UNICHAR(8596) -> ↔ | L7: =F7*I7*J7 -> 0 | N7: =L7+M7 -> 0 | O7: 70 | P7: 70 | Q7: =O7-P7 -> 0 | T7: =F7*Q7*R7 -> 0
A8: PANTRY | B8: 6 | C8: 3"-94 | D8: H | E8: 5 m x 2.7 m | F8: =10.7639 * (5*2.7) -> 145.31265 | G8: 78 | H8: 105 | I8: =H8-G8 -> 27 | J8: 0.158 | K8: =_xlfn.UNICHAR(8596) -> ↔ | L8: =F8*I8*J8 -> 619.90376 | N8: =L8+M8 -> 619.90376 | O8: 70 | P8: 70 | Q8: =O8-P8 -> 0 | T8: =F8*Q8*R8 -> 0
A9: ESCAPE TRUNK | B9: 6 | C9: 0"-6 | D9: H | E9: 0.8 m x 2.7 m | F9: =10.7639 * (0.8*2.7) -> 23.250024 | G9: 78 | H9: 120 | I9: =H9-G9 -> 42 | J9: 0.313 | K9: =_xlfn.UNICHAR(8596) -> ↔ | L9: =F9*I9*J9 -> 305.64482 | N9: =L9+M9 -> 305.64482 | O9: 70 | P9: 70 | Q9: =O9-P9 -> 0 | T9: =F9*Q9*R9 -> 0
A10: STAIRWAY | B10: 6 | C10: 3"-94 | D10: H | E10: 1.2 m x 2.7 m + 1.2 m x 2.7 m | F10: =10.7639 * (1.2*2.7 + 1.2*2.7) -> 69.750072 | G10: 78 | H10: 80 | I10: =H10-G10 -> 2 | J10: 0.158 | K10: =_xlfn.UNICHAR(8596) -> ↔ | L10: =F10*I10*J10 -> 22.041023 | N10: =L10+M10 -> 22.041023 | O10: 70 | P10: 70 | Q10: =O10-P10 -> 0 | T10: =F10*Q10*R10 -> 0
A11: VENTILATION TRUNK | B11: 6 | C11: 0"-6 | D11: H | E11: 0.8 m x 2.7 m | F11: =10.7639 * (0.8*2.7) -> 23.250024 | G11: 78 | H11: 120 | I11: =H11-G11 -> 42 | J11: 0.313 | K11: =_xlfn.UNICHAR(8596) -> ↔ | L11: =F11*I11*J11 -> 305.64482 | N11: =L11+M11 -> 305.64482 | O11: 70 | P11: 70 | Q11: =O11-P11 -> 0 | T11: =F11*Q11*R11 -> 0
A12: ENGINE ROOM | B12: 2 | C12: 3"-94 | D12: D | F12: =10.7639 * (24.32) -> 261.77805 | G12: 78 | H12: 130 | I12: =H12-G12 -> 52 | J12: 0.144 | K12: =_xlfn.UNICHAR(8595) -> ↓ | L12: =F12*I12*J12 -> 1960.194 | N12: =L12+M12 -> 1960.194 | O12: 70 | P12: 70 | Q12: =O12-P12 -> 0 | T12: =F12*Q12*R12 -> 0
A13: STAIRWAY | B13: 2 | C13: 3"-94 | D13: D | E13: 3 m x 1.2 m | F13: =10.7639 * (3*1.2) -> 38.75004 | G13: 78 | H13: 80 | I13: =H13-G13 -> 2 | J13: 0.144 | K13: =_xlfn.UNICHAR(8595) -> ↓ | L13: =F13*I13*J13 -> 11.160012 | N13: =L13+M13 -> 11.160012 | O13: 70 | P13: 70 | Q13: =O13-P13 -> 0 | T13: =F13*Q13*R13 -> 0
A14: CO2 ROOM | B14: 1 | C14: 3"-94 | D14: U | F14: =10.7639 * (10.08) -> 108.50011 | G14: 78 | H14: 110 | I14: =H14-G14 -> 32 | J14: 0.171 | K14: =_xlfn.UNICHAR(8593) -> ↑ | L14: =F14*I14*J14 -> 593.71261 | N14: =L14+M14 -> 593.71261 | O14: 70 | P14: 70 | Q14: =O14-P14 -> 0 | T14: =F14*Q14*R14 -> 0
A15: HOSPITAL | B15: 1 | C15: 3"-94 | D15: U | F15: =10.7639 * (13.64) -> 146.8196 | G15: 78 | H15: 78 | I15: =H15-G15 -> 0 | J15: 0.171 | K15: =_xlfn.UNICHAR(8593) -> ↑ | L15: =F15*I15*J15 -> 0 | N15: =L15+M15 -> 0 | O15: 70 | P15: 70 | Q15: =O15-P15 -> 0 | T15: =F15*Q15*R15 -> 0
A16: PASSAGEWAY | B16: 6 | C16: 3"-94 | D16: H | E16: 1 m x 2.7 m | F16: =10.7639 * (1*2.7) -> 29.06253 | G16: 78 | H16: 80 | I16: =H16-G16 -> 2 | J16: 0.158 | K16: =_xlfn.UNICHAR(8596) -> ↔ | L16: =F16*I16*J16 -> 9.1837595 | N16: =L16+M16 -> 9.1837595 | O16: 70 | P16: 70 | Q16: =O16-P16 -> 0 | T16: =F16*Q16*R16 -> 0
A17: PASSAGEWAY | B17: 1 | C17: 3"-94 | D17: U | E17: 0.6 m x 1 m | F17: =10.7639 * (0.6*1) -> 6.45834 | G17: 78 | H17: 80 | I17: =H17-G17 -> 2 | J17: 0.171 | K17: =_xlfn.UNICHAR(8593) -> ↑ | L17: =F17*I17*J17 -> 2.2087523 | N17: =L17+M17 -> 2.2087523 | O17: 70 | P17: 70 | Q17: =O17-P17 -> 0 | T17: =F17*Q17*R17 -> 0
A19: TRANSMISSION SUBTOTAL | N19: =SUM(N5:N17) -> 4053.8006 | T19: =SUM(T5:T17) -> 0
A20: WINDOW | F20: =(10.7639 * (0.6*0.5))*4 -> 12.91668 | L20: =F20*160 -> 2066.6688 | N20: =L20+M20 -> 2066.6688
A21: LIGHTS | B21: 7 | F21: =10.7639 * 27.92 -> 300.52809 | L21: =4*F21 -> 1202.1124 | N21: =L21+M21 -> 1202.1124
A22: EQUIPMENT: Convection Oven, Electric | B22: 8 | L22: 13500 | M22: 6900 | N22: =L22+M22 -> 20400
A23: EQUIPMENT: Griddle, Electric | B23: 8 | L23: 13500 | M23: 6900 | N23: =L23+M23 -> 20400
A24: EQUIPMENT: Mixer, Electric | B24: 8 | L24: 1120 | M24: 580 | N24: =L24+M24 -> 1700
A25: EQUIPMENT: Refrigerator (up to 20 cu.ft.) | B25: 8 | L25: 1300 | N25: =L25+M25 -> 1300
A26: FOOD | B26: 8 | L26: =30*21 -> 630 | M26: =30*21 -> 630 | N26: =L26+M26 -> 1260
A27: PERSONNEL | B27: 9 | L27: =2*315 -> 630 | M27: =2*485 -> 970 | N27: =L27+M27 -> 1600
A29: TOTAL HEAT | N29: =SUM(N19:N28) -> 53982.582 | T29: =SUM(T19:T28) -> 0
A30: TOTAL HEAT | G30: =N29+T29 -> 53982.582
E33: ΔT = | F33: 25 | G33: °F
E34: OCCUPANCY | F34: =15*1 -> 15
E35: Sq. ft. | F35: =$F$21 -> 300.52809 | G35: sq. ft
E36: HEIGHT | F36: =3.28084 * 2.7 -> 8.858268 | G36: ft
E37: VOLUME | F37: =F35*F36 -> 2662.1583 | G37: cb. ft
E38: R of C | F38: =F37/30 -> 88.738612 | G38: CFM
E39: qS TOTAL | F39: =SUM($L$5:$L$28) -> 38002.582 | G39: Btu/hr
E40: qL TOTAL | F40: =SUM($M$5:$M$28) -> 15980 | G40: Btu/hr
E41: qT TOTAL | F41: =$N$29 -> 53982.582 | G41: Btu/hr
E42: qW TOTAL | F42: =$T$29 -> 0 | G42: Btu/hr
E43: Q | F43: =F39/(1.08*F33) -> 1407.503 | G43: CFM
E44: CFM | F44: =ROUNDUP(F43,0) -> 1408 | G44: CFM
...

Sheet CREW MESS
A1: SPACE | C1: SPACE NO. | E1: DECK | F1: FRAMES | G1: SPACE TEMP COOLING 78 °F | O1: SPACE TEMP HEATING 70 °F
A2: GALLEY | C2: 5002 | E2: POOP DECK | F2: 16 ~ 24
A3: ADJOINING SPACE | B3: LOAD KEY | C3: INSUL TYPE | D3: U KEY | E3: DIMENSION | F3: AREA [ft2] | G3: T | H3: T0 | I3: ΔT | J3: U | L3: QS | M3: QL | N3: QT | O3: T | P3: T0 | Q3: ΔT | R3: U | T3: QW
J4: COEFF | K4: DIR | R4: COEFF | S4: DIR
A5: OUTDOOR SPACE | B5: 3 | C5: 4"-129 | D5: H | E5: (5.8 m + 6 m) x 2.7 m | F5: =10.7639 * (5.8*2.7 + 6*2.7) -> 342.93785 | G5: 78 | H5: 95 | I5: =H5-G5 -> 17 | J5: 0.063 | K5: =_xlfn.UNICHAR(8596) -> ↔ | L5: =F5*I5*J5 -> 367.28644 | N5: =L5+M5 -> 367.28644 | O5: 70 | P5: 70 | Q5: =O5-P5 -> 0 | T5: =F5*Q5*R5 -> 0
A6: PANTRY | B6: 6 | C6: 3"-94 | D6: H | E6: 4 m x 2.7 m | F6: =10.7639 *(4*2.7) -> 116.25012 | G6: 78 | H6: 105 | I6: =H6-G6 -> 27 | J6: 0.158 | K6: =_xlfn.UNICHAR(8596) -> ↔ | L6: =F6*I6*J6 -> 495.92301 | N6: =L6+M6 -> 495.92301 | O6: 70 | P6: 70 | Q6: =O6-P6 -> 0 | T6: =F6*Q6*R6 -> 0
A7: PASSAGEWAY | B7: 6 | C7: 3"-94 | D7: H | E7: (3 m + 3.5 m + 1.3 m) x 2.7 m | F7: =10.7639 *((3+3.5+1.3)*2.7) -> 226.68773 | G7: 78 | H7: 80 | I7: =H7-G7 -> 2 | J7: 0.158 | K7: =_xlfn.UNICHAR(8596) -> ↔ | L7: =F7*I7*J7 -> 71.633324 | N7: =L7+M7 -> 71.633324 | O7: 70 | P7: 70 | Q7: =O7-P7 -> 0 | T7: =F7*Q7*R7 -> 0
A8: ENGINE ROOM | B8: 2 | C8: 1"-22 | D8: D | F8: =10.7639 * (27.7) -> 298.16003 | G8: 78 | H8: 130 | I8: =H8-G8 -> 52 | J8: 0.199 | K8: =_xlfn.UNICHAR(8595) -> ↓ | L8: =F8*I8*J8 -> 3085.36 | N8: =L8+M8 -> 3085.36 | O8: 70 | P8: 70 | Q8: =O8-P8 -> 0 | T8: =F8*Q8*R8 -> 0
A9: ENGINE WORKSHOP ROOM | B9: 2 | C9: 1"-22 | D9: D | E9: 5.8 m x 1.7 m | F9: =10.7639 * (5.8*1.7) -> 106.13205 | G9: 78 | H9: 110 | I9: =H9-G9 -> 32 | J9: 0.199 | K9: =_xlfn.UNICHAR(8595) -> ↓ | L9: =F9*I9*J9 -> 675.84892 | N9: =L9+M9 -> 675.84892 | O9: 70 | P9: 70 | Q9: =O9-P9 -> 0 | T9: =F9*Q9*R9 -> 0
A10: AIR CONDITION ROOM | B10: 1 | C10: 3"-94 | D10: U | F10: =10.7639 * (27.26) -> 293.42391 | G10: 78 | H10: 110 | I10: =H10-G10 -> 32 | J10: 0.171 | K10: =_xlfn.UNICHAR(8593) -> ↑ | L10: =F10*I10*J10 -> 1605.6157 | N10: =L10+M10 -> 1605.6157 | O10: 70 | P10: 70 | Q10: =O10-P10 -> 0 | T10: =F10*Q10*R10 -> 0
A11: AB 1 CABIN | B11: 1 | C11: 3"-94 | D11: U | F11: =10.7639 * (2.89) -> 31.107671 | G11: 78 | H11: 78 | I11: =H11-G11 -> 0 | J11: 0.171 | K11: =_xlfn.UNICHAR(8593) -> ↑ | L11: =F11*I11*J11 -> 0 | N11: =L11+M11 -> 0 | O11: 70 | P11: 70 | Q11: =O11-P11 -> 0 | T11: =F11*Q11*R11 -> 0
A12: PASSAGEWAY | B12: 1 | C12: 3"-94 | D12: U | F12: =10.7639 * (5.2) -> 55.97228 | G12: 78 | H12: 80 | I12: =H12-G12 -> 2 | J12: 0.171 | K12: =_xlfn.UNICHAR(8593) -> ↑ | L12: =F12*I12*J12 -> 19.14252 | N12: =L12+M12 -> 19.14252 | O12: 70 | P12: 70 | Q12: =O12-P12 -> 0 | T12: =F12*Q12*R12 -> 0
A13: AB 1 TOILET | B13: 1 | C13: 3"-94 | D13: U | F13: =10.7639 * (2.21) -> 23.788219 | G13: 78 | H13: 85 | I13: =H13-G13 -> 7 | J13: 0.171 | K13: =_xlfn.UNICHAR(8593) -> ↑ | L13: =F13*I13*J13 -> 28.474498 | N13: =L13+M13 -> 28.474498 | O13: 70 | P13: 70 | Q13: =O13-P13 -> 0 | T13: =F13*Q13*R13 -> 0
A19: TRANSMISSION SUBTOTAL | N19: =SUM(N5:N17) -> 6349.2844 | T19: =SUM(T5:T17) -> 0
A20: WINDOW | F20: =(10.7639 * (0.6*0.5))*8 -> 25.83336 | L20: =F20*160 -> 4133.3376 | N20: =L20+M20 -> 4133.3376
A21: LIGHTS | B21: 7 | F21: =10.7639 * 37.56 -> 404.29208 | L21: =8*F21 -> 3234.3367 | N21: =L21+M21 -> 3234.3367
N22: =L22+M22 -> 0
N23: =L23+M23 -> 0
A24: EQUIPMENT: Refrigerator (up to 20 cu.ft.) | B24: 8 | L24: 1300 | N24: =L24+M24 -> 1300
A25: FOOD | B25: 8 | L25: =30*21 -> 630 | M25: =30*21 -> 630 | N25: =L25+M25 -> 1260
A26: PERSONNEL | B26: 9 | L26: =315*10 -> 3150 | M26: =485*10 -> 4850 | N26: =L26+M26 -> 8000
A27: INFILTRATION
A29: TOTAL HEAT | N29: =SUM(N19:N28) -> 24276.959 | T29: =SUM(T19:T28) -> 0
A30: TOTAL HEAT | G30: =N29+T29 -> 24276.959
E33: ΔT = | F33: 25 | G33: °F
E34: OCCUPANCY | F34: =15*1 -> 15
E35: Sq. ft. | F35: =$F$21 -> 404.29208 | G35: sq. ft
E36: HEIGHT | F36: =3.28084 * 2.7 -> 8.858268 | G36: ft
E37: VOLUME | F37: =F35*F36 -> 3581.3276 | G37: cb. ft
E38: R of C | F38: =F37/30 -> 119.37759 | G38: CFM
E39: qS TOTAL | F39: =SUM($L$5:$L$28) -> 18796.959 | G39: Btu/hr
E40: qL TOTAL | F40: =SUM($M$5:$M$28) -> 5480 | G40: Btu/hr
E41: qT TOTAL | F41: =$N$29 -> 24276.959 | G41: Btu/hr
E42: qW TOTAL | F42: =$T$29 -> 0 | G42: Btu/hr
E43: Q | F43: =F39/(1.08*F33) -> 696.18365 | G43: CFM
E44: CFM | F44: =ROUNDUP(F43,0) -> 697 | G44: CFM
E45: Q (kW) | F45: =F44*0.0002930711 -> 0.20427056 | G45: kW
E46: SHF | F46: =F39/F41 -> 0.77427156
A47: SYMBOLS | E47: KEY | G47: HEATING AND COOLING LOAD CALCULATION
A48: A = Boundary Area | B48: [ft2] | C48: U = Heat Transfer Coefficient | D48: [Btu/ft2/hr/°F] | E48: 1 = Deck Over | F48: 6 = Inboard Bulkhead
...

Sheet OFFICE MESS
A1: SPACE | C1: SPACE NO. | E1: DECK | F1: FRAMES | G1: SPACE TEMP COOLING 78 °F | O1: SPACE TEMP HEATING 70 °F
A2: OFFICE MESS | C2: 5003 | E2: POOP DECK | F2: 27 ~ 35
A3: ADJOINING SPACE | B3: LOAD KEY | C3: INSUL TYPE | D3: U KEY | E3: DIMENSION | F3: AREA [ft2] | G3: T | H3: T0 | I3: ΔT | J3: U | L3: QS | M3: QL | N3: QT | O3: T | P3: T0 | Q3: ΔT | R3: U | T3: QW
J4: COEFF | K4: DIR | R4: COEFF | S4: DIR
A5: OUTDOOR SPACE | B5: 3 | C5: 4"-129 | D5: H | E5: (5.9 m + 6.4 m) x 2.7 m | F5: =10.7639 * ((5.9*6.4)*2.7) -> 1097.4011 | G5: 78 | H5: 95 | I5: =H5-G5 -> 17 | J5: 0.063 | K5: =_xlfn.UNICHAR(8596) -> ↔ | L5: =F5*I5*J5 -> 1175.3166 | N5: =L5+M5 -> 1175.3166 | O5: 70 | P5: 70 | Q5: =O5-P5 -> 0 | T5: =F5*Q5*R5 -> 0
A6: PASSAGEWAY | B6: 6 | C6: 3"-94 | D6: H | E6: (5.1 m + 1 m + 1.3 m) x 2.7 m | F6: =10.7639 *((5.1 + 1 + 1.3)*2.7) -> 215.06272 | G6: 78 | H6: 80 | I6: =H6-G6 -> 2 | J6: 0.158 | K6: =_xlfn.UNICHAR(8596) -> ↔ | L6: =F6*I6*J6 -> 67.95982 | N6: =L6+M6 -> 67.95982 | O6: 70 | P6: 70 | Q6: =O6-P6 -> 0 | T6: =F6*Q6*R6 -> 0
A7: SHIP OFFICE | B7: 6 | C7: 0"-6 | D7: H | E7: 4.9 m x 2.7 m | F7: =10.7639 *(4.9*2.7) -> 142.4064 | G7: 78 | H7: 78 | I7: =H7-G7 -> 0 | J7: 0.425 | K7: =_xlfn.UNICHAR(8596) -> ↔ | L7: =F7*I7*J7 -> 0 | N7: =L7+M7 -> 0 | O7: 70 | P7: 70 | Q7: =O7-P7 -> 0 | T7: =F7*Q7*R7 -> 0
A8: VALVE CONTROL UNIT ROOM | B8: 2 | C8: 1"-22 | D8: D | F8: =10.7639 * (19.7) -> 212.04883 | G8: 78 | H8: 110 | I8: =H8-G8 -> 32 | J8: 0.199 | K8: =_xlfn.UNICHAR(8595) -> ↓ | L8: =F8*I8*J8 -> 1350.3269 | N8: =L8+M8 -> 1350.3269 | O8: 70 | P8: 70 | Q8: =O8-P8 -> 0 | T8: =F8*Q8*R8 -> 0
A9: ENGINE CONTROL ROOM | B9: 2 | C9: 1"-25 | D9: D | F9: =10.7639 * (16.99) -> 182.87866 | G9: 78 | H9: 78 | I9: =H9-G9 -> 0 | J9: 0.143 | K9: =_xlfn.UNICHAR(8595) -> ↓ | L9: =F9*I9*J9 -> 0 | N9: =L9+M9 -> 0 | O9: 70 | P9: 70 | Q9: =O9-P9 -> 0 | T9: =F9*Q9*R9 -> 0
A10: FITTER CABIN | B10: 1 | C10: 3"-94 | D10: U | F10: =10.7639 * (13.45) -> 144.77445 | G10: 78 | H10: 78 | I10: =H10-G10 -> 0 | J10: 0.171 | K10: =_xlfn.UNICHAR(8593) -> ↑ | L10: =F10*I10*J10 -> 0 | N10: =L10+M10 -> 0 | O10: 70 | P10: 70 | Q10: =O10-P10 -> 0 | T10: =F10*Q10*R10 -> 0
A11: MESSMAN CABIN | B11: 1 | C11: 3"-94 | D11: U | F11: =10.7639 * (12.47) -> 134.22583 | G11: 78 | H11: 78 | I11: =H11-G11 -> 0 | J11: 0.171 | K11: =_xlfn.UNICHAR(8593) -> ↑ | L11: =F11*I11*J11 -> 0 | N11: =L11+M11 -> 0 | O11: 70 | P11: 70 | Q11: =O11-P11 -> 0 | T11: =F11*Q11*R11 -> 0
A12: PASSAGEWAY | B12: 1 | C12: 3"-94 | D12: U | F12: =10.7639 * (5.1) -> 54.89589 | G12: 78 | H12: 80 | I12: =H12-G12 -> 2 | J12: 0.171 | K12: =_xlfn.UNICHAR(8593) -> ↑ | L12: =F12*I12*J12 -> 18.774394 | N12: =L12+M12 -> 18.774394 | O12: 70 | P12: 70 | Q12: =O12-P12 -> 0 | T12: =F12*Q12*R12 -> 0
A13: FITTER TOILET | B13: 1 | C13: 3"-94 | D13: U | E13: 1.6 m x 1.7 m | F13: =10.7639 *(1.6*1.7) -> 29.277808 | G13: 78 | H13: 85 | I13: =H13-G13 -> 7 | J13: 0.171 | K13: =_xlfn.UNICHAR(8593) -> ↑ | L13: =F13*I13*J13 -> 35.045536 | N13: =L13+M13 -> 35.045536 | O13: 70 | P13: 70 | Q13: =O13-P13 -> 0 | T13: =F13*Q13*R13 -> 0
A14: MESMAN TOILET | B14: 1 | C14: 3"-94 | D14: U | E14: 1.6 m x 1.7 m | F14: =10.7639 *(1.6*1.7) -> 29.277808 | G14: 78 | H14: 85 | I14: =H14-G14 -> 7 | J14: 0.171 | K14: =_xlfn.UNICHAR(8593) -> ↑ | L14: =F14*I14*J14 -> 35.045536 | N14: =L14+M14 -> 35.045536 | O14: 70 | P14: 70 | Q14: =O14-P14 -> 0 | T14: =F14*Q14*R14 -> 0
A19: TRANSMISSION SUBTOTAL | N19: =SUM(N5:N17) -> 2682.4688 | T19: =SUM(T5:T17) -> 0
A20: WINDOW | F20: =(10.7639 * (0.6*0.5))*7 -> 22.60419 | L20: =F20*160 -> 3616.6704 | N20: =L20+M20 -> 3616.6704
A21: LIGHTS | B21: 7 | F21: =10.7639 * 36.46 -> 392.45179 | L21: =8*F21 -> 3139.6144 | N21: =L21+M21 -> 3139.6144
N22: =L22+M22 -> 0
N23: =L23+M23 -> 0
N24: =L24+M24 -> 0
A25: FOOD | B25: 8 | L25: =30*10 -> 300 | M25: =30*10 -> 300 | N25: =L25+M25 -> 600
A26: PERSONNEL | B26: 9 | L26: =10*315 -> 3150 | M26: =10*485 -> 4850 | N26: =L26+M26 -> 8000
A27: INFILTRATION
A29: TOTAL HEAT | N29: =SUM(N19:N28) -> 18038.754 | T29: =SUM(T19:T28) -> 0
A30: TOTAL HEAT | G30: =N29+T29 -> 18038.754
E33: ΔT = | F33: 25 | G33: °F
E34: OCCUPANCY | F34: =15*1 -> 15
E35: Sq. ft. | F35: =$F$21 -> 392.45179 | G35: sq. ft
E36: HEIGHT | F36: =3.28084 * 2.7 -> 8.858268 | G36: ft
E37: VOLUME | F37: =F35*F36 -> 3476.4432 | G37: cb. ft
E38: R of C | F38: =F37/30 -> 115.88144 | G38: CFM
E39: qS TOTAL | F39: =SUM($L$5:$L$28) -> 12888.754 | G39: Btu/hr
E40: qL TOTAL | F40: =SUM($M$5:$M$28) -> 5150 | G40: Btu/hr
E41: qT TOTAL | F41: =$N$29 -> 18038.754 | G41: Btu/hr
E42: qW TOTAL | F42: =$T$29 -> 0 | G42: Btu/hr
E43: Q | F43: =F39/(1.08*F33) -> 477.36124 | G43: CFM
E44: CFM | F44: =ROUNDUP(F43,0) -> 478 | G44: CFM
E45: Q (kW) | F45: =F44*0.0002930711 -> 0.14008799 | G45: kW
E46: SHF | F46: =F39/F41 -> 0.71450356
A47: SYMBOLS | E47: KEY | G47: HEATING AND COOLING LOAD CALCULATION
...

Sheet SHIP OFFICE
A1: SPACE | C1: SPACE NO. | E1: DECK | F1: FRAMES | G1: SPACE TEMP COOLING 78 °F | O1: SPACE TEMP HEATING 70 °F
A2: SHIP OFFICE | C2: 5004 | E2: POOP DECK | F2: 28 ~ 35
A3: ADJOINING SPACE | B3: LOAD KEY | C3: INSUL TYPE | D3: U KEY | E3: DIMENSION | F3: AREA [ft2] | G3: T | H3: T0 | I3: ΔT | J3: U | L3: QS | M3: QL | N3: QT | O3: T | P3: T0 | Q3: ΔT | R3: U | T3: QW
J4: COEFF | K4: DIR | R4: COEFF | S4: DIR
A5: OUTDOOR SPACE | B5: 3 | C5: 4"-129 | D5: H | E5: 5.2 m x 2.7 m | F5: =10.7639 * (5.2*2.7) -> 151.12516 | G5: 78 | H5: 95 | I5: =H5-G5 -> 17 | J5: 0.073 | K5: =_xlfn.UNICHAR(8596) -> ↔ | L5: =F5*I5*J5 -> 187.54632 | N5: =L5+M5 -> 187.54632 | O5: 70 | P5: 70 | Q5: =O5-P5 -> 0 | R5: =J5 -> 0.073 | S5: =K5 -> ↔ | T5: =F5*Q5*R5 -> 0
A6: PASSAGEWAY | B6: 6 | C6: 3"-94 | D6: H | E6: (1 m + 1.1 m + 1 m) x 2.7 m | F6: =10.7639 *((1.1+1+1)*2.7) -> 90.093843 | G6: 78 | H6: 80 | I6: =H6-G6 -> 2 | J6: 0.158 | K6: =_xlfn.UNICHAR(8596) -> ↔ | L6: =F6*I6*J6 -> 28.469654 | N6: =L6+M6 -> 28.469654 | O6: 70 | P6: 70 | Q6: =O6-P6 -> 0 | R6: =J6 -> 0.158 | S6: =K6 -> ↔ | T6: =F6*Q6*R6 -> 0
A7: STAIRWAY | B7: 6 | C7: 3"-94 | D7: H | E7: 3.1 m x 2.7 m | F7: =10.7639 *(3.1*2.7) -> 90.093843 | G7: 78 | H7: 80 | I7: =H7-G7 -> 2 | J7: 0.158 | K7: =_xlfn.UNICHAR(8596) -> ↔ | L7: =F7*I7*J7 -> 28.469654 | N7: =L7+M7 -> 28.469654 | O7: 70 | P7: 70 | Q7: =O7-P7 -> 0 | R7: =J7 -> 0.158 | S7: =K7 -> ↔ | T7: =F7*Q7*R7 -> 0
A8: CARGO CONTROL ROOM | B8: 6 | C8: 3"-94 | D8: H | E8: 4.9 m x 2.7 m | F8: =10.7639 * (4.9*2.7) -> 142.4064 | G8: 78 | H8: 78 | I8: =H8-G8 -> 0 | J8: 0.158 | K8: =_xlfn.UNICHAR(8596) -> ↔ | L8: =F8*I8*J8 -> 0 | N8: =L8+M8 -> 0 | O8: 70 | P8: 70 | Q8: =O8-P8 -> 0 | R8: =J8 -> 0.158 | S8: =K8 -> ↔ | T8: =F8*Q8*R8 -> 0
A9: OFFICE MESS | B9: 6 | C9: 0"-6 | D9: H | E9: 4.9 m x 2.7 m | F9: =10.7639 * (4.9*2.7) -> 142.4064 | G9: 78 | H9: 78 | I9: =H9-G9 -> 0 | J9: 0.425 | K9: =_xlfn.UNICHAR(8596) -> ↔ | L9: =F9*I9*J9 -> 0 | N9: =L9+M9 -> 0 | O9: 70 | P9: 70 | Q9: =O9-P9 -> 0 | R9: =J9 -> 0.425 | S9: =K9 -> ↔ | T9: =F9*Q9*R9 -> 0
A10: ENGINE CONTROL ROOM | B10: 2 | C10: 1"-25 | D10: D | F10: =10.7639 * (29.58) -> 318.39616 | G10: 78 | H10: 78 | I10: =H10-G10 -> 0 | J10: 0.161 | K10: =_xlfn.UNICHAR(8595) -> ↓ | L10: =F10*I10*J10 -> 0 | N10: =L10+M10 -> 0 | O10: 70 | P10: 70 | Q10: =O10-P10 -> 0 | R10: =J10 -> 0.161 | S10: =K10 -> ↓ | T10: =F10*Q10*R10 -> 0
A11: MOTORMAN 1 CABIN | B11: 1 | C11: 3"-94 | D11: U | F11: =10.7639 * (9.27) -> 99.781353 | G11: 78 | H11: 78 | I11: =H11-G11 -> 0 | J11: 0.171 | K11: =_xlfn.UNICHAR(8593) -> ↑ | L11: =F11*I11*J11 -> 0 | N11: =L11+M11 -> 0 | O11: 70 | P11: 70 | Q11: =O11-P11 -> 0 | R11: =J11 -> 0.171 | S11: =K11 -> ↑ | T11: =F11*Q11*R11 -> 0
A12: MOTORMAN 1 TOILET | B12: 1 | C12: 3"-94 | D12: U | E12: 0.6 m x 1.7 m | F12: =10.7639 * (0.6*1.7) -> 10.979178 | G12: 78 | H12: 85 | I12: =H12-G12 -> 7 | J12: 0.171 | K12: =_xlfn.UNICHAR(8593) -> ↑ | L12: =F12*I12*J12 -> 13.142076 | N12: =L12+M12 -> 13.142076 | O12: 70 | P12: 70 | Q12: =O12-P12 -> 0 | R12: =J12 -> 0.171 | S12: =K12 -> ↑ | T12: =F12*Q12*R12 -> 0
A13: OS CABIN | B13: 1 | C13: 3"-94 | D13: U | F13: =10.7639 * (12.47) -> 134.22583 | G13: 78 | H13: 78 | I13: =H13-G13 -> 0 | J13: 0.171 | K13: =_xlfn.UNICHAR(8593) -> ↑ | L13: =F13*I13*J13 -> 0 | N13: =L13+M13 -> 0 | O13: 70 | P13: 70 | Q13: =O13-P13 -> 0 | R13: =J13 -> 0.171 | S13: =K13 -> ↑ | T13: =F13*Q13*R13 -> 0
A14: PASSAGEWAY | B14: 1 | C14: 3"-94 | D14: U | F14: =10.7639 * (4.1) -> 44.13199 | G14: 78 | H14: 80 | I14: =H14-G14 -> 2 | J14: 0.171 | K14: =_xlfn.UNICHAR(8593) -> ↑ | L14: =F14*I14*J14 -> 15.093141 | N14: =L14+M14 -> 15.093141 | O14: 70 | P14: 70 | Q14: =O14-P14 -> 0 | R14: =J14 -> 0.171 | S14: =K14 -> ↑ | T14: =F14*Q14*R14 -> 0
A15: OS TOILET | B15: 1 | C15: 3"-94 | D15: U | E15: 1.7 m x 1.6 m | F15: =10.7639 * (1.7*1.6) -> 29.277808 | G15: 78 | H15: 85 | I15: =H15-G15 -> 7 | J15: 0.171 | K15: =_xlfn.UNICHAR(8593) -> ↑ | L15: =F15*I15*J15 -> 35.045536 | N15: =L15+M15 -> 35.045536 | O15: 70 | P15: 70 | Q15: =O15-P15 -> 0 | R15: =J15 -> 0.171 | S15: =K15 -> ↑ | T15: =F15*Q15*R15 -> 0
A19: TRANSMISSION SUBTOTAL | N19: =SUM(N5:N18) -> 307.76638 | T19: =SUM(T5:T18) -> 0
A20: WINDOW | F20: =(10.7639 * (0.6*0.5))*4 -> 12.91668 | L20: =F20*160 -> 2066.6688 | N20: =L20+M20 -> 2066.6688
A21: LIGHTS | B21: 7 | F21: =10.7639 * 29.58 -> 318.39616 | L21: =8*F21 -> 2547.1693 | N21: =L21+M21 -> 2547.1693
A22: EQUIPMENT: Computer | B22: 8 | L22: =3.412 * 150 * 4 * 0.9 -> 1842.48 | N22: =L22+M22 -> 1842.48
A23: EQUIPMENT: Monitor LCD | B23: 8 | L23: =3.412 * 40 * 4 * 0.9 -> 491.328 | N23: =L23+M23 -> 491.328
A24: EQUIPMENT: Printer | B24: 8 | L24: =3.412 * 100 * 1 * 0.9 -> 307.08 | N24: =L24+M24 -> 307.08
A25: EQUIPMENT: Telephone | B25: 8 | L25: =3.412 * 10 * 2 * 0.9 -> 61.416 | N25: =L25+M25 -> 61.416
A26: EQUIPMENT: Chart
A27: PERSONNEL | B27: 9 | L27: =2*315 -> 630 | M27: =2*485 -> 970 | N27: =L27+M27 -> 1600
A28: INFILTRATION
A29: TOTAL HEAT | N29: =SUM(N19:N28) -> 9223.9085 | T29: =SUM(T19:T28) -> 0
A30: TOTAL HEAT | G30: =N29+T29 -> 9223.9085
E33: ΔT = | F33: 25 | G33: °F
E34: OCCUPANCY | F34: =15*1 -> 15
E35: Sq. ft. | F35: =$F$21 -> 318.39616 | G35: sq. ft
E36: HEIGHT | F36: =3.28084 * 2.7 -> 8.858268 | G36: ft
E37: VOLUME | F37: =F35*F36 -> 2820.4385 | G37: cb. ft
E38: R of C | F38: =F37/30 -> 94.014618 | G38: CFM
E39: qS TOTAL | F39: =SUM($L$5:$L$28) -> 8253.9085 | G39: Btu/hr
E40: qL TOTAL | F40: =SUM($M$5:$M$28) -> 970 | G40: Btu/hr
E41: qT TOTAL | F41: =$N$29 -> 9223.9085 | G41: Btu/hr
E42: qW TOTAL | F42: =$T$29 -> 0 | G42: Btu/hr
E43: Q | F43: =F39/(1.08*F33) -> 305.70031 | G43: CFM
E44: CFM | F44: =ROUNDUP(F43,0) -> 306 | G44: CFM
E45: Q (kW) | F45: =F44*0.0002930711 -> 0.089679757 | G45: kW
...

Sheet CARGO CONTROL ROOM
A1: SPACE | C1: SPACE NO. | E1: DECK | F1: FRAMES | G1: SPACE TEMP COOLING 78 °F | O1: SPACE TEMP HEATING 70 °F
A2: CARGO CONTROL ROOM | C2: 5005 | E2: POOP DECK | F2: 28 ~ 35
A3: ADJOINING SPACE | B3: LOAD KEY | C3: INSUL TYPE | D3: U KEY | E3: DIMENSION | F3: AREA [ft2] | G3: T | H3: T0 | I3: ΔT | J3: U | L3: QS | M3: QL | N3: QT | O3: T | P3: T0 | Q3: ΔT | R3: U | T3: QW
J4: COEFF | K4: DIR | R4: COEFF | S4: DIR
A5: OUTDOOR SPACE | B5: 3 | C5: 4"-129 | D5: H | E5: (4.2 m + 5.9 m) x 2.7 m | F5: =10.7639 * ((4.2+5.9)*2.7) -> 293.53155 | G5: 78 | H5: 95 | I5: =H5-G5 -> 17 | J5: 0.073 | K5: =_xlfn.UNICHAR(8596) -> ↔ | L5: =F5*I5*J5 -> 364.27266 | N5: =L5+M5 -> 364.27266 | O5: 70 | P5: 70 | Q5: =O5-P5 -> 0 | T5: =F5*Q5*R5 -> 0
A6: PASSAGEWAY | B6: 6 | C6: 3"-94 | D6: H | E6: (3.1 m + 1 m + 1.1 m) x 2.7 m | F6: =10.7639 *((3.1+1+1.1)*2.7) -> 151.12516 | G6: 78 | H6: 80 | I6: =H6-G6 -> 2 | J6: 0.158 | K6: =_xlfn.UNICHAR(8596) -> ↔ | L6: =F6*I6*J6 -> 47.755549 | N6: =L6+M6 -> 47.755549 | O6: 70 | P6: 70 | Q6: =O6-P6 -> 0 | T6: =F6*Q6*R6 -> 0
A7: SHIP OFFICE | B7: 6 | C7: 3"-94 | D7: H | E7: 4.9 m x 2.7 m | F7: =10.7639 *(4.9*2.7) -> 142.4064 | G7: 78 | H7: 78 | I7: =H7-G7 -> 0 | J7: 0.158 | K7: =_xlfn.UNICHAR(8596) -> ↔ | L7: =F7*I7*J7 -> 0 | N7: =L7+M7 -> 0 | O7: 70 | P7: 70 | Q7: =O7-P7 -> 0 | T7: =F7*Q7*R7 -> 0
A8: ENGINE CONTROL ROOM | B8: 2 | C8: 1"-25 | D8: D | F8: =10.7639 * (15.42) -> 165.97934 | G8: 78 | H8: 78 | I8: =H8-G8 -> 0 | J8: 0.161 | K8: =_xlfn.UNICHAR(8595) -> ↓ | L8: =F8*I8*J8 -> 0 | N8: =L8+M8 -> 0 | O8: 70 | P8: 70 | Q8: =O8-P8 -> 0 | T8: =F8*Q8*R8 -> 0
A9: FIRE FOAM STATION | B9: 2 | C9: 1"-22 | D9: D | E9: 1.4 m x 5.9 m | F9: =10.7639 * (1.4*5.9) -> 88.909814 | G9: 78 | H9: 110 | I9: =H9-G9 -> 32 | J9: 0.199 | K9: =_xlfn.UNICHAR(8595) -> ↓ | L9: =F9*I9*J9 -> 566.1777 | N9: =L9+M9 -> 566.1777 | O9: 70 | P9: 70 | Q9: =O9-P9 -> 0 | T9: =F9*Q9*R9 -> 0
A10: MOTORMAN 2 CABIN | B10: 1 | C10: 3"-94 | D10: U | F10: =10.7639 * (12.96) -> 139.50014 | G10: 78 | H10: 78 | I10: =H10-G10 -> 0 | J10: 0.171 | K10: =_xlfn.UNICHAR(8593) -> ↑ | L10: =F10*I10*J10 -> 0 | N10: =L10+M10 -> 0 | O10: 70 | P10: 70 | Q10: =O10-P10 -> 0 | T10: =F10*Q10*R10 -> 0
A11: MOTORMAN 2 TOILET | B11: 1 | C11: 3"-94 | D11: U | F11: =10.7639 * (2.42) -> 26.048638 | G11: 78 | H11: 85 | I11: =H11-G11 -> 7 | J11: 0.171 | K11: =_xlfn.UNICHAR(8593) -> ↑ | L11: =F11*I11*J11 -> 31.18022 | N11: =L11+M11 -> 31.18022 | O11: 70 | P11: 70 | Q11: =O11-P11 -> 0 | T11: =F11*Q11*R11 -> 0
A12: PASSAGEWAY | B12: 1 | C12: 3"-94 | D12: U | F12: =10.7639 * (3.1) -> 33.36809 | G12: 78 | H12: 80 | I12: =H12-G12 -> 2 | J12: 0.171 | K12: =_xlfn.UNICHAR(8593) -> ↑ | L12: =F12*I12*J12 -> 11.411887 | N12: =L12+M12 -> 11.411887 | O12: 70 | P12: 70 | Q12: =O12-P12 -> 0 | T12: =F12*Q12*R12 -> 0
A13: MOTORMAN 1 CABIN | B13: 1 | C13: 3"-94 | D13: U | E13: 3.2 m x 1 m | F13: =10.7639 * (3.2*1) -> 34.44448 | G13: 78 | H13: 78 | I13: =H13-G13 -> 0 | J13: 0.171 | K13: =_xlfn.UNICHAR(8593) -> ↑ | L13: =F13*I13*J13 -> 0 | N13: =L13+M13 -> 0 | O13: 70 | P13: 70 | Q13: =O13-P13 -> 0 | T13: =F13*Q13*R13 -> 0
A14: MOTORMAN 1 TOILET | B14: 1 | C14: 3"-94 | D14: U | E14: 1.7 m x 1 m | F14: =10.7639 * (1.7*1) -> 18.29863 | G14: 78 | H14: 85 | I14: =H14-G14 -> 7 | J14: 0.171 | K14: =_xlfn.UNICHAR(8593) -> ↑ | L14: =F14*I14*J14 -> 21.90346 | N14: =L14+M14 -> 21.90346 | O14: 70 | P14: 70 | Q14: =O14-P14 -> 0 | T14: =F14*Q14*R14 -> 0
A15: MOTORMAN 2 TOILET VOID | B15: 1 | C15: 3"-94 | D15: U | F15: =10.7639 * (0.3) -> 3.22917 | G15: 78 | H15: 120 | I15: =H15-G15 -> 42 | J15: 0.171 | K15: =_xlfn.UNICHAR(8593) -> ↑ | L15: =F15*I15*J15 -> 23.191899 | N15: =L15+M15 -> 23.191899 | O15: 70 | P15: 70 | Q15: =O15-P15 -> 0 | T15: =F15*Q15*R15 -> 0
A19: TRANSMISSION SUBTOTAL | N19: =SUM(N5:N17) -> 1065.8934 | T19: =SUM(T5:T17) -> 0
A20: SOLAR | F20: =(10.7639 * (0.6*0.5))*4 -> 12.91668 | L20: =F20*160 -> 2066.6688 | N20: =L20+M20 -> 2066.6688
A21: LIGHTS | B21: 7 | F21: =10.7639 * 23.68 -> 254.88915 | L21: =8*F21 -> 2039.1132 | N21: =L21+M21 -> 2039.1132
A22: EQUIPMENT: Cargo control console | B22: 8
A23: EQUIPMENT: Cargo pump control console | B23: 8
A24: EQUIPMENT: Computer | B24: 8
A25: EQUIPMENT: Electrical cabinet | B25: 8
A26: PERSONNEL | B26: 9 | L26: =2*315 -> 630 | M26: =2*485 -> 970 | N26: =L26+M26 -> 1600
A27: INFILTRATION
A29: TOTAL HEAT | N29: =SUM(N19:N28) -> 6771.6754 | T29: =SUM(T19:T28) -> 0
A30: TOTAL HEAT | G30: =N29+T29 -> 6771.6754
E33: ΔT = | F33: 25 | G33: °F
E34: OCCUPANCY | F34: =15*1 -> 15
E35: Sq. ft. | F35: =$F$21 -> 254.88915 | G35: sq. ft
E36: HEIGHT | F36: =3.28084 * 2.7 -> 8.858268 | G36: ft
E37: VOLUME | F37: =F35*F36 -> 2257.8764 | G37: cb. ft
E38: R of C | F38: =F37/30 -> 75.262547 | G38: CFM
E39: qS TOTAL | F39: =SUM($L$5:$L$28) -> 5801.6754 | G39: Btu/hr
E40: qL TOTAL | F40: =SUM($M$5:$M$28) -> 970 | G40: Btu/hr
E41: qT TOTAL | F41: =$N$29 -> 6771.6754 | G41: Btu/hr
E42: qW TOTAL | F42: =$T$29 -> 0 | G42: Btu/hr
E43: Q | F43: =F39/(1.08*F33) -> 214.87687 | G43: CFM
E44: CFM | F44: =ROUNDUP(F43,0) -> 215 | G44: CFM
E45: Q (kW) | F45: =F44*0.0002930711 -> 0.063010286 | G45: kW
E46: SHF | F46: =F39/F41 -> 0.85675628
...

Sheet DECK CHANGE ROOM
A1: SPACE | C1: SPACE NO. | E1: DECK | F1: FRAMES | G1: SPACE TEMP COOLING 78 °F | O1: SPACE TEMP HEATING 70 °F
A2: DECK CHANGE ROOM | C2: 5006 | E2: POOP DECK | F2: 23 ~ 26
A3: ADJOINING SPACE | B3: LOAD KEY | C3: INSUL TYPE | D3: U KEY | E3: DIMENSION | F3: AREA [ft2] | G3: T | H3: T0 | I3: ΔT | J3: U | L3: QS | M3: QL | N3: QT | O3: T | P3: T0 | Q3: ΔT | R3: U | T3: QW
J4: COEFF | K4: DIR | R4: COEFF | S4: DIR
A5: PASSAGEWAY | B5: 6 | C5: 3"-94 | D5: H | E5: 2.6 m x 2.7 m | F5: =10.7639 * (2.8*2.7) -> 81.375084 | G5: 78 | H5: 80 | I5: =H5-G5 -> 2 | J5: 0.158 | K5: =_xlfn.UNICHAR(8596) -> ↔ | L5: =F5*I5*J5 -> 25.714527 | N5: =L5+M5 -> 25.714527 | O5: 70 | P5: 70 | Q5: =O5-P5 -> 0 | T5: =F5*Q5*R5 -> 0
A6: STORE | B6: 6 | C6: 0"-6 | D6: H | E6: 2.4 m x 2.7 m | F6: =10.7639 *(2.2*2.7) -> 63.937566 | G6: 78 | H6: 78 | I6: =H6-G6 -> 0 | J6: 0.425 | K6: =_xlfn.UNICHAR(8596) -> ↔ | L6: =F6*I6*J6 -> 0 | N6: =L6+M6 -> 0 | O6: 70 | P6: 70 | Q6: =O6-P6 -> 0 | T6: =F6*Q6*R6 -> 0
A7: STAIRWAY | B7: 6 | C7: 3"-94 | D7: H | E7: 2.4 m x 2.7 m | F7: =10.7639 *(2.2*2.7) -> 63.937566 | G7: 78 | H7: 80 | I7: =H7-G7 -> 2 | J7: 0.158 | K7: =_xlfn.UNICHAR(8596) -> ↔ | L7: =F7*I7*J7 -> 20.204271 | N7: =L7+M7 -> 20.204271 | O7: 70 | P7: 70 | Q7: =O7-P7 -> 0 | T7: =F7*Q7*R7 -> 0
A8: GALLEY | B8: 6 | C8: 3"-94 | D8: H | E8: 2.6 m x 2.7 m | F8: =10.7639 * (2.8*2.7) -> 81.375084 | G8: 78 | H8: 78 | I8: =H8-G8 -> 0 | J8: 0.158 | K8: =_xlfn.UNICHAR(8596) -> ↔ | L8: =F8*I8*J8 -> 0 | N8: =L8+M8 -> 0 | O8: 70 | P8: 70 | Q8: =O8-P8 -> 0 | T8: =F8*Q8*R8 -> 0
A9: ENGINE ROOM | B9: 2 | C9: 0"-0 | D9: D | E9: 2.6 m x 2.4 m | F9: =10.7639 * (4.78) -> 51.451442 | G9: 78 | H9: 130 | I9: =H9-G9 -> 52 | J9: 0.801 | K9: =_xlfn.UNICHAR(8595) -> ↓ | L9: =F9*I9*J9 -> 2143.0555 | N9: =L9+M9 -> 2143.0555 | O9: 70 | P9: 70 | Q9: =O9-P9 -> 0 | T9: =F9*Q9*R9 -> 0
